[2023-08-01 15:39:52,621] [log.py:228] [log:log_response] [ERROR]- Internal Server Error: /INVGantt/INVGantt-searchByProject/
Traceback (most recent call last):
  File "C:\Python372\mecheck\lib\site-packages\django\core\handlers\exception.py", line 34, in inner
    response = get_response(request)
  File "C:\Python372\mecheck\lib\site-packages\django\core\handlers\base.py", line 126, in _get_response
    response = self.process_exception_by_middleware(e, request)
  File "C:\Python372\mecheck\lib\site-packages\django\core\handlers\base.py", line 124, in _get_response
    response = wrapped_callback(request, *callback_args, **callback_kwargs)
  File "C:\Python372\mecheck\lib\site-packages\django\views\decorators\csrf.py", line 54, in wrapped_view
    return view_func(*args, **kwargs)
  File "C:\djangoproject\Reliability_Row_data\INVGantt\views.py", line 498, in INVGantt_searchByProject
    print(datetime.datetime.strftime(starttime, "Y%-m%"),datetime.datetime.strftime(endtime, "Y%-m%"))
TypeError: descriptor 'strftime' requires a 'datetime.date' object but received a 'str'
[2023-08-01 15:39:52,623] [basehttp.py:154] [basehttp:log_message] [ERROR]- "POST /INVGantt/INVGantt-searchByProject/ HTTP/1.1" 500 108178
[2023-08-01 15:44:42,828] [log.py:228] [log:log_response] [ERROR]- Internal Server Error: /INVGantt/INVGantt-searchByProject/
Traceback (most recent call last):
  File "C:\Python372\mecheck\lib\site-packages\django\core\handlers\exception.py", line 34, in inner
    response = get_response(request)
  File "C:\Python372\mecheck\lib\site-packages\django\core\handlers\base.py", line 126, in _get_response
    response = self.process_exception_by_middleware(e, request)
  File "C:\Python372\mecheck\lib\site-packages\django\core\handlers\base.py", line 124, in _get_response
    response = wrapped_callback(request, *callback_args, **callback_kwargs)
  File "C:\Python372\mecheck\lib\site-packages\django\views\decorators\csrf.py", line 54, in wrapped_view
    return view_func(*args, **kwargs)
  File "C:\djangoproject\Reliability_Row_data\INVGantt\views.py", line 498, in INVGantt_searchByProject
    print(datetime.datetime.strptime(starttime, "Y%-m%"),datetime.datetime.strptime(endtime, "Y%-m%"))
  File "C:\Python372\lib\_strptime.py", line 577, in _strptime_datetime
    tt, fraction, gmtoff_fraction = _strptime(data_string, format)
  File "C:\Python372\lib\_strptime.py", line 351, in _strptime
    (bad_directive, format)) from None
ValueError: '-' is a bad directive in format 'Y%-m%'
[2023-08-01 15:44:42,843] [basehttp.py:154] [basehttp:log_message] [ERROR]- "POST /INVGantt/INVGantt-searchByProject/ HTTP/1.1" 500 134532
[2023-08-01 15:46:12,016] [log.py:228] [log:log_response] [ERROR]- Internal Server Error: /INVGantt/INVGantt-searchByProject/
Traceback (most recent call last):
  File "C:\Python372\mecheck\lib\site-packages\django\core\handlers\exception.py", line 34, in inner
    response = get_response(request)
  File "C:\Python372\mecheck\lib\site-packages\django\core\handlers\base.py", line 126, in _get_response
    response = self.process_exception_by_middleware(e, request)
  File "C:\Python372\mecheck\lib\site-packages\django\core\handlers\base.py", line 124, in _get_response
    response = wrapped_callback(request, *callback_args, **callback_kwargs)
  File "C:\Python372\mecheck\lib\site-packages\django\views\decorators\csrf.py", line 54, in wrapped_view
    return view_func(*args, **kwargs)
  File "C:\djangoproject\Reliability_Row_data\INVGantt\views.py", line 498, in INVGantt_searchByProject
    print(datetime.datetime.strptime(starttime, "%Y-%m-%d"),datetime.datetime.strptime(endtime, "%Y-%m-%d"))
  File "C:\Python372\lib\_strptime.py", line 577, in _strptime_datetime
    tt, fraction, gmtoff_fraction = _strptime(data_string, format)
  File "C:\Python372\lib\_strptime.py", line 359, in _strptime
    (data_string, format))
ValueError: time data '2020-6' does not match format '%Y-%m-%d'
[2023-08-01 15:46:12,033] [basehttp.py:154] [basehttp:log_message] [ERROR]- "POST /INVGantt/INVGantt-searchByProject/ HTTP/1.1" 500 116891
[2023-08-01 16:07:11,165] [log.py:228] [log:log_response] [ERROR]- Internal Server Error: /INVGantt/INVGantt-searchByProject/
Traceback (most recent call last):
  File "C:\Python372\mecheck\lib\site-packages\django\core\handlers\exception.py", line 34, in inner
    response = get_response(request)
  File "C:\Python372\mecheck\lib\site-packages\django\core\handlers\base.py", line 126, in _get_response
    response = self.process_exception_by_middleware(e, request)
  File "C:\Python372\mecheck\lib\site-packages\django\core\handlers\base.py", line 124, in _get_response
    response = wrapped_callback(request, *callback_args, **callback_kwargs)
  File "C:\Python372\mecheck\lib\site-packages\django\views\decorators\csrf.py", line 54, in wrapped_view
    return view_func(*args, **kwargs)
  File "C:\djangoproject\Reliability_Row_data\INVGantt\views.py", line 507, in INVGantt_searchByProject
    start_date = datetime.strptime(starttime_data, '%Y-%m')
AttributeError: module 'datetime' has no attribute 'strptime'
[2023-08-01 16:07:11,181] [basehttp.py:154] [basehttp:log_message] [ERROR]- "POST /INVGantt/INVGantt-searchByProject/ HTTP/1.1" 500 108370
[2023-08-01 16:07:59,496] [log.py:228] [log:log_response] [ERROR]- Internal Server Error: /INVGantt/INVGantt-searchByProject/
Traceback (most recent call last):
  File "C:\Python372\mecheck\lib\site-packages\django\core\handlers\exception.py", line 34, in inner
    response = get_response(request)
  File "C:\Python372\mecheck\lib\site-packages\django\core\handlers\base.py", line 126, in _get_response
    response = self.process_exception_by_middleware(e, request)
  File "C:\Python372\mecheck\lib\site-packages\django\core\handlers\base.py", line 124, in _get_response
    response = wrapped_callback(request, *callback_args, **callback_kwargs)
  File "C:\Python372\mecheck\lib\site-packages\django\views\decorators\csrf.py", line 54, in wrapped_view
    return view_func(*args, **kwargs)
  File "C:\djangoproject\Reliability_Row_data\INVGantt\views.py", line 508, in INVGantt_searchByProject
    start_date = datetime.strptime(starttime_data, '%Y-%m')
AttributeError: module 'datetime' has no attribute 'strptime'
[2023-08-01 16:07:59,508] [basehttp.py:154] [basehttp:log_message] [ERROR]- "POST /INVGantt/INVGantt-searchByProject/ HTTP/1.1" 500 108277
[2023-08-01 16:09:34,390] [log.py:228] [log:log_response] [ERROR]- Internal Server Error: /INVGantt/INVGantt-searchByProject/
Traceback (most recent call last):
  File "C:\Python372\mecheck\lib\site-packages\django\core\handlers\exception.py", line 34, in inner
    response = get_response(request)
  File "C:\Python372\mecheck\lib\site-packages\django\core\handlers\base.py", line 126, in _get_response
    response = self.process_exception_by_middleware(e, request)
  File "C:\Python372\mecheck\lib\site-packages\django\core\handlers\base.py", line 124, in _get_response
    response = wrapped_callback(request, *callback_args, **callback_kwargs)
  File "C:\Python372\mecheck\lib\site-packages\django\views\decorators\csrf.py", line 54, in wrapped_view
    return view_func(*args, **kwargs)
  File "C:\djangoproject\Reliability_Row_data\INVGantt\views.py", line 521, in INVGantt_searchByProject
    cur_date = datetime.strptime(f'{year_tmp}-{month_tmp}', '%Y-%m')
AttributeError: module 'datetime' has no attribute 'strptime'
[2023-08-01 16:09:34,403] [basehttp.py:154] [basehttp:log_message] [ERROR]- "POST /INVGantt/INVGantt-searchByProject/ HTTP/1.1" 500 110160
[2023-08-01 16:36:33,517] [log.py:228] [log:log_response] [ERROR]- Internal Server Error: /INVGantt/INVGantt-searchByProject/
Traceback (most recent call last):
  File "C:\Python372\mecheck\lib\site-packages\django\core\handlers\exception.py", line 34, in inner
    response = get_response(request)
  File "C:\Python372\mecheck\lib\site-packages\django\core\handlers\base.py", line 126, in _get_response
    response = self.process_exception_by_middleware(e, request)
  File "C:\Python372\mecheck\lib\site-packages\django\core\handlers\base.py", line 124, in _get_response
    response = wrapped_callback(request, *callback_args, **callback_kwargs)
  File "C:\Python372\mecheck\lib\site-packages\django\views\decorators\csrf.py", line 54, in wrapped_view
    return view_func(*args, **kwargs)
  File "C:\djangoproject\Reliability_Row_data\INVGantt\views.py", line 529, in INVGantt_searchByProject
    print(cur_ym_num = [cur_ym, ])
TypeError: 'cur_ym_num' is an invalid keyword argument for print()
[2023-08-01 16:36:33,520] [basehttp.py:154] [basehttp:log_message] [ERROR]- "POST /INVGantt/INVGantt-searchByProject/ HTTP/1.1" 500 110539
