[2021-12-09 09:09:56,230] [UserIP.py:89] [UserIP:process_response] [CRITICAL]- 系统错误
[2021-12-09 09:10:21,925] [UserIP.py:89] [UserIP:process_response] [CRITICAL]- 系统错误
[2021-12-09 09:13:27,823] [UserIP.py:89] [UserIP:process_response] [CRITICAL]- 系统错误
[2021-12-09 09:14:17,132] [log.py:228] [log:log_response] [ERROR]- Internal Server Error: /CQM/CQM_upload/
Traceback (most recent call last):
  File "C:\Python372\mecheck\lib\site-packages\django\core\handlers\exception.py", line 34, in inner
    response = get_response(request)
  File "C:\Python372\mecheck\lib\site-packages\django\core\handlers\base.py", line 126, in _get_response
    response = self.process_exception_by_middleware(e, request)
  File "C:\Python372\mecheck\lib\site-packages\django\core\handlers\base.py", line 124, in _get_response
    response = wrapped_callback(request, *callback_args, **callback_kwargs)
  File "C:\Python372\mecheck\lib\site-packages\django\views\decorators\csrf.py", line 54, in wrapped_view
    return view_func(*args, **kwargs)
  File "C:\djangoproject\Reliability_Row_data\CQM\views.py", line 568, in CQM_upload
    CQM.objects.create(**updatedic)
  File "C:\Python372\mecheck\lib\site-packages\django\db\models\manager.py", line 82, in manager_method
    return getattr(self.get_queryset(), name)(*args, **kwargs)
  File "C:\Python372\mecheck\lib\site-packages\django\db\models\query.py", line 411, in create
    obj = self.model(**kwargs)
  File "C:\Python372\mecheck\lib\site-packages\django\db\models\base.py", line 467, in __init__
    _setattr(self, field.name, rel_obj)
  File "C:\Python372\mecheck\lib\site-packages\django\db\models\fields\related_descriptors.py", line 210, in __set__
    self.field.remote_field.model._meta.object_name,
ValueError: Cannot assign "''": "CQM.Projectinfo" must be a "CQMProject" instance.
[2021-12-09 09:14:17,134] [UserIP.py:89] [UserIP:process_response] [CRITICAL]- 系统错误
[2021-12-09 09:14:17,135] [basehttp.py:154] [basehttp:log_message] [ERROR]- "POST /CQM/CQM_upload/ HTTP/1.1" 500 29760
[2021-12-09 09:16:55,029] [log.py:228] [log:log_response] [ERROR]- Internal Server Error: /CQM/CQM_upload/
Traceback (most recent call last):
  File "C:\Python372\mecheck\lib\site-packages\django\core\handlers\exception.py", line 34, in inner
    response = get_response(request)
  File "C:\Python372\mecheck\lib\site-packages\django\core\handlers\base.py", line 126, in _get_response
    response = self.process_exception_by_middleware(e, request)
  File "C:\Python372\mecheck\lib\site-packages\django\core\handlers\base.py", line 124, in _get_response
    response = wrapped_callback(request, *callback_args, **callback_kwargs)
  File "C:\Python372\mecheck\lib\site-packages\django\views\decorators\csrf.py", line 54, in wrapped_view
    return view_func(*args, **kwargs)
  File "C:\djangoproject\Reliability_Row_data\CQM\views.py", line 569, in CQM_upload
    CQM.objects.create(**updatedic)
  File "C:\Python372\mecheck\lib\site-packages\django\db\models\manager.py", line 82, in manager_method
    return getattr(self.get_queryset(), name)(*args, **kwargs)
  File "C:\Python372\mecheck\lib\site-packages\django\db\models\query.py", line 411, in create
    obj = self.model(**kwargs)
  File "C:\Python372\mecheck\lib\site-packages\django\db\models\base.py", line 467, in __init__
    _setattr(self, field.name, rel_obj)
  File "C:\Python372\mecheck\lib\site-packages\django\db\models\fields\related_descriptors.py", line 210, in __set__
    self.field.remote_field.model._meta.object_name,
ValueError: Cannot assign "''": "CQM.Projectinfo" must be a "CQMProject" instance.
[2021-12-09 09:16:55,031] [UserIP.py:89] [UserIP:process_response] [CRITICAL]- 系统错误
[2021-12-09 09:16:55,031] [basehttp.py:154] [basehttp:log_message] [ERROR]- "POST /CQM/CQM_upload/ HTTP/1.1" 500 29760
[2021-12-09 09:18:07,007] [log.py:228] [log:log_response] [ERROR]- Internal Server Error: /CQM/CQM_upload/
Traceback (most recent call last):
  File "C:\Python372\mecheck\lib\site-packages\django\core\handlers\exception.py", line 34, in inner
    response = get_response(request)
  File "C:\Python372\mecheck\lib\site-packages\django\core\handlers\base.py", line 126, in _get_response
    response = self.process_exception_by_middleware(e, request)
  File "C:\Python372\mecheck\lib\site-packages\django\core\handlers\base.py", line 124, in _get_response
    response = wrapped_callback(request, *callback_args, **callback_kwargs)
  File "C:\Python372\mecheck\lib\site-packages\django\views\decorators\csrf.py", line 54, in wrapped_view
    return view_func(*args, **kwargs)
  File "C:\djangoproject\Reliability_Row_data\CQM\views.py", line 570, in CQM_upload
    CQM.objects.create(**updatedic)
  File "C:\Python372\mecheck\lib\site-packages\django\db\models\manager.py", line 82, in manager_method
    return getattr(self.get_queryset(), name)(*args, **kwargs)
  File "C:\Python372\mecheck\lib\site-packages\django\db\models\query.py", line 411, in create
    obj = self.model(**kwargs)
  File "C:\Python372\mecheck\lib\site-packages\django\db\models\base.py", line 467, in __init__
    _setattr(self, field.name, rel_obj)
  File "C:\Python372\mecheck\lib\site-packages\django\db\models\fields\related_descriptors.py", line 210, in __set__
    self.field.remote_field.model._meta.object_name,
ValueError: Cannot assign "''": "CQM.Projectinfo" must be a "CQMProject" instance.
[2021-12-09 09:18:07,009] [UserIP.py:89] [UserIP:process_response] [CRITICAL]- 系统错误
[2021-12-09 09:18:07,010] [basehttp.py:154] [basehttp:log_message] [ERROR]- "POST /CQM/CQM_upload/ HTTP/1.1" 500 29760
[2021-12-09 10:48:02,035] [UserIP.py:89] [UserIP:process_response] [CRITICAL]- 系统错误
[2021-12-10 08:07:43,636] [UserIP.py:89] [UserIP:process_response] [CRITICAL]- 系统错误
[2021-12-10 08:55:10,496] [log.py:228] [log:log_response] [ERROR]- Internal Server Error: /AutoResult/AutoItem_edit/
Traceback (most recent call last):
  File "C:\Python372\mecheck\lib\site-packages\django\core\handlers\exception.py", line 34, in inner
    response = get_response(request)
  File "C:\Python372\mecheck\lib\site-packages\django\core\handlers\base.py", line 126, in _get_response
    response = self.process_exception_by_middleware(e, request)
  File "C:\Python372\mecheck\lib\site-packages\django\core\handlers\base.py", line 124, in _get_response
    response = wrapped_callback(request, *callback_args, **callback_kwargs)
  File "C:\Python372\mecheck\lib\site-packages\django\views\decorators\csrf.py", line 54, in wrapped_view
    return view_func(*args, **kwargs)
  File "C:\djangoproject\Reliability_Row_data\AutoResult\views.py", line 131, in AutoItem_edit
    DevCtgry = responseData['DevCtgry']
KeyError: 'DevCtgry'
[2021-12-10 08:55:10,499] [UserIP.py:89] [UserIP:process_response] [CRITICAL]- 系统错误
[2021-12-10 08:55:10,499] [basehttp.py:154] [basehttp:log_message] [ERROR]- "POST /AutoResult/AutoItem_edit/ HTTP/1.1" 500 90904
