[2020-08-27 12:19:49,944] [log.py:228] [log:log_response] [ERROR]- Internal Server Error: /login/
Traceback (most recent call last):
  File "C:\Python372\mecheck\lib\site-packages\django\core\handlers\exception.py", line 34, in inner
    response = get_response(request)
  File "C:\Python372\mecheck\lib\site-packages\django\core\handlers\base.py", line 126, in _get_response
    response = self.process_exception_by_middleware(e, request)
  File "C:\Python372\mecheck\lib\site-packages\django\core\handlers\base.py", line 124, in _get_response
    response = wrapped_callback(request, *callback_args, **callback_kwargs)
  File "C:\Python372\mecheck\lib\site-packages\django\views\decorators\csrf.py", line 54, in wrapped_view
    return view_func(*args, **kwargs)
  File "C:\djangoproject\Reliability_Row_data\app01\views.py", line 178, in login
    print(request.user.type)
  File "C:\Python372\mecheck\lib\site-packages\django\utils\functional.py", line 214, in inner
    return func(self._wrapped, *args)
AttributeError: 'AnonymousUser' object has no attribute 'type'
[2020-08-27 12:19:49,946] [basehttp.py:154] [basehttp:log_message] [ERROR]- "POST /login/ HTTP/1.1" 500 82431
[2020-08-27 13:33:03,950] [log.py:228] [log:log_response] [ERROR]- Internal Server Error: /index/
Traceback (most recent call last):
  File "C:\Python372\mecheck\lib\site-packages\django\core\handlers\exception.py", line 34, in inner
    response = get_response(request)
  File "C:\Python372\mecheck\lib\site-packages\django\core\handlers\base.py", line 126, in _get_response
    response = self.process_exception_by_middleware(e, request)
  File "C:\Python372\mecheck\lib\site-packages\django\core\handlers\base.py", line 124, in _get_response
    response = wrapped_callback(request, *callback_args, **callback_kwargs)
  File "C:\djangoproject\Reliability_Row_data\app01\views.py", line 234, in index
    print(request.user.type)
  File "C:\Python372\mecheck\lib\site-packages\django\utils\functional.py", line 214, in inner
    return func(self._wrapped, *args)
AttributeError: 'AnonymousUser' object has no attribute 'type'
[2020-08-27 13:33:03,952] [basehttp.py:154] [basehttp:log_message] [ERROR]- "GET /index/ HTTP/1.1" 500 79853
