[2020-06-24 14:16:18,709] [log.py:228] [log:log_response] [ERROR]- Internal Server Error: /TestPlanSW/TestPlanSW-search/
Traceback (most recent call last):
  File "C:\Python372\mecheck\lib\site-packages\django\core\handlers\exception.py", line 34, in inner
    response = get_response(request)
  File "C:\Python372\mecheck\lib\site-packages\django\core\handlers\base.py", line 126, in _get_response
    response = self.process_exception_by_middleware(e, request)
  File "C:\Python372\mecheck\lib\site-packages\django\core\handlers\base.py", line 124, in _get_response
    response = wrapped_callback(request, *callback_args, **callback_kwargs)
  File "C:\djangoproject\Reliability_Row_data\TestPlanSW\views.py", line 4776, in TestPlanSW_search
    Sum('BaseTime')), 0)
TypeError: type dict doesn't define __round__ method
[2020-06-24 14:16:18,714] [basehttp.py:154] [basehttp:log_message] [ERROR]- "GET /TestPlanSW/TestPlanSW-search/?action=getContent&customer=C38(NB)&project=FLY00_Peppa&phase=14&category= HTTP/1.1" 500 109629
[2020-06-24 14:16:23,918] [log.py:228] [log:log_response] [ERROR]- Internal Server Error: /TestPlanSW/TestPlanSW-search/
Traceback (most recent call last):
  File "C:\Python372\mecheck\lib\site-packages\django\core\handlers\exception.py", line 34, in inner
    response = get_response(request)
  File "C:\Python372\mecheck\lib\site-packages\django\core\handlers\base.py", line 126, in _get_response
    response = self.process_exception_by_middleware(e, request)
  File "C:\Python372\mecheck\lib\site-packages\django\core\handlers\base.py", line 124, in _get_response
    response = wrapped_callback(request, *callback_args, **callback_kwargs)
  File "C:\djangoproject\Reliability_Row_data\TestPlanSW\views.py", line 4776, in TestPlanSW_search
    Sum('BaseTime')), 0)
TypeError: type dict doesn't define __round__ method
[2020-06-24 14:16:23,919] [basehttp.py:154] [basehttp:log_message] [ERROR]- "GET /TestPlanSW/TestPlanSW-search/?action=getContent&customer=C38(NB)&project=FLY00_Peppa&phase=14&category= HTTP/1.1" 500 109629
[2020-06-24 14:19:31,594] [log.py:228] [log:log_response] [ERROR]- Internal Server Error: /TestPlanSW/TestPlanSW-search/
Traceback (most recent call last):
  File "C:\Python372\mecheck\lib\site-packages\django\core\handlers\exception.py", line 34, in inner
    response = get_response(request)
  File "C:\Python372\mecheck\lib\site-packages\django\core\handlers\base.py", line 126, in _get_response
    response = self.process_exception_by_middleware(e, request)
  File "C:\Python372\mecheck\lib\site-packages\django\core\handlers\base.py", line 124, in _get_response
    response = wrapped_callback(request, *callback_args, **callback_kwargs)
  File "C:\djangoproject\Reliability_Row_data\TestPlanSW\views.py", line 4775, in TestPlanSW_search
    basetime_Total = round(TestPlanSW.objects.filter(Projectinfo=ProjectSum).aggregate(Sum('BaseTime'))/60, 0)
TypeError: unsupported operand type(s) for /: 'dict' and 'int'
[2020-06-24 14:19:31,600] [basehttp.py:154] [basehttp:log_message] [ERROR]- "GET /TestPlanSW/TestPlanSW-search/?action=getContent&customer=C38(NB)&project=FLY00_Peppa&phase=14&category= HTTP/1.1" 500 109826
[2020-06-24 14:22:27,752] [log.py:228] [log:log_response] [ERROR]- Internal Server Error: /TestPlanSW/TestPlanSW-search/
Traceback (most recent call last):
  File "C:\Python372\mecheck\lib\site-packages\django\core\handlers\exception.py", line 34, in inner
    response = get_response(request)
  File "C:\Python372\mecheck\lib\site-packages\django\core\handlers\base.py", line 126, in _get_response
    response = self.process_exception_by_middleware(e, request)
  File "C:\Python372\mecheck\lib\site-packages\django\core\handlers\base.py", line 124, in _get_response
    response = wrapped_callback(request, *callback_args, **callback_kwargs)
  File "C:\djangoproject\Reliability_Row_data\TestPlanSW\views.py", line 4783, in TestPlanSW_search
    Sum('ConfigLeverageTime'))['ConfigLeverageTime__sum']/60, 0)
TypeError: unsupported operand type(s) for /: 'NoneType' and 'int'
[2020-06-24 14:22:27,757] [basehttp.py:154] [basehttp:log_message] [ERROR]- "GET /TestPlanSW/TestPlanSW-search/?action=getContent&customer=C38(NB)&project=FLY00_Peppa&phase=14&category= HTTP/1.1" 500 110188
[2020-06-24 14:37:37,711] [log.py:228] [log:log_response] [ERROR]- Internal Server Error: /TestPlanSW/TestPlanSW-search/
Traceback (most recent call last):
  File "C:\Python372\mecheck\lib\site-packages\django\core\handlers\exception.py", line 34, in inner
    response = get_response(request)
  File "C:\Python372\mecheck\lib\site-packages\django\core\handlers\base.py", line 126, in _get_response
    response = self.process_exception_by_middleware(e, request)
  File "C:\Python372\mecheck\lib\site-packages\django\core\handlers\base.py", line 124, in _get_response
    response = wrapped_callback(request, *callback_args, **callback_kwargs)
  File "C:\djangoproject\Reliability_Row_data\TestPlanSW\views.py", line 5335, in TestPlanSW_search
    if ATOsuminre["ConfigRetestTime__sum"]:
KeyError: 'ConfigRetestTime__sum'
[2020-06-24 14:37:37,715] [basehttp.py:154] [basehttp:log_message] [ERROR]- "POST /TestPlanSW/TestPlanSW-search/ HTTP/1.1" 500 82062
