[2023-07-12 09:21:50,896] [log.py:228] [log:log_response] [ERROR]- Internal Server Error: /ABOTestPlan/ABOTestPlan_edit/
Traceback (most recent call last):
  File "C:\Python372\mecheck\lib\site-packages\django\core\handlers\exception.py", line 34, in inner
    response = get_response(request)
  File "C:\Python372\mecheck\lib\site-packages\django\core\handlers\base.py", line 126, in _get_response
    response = self.process_exception_by_middleware(e, request)
  File "C:\Python372\mecheck\lib\site-packages\django\core\handlers\base.py", line 124, in _get_response
    response = wrapped_callback(request, *callback_args, **callback_kwargs)
  File "C:\Python372\mecheck\lib\site-packages\django\views\decorators\csrf.py", line 54, in wrapped_view
    return view_func(*args, **kwargs)
  File "C:\djangoproject\Reliability_Row_data\ABOTestPlan\views.py", line 531, in ABOTestPlan_edit
    return HttpResponse(json.dumps(data), content_type="application/json")
  File "C:\Python372\lib\json\__init__.py", line 231, in dumps
    return _default_encoder.encode(obj)
  File "C:\Python372\lib\json\encoder.py", line 199, in encode
    chunks = self.iterencode(o, _one_shot=True)
  File "C:\Python372\lib\json\encoder.py", line 257, in iterencode
    return _iterencode(o, 0)
  File "C:\Python372\lib\json\encoder.py", line 179, in default
    raise TypeError(f'Object of type {o.__class__.__name__} '
TypeError: Object of type AttributeError is not JSON serializable
[2023-07-12 09:21:50,898] [basehttp.py:154] [basehttp:log_message] [ERROR]- "POST /ABOTestPlan/ABOTestPlan_edit/ HTTP/1.1" 500 102192
[2023-07-12 09:23:59,869] [log.py:228] [log:log_response] [ERROR]- Internal Server Error: /ABOTestPlan/ABOTestPlan_edit/
Traceback (most recent call last):
  File "C:\Python372\mecheck\lib\site-packages\django\core\handlers\exception.py", line 34, in inner
    response = get_response(request)
  File "C:\Python372\mecheck\lib\site-packages\django\core\handlers\base.py", line 126, in _get_response
    response = self.process_exception_by_middleware(e, request)
  File "C:\Python372\mecheck\lib\site-packages\django\core\handlers\base.py", line 124, in _get_response
    response = wrapped_callback(request, *callback_args, **callback_kwargs)
  File "C:\Python372\mecheck\lib\site-packages\django\views\decorators\csrf.py", line 54, in wrapped_view
    return view_func(*args, **kwargs)
  File "C:\djangoproject\Reliability_Row_data\ABOTestPlan\views.py", line 531, in ABOTestPlan_edit
    return HttpResponse(json.dumps(data), content_type="application/json")
  File "C:\Python372\lib\json\__init__.py", line 231, in dumps
    return _default_encoder.encode(obj)
  File "C:\Python372\lib\json\encoder.py", line 199, in encode
    chunks = self.iterencode(o, _one_shot=True)
  File "C:\Python372\lib\json\encoder.py", line 257, in iterencode
    return _iterencode(o, 0)
  File "C:\Python372\lib\json\encoder.py", line 179, in default
    raise TypeError(f'Object of type {o.__class__.__name__} '
TypeError: Object of type AttributeError is not JSON serializable
[2023-07-12 09:23:59,871] [basehttp.py:154] [basehttp:log_message] [ERROR]- "POST /ABOTestPlan/ABOTestPlan_edit/ HTTP/1.1" 500 102192
[2023-07-12 09:27:00,852] [log.py:228] [log:log_response] [ERROR]- Internal Server Error: /ABOTestPlan/ABOTestPlan_edit/
Traceback (most recent call last):
  File "C:\Python372\mecheck\lib\site-packages\django\core\handlers\exception.py", line 34, in inner
    response = get_response(request)
  File "C:\Python372\mecheck\lib\site-packages\django\core\handlers\base.py", line 126, in _get_response
    response = self.process_exception_by_middleware(e, request)
  File "C:\Python372\mecheck\lib\site-packages\django\core\handlers\base.py", line 124, in _get_response
    response = wrapped_callback(request, *callback_args, **callback_kwargs)
  File "C:\Python372\mecheck\lib\site-packages\django\views\decorators\csrf.py", line 54, in wrapped_view
    return view_func(*args, **kwargs)
  File "C:\djangoproject\Reliability_Row_data\ABOTestPlan\views.py", line 533, in ABOTestPlan_edit
    return HttpResponse(json.dumps(data), content_type="application/json")
  File "C:\Python372\lib\json\__init__.py", line 231, in dumps
    return _default_encoder.encode(obj)
  File "C:\Python372\lib\json\encoder.py", line 199, in encode
    chunks = self.iterencode(o, _one_shot=True)
  File "C:\Python372\lib\json\encoder.py", line 257, in iterencode
    return _iterencode(o, 0)
  File "C:\Python372\lib\json\encoder.py", line 179, in default
    raise TypeError(f'Object of type {o.__class__.__name__} '
TypeError: Object of type ValueError is not JSON serializable
[2023-07-12 09:27:00,854] [basehttp.py:154] [basehttp:log_message] [ERROR]- "POST /ABOTestPlan/ABOTestPlan_edit/ HTTP/1.1" 500 102000
[2023-07-12 09:31:15,097] [log.py:228] [log:log_response] [ERROR]- Internal Server Error: /ABOTestPlan/ABOTestPlan_edit/
Traceback (most recent call last):
  File "C:\Python372\mecheck\lib\site-packages\django\core\handlers\exception.py", line 34, in inner
    response = get_response(request)
  File "C:\Python372\mecheck\lib\site-packages\django\core\handlers\base.py", line 126, in _get_response
    response = self.process_exception_by_middleware(e, request)
  File "C:\Python372\mecheck\lib\site-packages\django\core\handlers\base.py", line 124, in _get_response
    response = wrapped_callback(request, *callback_args, **callback_kwargs)
  File "C:\Python372\mecheck\lib\site-packages\django\views\decorators\csrf.py", line 54, in wrapped_view
    return view_func(*args, **kwargs)
  File "C:\djangoproject\Reliability_Row_data\ABOTestPlan\views.py", line 535, in ABOTestPlan_edit
    return HttpResponse(json.dumps(data), content_type="application/json")
  File "C:\Python372\lib\json\__init__.py", line 231, in dumps
    return _default_encoder.encode(obj)
  File "C:\Python372\lib\json\encoder.py", line 199, in encode
    chunks = self.iterencode(o, _one_shot=True)
  File "C:\Python372\lib\json\encoder.py", line 257, in iterencode
    return _iterencode(o, 0)
  File "C:\Python372\lib\json\encoder.py", line 179, in default
    raise TypeError(f'Object of type {o.__class__.__name__} '
TypeError: Object of type AttributeError is not JSON serializable
[2023-07-12 09:31:15,100] [basehttp.py:154] [basehttp:log_message] [ERROR]- "POST /ABOTestPlan/ABOTestPlan_edit/ HTTP/1.1" 500 102232
[2023-07-12 09:32:17,278] [log.py:228] [log:log_response] [ERROR]- Internal Server Error: /ABOTestPlan/ABOTestPlan_edit/
Traceback (most recent call last):
  File "C:\Python372\mecheck\lib\site-packages\django\core\handlers\exception.py", line 34, in inner
    response = get_response(request)
  File "C:\Python372\mecheck\lib\site-packages\django\core\handlers\base.py", line 126, in _get_response
    response = self.process_exception_by_middleware(e, request)
  File "C:\Python372\mecheck\lib\site-packages\django\core\handlers\base.py", line 124, in _get_response
    response = wrapped_callback(request, *callback_args, **callback_kwargs)
  File "C:\Python372\mecheck\lib\site-packages\django\views\decorators\csrf.py", line 54, in wrapped_view
    return view_func(*args, **kwargs)
  File "C:\djangoproject\Reliability_Row_data\ABOTestPlan\views.py", line 536, in ABOTestPlan_edit
    return HttpResponse(json.dumps(data), content_type="application/json")
  File "C:\Python372\lib\json\__init__.py", line 231, in dumps
    return _default_encoder.encode(obj)
  File "C:\Python372\lib\json\encoder.py", line 199, in encode
    chunks = self.iterencode(o, _one_shot=True)
  File "C:\Python372\lib\json\encoder.py", line 257, in iterencode
    return _iterencode(o, 0)
  File "C:\Python372\lib\json\encoder.py", line 179, in default
    raise TypeError(f'Object of type {o.__class__.__name__} '
TypeError: Object of type AttributeError is not JSON serializable
[2023-07-12 09:32:17,280] [basehttp.py:154] [basehttp:log_message] [ERROR]- "POST /ABOTestPlan/ABOTestPlan_edit/ HTTP/1.1" 500 102232
[2023-07-12 09:32:28,339] [log.py:228] [log:log_response] [ERROR]- Internal Server Error: /ABOTestPlan/ABOTestPlan_edit/
Traceback (most recent call last):
  File "C:\Python372\mecheck\lib\site-packages\django\core\handlers\exception.py", line 34, in inner
    response = get_response(request)
  File "C:\Python372\mecheck\lib\site-packages\django\core\handlers\base.py", line 126, in _get_response
    response = self.process_exception_by_middleware(e, request)
  File "C:\Python372\mecheck\lib\site-packages\django\core\handlers\base.py", line 124, in _get_response
    response = wrapped_callback(request, *callback_args, **callback_kwargs)
  File "C:\Python372\mecheck\lib\site-packages\django\views\decorators\csrf.py", line 54, in wrapped_view
    return view_func(*args, **kwargs)
  File "C:\djangoproject\Reliability_Row_data\ABOTestPlan\views.py", line 536, in ABOTestPlan_edit
    return HttpResponse(json.dumps(data), content_type="application/json")
  File "C:\Python372\lib\json\__init__.py", line 231, in dumps
    return _default_encoder.encode(obj)
  File "C:\Python372\lib\json\encoder.py", line 199, in encode
    chunks = self.iterencode(o, _one_shot=True)
  File "C:\Python372\lib\json\encoder.py", line 257, in iterencode
    return _iterencode(o, 0)
  File "C:\Python372\lib\json\encoder.py", line 179, in default
    raise TypeError(f'Object of type {o.__class__.__name__} '
TypeError: Object of type AttributeError is not JSON serializable
[2023-07-12 09:32:28,340] [basehttp.py:154] [basehttp:log_message] [ERROR]- "POST /ABOTestPlan/ABOTestPlan_edit/ HTTP/1.1" 500 102232
[2023-07-12 09:33:07,438] [log.py:228] [log:log_response] [ERROR]- Internal Server Error: /ABOTestPlan/ABOTestPlan_edit/
Traceback (most recent call last):
  File "C:\Python372\mecheck\lib\site-packages\django\core\handlers\exception.py", line 34, in inner
    response = get_response(request)
  File "C:\Python372\mecheck\lib\site-packages\django\core\handlers\base.py", line 126, in _get_response
    response = self.process_exception_by_middleware(e, request)
  File "C:\Python372\mecheck\lib\site-packages\django\core\handlers\base.py", line 124, in _get_response
    response = wrapped_callback(request, *callback_args, **callback_kwargs)
  File "C:\Python372\mecheck\lib\site-packages\django\views\decorators\csrf.py", line 54, in wrapped_view
    return view_func(*args, **kwargs)
  File "C:\djangoproject\Reliability_Row_data\ABOTestPlan\views.py", line 536, in ABOTestPlan_edit
    return HttpResponse(json.dumps(data), content_type="application/json")
  File "C:\Python372\lib\json\__init__.py", line 231, in dumps
    return _default_encoder.encode(obj)
  File "C:\Python372\lib\json\encoder.py", line 199, in encode
    chunks = self.iterencode(o, _one_shot=True)
  File "C:\Python372\lib\json\encoder.py", line 257, in iterencode
    return _iterencode(o, 0)
  File "C:\Python372\lib\json\encoder.py", line 179, in default
    raise TypeError(f'Object of type {o.__class__.__name__} '
TypeError: Object of type AttributeError is not JSON serializable
[2023-07-12 09:33:07,441] [basehttp.py:154] [basehttp:log_message] [ERROR]- "POST /ABOTestPlan/ABOTestPlan_edit/ HTTP/1.1" 500 102232
[2023-07-12 09:41:01,081] [log.py:228] [log:log_response] [ERROR]- Internal Server Error: /ABOTestPlan/ABOTestPlan_edit/
Traceback (most recent call last):
  File "C:\Python372\mecheck\lib\site-packages\django\core\handlers\exception.py", line 34, in inner
    response = get_response(request)
  File "C:\Python372\mecheck\lib\site-packages\django\core\handlers\base.py", line 126, in _get_response
    response = self.process_exception_by_middleware(e, request)
  File "C:\Python372\mecheck\lib\site-packages\django\core\handlers\base.py", line 124, in _get_response
    response = wrapped_callback(request, *callback_args, **callback_kwargs)
  File "C:\Python372\mecheck\lib\site-packages\django\views\decorators\csrf.py", line 54, in wrapped_view
    return view_func(*args, **kwargs)
  File "C:\djangoproject\Reliability_Row_data\ABOTestPlan\views.py", line 538, in ABOTestPlan_edit
    return HttpResponse(json.dumps(data), content_type="application/json")
  File "C:\Python372\lib\json\__init__.py", line 231, in dumps
    return _default_encoder.encode(obj)
  File "C:\Python372\lib\json\encoder.py", line 199, in encode
    chunks = self.iterencode(o, _one_shot=True)
  File "C:\Python372\lib\json\encoder.py", line 257, in iterencode
    return _iterencode(o, 0)
  File "C:\Python372\lib\json\encoder.py", line 179, in default
    raise TypeError(f'Object of type {o.__class__.__name__} '
TypeError: Object of type AttributeError is not JSON serializable
[2023-07-12 09:41:01,083] [basehttp.py:154] [basehttp:log_message] [ERROR]- "POST /ABOTestPlan/ABOTestPlan_edit/ HTTP/1.1" 500 102192
[2023-07-12 09:41:29,296] [log.py:228] [log:log_response] [ERROR]- Internal Server Error: /ABOTestPlan/ABOTestPlan_edit/
Traceback (most recent call last):
  File "C:\Python372\mecheck\lib\site-packages\django\core\handlers\exception.py", line 34, in inner
    response = get_response(request)
  File "C:\Python372\mecheck\lib\site-packages\django\core\handlers\base.py", line 126, in _get_response
    response = self.process_exception_by_middleware(e, request)
  File "C:\Python372\mecheck\lib\site-packages\django\core\handlers\base.py", line 124, in _get_response
    response = wrapped_callback(request, *callback_args, **callback_kwargs)
  File "C:\Python372\mecheck\lib\site-packages\django\views\decorators\csrf.py", line 54, in wrapped_view
    return view_func(*args, **kwargs)
  File "C:\djangoproject\Reliability_Row_data\ABOTestPlan\views.py", line 538, in ABOTestPlan_edit
    return HttpResponse(json.dumps(data), content_type="application/json")
  File "C:\Python372\lib\json\__init__.py", line 231, in dumps
    return _default_encoder.encode(obj)
  File "C:\Python372\lib\json\encoder.py", line 199, in encode
    chunks = self.iterencode(o, _one_shot=True)
  File "C:\Python372\lib\json\encoder.py", line 257, in iterencode
    return _iterencode(o, 0)
  File "C:\Python372\lib\json\encoder.py", line 179, in default
    raise TypeError(f'Object of type {o.__class__.__name__} '
TypeError: Object of type AttributeError is not JSON serializable
[2023-07-12 09:41:29,298] [basehttp.py:154] [basehttp:log_message] [ERROR]- "POST /ABOTestPlan/ABOTestPlan_edit/ HTTP/1.1" 500 102184
[2023-07-12 10:30:10,955] [log.py:228] [log:log_response] [ERROR]- Internal Server Error: /ABOTestPlan/ABOTestPlan_edit/
Traceback (most recent call last):
  File "C:\Python372\mecheck\lib\site-packages\django\core\handlers\exception.py", line 34, in inner
    response = get_response(request)
  File "C:\Python372\mecheck\lib\site-packages\django\core\handlers\base.py", line 126, in _get_response
    response = self.process_exception_by_middleware(e, request)
  File "C:\Python372\mecheck\lib\site-packages\django\core\handlers\base.py", line 124, in _get_response
    response = wrapped_callback(request, *callback_args, **callback_kwargs)
  File "C:\Python372\mecheck\lib\site-packages\django\views\decorators\csrf.py", line 54, in wrapped_view
    return view_func(*args, **kwargs)
  File "C:\djangoproject\Reliability_Row_data\ABOTestPlan\views.py", line 591, in ABOTestPlan_edit
    return HttpResponse(json.dumps(data), content_type="application/json")
  File "C:\Python372\lib\json\__init__.py", line 231, in dumps
    return _default_encoder.encode(obj)
  File "C:\Python372\lib\json\encoder.py", line 199, in encode
    chunks = self.iterencode(o, _one_shot=True)
  File "C:\Python372\lib\json\encoder.py", line 257, in iterencode
    return _iterencode(o, 0)
  File "C:\Python372\lib\json\encoder.py", line 179, in default
    raise TypeError(f'Object of type {o.__class__.__name__} '
TypeError: Object of type com_error is not JSON serializable
[2023-07-12 10:30:10,957] [basehttp.py:154] [basehttp:log_message] [ERROR]- "POST /ABOTestPlan/ABOTestPlan_edit/ HTTP/1.1" 500 102100
[2023-07-12 10:31:11,880] [log.py:228] [log:log_response] [ERROR]- Internal Server Error: /ABOTestPlan/ABOTestPlan_edit/
Traceback (most recent call last):
  File "C:\Python372\mecheck\lib\site-packages\win32com\client\dynamic.py", line 86, in _GetGoodDispatch
    IDispatch = pythoncom.connect(IDispatch)
pywintypes.com_error: (-2147221008, '尚未调用 CoInitialize。', None, None)

During handling of the above exception, another exception occurred:

Traceback (most recent call last):
  File "C:\Python372\mecheck\lib\site-packages\django\core\handlers\exception.py", line 34, in inner
    response = get_response(request)
  File "C:\Python372\mecheck\lib\site-packages\django\core\handlers\base.py", line 126, in _get_response
    response = self.process_exception_by_middleware(e, request)
  File "C:\Python372\mecheck\lib\site-packages\django\core\handlers\base.py", line 124, in _get_response
    response = wrapped_callback(request, *callback_args, **callback_kwargs)
  File "C:\Python372\mecheck\lib\site-packages\django\views\decorators\csrf.py", line 54, in wrapped_view
    return view_func(*args, **kwargs)
  File "C:\djangoproject\Reliability_Row_data\ABOTestPlan\views.py", line 537, in ABOTestPlan_edit
    excel_dic = read_excel(filepath)[0]
  File "C:\djangoproject\Reliability_Row_data\ABOTestPlan\views.py", line 159, in read_excel
    just_open(src_file)
  File "C:\djangoproject\Reliability_Row_data\ABOTestPlan\views.py", line 27, in just_open
    xlApp = Dispatch("Excel.Application")
  File "C:\Python372\mecheck\lib\site-packages\win32com\client\__init__.py", line 117, in Dispatch
    dispatch, userName = dynamic._GetGoodDispatchAndUserName(dispatch, userName, clsctx)
  File "C:\Python372\mecheck\lib\site-packages\win32com\client\dynamic.py", line 106, in _GetGoodDispatchAndUserName
    return (_GetGoodDispatch(IDispatch, clsctx), userName)
  File "C:\Python372\mecheck\lib\site-packages\win32com\client\dynamic.py", line 89, in _GetGoodDispatch
    IDispatch, None, clsctx, pythoncom.IID_IDispatch
pywintypes.com_error: (-2147221008, '尚未调用 CoInitialize。', None, None)
[2023-07-12 10:31:11,882] [basehttp.py:154] [basehttp:log_message] [ERROR]- "POST /ABOTestPlan/ABOTestPlan_edit/ HTTP/1.1" 500 126789
[2023-07-12 11:21:57,219] [log.py:228] [log:log_response] [ERROR]- Internal Server Error: /ABOTestPlan/ABOTestPlan_edit/
Traceback (most recent call last):
  File "C:\Python372\mecheck\lib\site-packages\django\core\handlers\exception.py", line 34, in inner
    response = get_response(request)
  File "C:\Python372\mecheck\lib\site-packages\django\core\handlers\base.py", line 126, in _get_response
    response = self.process_exception_by_middleware(e, request)
  File "C:\Python372\mecheck\lib\site-packages\django\core\handlers\base.py", line 124, in _get_response
    response = wrapped_callback(request, *callback_args, **callback_kwargs)
  File "C:\Python372\mecheck\lib\site-packages\django\views\decorators\csrf.py", line 54, in wrapped_view
    return view_func(*args, **kwargs)
  File "C:\djangoproject\Reliability_Row_data\ABOTestPlan\views.py", line 580, in ABOTestPlan_edit
    save_exel(folder_path_Sys,uploaddata,upload_zhushi,upload_zhushi_delete, filepath,auther)
  File "C:\djangoproject\Reliability_Row_data\ABOTestPlan\views.py", line 412, in save_exel
    cell.height = 50
AttributeError: 'Cell' object has no attribute 'height'
[2023-07-12 11:21:57,239] [basehttp.py:154] [basehttp:log_message] [ERROR]- "POST /ABOTestPlan/ABOTestPlan_edit/ HTTP/1.1" 500 101801
[2023-07-12 11:31:55,248] [log.py:228] [log:log_response] [ERROR]- Internal Server Error: /ABOTestPlan/ABOTestPlan_edit/
Traceback (most recent call last):
  File "C:\Python372\mecheck\lib\site-packages\django\core\handlers\exception.py", line 34, in inner
    response = get_response(request)
  File "C:\Python372\mecheck\lib\site-packages\django\core\handlers\base.py", line 126, in _get_response
    response = self.process_exception_by_middleware(e, request)
  File "C:\Python372\mecheck\lib\site-packages\django\core\handlers\base.py", line 124, in _get_response
    response = wrapped_callback(request, *callback_args, **callback_kwargs)
  File "C:\Python372\mecheck\lib\site-packages\django\views\decorators\csrf.py", line 54, in wrapped_view
    return view_func(*args, **kwargs)
  File "C:\djangoproject\Reliability_Row_data\ABOTestPlan\views.py", line 577, in ABOTestPlan_edit
    save_exel(folder_path_Sys,uploaddata,upload_zhushi,upload_zhushi_delete, filepath,auther)
  File "C:\djangoproject\Reliability_Row_data\ABOTestPlan\views.py", line 417, in save_exel
    shutil.copy(src_file, folder_path_Sys)
  File "C:\Python372\lib\shutil.py", line 245, in copy
    copyfile(src, dst, follow_symlinks=follow_symlinks)
  File "C:\Python372\lib\shutil.py", line 121, in copyfile
    with open(dst, 'wb') as fdst:
PermissionError: [Errno 13] Permission denied: 'c:/media/ABOTestPlanSys/T88_ProjectName1_B Phase_Compatibility/ME-ENV005_All.xlsx'
[2023-07-12 11:31:55,258] [basehttp.py:154] [basehttp:log_message] [ERROR]- "POST /ABOTestPlan/ABOTestPlan_edit/ HTTP/1.1" 500 105630
[2023-07-12 11:36:31,182] [log.py:228] [log:log_response] [ERROR]- Internal Server Error: /ABOTestPlan/ABOTestPlan_edit/
Traceback (most recent call last):
  File "C:\Python372\mecheck\lib\site-packages\django\core\handlers\exception.py", line 34, in inner
    response = get_response(request)
  File "C:\Python372\mecheck\lib\site-packages\django\core\handlers\base.py", line 126, in _get_response
    response = self.process_exception_by_middleware(e, request)
  File "C:\Python372\mecheck\lib\site-packages\django\core\handlers\base.py", line 124, in _get_response
    response = wrapped_callback(request, *callback_args, **callback_kwargs)
  File "C:\Python372\mecheck\lib\site-packages\django\views\decorators\csrf.py", line 54, in wrapped_view
    return view_func(*args, **kwargs)
  File "C:\djangoproject\Reliability_Row_data\ABOTestPlan\views.py", line 599, in ABOTestPlan_edit
    return HttpResponse(json.dumps(data), content_type="application/json")
  File "C:\Python372\lib\json\__init__.py", line 231, in dumps
    return _default_encoder.encode(obj)
  File "C:\Python372\lib\json\encoder.py", line 199, in encode
    chunks = self.iterencode(o, _one_shot=True)
  File "C:\Python372\lib\json\encoder.py", line 257, in iterencode
    return _iterencode(o, 0)
  File "C:\Python372\lib\json\encoder.py", line 179, in default
    raise TypeError(f'Object of type {o.__class__.__name__} '
TypeError: Object of type com_error is not JSON serializable
[2023-07-12 11:36:31,184] [basehttp.py:154] [basehttp:log_message] [ERROR]- "POST /ABOTestPlan/ABOTestPlan_edit/ HTTP/1.1" 500 102916
[2023-07-12 16:27:39,668] [basehttp.py:154] [basehttp:log_message] [ERROR]- "POST /ABOTestPlan/ABOTestPlan_edit/ HTTP/1.1" 500 59
