[2022-06-02 16:25:54,614] [UserIP.py:89] [UserIP:process_response] [CRITICAL]- 系统错误
[2022-06-02 16:49:17,115] [UserIP.py:89] [UserIP:process_response] [CRITICAL]- 系统错误
[2022-06-02 16:58:17,815] [log.py:228] [log:log_response] [ERROR]- Internal Server Error: /CQM/CQMSeriv/
Traceback (most recent call last):
  File "C:\Python372\mecheck\lib\site-packages\django\core\handlers\exception.py", line 34, in inner
    response = get_response(request)
  File "C:\Python372\mecheck\lib\site-packages\django\core\handlers\base.py", line 126, in _get_response
    response = self.process_exception_by_middleware(e, request)
  File "C:\Python372\mecheck\lib\site-packages\django\core\handlers\base.py", line 124, in _get_response
    response = wrapped_callback(request, *callback_args, **callback_kwargs)
  File "C:\Python372\mecheck\lib\site-packages\django\views\decorators\csrf.py", line 54, in wrapped_view
    return view_func(*args, **kwargs)
  File "C:\Python372\mecheck\lib\site-packages\django\views\generic\base.py", line 68, in view
    return self.dispatch(request, *args, **kwargs)
  File "C:\Python372\mecheck\lib\site-packages\rest_framework\views.py", line 505, in dispatch
    response = self.handle_exception(exc)
  File "C:\Python372\mecheck\lib\site-packages\rest_framework\views.py", line 465, in handle_exception
    self.raise_uncaught_exception(exc)
  File "C:\Python372\mecheck\lib\site-packages\rest_framework\views.py", line 476, in raise_uncaught_exception
    raise exc
  File "C:\Python372\mecheck\lib\site-packages\rest_framework\views.py", line 493, in dispatch
    self.initial(request, *args, **kwargs)
  File "C:\Python372\mecheck\lib\site-packages\rest_framework\views.py", line 411, in initial
    self.check_permissions(request)
  File "C:\Python372\mecheck\lib\site-packages\rest_framework\views.py", line 332, in check_permissions
    if not permission.has_permission(request, self):
  File "C:\djangoproject\Reliability_Row_data\INVGantt\permissions.py", line 38, in has_permission
    groups = request.user.role.all()
  File "C:\Python372\mecheck\lib\site-packages\django\utils\functional.py", line 214, in inner
    return func(self._wrapped, *args)
AttributeError: 'User' object has no attribute 'role'
[2022-06-02 16:58:17,817] [basehttp.py:154] [basehttp:log_message] [ERROR]- "GET /CQM/CQMSeriv/?Project=GLMS1 HTTP/1.1" 500 116174
[2022-06-02 16:59:23,718] [log.py:228] [log:log_response] [ERROR]- Internal Server Error: /CQM/CQMSeriv/
Traceback (most recent call last):
  File "C:\Python372\mecheck\lib\site-packages\django\core\handlers\exception.py", line 34, in inner
    response = get_response(request)
  File "C:\Python372\mecheck\lib\site-packages\django\core\handlers\base.py", line 126, in _get_response
    response = self.process_exception_by_middleware(e, request)
  File "C:\Python372\mecheck\lib\site-packages\django\core\handlers\base.py", line 124, in _get_response
    response = wrapped_callback(request, *callback_args, **callback_kwargs)
  File "C:\Python372\mecheck\lib\site-packages\django\views\decorators\csrf.py", line 54, in wrapped_view
    return view_func(*args, **kwargs)
  File "C:\Python372\mecheck\lib\site-packages\django\views\generic\base.py", line 68, in view
    return self.dispatch(request, *args, **kwargs)
  File "C:\Python372\mecheck\lib\site-packages\rest_framework\views.py", line 505, in dispatch
    response = self.handle_exception(exc)
  File "C:\Python372\mecheck\lib\site-packages\rest_framework\views.py", line 465, in handle_exception
    self.raise_uncaught_exception(exc)
  File "C:\Python372\mecheck\lib\site-packages\rest_framework\views.py", line 476, in raise_uncaught_exception
    raise exc
  File "C:\Python372\mecheck\lib\site-packages\rest_framework\views.py", line 493, in dispatch
    self.initial(request, *args, **kwargs)
  File "C:\Python372\mecheck\lib\site-packages\rest_framework\views.py", line 411, in initial
    self.check_permissions(request)
  File "C:\Python372\mecheck\lib\site-packages\rest_framework\views.py", line 332, in check_permissions
    if not permission.has_permission(request, self):
  File "C:\djangoproject\Reliability_Row_data\INVGantt\permissions.py", line 38, in has_permission
    groups = request.user.role.all()
  File "C:\Python372\mecheck\lib\site-packages\django\utils\functional.py", line 214, in inner
    return func(self._wrapped, *args)
AttributeError: 'User' object has no attribute 'role'
[2022-06-02 16:59:23,720] [basehttp.py:154] [basehttp:log_message] [ERROR]- "GET /CQM/CQMSeriv/ HTTP/1.1" 500 115637
[2022-06-02 17:06:04,497] [log.py:228] [log:log_response] [ERROR]- Internal Server Error: /CQM/CQMSeriv/
Traceback (most recent call last):
  File "C:\Python372\mecheck\lib\site-packages\django\core\handlers\exception.py", line 34, in inner
    response = get_response(request)
  File "C:\Python372\mecheck\lib\site-packages\django\core\handlers\base.py", line 126, in _get_response
    response = self.process_exception_by_middleware(e, request)
  File "C:\Python372\mecheck\lib\site-packages\django\core\handlers\base.py", line 124, in _get_response
    response = wrapped_callback(request, *callback_args, **callback_kwargs)
  File "C:\Python372\mecheck\lib\site-packages\django\views\decorators\csrf.py", line 54, in wrapped_view
    return view_func(*args, **kwargs)
  File "C:\Python372\mecheck\lib\site-packages\django\views\generic\base.py", line 68, in view
    return self.dispatch(request, *args, **kwargs)
  File "C:\Python372\mecheck\lib\site-packages\rest_framework\views.py", line 505, in dispatch
    response = self.handle_exception(exc)
  File "C:\Python372\mecheck\lib\site-packages\rest_framework\views.py", line 465, in handle_exception
    self.raise_uncaught_exception(exc)
  File "C:\Python372\mecheck\lib\site-packages\rest_framework\views.py", line 476, in raise_uncaught_exception
    raise exc
  File "C:\Python372\mecheck\lib\site-packages\rest_framework\views.py", line 493, in dispatch
    self.initial(request, *args, **kwargs)
  File "C:\Python372\mecheck\lib\site-packages\rest_framework\views.py", line 411, in initial
    self.check_permissions(request)
  File "C:\Python372\mecheck\lib\site-packages\rest_framework\views.py", line 332, in check_permissions
    if not permission.has_permission(request, self):
  File "C:\Python372\mecheck\lib\site-packages\rest_framework\permissions.py", line 146, in has_permission
    return bool(request.user and request.user.is_staff)
AttributeError: 'UserInfo' object has no attribute 'is_staff'
[2022-06-02 17:06:04,500] [basehttp.py:154] [basehttp:log_message] [ERROR]- "GET /CQM/CQMSeriv/?username=API_CQM&password=12345678&Project=GLMS1 HTTP/1.1" 500 112558
[2022-06-02 17:07:57,904] [UserIP.py:89] [UserIP:process_response] [CRITICAL]- 系统错误
[2022-06-06 13:30:56,062] [UserIP.py:89] [UserIP:process_response] [CRITICAL]- 系统错误
[2022-06-08 09:10:37,384] [UserIP.py:89] [UserIP:process_response] [CRITICAL]- 系统错误
[2022-06-08 09:10:47,157] [UserIP.py:89] [UserIP:process_response] [CRITICAL]- 系统错误
[2022-06-08 09:11:28,197] [UserIP.py:89] [UserIP:process_response] [CRITICAL]- 系统错误
