[2021-05-28 16:03:07,819] [log.py:228] [log:log_response] [ERROR]- Internal Server Error: /PersonalInfo/Summary3/
Traceback (most recent call last):
  File "C:\Python372\mecheck\lib\site-packages\django\core\handlers\exception.py", line 34, in inner
    response = get_response(request)
  File "C:\Python372\mecheck\lib\site-packages\django\core\handlers\base.py", line 126, in _get_response
    response = self.process_exception_by_middleware(e, request)
  File "C:\Python372\mecheck\lib\site-packages\django\core\handlers\base.py", line 124, in _get_response
    response = wrapped_callback(request, *callback_args, **callback_kwargs)
  File "C:\Python372\mecheck\lib\site-packages\django\views\decorators\csrf.py", line 54, in wrapped_view
    return view_func(*args, **kwargs)
  File "C:\djangoproject\Reliability_Row_data\PersonalInfo\views.py", line 6150, in Summary3
    for Per in PersonalInfo.objects.filter(Status__in=["離職"], QuitDate__range=Search_Endperiod):
  File "C:\Python372\mecheck\lib\site-packages\django\db\models\query.py", line 268, in __iter__
    self._fetch_all()
  File "C:\Python372\mecheck\lib\site-packages\django\db\models\query.py", line 1186, in _fetch_all
    self._result_cache = list(self._iterable_class(self))
  File "C:\Python372\mecheck\lib\site-packages\django\db\models\query.py", line 54, in __iter__
    results = compiler.execute_sql(chunked_fetch=self.chunked_fetch, chunk_size=self.chunk_size)
  File "C:\Python372\mecheck\lib\site-packages\django\db\models\sql\compiler.py", line 1052, in execute_sql
    sql, params = self.as_sql()
  File "C:\Python372\mecheck\lib\site-packages\django\db\models\sql\compiler.py", line 464, in as_sql
    where, w_params = self.compile(self.where) if self.where is not None else ("", [])
  File "C:\Python372\mecheck\lib\site-packages\django\db\models\sql\compiler.py", line 390, in compile
    sql, params = node.as_sql(self, self.connection)
  File "C:\Python372\mecheck\lib\site-packages\django\db\models\sql\where.py", line 81, in as_sql
    sql, params = compiler.compile(child)
  File "C:\Python372\mecheck\lib\site-packages\django\db\models\sql\compiler.py", line 390, in compile
    sql, params = node.as_sql(self, self.connection)
  File "C:\Python372\mecheck\lib\site-packages\django\db\models\lookups.py", line 163, in as_sql
    rhs_sql, rhs_params = self.process_rhs(compiler, connection)
  File "C:\Python372\mecheck\lib\site-packages\django\db\models\lookups.py", line 218, in process_rhs
    return self.batch_process_rhs(compiler, connection)
  File "C:\Python372\mecheck\lib\site-packages\django\db\models\lookups.py", line 238, in batch_process_rhs
    for sql, param in zip(*pre_processed)
ValueError: not enough values to unpack (expected 2, got 0)
[2021-05-28 16:03:07,830] [basehttp.py:154] [basehttp:log_message] [ERROR]- "POST /PersonalInfo/Summary3/ HTTP/1.1" 500 135003
[2021-05-28 16:04:01,031] [log.py:228] [log:log_response] [ERROR]- Internal Server Error: /PersonalInfo/Summary3/
Traceback (most recent call last):
  File "C:\Python372\mecheck\lib\site-packages\django\core\handlers\exception.py", line 34, in inner
    response = get_response(request)
  File "C:\Python372\mecheck\lib\site-packages\django\core\handlers\base.py", line 126, in _get_response
    response = self.process_exception_by_middleware(e, request)
  File "C:\Python372\mecheck\lib\site-packages\django\core\handlers\base.py", line 124, in _get_response
    response = wrapped_callback(request, *callback_args, **callback_kwargs)
  File "C:\Python372\mecheck\lib\site-packages\django\views\decorators\csrf.py", line 54, in wrapped_view
    return view_func(*args, **kwargs)
  File "C:\djangoproject\Reliability_Row_data\PersonalInfo\views.py", line 6151, in Summary3
    for Per in PersonalInfo.objects.filter(Status__in=["離職"], QuitDate__range=Search_Endperiod):
  File "C:\Python372\mecheck\lib\site-packages\django\db\models\query.py", line 268, in __iter__
    self._fetch_all()
  File "C:\Python372\mecheck\lib\site-packages\django\db\models\query.py", line 1186, in _fetch_all
    self._result_cache = list(self._iterable_class(self))
  File "C:\Python372\mecheck\lib\site-packages\django\db\models\query.py", line 54, in __iter__
    results = compiler.execute_sql(chunked_fetch=self.chunked_fetch, chunk_size=self.chunk_size)
  File "C:\Python372\mecheck\lib\site-packages\django\db\models\sql\compiler.py", line 1052, in execute_sql
    sql, params = self.as_sql()
  File "C:\Python372\mecheck\lib\site-packages\django\db\models\sql\compiler.py", line 464, in as_sql
    where, w_params = self.compile(self.where) if self.where is not None else ("", [])
  File "C:\Python372\mecheck\lib\site-packages\django\db\models\sql\compiler.py", line 390, in compile
    sql, params = node.as_sql(self, self.connection)
  File "C:\Python372\mecheck\lib\site-packages\django\db\models\sql\where.py", line 81, in as_sql
    sql, params = compiler.compile(child)
  File "C:\Python372\mecheck\lib\site-packages\django\db\models\sql\compiler.py", line 390, in compile
    sql, params = node.as_sql(self, self.connection)
  File "C:\Python372\mecheck\lib\site-packages\django\db\models\lookups.py", line 163, in as_sql
    rhs_sql, rhs_params = self.process_rhs(compiler, connection)
  File "C:\Python372\mecheck\lib\site-packages\django\db\models\lookups.py", line 218, in process_rhs
    return self.batch_process_rhs(compiler, connection)
  File "C:\Python372\mecheck\lib\site-packages\django\db\models\lookups.py", line 238, in batch_process_rhs
    for sql, param in zip(*pre_processed)
ValueError: not enough values to unpack (expected 2, got 0)
[2021-05-28 16:04:01,038] [basehttp.py:154] [basehttp:log_message] [ERROR]- "POST /PersonalInfo/Summary3/ HTTP/1.1" 500 135038
[2021-05-28 16:05:03,845] [log.py:228] [log:log_response] [ERROR]- Internal Server Error: /PersonalInfo/Summary3/
Traceback (most recent call last):
  File "C:\Python372\mecheck\lib\site-packages\django\core\handlers\exception.py", line 34, in inner
    response = get_response(request)
  File "C:\Python372\mecheck\lib\site-packages\django\core\handlers\base.py", line 126, in _get_response
    response = self.process_exception_by_middleware(e, request)
  File "C:\Python372\mecheck\lib\site-packages\django\core\handlers\base.py", line 124, in _get_response
    response = wrapped_callback(request, *callback_args, **callback_kwargs)
  File "C:\Python372\mecheck\lib\site-packages\django\views\decorators\csrf.py", line 54, in wrapped_view
    return view_func(*args, **kwargs)
  File "C:\djangoproject\Reliability_Row_data\PersonalInfo\views.py", line 6151, in Summary3
    for Per in PersonalInfo.objects.filter(Status__in=["離職"], QuitDate__range=Search_Endperiod):
  File "C:\Python372\mecheck\lib\site-packages\django\db\models\query.py", line 268, in __iter__
    self._fetch_all()
  File "C:\Python372\mecheck\lib\site-packages\django\db\models\query.py", line 1186, in _fetch_all
    self._result_cache = list(self._iterable_class(self))
  File "C:\Python372\mecheck\lib\site-packages\django\db\models\query.py", line 54, in __iter__
    results = compiler.execute_sql(chunked_fetch=self.chunked_fetch, chunk_size=self.chunk_size)
  File "C:\Python372\mecheck\lib\site-packages\django\db\models\sql\compiler.py", line 1052, in execute_sql
    sql, params = self.as_sql()
  File "C:\Python372\mecheck\lib\site-packages\django\db\models\sql\compiler.py", line 464, in as_sql
    where, w_params = self.compile(self.where) if self.where is not None else ("", [])
  File "C:\Python372\mecheck\lib\site-packages\django\db\models\sql\compiler.py", line 390, in compile
    sql, params = node.as_sql(self, self.connection)
  File "C:\Python372\mecheck\lib\site-packages\django\db\models\sql\where.py", line 81, in as_sql
    sql, params = compiler.compile(child)
  File "C:\Python372\mecheck\lib\site-packages\django\db\models\sql\compiler.py", line 390, in compile
    sql, params = node.as_sql(self, self.connection)
  File "C:\Python372\mecheck\lib\site-packages\django\db\models\lookups.py", line 163, in as_sql
    rhs_sql, rhs_params = self.process_rhs(compiler, connection)
  File "C:\Python372\mecheck\lib\site-packages\django\db\models\lookups.py", line 218, in process_rhs
    return self.batch_process_rhs(compiler, connection)
  File "C:\Python372\mecheck\lib\site-packages\django\db\models\lookups.py", line 238, in batch_process_rhs
    for sql, param in zip(*pre_processed)
ValueError: not enough values to unpack (expected 2, got 0)
[2021-05-28 16:05:03,846] [basehttp.py:154] [basehttp:log_message] [ERROR]- "POST /PersonalInfo/Summary3/ HTTP/1.1" 500 135038
[2021-05-28 16:08:01,892] [log.py:228] [log:log_response] [ERROR]- Internal Server Error: /PersonalInfo/Summary3/
Traceback (most recent call last):
  File "C:\Python372\mecheck\lib\site-packages\django\core\handlers\exception.py", line 34, in inner
    response = get_response(request)
  File "C:\Python372\mecheck\lib\site-packages\django\core\handlers\base.py", line 126, in _get_response
    response = self.process_exception_by_middleware(e, request)
  File "C:\Python372\mecheck\lib\site-packages\django\core\handlers\base.py", line 124, in _get_response
    response = wrapped_callback(request, *callback_args, **callback_kwargs)
  File "C:\Python372\mecheck\lib\site-packages\django\views\decorators\csrf.py", line 54, in wrapped_view
    return view_func(*args, **kwargs)
  File "C:\djangoproject\Reliability_Row_data\PersonalInfo\views.py", line 6151, in Summary3
    for Per in PersonalInfo.objects.filter(Status__in=["離職"], QuitDate__range=Search_Endperiod):
  File "C:\Python372\mecheck\lib\site-packages\django\db\models\query.py", line 268, in __iter__
    self._fetch_all()
  File "C:\Python372\mecheck\lib\site-packages\django\db\models\query.py", line 1186, in _fetch_all
    self._result_cache = list(self._iterable_class(self))
  File "C:\Python372\mecheck\lib\site-packages\django\db\models\query.py", line 54, in __iter__
    results = compiler.execute_sql(chunked_fetch=self.chunked_fetch, chunk_size=self.chunk_size)
  File "C:\Python372\mecheck\lib\site-packages\django\db\models\sql\compiler.py", line 1052, in execute_sql
    sql, params = self.as_sql()
  File "C:\Python372\mecheck\lib\site-packages\django\db\models\sql\compiler.py", line 464, in as_sql
    where, w_params = self.compile(self.where) if self.where is not None else ("", [])
  File "C:\Python372\mecheck\lib\site-packages\django\db\models\sql\compiler.py", line 390, in compile
    sql, params = node.as_sql(self, self.connection)
  File "C:\Python372\mecheck\lib\site-packages\django\db\models\sql\where.py", line 81, in as_sql
    sql, params = compiler.compile(child)
  File "C:\Python372\mecheck\lib\site-packages\django\db\models\sql\compiler.py", line 390, in compile
    sql, params = node.as_sql(self, self.connection)
  File "C:\Python372\mecheck\lib\site-packages\django\db\models\lookups.py", line 163, in as_sql
    rhs_sql, rhs_params = self.process_rhs(compiler, connection)
  File "C:\Python372\mecheck\lib\site-packages\django\db\models\lookups.py", line 218, in process_rhs
    return self.batch_process_rhs(compiler, connection)
  File "C:\Python372\mecheck\lib\site-packages\django\db\models\lookups.py", line 238, in batch_process_rhs
    for sql, param in zip(*pre_processed)
ValueError: not enough values to unpack (expected 2, got 0)
[2021-05-28 16:08:01,893] [basehttp.py:154] [basehttp:log_message] [ERROR]- "POST /PersonalInfo/Summary3/ HTTP/1.1" 500 135038
[2021-05-28 16:15:18,007] [log.py:228] [log:log_response] [ERROR]- Internal Server Error: /PersonalInfo/Summary3/
Traceback (most recent call last):
  File "C:\Python372\mecheck\lib\site-packages\django\core\handlers\exception.py", line 34, in inner
    response = get_response(request)
  File "C:\Python372\mecheck\lib\site-packages\django\core\handlers\base.py", line 126, in _get_response
    response = self.process_exception_by_middleware(e, request)
  File "C:\Python372\mecheck\lib\site-packages\django\core\handlers\base.py", line 124, in _get_response
    response = wrapped_callback(request, *callback_args, **callback_kwargs)
  File "C:\Python372\mecheck\lib\site-packages\django\views\decorators\csrf.py", line 54, in wrapped_view
    return view_func(*args, **kwargs)
  File "C:\djangoproject\Reliability_Row_data\PersonalInfo\views.py", line 6151, in Summary3
    for Per in PersonalInfo.objects.filter(Status__in=["離職"], QuitDate__range=Search_Endperiod):
  File "C:\Python372\mecheck\lib\site-packages\django\db\models\manager.py", line 82, in manager_method
    return getattr(self.get_queryset(), name)(*args, **kwargs)
  File "C:\Python372\mecheck\lib\site-packages\django\db\models\query.py", line 844, in filter
    return self._filter_or_exclude(False, *args, **kwargs)
  File "C:\Python372\mecheck\lib\site-packages\django\db\models\query.py", line 862, in _filter_or_exclude
    clone.query.add_q(Q(*args, **kwargs))
  File "C:\Python372\mecheck\lib\site-packages\django\db\models\sql\query.py", line 1263, in add_q
    clause, _ = self._add_q(q_object, self.used_aliases)
  File "C:\Python372\mecheck\lib\site-packages\django\db\models\sql\query.py", line 1287, in _add_q
    split_subq=split_subq,
  File "C:\Python372\mecheck\lib\site-packages\django\db\models\sql\query.py", line 1225, in build_filter
    condition = self.build_lookup(lookups, col, value)
  File "C:\Python372\mecheck\lib\site-packages\django\db\models\sql\query.py", line 1096, in build_lookup
    lookup = lookup_class(lhs, rhs)
  File "C:\Python372\mecheck\lib\site-packages\django\db\models\lookups.py", line 20, in __init__
    self.rhs = self.get_prep_lookup()
  File "C:\Python372\mecheck\lib\site-packages\django\db\models\lookups.py", line 210, in get_prep_lookup
    rhs_value = self.lhs.output_field.get_prep_value(rhs_value)
  File "C:\Python372\mecheck\lib\site-packages\django\db\models\fields\__init__.py", line 1268, in get_prep_value
    return self.to_python(value)
  File "C:\Python372\mecheck\lib\site-packages\django\db\models\fields\__init__.py", line 1243, in to_python
    params={'value': value},
django.core.exceptions.ValidationError: ['’‘ 必须为合法的日期格式，请使用 YYYY-MM-DD 格式。']
[2021-05-28 16:15:18,014] [basehttp.py:154] [basehttp:log_message] [ERROR]- "POST /PersonalInfo/Summary3/ HTTP/1.1" 500 140293
[2021-05-28 16:17:06,023] [log.py:228] [log:log_response] [ERROR]- Internal Server Error: /PersonalInfo/Summary3/
Traceback (most recent call last):
  File "C:\Python372\mecheck\lib\site-packages\django\core\handlers\exception.py", line 34, in inner
    response = get_response(request)
  File "C:\Python372\mecheck\lib\site-packages\django\core\handlers\base.py", line 126, in _get_response
    response = self.process_exception_by_middleware(e, request)
  File "C:\Python372\mecheck\lib\site-packages\django\core\handlers\base.py", line 124, in _get_response
    response = wrapped_callback(request, *callback_args, **callback_kwargs)
  File "C:\Python372\mecheck\lib\site-packages\django\views\decorators\csrf.py", line 54, in wrapped_view
    return view_func(*args, **kwargs)
  File "C:\djangoproject\Reliability_Row_data\PersonalInfo\views.py", line 6151, in Summary3
    for Per in PersonalInfo.objects.filter(Status__in=["離職"], QuitDate__range=Search_Endperiod):
  File "C:\Python372\mecheck\lib\site-packages\django\db\models\manager.py", line 82, in manager_method
    return getattr(self.get_queryset(), name)(*args, **kwargs)
  File "C:\Python372\mecheck\lib\site-packages\django\db\models\query.py", line 844, in filter
    return self._filter_or_exclude(False, *args, **kwargs)
  File "C:\Python372\mecheck\lib\site-packages\django\db\models\query.py", line 862, in _filter_or_exclude
    clone.query.add_q(Q(*args, **kwargs))
  File "C:\Python372\mecheck\lib\site-packages\django\db\models\sql\query.py", line 1263, in add_q
    clause, _ = self._add_q(q_object, self.used_aliases)
  File "C:\Python372\mecheck\lib\site-packages\django\db\models\sql\query.py", line 1287, in _add_q
    split_subq=split_subq,
  File "C:\Python372\mecheck\lib\site-packages\django\db\models\sql\query.py", line 1225, in build_filter
    condition = self.build_lookup(lookups, col, value)
  File "C:\Python372\mecheck\lib\site-packages\django\db\models\sql\query.py", line 1096, in build_lookup
    lookup = lookup_class(lhs, rhs)
  File "C:\Python372\mecheck\lib\site-packages\django\db\models\lookups.py", line 20, in __init__
    self.rhs = self.get_prep_lookup()
  File "C:\Python372\mecheck\lib\site-packages\django\db\models\lookups.py", line 210, in get_prep_lookup
    rhs_value = self.lhs.output_field.get_prep_value(rhs_value)
  File "C:\Python372\mecheck\lib\site-packages\django\db\models\fields\__init__.py", line 1268, in get_prep_value
    return self.to_python(value)
  File "C:\Python372\mecheck\lib\site-packages\django\db\models\fields\__init__.py", line 1243, in to_python
    params={'value': value},
django.core.exceptions.ValidationError: ['’‘ 必须为合法的日期格式，请使用 YYYY-MM-DD 格式。']
[2021-05-28 16:17:06,040] [basehttp.py:154] [basehttp:log_message] [ERROR]- "POST /PersonalInfo/Summary3/ HTTP/1.1" 500 140335
[2021-05-28 16:17:33,959] [log.py:228] [log:log_response] [ERROR]- Internal Server Error: /PersonalInfo/Summary3/
Traceback (most recent call last):
  File "C:\Python372\mecheck\lib\site-packages\django\core\handlers\exception.py", line 34, in inner
    response = get_response(request)
  File "C:\Python372\mecheck\lib\site-packages\django\core\handlers\base.py", line 126, in _get_response
    response = self.process_exception_by_middleware(e, request)
  File "C:\Python372\mecheck\lib\site-packages\django\core\handlers\base.py", line 124, in _get_response
    response = wrapped_callback(request, *callback_args, **callback_kwargs)
  File "C:\Python372\mecheck\lib\site-packages\django\views\decorators\csrf.py", line 54, in wrapped_view
    return view_func(*args, **kwargs)
  File "C:\djangoproject\Reliability_Row_data\PersonalInfo\views.py", line 6151, in Summary3
    for Per in PersonalInfo.objects.filter(Status__in=["離職"], QuitDate__range=Search_Endperiod):
  File "C:\Python372\mecheck\lib\site-packages\django\db\models\manager.py", line 82, in manager_method
    return getattr(self.get_queryset(), name)(*args, **kwargs)
  File "C:\Python372\mecheck\lib\site-packages\django\db\models\query.py", line 844, in filter
    return self._filter_or_exclude(False, *args, **kwargs)
  File "C:\Python372\mecheck\lib\site-packages\django\db\models\query.py", line 862, in _filter_or_exclude
    clone.query.add_q(Q(*args, **kwargs))
  File "C:\Python372\mecheck\lib\site-packages\django\db\models\sql\query.py", line 1263, in add_q
    clause, _ = self._add_q(q_object, self.used_aliases)
  File "C:\Python372\mecheck\lib\site-packages\django\db\models\sql\query.py", line 1287, in _add_q
    split_subq=split_subq,
  File "C:\Python372\mecheck\lib\site-packages\django\db\models\sql\query.py", line 1225, in build_filter
    condition = self.build_lookup(lookups, col, value)
  File "C:\Python372\mecheck\lib\site-packages\django\db\models\sql\query.py", line 1096, in build_lookup
    lookup = lookup_class(lhs, rhs)
  File "C:\Python372\mecheck\lib\site-packages\django\db\models\lookups.py", line 20, in __init__
    self.rhs = self.get_prep_lookup()
  File "C:\Python372\mecheck\lib\site-packages\django\db\models\lookups.py", line 210, in get_prep_lookup
    rhs_value = self.lhs.output_field.get_prep_value(rhs_value)
  File "C:\Python372\mecheck\lib\site-packages\django\db\models\fields\__init__.py", line 1268, in get_prep_value
    return self.to_python(value)
  File "C:\Python372\mecheck\lib\site-packages\django\db\models\fields\__init__.py", line 1243, in to_python
    params={'value': value},
django.core.exceptions.ValidationError: ['’‘ 必须为合法的日期格式，请使用 YYYY-MM-DD 格式。']
[2021-05-28 16:17:33,969] [basehttp.py:154] [basehttp:log_message] [ERROR]- "POST /PersonalInfo/Summary3/ HTTP/1.1" 500 140335
[2021-05-28 16:55:57,458] [log.py:228] [log:log_response] [ERROR]- Internal Server Error: /PersonalInfo/Summary3/
Traceback (most recent call last):
  File "C:\Python372\mecheck\lib\site-packages\django\core\handlers\exception.py", line 34, in inner
    response = get_response(request)
  File "C:\Python372\mecheck\lib\site-packages\django\core\handlers\base.py", line 126, in _get_response
    response = self.process_exception_by_middleware(e, request)
  File "C:\Python372\mecheck\lib\site-packages\django\core\handlers\base.py", line 124, in _get_response
    response = wrapped_callback(request, *callback_args, **callback_kwargs)
  File "C:\Python372\mecheck\lib\site-packages\django\views\decorators\csrf.py", line 54, in wrapped_view
    return view_func(*args, **kwargs)
  File "C:\djangoproject\Reliability_Row_data\PersonalInfo\views.py", line 6224, in Summary3
    ZHANZONG.append(round(i["zhanReasons"] / 100, 3))
KeyError: 'zhanReasons'
[2021-05-28 16:55:57,466] [basehttp.py:154] [basehttp:log_message] [ERROR]- "POST /PersonalInfo/Summary3/ HTTP/1.1" 500 86029
[2021-05-28 16:57:35,389] [log.py:228] [log:log_response] [ERROR]- Internal Server Error: /PersonalInfo/Summary3/
Traceback (most recent call last):
  File "C:\Python372\mecheck\lib\site-packages\django\core\handlers\exception.py", line 34, in inner
    response = get_response(request)
  File "C:\Python372\mecheck\lib\site-packages\django\core\handlers\base.py", line 126, in _get_response
    response = self.process_exception_by_middleware(e, request)
  File "C:\Python372\mecheck\lib\site-packages\django\core\handlers\base.py", line 124, in _get_response
    response = wrapped_callback(request, *callback_args, **callback_kwargs)
  File "C:\Python372\mecheck\lib\site-packages\django\views\decorators\csrf.py", line 54, in wrapped_view
    return view_func(*args, **kwargs)
  File "C:\djangoproject\Reliability_Row_data\PersonalInfo\views.py", line 6225, in Summary3
    ZHANZONG.append(round(i["zhanReasons"] / 100, 3))
KeyError: 'zhanReasons'
[2021-05-28 16:57:35,402] [basehttp.py:154] [basehttp:log_message] [ERROR]- "POST /PersonalInfo/Summary3/ HTTP/1.1" 500 86022
[2021-05-28 17:00:40,052] [log.py:228] [log:log_response] [ERROR]- Internal Server Error: /PersonalInfo/Summary3/
Traceback (most recent call last):
  File "C:\Python372\mecheck\lib\site-packages\django\core\handlers\exception.py", line 34, in inner
    response = get_response(request)
  File "C:\Python372\mecheck\lib\site-packages\django\core\handlers\base.py", line 126, in _get_response
    response = self.process_exception_by_middleware(e, request)
  File "C:\Python372\mecheck\lib\site-packages\django\core\handlers\base.py", line 124, in _get_response
    response = wrapped_callback(request, *callback_args, **callback_kwargs)
  File "C:\Python372\mecheck\lib\site-packages\django\views\decorators\csrf.py", line 54, in wrapped_view
    return view_func(*args, **kwargs)
  File "C:\djangoproject\Reliability_Row_data\PersonalInfo\views.py", line 6751, in Summary3
    educationDiagramZH_educationDiagram.append(round(i["accountFor"] / 100, 3))
KeyError: 'accountFor'
[2021-05-28 17:00:40,061] [basehttp.py:154] [basehttp:log_message] [ERROR]- "POST /PersonalInfo/Summary3/ HTTP/1.1" 500 103691
