[2023-03-09 13:27:38,371] [log.py:228] [log:log_response] [ERROR]- Internal Server Error: /PersonalInfo/Summary1/
Traceback (most recent call last):
  File "C:\Python372\mecheck\lib\site-packages\django\core\handlers\exception.py", line 34, in inner
    response = get_response(request)
  File "C:\Python372\mecheck\lib\site-packages\django\core\handlers\base.py", line 126, in _get_response
    response = self.process_exception_by_middleware(e, request)
  File "C:\Python372\mecheck\lib\site-packages\django\core\handlers\base.py", line 124, in _get_response
    response = wrapped_callback(request, *callback_args, **callback_kwargs)
  File "C:\Python372\mecheck\lib\site-packages\django\views\decorators\csrf.py", line 54, in wrapped_view
    return view_func(*args, **kwargs)
  File "C:\djangoproject\Reliability_Row_data\PersonalInfo\views.py", line 3427, in Summary1
    for i in PersonalInfo.objects.all().values("Customer").distinct().count():
TypeError: 'int' object is not iterable
[2023-03-09 13:27:38,407] [basehttp.py:154] [basehttp:log_message] [ERROR]- "POST /PersonalInfo/Summary1/ HTTP/1.1" 500 98116
[2023-03-09 13:28:16,171] [log.py:228] [log:log_response] [ERROR]- Internal Server Error: /PersonalInfo/Summary1/
Traceback (most recent call last):
  File "C:\Python372\mecheck\lib\site-packages\django\core\handlers\exception.py", line 34, in inner
    response = get_response(request)
  File "C:\Python372\mecheck\lib\site-packages\django\core\handlers\base.py", line 126, in _get_response
    response = self.process_exception_by_middleware(e, request)
  File "C:\Python372\mecheck\lib\site-packages\django\core\handlers\base.py", line 124, in _get_response
    response = wrapped_callback(request, *callback_args, **callback_kwargs)
  File "C:\Python372\mecheck\lib\site-packages\django\views\decorators\csrf.py", line 54, in wrapped_view
    return view_func(*args, **kwargs)
  File "C:\djangoproject\Reliability_Row_data\PersonalInfo\views.py", line 3428, in Summary1
    for i in PersonalInfo.objects.all().values("Customer").distinct().count():
TypeError: 'int' object is not iterable
[2023-03-09 13:28:16,178] [basehttp.py:154] [basehttp:log_message] [ERROR]- "POST /PersonalInfo/Summary1/ HTTP/1.1" 500 98170
[2023-03-09 13:34:25,883] [log.py:228] [log:log_response] [ERROR]- Internal Server Error: /PersonalInfo/Summary1/
Traceback (most recent call last):
  File "C:\Python372\mecheck\lib\site-packages\django\core\handlers\exception.py", line 34, in inner
    response = get_response(request)
  File "C:\Python372\mecheck\lib\site-packages\django\core\handlers\base.py", line 126, in _get_response
    response = self.process_exception_by_middleware(e, request)
  File "C:\Python372\mecheck\lib\site-packages\django\core\handlers\base.py", line 124, in _get_response
    response = wrapped_callback(request, *callback_args, **callback_kwargs)
  File "C:\Python372\mecheck\lib\site-packages\django\views\decorators\csrf.py", line 54, in wrapped_view
    return view_func(*args, **kwargs)
  File "C:\djangoproject\Reliability_Row_data\PersonalInfo\views.py", line 3505, in Summary1
    overtimePdic[j[0]] = round(overtimedic[j[0]] / zaizhimounth, 2) if zaizhimounth else 0.00
TypeError: unsupported operand type(s) for /: 'NoneType' and 'int'
[2023-03-09 13:34:25,890] [basehttp.py:154] [basehttp:log_message] [ERROR]- "POST /PersonalInfo/Summary1/ HTTP/1.1" 500 101320
[2023-03-09 15:28:44,485] [log.py:228] [log:log_response] [ERROR]- Internal Server Error: /PersonalInfo/Summary1/
Traceback (most recent call last):
  File "C:\Python372\mecheck\lib\site-packages\django\core\handlers\exception.py", line 34, in inner
    response = get_response(request)
  File "C:\Python372\mecheck\lib\site-packages\django\core\handlers\base.py", line 126, in _get_response
    response = self.process_exception_by_middleware(e, request)
  File "C:\Python372\mecheck\lib\site-packages\django\core\handlers\base.py", line 124, in _get_response
    response = wrapped_callback(request, *callback_args, **callback_kwargs)
  File "C:\Python372\mecheck\lib\site-packages\django\views\decorators\csrf.py", line 54, in wrapped_view
    return view_func(*args, **kwargs)
  File "C:\djangoproject\Reliability_Row_data\PersonalInfo\views.py", line 4081, in Summary1
    Item=k["GroupNum"], Year=YearSearch).first() else "员工%s 該年份的Customer缺失" % k["GroupNum"]
TypeError: 'WorkOvertime' object is not subscriptable
[2023-03-09 15:28:44,523] [basehttp.py:154] [basehttp:log_message] [ERROR]- "POST /PersonalInfo/Summary1/ HTTP/1.1" 500 94543
[2023-03-09 15:31:29,038] [log.py:228] [log:log_response] [ERROR]- Internal Server Error: /PersonalInfo/Summary1/
Traceback (most recent call last):
  File "C:\Python372\mecheck\lib\site-packages\django\core\handlers\exception.py", line 34, in inner
    response = get_response(request)
  File "C:\Python372\mecheck\lib\site-packages\django\core\handlers\base.py", line 126, in _get_response
    response = self.process_exception_by_middleware(e, request)
  File "C:\Python372\mecheck\lib\site-packages\django\core\handlers\base.py", line 124, in _get_response
    response = wrapped_callback(request, *callback_args, **callback_kwargs)
  File "C:\Python372\mecheck\lib\site-packages\django\views\decorators\csrf.py", line 54, in wrapped_view
    return view_func(*args, **kwargs)
  File "C:\djangoproject\Reliability_Row_data\PersonalInfo\views.py", line 4080, in Summary1
    Item=k["GroupNum"], Year=YearSearch).first().Customer if PersonalInfoHisByYear.objects.filter(Item=k["GroupNum"], Year=YearSearch).first() else "员工%s 該年份的Customer缺失" % k["GroupNum"]
TypeError: 'WorkOvertime' object is not subscriptable
[2023-03-09 15:31:29,043] [basehttp.py:154] [basehttp:log_message] [ERROR]- "POST /PersonalInfo/Summary1/ HTTP/1.1" 500 94669
[2023-03-09 15:32:12,117] [log.py:228] [log:log_response] [ERROR]- Internal Server Error: /PersonalInfo/Summary1/
Traceback (most recent call last):
  File "C:\Python372\mecheck\lib\site-packages\django\core\handlers\exception.py", line 34, in inner
    response = get_response(request)
  File "C:\Python372\mecheck\lib\site-packages\django\core\handlers\base.py", line 126, in _get_response
    response = self.process_exception_by_middleware(e, request)
  File "C:\Python372\mecheck\lib\site-packages\django\core\handlers\base.py", line 124, in _get_response
    response = wrapped_callback(request, *callback_args, **callback_kwargs)
  File "C:\Python372\mecheck\lib\site-packages\django\views\decorators\csrf.py", line 54, in wrapped_view
    return view_func(*args, **kwargs)
  File "C:\djangoproject\Reliability_Row_data\PersonalInfo\views.py", line 4080, in Summary1
    Item=k["GroupNum"], Year=YearSearch).first().Customer if PersonalInfoHisByYear.objects.filter(Item=k["GroupNum"], Year=YearSearch).first() else "员工該年份的Customer缺失"
TypeError: 'WorkOvertime' object is not subscriptable
[2023-03-09 15:32:12,122] [basehttp.py:154] [basehttp:log_message] [ERROR]- "POST /PersonalInfo/Summary1/ HTTP/1.1" 500 94611
[2023-03-09 15:37:59,393] [log.py:228] [log:log_response] [ERROR]- Internal Server Error: /PersonalInfo/Summary1/
Traceback (most recent call last):
  File "C:\Python372\mecheck\lib\site-packages\django\core\handlers\exception.py", line 34, in inner
    response = get_response(request)
  File "C:\Python372\mecheck\lib\site-packages\django\core\handlers\base.py", line 126, in _get_response
    response = self.process_exception_by_middleware(e, request)
  File "C:\Python372\mecheck\lib\site-packages\django\core\handlers\base.py", line 124, in _get_response
    response = wrapped_callback(request, *callback_args, **callback_kwargs)
  File "C:\Python372\mecheck\lib\site-packages\django\views\decorators\csrf.py", line 54, in wrapped_view
    return view_func(*args, **kwargs)
  File "C:\djangoproject\Reliability_Row_data\PersonalInfo\views.py", line 4082, in Summary1
    Item=k["GroupNum"], Year=YearSearch).first() else "员工%s 該年份的Customer缺失" % k["GroupNum"]
TypeError: 'WorkOvertime' object is not subscriptable
[2023-03-09 15:37:59,426] [basehttp.py:154] [basehttp:log_message] [ERROR]- "POST /PersonalInfo/Summary1/ HTTP/1.1" 500 94542
[2023-03-09 15:39:50,847] [log.py:228] [log:log_response] [ERROR]- Internal Server Error: /PersonalInfo/Summary1/
Traceback (most recent call last):
  File "C:\Python372\mecheck\lib\site-packages\django\core\handlers\exception.py", line 34, in inner
    response = get_response(request)
  File "C:\Python372\mecheck\lib\site-packages\django\core\handlers\base.py", line 126, in _get_response
    response = self.process_exception_by_middleware(e, request)
  File "C:\Python372\mecheck\lib\site-packages\django\core\handlers\base.py", line 124, in _get_response
    response = wrapped_callback(request, *callback_args, **callback_kwargs)
  File "C:\Python372\mecheck\lib\site-packages\django\views\decorators\csrf.py", line 54, in wrapped_view
    return view_func(*args, **kwargs)
  File "C:\djangoproject\Reliability_Row_data\PersonalInfo\views.py", line 4079, in Summary1
    print(k, PersonalInfoHisByYear.objects.filter(Item=k["GroupNum"], Year=YearSearch).first().Customer)
TypeError: 'WorkOvertime' object is not subscriptable
[2023-03-09 15:39:50,874] [basehttp.py:154] [basehttp:log_message] [ERROR]- "POST /PersonalInfo/Summary1/ HTTP/1.1" 500 94583
[2023-03-09 15:40:59,726] [log.py:228] [log:log_response] [ERROR]- Internal Server Error: /PersonalInfo/Summary1/
Traceback (most recent call last):
  File "C:\Python372\mecheck\lib\site-packages\django\core\handlers\exception.py", line 34, in inner
    response = get_response(request)
  File "C:\Python372\mecheck\lib\site-packages\django\core\handlers\base.py", line 126, in _get_response
    response = self.process_exception_by_middleware(e, request)
  File "C:\Python372\mecheck\lib\site-packages\django\core\handlers\base.py", line 124, in _get_response
    response = wrapped_callback(request, *callback_args, **callback_kwargs)
  File "C:\Python372\mecheck\lib\site-packages\django\views\decorators\csrf.py", line 54, in wrapped_view
    return view_func(*args, **kwargs)
  File "C:\djangoproject\Reliability_Row_data\PersonalInfo\views.py", line 4079, in Summary1
    print(k, k["GroupNum"])
TypeError: 'WorkOvertime' object is not subscriptable
[2023-03-09 15:40:59,731] [basehttp.py:154] [basehttp:log_message] [ERROR]- "POST /PersonalInfo/Summary1/ HTTP/1.1" 500 94520
[2023-03-09 15:42:31,304] [log.py:228] [log:log_response] [ERROR]- Internal Server Error: /PersonalInfo/Summary1/
Traceback (most recent call last):
  File "C:\Python372\mecheck\lib\site-packages\django\core\handlers\exception.py", line 34, in inner
    response = get_response(request)
  File "C:\Python372\mecheck\lib\site-packages\django\core\handlers\base.py", line 126, in _get_response
    response = self.process_exception_by_middleware(e, request)
  File "C:\Python372\mecheck\lib\site-packages\django\core\handlers\base.py", line 124, in _get_response
    response = wrapped_callback(request, *callback_args, **callback_kwargs)
  File "C:\Python372\mecheck\lib\site-packages\django\views\decorators\csrf.py", line 54, in wrapped_view
    return view_func(*args, **kwargs)
  File "C:\djangoproject\Reliability_Row_data\PersonalInfo\views.py", line 4080, in Summary1
    print(PersonalInfoHisByYear.objects.filter(Item=k.GroupNum, Year=YearSearch).first().Customer)
  File "C:\Python372\mecheck\lib\site-packages\django\db\models\manager.py", line 82, in manager_method
    return getattr(self.get_queryset(), name)(*args, **kwargs)
  File "C:\Python372\mecheck\lib\site-packages\django\db\models\query.py", line 844, in filter
    return self._filter_or_exclude(False, *args, **kwargs)
  File "C:\Python372\mecheck\lib\site-packages\django\db\models\query.py", line 862, in _filter_or_exclude
    clone.query.add_q(Q(*args, **kwargs))
  File "C:\Python372\mecheck\lib\site-packages\django\db\models\sql\query.py", line 1263, in add_q
    clause, _ = self._add_q(q_object, self.used_aliases)
  File "C:\Python372\mecheck\lib\site-packages\django\db\models\sql\query.py", line 1287, in _add_q
    split_subq=split_subq,
  File "C:\Python372\mecheck\lib\site-packages\django\db\models\sql\query.py", line 1164, in build_filter
    lookups, parts, reffed_expression = self.solve_lookup_type(arg)
  File "C:\Python372\mecheck\lib\site-packages\django\db\models\sql\query.py", line 1028, in solve_lookup_type
    _, field, _, lookup_parts = self.names_to_path(lookup_splitted, self.get_meta())
  File "C:\Python372\mecheck\lib\site-packages\django\db\models\sql\query.py", line 1389, in names_to_path
    "Choices are: %s" % (name, ", ".join(available)))
django.core.exceptions.FieldError: Cannot resolve keyword 'Item' into field. Choices are: Aalary, CNName, Customer, Department, DepartmentCode, ENLevel, Education, EngName, Experience, GraduationYear, GroupNum, IdCard, LastAchievements, LastPromotionData, Major, MajorAscription, MobileNum, NativeCity, NativeCounty, NativeProvince, NewCompany, PlanQuitDate, Portrait, PositionNow, PositionTimes, QuitDate, QuitDetail, QuitReason, RegistPosition, RegistrationDate, ResidenceCity, ResidenceCounty, ResidenceProvince, SAPNum, School, Sex, Status, Whereabouts, Year, id
[2023-03-09 15:42:31,313] [basehttp.py:154] [basehttp:log_message] [ERROR]- "POST /PersonalInfo/Summary1/ HTTP/1.1" 500 140905
[2023-03-09 15:48:58,905] [log.py:228] [log:log_response] [ERROR]- Internal Server Error: /PersonalInfo/Summary1/
Traceback (most recent call last):
  File "C:\Python372\mecheck\lib\site-packages\django\core\handlers\exception.py", line 34, in inner
    response = get_response(request)
  File "C:\Python372\mecheck\lib\site-packages\django\core\handlers\base.py", line 126, in _get_response
    response = self.process_exception_by_middleware(e, request)
  File "C:\Python372\mecheck\lib\site-packages\django\core\handlers\base.py", line 124, in _get_response
    response = wrapped_callback(request, *callback_args, **callback_kwargs)
  File "C:\Python372\mecheck\lib\site-packages\django\views\decorators\csrf.py", line 54, in wrapped_view
    return view_func(*args, **kwargs)
  File "C:\djangoproject\Reliability_Row_data\PersonalInfo\views.py", line 4076, in Summary1
    Item=k.GroupNum, Year=YearSearch).first() else "员工%s 該年份的Customer缺失" % k.GroupNum
  File "C:\Python372\mecheck\lib\site-packages\django\db\models\manager.py", line 82, in manager_method
    return getattr(self.get_queryset(), name)(*args, **kwargs)
  File "C:\Python372\mecheck\lib\site-packages\django\db\models\query.py", line 844, in filter
    return self._filter_or_exclude(False, *args, **kwargs)
  File "C:\Python372\mecheck\lib\site-packages\django\db\models\query.py", line 862, in _filter_or_exclude
    clone.query.add_q(Q(*args, **kwargs))
  File "C:\Python372\mecheck\lib\site-packages\django\db\models\sql\query.py", line 1263, in add_q
    clause, _ = self._add_q(q_object, self.used_aliases)
  File "C:\Python372\mecheck\lib\site-packages\django\db\models\sql\query.py", line 1287, in _add_q
    split_subq=split_subq,
  File "C:\Python372\mecheck\lib\site-packages\django\db\models\sql\query.py", line 1164, in build_filter
    lookups, parts, reffed_expression = self.solve_lookup_type(arg)
  File "C:\Python372\mecheck\lib\site-packages\django\db\models\sql\query.py", line 1028, in solve_lookup_type
    _, field, _, lookup_parts = self.names_to_path(lookup_splitted, self.get_meta())
  File "C:\Python372\mecheck\lib\site-packages\django\db\models\sql\query.py", line 1389, in names_to_path
    "Choices are: %s" % (name, ", ".join(available)))
django.core.exceptions.FieldError: Cannot resolve keyword 'Item' into field. Choices are: Aalary, CNName, Customer, Department, DepartmentCode, ENLevel, Education, EngName, Experience, GraduationYear, GroupNum, IdCard, LastAchievements, LastPromotionData, Major, MajorAscription, MobileNum, NativeCity, NativeCounty, NativeProvince, NewCompany, PlanQuitDate, Portrait, PositionNow, PositionTimes, QuitDate, QuitDetail, QuitReason, RegistPosition, RegistrationDate, ResidenceCity, ResidenceCounty, ResidenceProvince, SAPNum, School, Sex, Status, Whereabouts, Year, id
[2023-03-09 15:48:58,945] [basehttp.py:154] [basehttp:log_message] [ERROR]- "POST /PersonalInfo/Summary1/ HTTP/1.1" 500 140880
[2023-03-09 16:49:24,111] [log.py:228] [log:log_response] [ERROR]- Internal Server Error: /PersonalInfo/Summary1/
Traceback (most recent call last):
  File "C:\Python372\mecheck\lib\site-packages\django\core\handlers\exception.py", line 34, in inner
    response = get_response(request)
  File "C:\Python372\mecheck\lib\site-packages\django\core\handlers\base.py", line 126, in _get_response
    response = self.process_exception_by_middleware(e, request)
  File "C:\Python372\mecheck\lib\site-packages\django\core\handlers\base.py", line 124, in _get_response
    response = wrapped_callback(request, *callback_args, **callback_kwargs)
  File "C:\Python372\mecheck\lib\site-packages\django\views\decorators\csrf.py", line 54, in wrapped_view
    return view_func(*args, **kwargs)
  File "C:\djangoproject\Reliability_Row_data\PersonalInfo\views.py", line 4082, in Summary1
    print(WorkOvertimeQuerySet.objects.all().values('Customer').annotate(Sum('Total')).order_by('Customer'))
AttributeError: 'QuerySet' object has no attribute 'objects'
[2023-03-09 16:49:24,117] [basehttp.py:154] [basehttp:log_message] [ERROR]- "POST /PersonalInfo/Summary1/ HTTP/1.1" 500 103597
[2023-03-09 16:50:16,666] [log.py:228] [log:log_response] [ERROR]- Internal Server Error: /PersonalInfo/Summary1/
Traceback (most recent call last):
  File "C:\Python372\mecheck\lib\site-packages\django\core\handlers\exception.py", line 34, in inner
    response = get_response(request)
  File "C:\Python372\mecheck\lib\site-packages\django\core\handlers\base.py", line 126, in _get_response
    response = self.process_exception_by_middleware(e, request)
  File "C:\Python372\mecheck\lib\site-packages\django\core\handlers\base.py", line 124, in _get_response
    response = wrapped_callback(request, *callback_args, **callback_kwargs)
  File "C:\Python372\mecheck\lib\site-packages\django\views\decorators\csrf.py", line 54, in wrapped_view
    return view_func(*args, **kwargs)
  File "C:\djangoproject\Reliability_Row_data\PersonalInfo\views.py", line 4082, in Summary1
    print(WorkOvertimeQuerySet.objects.all().values('Customer').annotate(Sum('Total')).order_by('Customer'))
AttributeError: 'QuerySet' object has no attribute 'objects'
[2023-03-09 16:50:16,667] [basehttp.py:154] [basehttp:log_message] [ERROR]- "POST /PersonalInfo/Summary1/ HTTP/1.1" 500 103597
[2023-03-09 17:19:22,281] [log.py:228] [log:log_response] [ERROR]- Internal Server Error: /PersonalInfo/Summary1/
Traceback (most recent call last):
  File "C:\Python372\mecheck\lib\site-packages\django\core\handlers\exception.py", line 34, in inner
    response = get_response(request)
  File "C:\Python372\mecheck\lib\site-packages\django\core\handlers\base.py", line 126, in _get_response
    response = self.process_exception_by_middleware(e, request)
  File "C:\Python372\mecheck\lib\site-packages\django\core\handlers\base.py", line 124, in _get_response
    response = wrapped_callback(request, *callback_args, **callback_kwargs)
  File "C:\Python372\mecheck\lib\site-packages\django\views\decorators\csrf.py", line 54, in wrapped_view
    return view_func(*args, **kwargs)
  File "C:\djangoproject\Reliability_Row_data\PersonalInfo\views.py", line 4079, in Summary1
    GroupNum=k.GroupNum, Year=YearSearch).first() else "员工%s 該年份的Customer缺失" % k.GroupNum
AttributeError: 'tuple' object has no attribute 'GroupNum'
[2023-03-09 17:19:22,286] [basehttp.py:154] [basehttp:log_message] [ERROR]- "POST /PersonalInfo/Summary1/ HTTP/1.1" 500 103908
[2023-03-09 17:20:42,622] [log.py:228] [log:log_response] [ERROR]- Internal Server Error: /PersonalInfo/Summary1/
Traceback (most recent call last):
  File "C:\Python372\mecheck\lib\site-packages\django\core\handlers\exception.py", line 34, in inner
    response = get_response(request)
  File "C:\Python372\mecheck\lib\site-packages\django\core\handlers\base.py", line 126, in _get_response
    response = self.process_exception_by_middleware(e, request)
  File "C:\Python372\mecheck\lib\site-packages\django\core\handlers\base.py", line 124, in _get_response
    response = wrapped_callback(request, *callback_args, **callback_kwargs)
  File "C:\Python372\mecheck\lib\site-packages\django\views\decorators\csrf.py", line 54, in wrapped_view
    return view_func(*args, **kwargs)
  File "C:\djangoproject\Reliability_Row_data\PersonalInfo\views.py", line 4077, in Summary1
    print(k.GroupNum)
AttributeError: 'tuple' object has no attribute 'GroupNum'
[2023-03-09 17:20:42,627] [basehttp.py:154] [basehttp:log_message] [ERROR]- "POST /PersonalInfo/Summary1/ HTTP/1.1" 500 103438
[2023-03-09 17:21:22,503] [log.py:228] [log:log_response] [ERROR]- Internal Server Error: /PersonalInfo/Summary1/
Traceback (most recent call last):
  File "C:\Python372\mecheck\lib\site-packages\django\core\handlers\exception.py", line 34, in inner
    response = get_response(request)
  File "C:\Python372\mecheck\lib\site-packages\django\core\handlers\base.py", line 126, in _get_response
    response = self.process_exception_by_middleware(e, request)
  File "C:\Python372\mecheck\lib\site-packages\django\core\handlers\base.py", line 124, in _get_response
    response = wrapped_callback(request, *callback_args, **callback_kwargs)
  File "C:\Python372\mecheck\lib\site-packages\django\views\decorators\csrf.py", line 54, in wrapped_view
    return view_func(*args, **kwargs)
  File "C:\djangoproject\Reliability_Row_data\PersonalInfo\views.py", line 4077, in Summary1
    print(k["GroupNum"])
TypeError: tuple indices must be integers or slices, not str
[2023-03-09 17:21:22,510] [basehttp.py:154] [basehttp:log_message] [ERROR]- "POST /PersonalInfo/Summary1/ HTTP/1.1" 500 103396
