[2024-06-20 12:04:42,267] [log.py:228] [log:log_response] [ERROR]- Internal Server Error: /INVGantt/INVGantt-upload/
Traceback (most recent call last):
  File "C:\Python372\mecheck\lib\site-packages\django\core\handlers\exception.py", line 34, in inner
    response = get_response(request)
  File "C:\Python372\mecheck\lib\site-packages\django\core\handlers\base.py", line 126, in _get_response
    response = self.process_exception_by_middleware(e, request)
  File "C:\Python372\mecheck\lib\site-packages\django\core\handlers\base.py", line 124, in _get_response
    response = wrapped_callback(request, *callback_args, **callback_kwargs)
  File "C:\Python372\mecheck\lib\site-packages\django\views\decorators\csrf.py", line 54, in wrapped_view
    return view_func(*args, **kwargs)
  File "C:\djangoproject\Reliability_Row_data\INVGantt\views.py", line 268, in INVGantt_upload
    if INVGantt.objects.filter(**Check_dic_Gantt).first():
  File "C:\Python372\mecheck\lib\site-packages\django\db\models\manager.py", line 82, in manager_method
    return getattr(self.get_queryset(), name)(*args, **kwargs)
  File "C:\Python372\mecheck\lib\site-packages\django\db\models\query.py", line 844, in filter
    return self._filter_or_exclude(False, *args, **kwargs)
  File "C:\Python372\mecheck\lib\site-packages\django\db\models\query.py", line 862, in _filter_or_exclude
    clone.query.add_q(Q(*args, **kwargs))
  File "C:\Python372\mecheck\lib\site-packages\django\db\models\sql\query.py", line 1263, in add_q
    clause, _ = self._add_q(q_object, self.used_aliases)
  File "C:\Python372\mecheck\lib\site-packages\django\db\models\sql\query.py", line 1287, in _add_q
    split_subq=split_subq,
  File "C:\Python372\mecheck\lib\site-packages\django\db\models\sql\query.py", line 1225, in build_filter
    condition = self.build_lookup(lookups, col, value)
  File "C:\Python372\mecheck\lib\site-packages\django\db\models\sql\query.py", line 1096, in build_lookup
    lookup = lookup_class(lhs, rhs)
  File "C:\Python372\mecheck\lib\site-packages\django\db\models\lookups.py", line 20, in __init__
    self.rhs = self.get_prep_lookup()
  File "C:\Python372\mecheck\lib\site-packages\django\db\models\lookups.py", line 70, in get_prep_lookup
    return self.lhs.output_field.get_prep_value(self.rhs)
  File "C:\Python372\mecheck\lib\site-packages\django\db\models\fields\__init__.py", line 1268, in get_prep_value
    return self.to_python(value)
  File "C:\Python372\mecheck\lib\site-packages\django\db\models\fields\__init__.py", line 1230, in to_python
    parsed = parse_date(value)
  File "C:\Python372\mecheck\lib\site-packages\django\utils\dateparse.py", line 74, in parse_date
    match = date_re.match(value)
TypeError: expected string or bytes-like object
[2024-06-20 12:04:42,277] [runserver.py:154] [runserver:log_action] [ERROR]- HTTP POST /INVGantt/INVGantt-upload/ 500 [3.75, 127.0.0.1:57018]
[2024-06-20 12:06:15,597] [log.py:228] [log:log_response] [ERROR]- Internal Server Error: /INVGantt/INVGantt-upload/
Traceback (most recent call last):
  File "C:\Python372\mecheck\lib\site-packages\django\db\models\options.py", line 564, in get_field
    return self.fields_map[field_name]
KeyError: 'Series'

During handling of the above exception, another exception occurred:

Traceback (most recent call last):
  File "C:\Python372\mecheck\lib\site-packages\django\core\handlers\exception.py", line 34, in inner
    response = get_response(request)
  File "C:\Python372\mecheck\lib\site-packages\django\core\handlers\base.py", line 126, in _get_response
    response = self.process_exception_by_middleware(e, request)
  File "C:\Python372\mecheck\lib\site-packages\django\core\handlers\base.py", line 124, in _get_response
    response = wrapped_callback(request, *callback_args, **callback_kwargs)
  File "C:\Python372\mecheck\lib\site-packages\django\views\decorators\csrf.py", line 54, in wrapped_view
    return view_func(*args, **kwargs)
  File "C:\djangoproject\Reliability_Row_data\INVGantt\views.py", line 279, in INVGantt_upload
    INVGantt.objects.filter(**Check_dic_Gantt).update(**Update_dic_Gantt)
  File "C:\Python372\mecheck\lib\site-packages\django\db\models\query.py", line 689, in update
    query.add_update_values(kwargs)
  File "C:\Python372\mecheck\lib\site-packages\django\db\models\sql\subqueries.py", line 117, in add_update_values
    field = self.get_meta().get_field(name)
  File "C:\Python372\mecheck\lib\site-packages\django\db\models\options.py", line 566, in get_field
    raise FieldDoesNotExist("%s has no field named '%s'" % (self.object_name, field_name))
django.core.exceptions.FieldDoesNotExist: INVGantt has no field named 'Series'
[2024-06-20 12:06:15,614] [runserver.py:154] [runserver:log_action] [ERROR]- HTTP POST /INVGantt/INVGantt-upload/ 500 [0.96, 127.0.0.1:57181]
[2024-06-20 13:21:01,960] [log.py:228] [log:log_response] [ERROR]- Internal Server Error: /INVGantt/INVGantt-upload/
Traceback (most recent call last):
  File "C:\Python372\mecheck\lib\site-packages\django\core\handlers\exception.py", line 34, in inner
    response = get_response(request)
  File "C:\Python372\mecheck\lib\site-packages\django\core\handlers\base.py", line 126, in _get_response
    response = self.process_exception_by_middleware(e, request)
  File "C:\Python372\mecheck\lib\site-packages\django\core\handlers\base.py", line 124, in _get_response
    response = wrapped_callback(request, *callback_args, **callback_kwargs)
  File "C:\Python372\mecheck\lib\site-packages\django\views\decorators\csrf.py", line 54, in wrapped_view
    return view_func(*args, **kwargs)
  File "C:\djangoproject\Reliability_Row_data\INVGantt\views.py", line 268, in INVGantt_upload
    if INVGantt.objects.filter(**Check_dic_Gantt).first():
  File "C:\Python372\mecheck\lib\site-packages\django\db\models\manager.py", line 82, in manager_method
    return getattr(self.get_queryset(), name)(*args, **kwargs)
  File "C:\Python372\mecheck\lib\site-packages\django\db\models\query.py", line 844, in filter
    return self._filter_or_exclude(False, *args, **kwargs)
  File "C:\Python372\mecheck\lib\site-packages\django\db\models\query.py", line 862, in _filter_or_exclude
    clone.query.add_q(Q(*args, **kwargs))
  File "C:\Python372\mecheck\lib\site-packages\django\db\models\sql\query.py", line 1263, in add_q
    clause, _ = self._add_q(q_object, self.used_aliases)
  File "C:\Python372\mecheck\lib\site-packages\django\db\models\sql\query.py", line 1287, in _add_q
    split_subq=split_subq,
  File "C:\Python372\mecheck\lib\site-packages\django\db\models\sql\query.py", line 1225, in build_filter
    condition = self.build_lookup(lookups, col, value)
  File "C:\Python372\mecheck\lib\site-packages\django\db\models\sql\query.py", line 1096, in build_lookup
    lookup = lookup_class(lhs, rhs)
  File "C:\Python372\mecheck\lib\site-packages\django\db\models\lookups.py", line 20, in __init__
    self.rhs = self.get_prep_lookup()
  File "C:\Python372\mecheck\lib\site-packages\django\db\models\lookups.py", line 70, in get_prep_lookup
    return self.lhs.output_field.get_prep_value(self.rhs)
  File "C:\Python372\mecheck\lib\site-packages\django\db\models\fields\__init__.py", line 1268, in get_prep_value
    return self.to_python(value)
  File "C:\Python372\mecheck\lib\site-packages\django\db\models\fields\__init__.py", line 1230, in to_python
    parsed = parse_date(value)
  File "C:\Python372\mecheck\lib\site-packages\django\utils\dateparse.py", line 74, in parse_date
    match = date_re.match(value)
TypeError: expected string or bytes-like object
[2024-06-20 13:21:01,998] [runserver.py:154] [runserver:log_action] [ERROR]- HTTP POST /INVGantt/INVGantt-upload/ 500 [7.76, 127.0.0.1:54336]
