[2020-05-11 12:15:34,284] [log.py:228] [log:log_response] [ERROR]- Internal Server Error: /TestPlanSW/TestPlanSW-summary/
Traceback (most recent call last):
  File "C:\Python372\mecheck\lib\site-packages\django\core\handlers\exception.py", line 34, in inner
    response = get_response(request)
  File "C:\Python372\mecheck\lib\site-packages\django\core\handlers\base.py", line 126, in _get_response
    response = self.process_exception_by_middleware(e, request)
  File "C:\Python372\mecheck\lib\site-packages\django\core\handlers\base.py", line 124, in _get_response
    response = wrapped_callback(request, *callback_args, **callback_kwargs)
  File "C:\djangoproject\Reliability_Row_data\TestPlanSW\views.py", line 201, in TestPlanSW_summary
    CRTsum = TestPlanSW.objects.filter(Projectinfo=check_dic).aggregate(
  File "C:\Python372\mecheck\lib\site-packages\django\db\models\manager.py", line 82, in manager_method
    return getattr(self.get_queryset(), name)(*args, **kwargs)
  File "C:\Python372\mecheck\lib\site-packages\django\db\models\query.py", line 844, in filter
    return self._filter_or_exclude(False, *args, **kwargs)
  File "C:\Python372\mecheck\lib\site-packages\django\db\models\query.py", line 862, in _filter_or_exclude
    clone.query.add_q(Q(*args, **kwargs))
  File "C:\Python372\mecheck\lib\site-packages\django\db\models\sql\query.py", line 1263, in add_q
    clause, _ = self._add_q(q_object, self.used_aliases)
  File "C:\Python372\mecheck\lib\site-packages\django\db\models\sql\query.py", line 1287, in _add_q
    split_subq=split_subq,
  File "C:\Python372\mecheck\lib\site-packages\django\db\models\sql\query.py", line 1225, in build_filter
    condition = self.build_lookup(lookups, col, value)
  File "C:\Python372\mecheck\lib\site-packages\django\db\models\sql\query.py", line 1096, in build_lookup
    lookup = lookup_class(lhs, rhs)
  File "C:\Python372\mecheck\lib\site-packages\django\db\models\lookups.py", line 20, in __init__
    self.rhs = self.get_prep_lookup()
  File "C:\Python372\mecheck\lib\site-packages\django\db\models\fields\related_lookups.py", line 115, in get_prep_lookup
    self.rhs = target_field.get_prep_value(self.rhs)
  File "C:\Python372\mecheck\lib\site-packages\django\db\models\fields\__init__.py", line 965, in get_prep_value
    return int(value)
TypeError: int() argument must be a string, a bytes-like object or a number, not 'dict'
[2020-05-11 12:15:34,291] [basehttp.py:154] [basehttp:log_message] [ERROR]- "POST /TestPlanSW/TestPlanSW-summary/ HTTP/1.1" 500 129388
[2020-05-11 13:18:33,301] [log.py:228] [log:log_response] [ERROR]- Internal Server Error: /TestPlanSW/TestPlanSW-summary/
Traceback (most recent call last):
  File "C:\Python372\mecheck\lib\site-packages\django\core\handlers\exception.py", line 34, in inner
    response = get_response(request)
  File "C:\Python372\mecheck\lib\site-packages\django\core\handlers\base.py", line 126, in _get_response
    response = self.process_exception_by_middleware(e, request)
  File "C:\Python372\mecheck\lib\site-packages\django\core\handlers\base.py", line 124, in _get_response
    response = wrapped_callback(request, *callback_args, **callback_kwargs)
  File "C:\djangoproject\Reliability_Row_data\TestPlanSW\views.py", line 202, in TestPlanSW_summary
    CRTsum = TestPlanSW.objects.filter(Projectinfo=check_dic).aggregate(
  File "C:\Python372\mecheck\lib\site-packages\django\db\models\manager.py", line 82, in manager_method
    return getattr(self.get_queryset(), name)(*args, **kwargs)
  File "C:\Python372\mecheck\lib\site-packages\django\db\models\query.py", line 844, in filter
    return self._filter_or_exclude(False, *args, **kwargs)
  File "C:\Python372\mecheck\lib\site-packages\django\db\models\query.py", line 862, in _filter_or_exclude
    clone.query.add_q(Q(*args, **kwargs))
  File "C:\Python372\mecheck\lib\site-packages\django\db\models\sql\query.py", line 1263, in add_q
    clause, _ = self._add_q(q_object, self.used_aliases)
  File "C:\Python372\mecheck\lib\site-packages\django\db\models\sql\query.py", line 1287, in _add_q
    split_subq=split_subq,
  File "C:\Python372\mecheck\lib\site-packages\django\db\models\sql\query.py", line 1225, in build_filter
    condition = self.build_lookup(lookups, col, value)
  File "C:\Python372\mecheck\lib\site-packages\django\db\models\sql\query.py", line 1096, in build_lookup
    lookup = lookup_class(lhs, rhs)
  File "C:\Python372\mecheck\lib\site-packages\django\db\models\lookups.py", line 20, in __init__
    self.rhs = self.get_prep_lookup()
  File "C:\Python372\mecheck\lib\site-packages\django\db\models\fields\related_lookups.py", line 115, in get_prep_lookup
    self.rhs = target_field.get_prep_value(self.rhs)
  File "C:\Python372\mecheck\lib\site-packages\django\db\models\fields\__init__.py", line 965, in get_prep_value
    return int(value)
TypeError: int() argument must be a string, a bytes-like object or a number, not 'dict'
[2020-05-11 13:18:33,309] [basehttp.py:154] [basehttp:log_message] [ERROR]- "POST /TestPlanSW/TestPlanSW-summary/ HTTP/1.1" 500 129399
[2020-05-11 13:44:47,706] [log.py:228] [log:log_response] [ERROR]- Internal Server Error: /CQM/CQM_edit/
Traceback (most recent call last):
  File "C:\Python372\mecheck\lib\site-packages\django\core\handlers\exception.py", line 34, in inner
    response = get_response(request)
  File "C:\Python372\mecheck\lib\site-packages\django\core\handlers\base.py", line 126, in _get_response
    response = self.process_exception_by_middleware(e, request)
  File "C:\Python372\mecheck\lib\site-packages\django\core\handlers\base.py", line 124, in _get_response
    response = wrapped_callback(request, *callback_args, **callback_kwargs)
  File "C:\Python372\mecheck\lib\site-packages\django\views\decorators\csrf.py", line 54, in wrapped_view
    return view_func(*args, **kwargs)
  File "C:\djangoproject\Reliability_Row_data\CQM\views.py", line 479, in CQM_edit
    Changecontent = i + ":" + datadic[i]
TypeError: can only concatenate str (not "NoneType") to str
[2020-05-11 13:44:47,712] [basehttp.py:154] [basehttp:log_message] [ERROR]- "POST /CQM/CQM_edit/ HTTP/1.1" 500 83337
[2020-05-11 13:55:03,680] [log.py:228] [log:log_response] [ERROR]- Internal Server Error: /admin/CQM/cqm/
Traceback (most recent call last):
  File "C:\Python372\mecheck\lib\site-packages\django\core\handlers\exception.py", line 34, in inner
    response = get_response(request)
  File "C:\Python372\mecheck\lib\site-packages\django\core\handlers\base.py", line 126, in _get_response
    response = self.process_exception_by_middleware(e, request)
  File "C:\Python372\mecheck\lib\site-packages\django\core\handlers\base.py", line 124, in _get_response
    response = wrapped_callback(request, *callback_args, **callback_kwargs)
  File "C:\Python372\mecheck\lib\site-packages\django\contrib\admin\options.py", line 604, in wrapper
    return self.admin_site.admin_view(view)(*args, **kwargs)
  File "C:\Python372\mecheck\lib\site-packages\django\utils\decorators.py", line 142, in _wrapped_view
    response = view_func(request, *args, **kwargs)
  File "C:\Python372\mecheck\lib\site-packages\django\views\decorators\cache.py", line 44, in _wrapped_view_func
    response = view_func(request, *args, **kwargs)
  File "C:\Python372\mecheck\lib\site-packages\django\contrib\admin\sites.py", line 223, in inner
    return view(request, *args, **kwargs)
  File "C:\Python372\mecheck\lib\site-packages\django\utils\decorators.py", line 45, in _wrapper
    return bound_method(*args, **kwargs)
  File "C:\Python372\mecheck\lib\site-packages\django\utils\decorators.py", line 142, in _wrapped_view
    response = view_func(request, *args, **kwargs)
  File "C:\Python372\mecheck\lib\site-packages\django\contrib\admin\options.py", line 1675, in changelist_view
    cl = self.get_changelist_instance(request)
  File "C:\Python372\mecheck\lib\site-packages\django\contrib\admin\options.py", line 742, in get_changelist_instance
    sortable_by,
  File "C:\Python372\mecheck\lib\site-packages\django\contrib\admin\views\main.py", line 80, in __init__
    self.queryset = self.get_queryset(request)
  File "C:\Python372\mecheck\lib\site-packages\django\contrib\admin\views\main.py", line 393, in get_queryset
    qs, search_use_distinct = self.model_admin.get_search_results(request, qs, self.query)
  File "C:\Python372\mecheck\lib\site-packages\django\contrib\admin\options.py", line 1026, in get_search_results
    queryset = queryset.filter(reduce(operator.or_, or_queries))
  File "C:\Python372\mecheck\lib\site-packages\django\db\models\query.py", line 844, in filter
    return self._filter_or_exclude(False, *args, **kwargs)
  File "C:\Python372\mecheck\lib\site-packages\django\db\models\query.py", line 862, in _filter_or_exclude
    clone.query.add_q(Q(*args, **kwargs))
  File "C:\Python372\mecheck\lib\site-packages\django\db\models\sql\query.py", line 1263, in add_q
    clause, _ = self._add_q(q_object, self.used_aliases)
  File "C:\Python372\mecheck\lib\site-packages\django\db\models\sql\query.py", line 1281, in _add_q
    current_negated, allow_joins, split_subq)
  File "C:\Python372\mecheck\lib\site-packages\django\db\models\sql\query.py", line 1287, in _add_q
    split_subq=split_subq,
  File "C:\Python372\mecheck\lib\site-packages\django\db\models\sql\query.py", line 1164, in build_filter
    lookups, parts, reffed_expression = self.solve_lookup_type(arg)
  File "C:\Python372\mecheck\lib\site-packages\django\db\models\sql\query.py", line 1028, in solve_lookup_type
    _, field, _, lookup_parts = self.names_to_path(lookup_splitted, self.get_meta())
  File "C:\Python372\mecheck\lib\site-packages\django\db\models\sql\query.py", line 1389, in names_to_path
    "Choices are: %s" % (name, ", ".join(available)))
django.core.exceptions.FieldError: Cannot resolve keyword 'result' into field. Choices are: Character, Comments, Compal_R1_PN, Compal_R3_PN, Compatibility, Controlrun, Customer, EMI, ESD, FW, HW, Keyparts, Material_Group, PID, PMsummary, Phase, Project, Projectinfo, Projectinfo_id, R1_PN_Description, RD1, RD2, RD3, RD4, RD5, RD6, RF, Reliability, Supplier, Testresult, VID, cqm_history, edit_time, editor, id
[2020-05-11 13:55:03,689] [basehttp.py:154] [basehttp:log_message] [ERROR]- "GET /admin/CQM/cqm/?q=EL432 HTTP/1.1" 500 178732
[2020-05-11 14:02:52,384] [log.py:228] [log:log_response] [ERROR]- Internal Server Error: /TestPlanSW/TestPlanSW-summary/
Traceback (most recent call last):
  File "C:\Python372\mecheck\lib\site-packages\django\core\handlers\exception.py", line 34, in inner
    response = get_response(request)
  File "C:\Python372\mecheck\lib\site-packages\django\core\handlers\base.py", line 126, in _get_response
    response = self.process_exception_by_middleware(e, request)
  File "C:\Python372\mecheck\lib\site-packages\django\core\handlers\base.py", line 124, in _get_response
    response = wrapped_callback(request, *callback_args, **callback_kwargs)
  File "C:\djangoproject\Reliability_Row_data\TestPlanSW\views.py", line 202, in TestPlanSW_summary
    CRTsum = TestPlanSW.objects.filter(Projectinfo=check_dic).aggregate(
  File "C:\Python372\mecheck\lib\site-packages\django\db\models\manager.py", line 82, in manager_method
    return getattr(self.get_queryset(), name)(*args, **kwargs)
  File "C:\Python372\mecheck\lib\site-packages\django\db\models\query.py", line 844, in filter
    return self._filter_or_exclude(False, *args, **kwargs)
  File "C:\Python372\mecheck\lib\site-packages\django\db\models\query.py", line 862, in _filter_or_exclude
    clone.query.add_q(Q(*args, **kwargs))
  File "C:\Python372\mecheck\lib\site-packages\django\db\models\sql\query.py", line 1263, in add_q
    clause, _ = self._add_q(q_object, self.used_aliases)
  File "C:\Python372\mecheck\lib\site-packages\django\db\models\sql\query.py", line 1287, in _add_q
    split_subq=split_subq,
  File "C:\Python372\mecheck\lib\site-packages\django\db\models\sql\query.py", line 1225, in build_filter
    condition = self.build_lookup(lookups, col, value)
  File "C:\Python372\mecheck\lib\site-packages\django\db\models\sql\query.py", line 1096, in build_lookup
    lookup = lookup_class(lhs, rhs)
  File "C:\Python372\mecheck\lib\site-packages\django\db\models\lookups.py", line 20, in __init__
    self.rhs = self.get_prep_lookup()
  File "C:\Python372\mecheck\lib\site-packages\django\db\models\fields\related_lookups.py", line 115, in get_prep_lookup
    self.rhs = target_field.get_prep_value(self.rhs)
  File "C:\Python372\mecheck\lib\site-packages\django\db\models\fields\__init__.py", line 965, in get_prep_value
    return int(value)
TypeError: int() argument must be a string, a bytes-like object or a number, not 'dict'
[2020-05-11 14:02:52,393] [basehttp.py:154] [basehttp:log_message] [ERROR]- "POST /TestPlanSW/TestPlanSW-summary/ HTTP/1.1" 500 129399
[2020-05-11 14:02:53,910] [log.py:228] [log:log_response] [ERROR]- Internal Server Error: /TestPlanSW/TestPlanSW-summary/
Traceback (most recent call last):
  File "C:\Python372\mecheck\lib\site-packages\django\core\handlers\exception.py", line 34, in inner
    response = get_response(request)
  File "C:\Python372\mecheck\lib\site-packages\django\core\handlers\base.py", line 126, in _get_response
    response = self.process_exception_by_middleware(e, request)
  File "C:\Python372\mecheck\lib\site-packages\django\core\handlers\base.py", line 124, in _get_response
    response = wrapped_callback(request, *callback_args, **callback_kwargs)
  File "C:\djangoproject\Reliability_Row_data\TestPlanSW\views.py", line 202, in TestPlanSW_summary
    CRTsum = TestPlanSW.objects.filter(Projectinfo=check_dic).aggregate(
  File "C:\Python372\mecheck\lib\site-packages\django\db\models\manager.py", line 82, in manager_method
    return getattr(self.get_queryset(), name)(*args, **kwargs)
  File "C:\Python372\mecheck\lib\site-packages\django\db\models\query.py", line 844, in filter
    return self._filter_or_exclude(False, *args, **kwargs)
  File "C:\Python372\mecheck\lib\site-packages\django\db\models\query.py", line 862, in _filter_or_exclude
    clone.query.add_q(Q(*args, **kwargs))
  File "C:\Python372\mecheck\lib\site-packages\django\db\models\sql\query.py", line 1263, in add_q
    clause, _ = self._add_q(q_object, self.used_aliases)
  File "C:\Python372\mecheck\lib\site-packages\django\db\models\sql\query.py", line 1287, in _add_q
    split_subq=split_subq,
  File "C:\Python372\mecheck\lib\site-packages\django\db\models\sql\query.py", line 1225, in build_filter
    condition = self.build_lookup(lookups, col, value)
  File "C:\Python372\mecheck\lib\site-packages\django\db\models\sql\query.py", line 1096, in build_lookup
    lookup = lookup_class(lhs, rhs)
  File "C:\Python372\mecheck\lib\site-packages\django\db\models\lookups.py", line 20, in __init__
    self.rhs = self.get_prep_lookup()
  File "C:\Python372\mecheck\lib\site-packages\django\db\models\fields\related_lookups.py", line 115, in get_prep_lookup
    self.rhs = target_field.get_prep_value(self.rhs)
  File "C:\Python372\mecheck\lib\site-packages\django\db\models\fields\__init__.py", line 965, in get_prep_value
    return int(value)
TypeError: int() argument must be a string, a bytes-like object or a number, not 'dict'
[2020-05-11 14:02:53,912] [basehttp.py:154] [basehttp:log_message] [ERROR]- "POST /TestPlanSW/TestPlanSW-summary/ HTTP/1.1" 500 129399
[2020-05-11 14:20:14,482] [log.py:228] [log:log_response] [ERROR]- Internal Server Error: /TestPlanSW/TestPlanSW-summary/
Traceback (most recent call last):
  File "C:\Python372\mecheck\lib\site-packages\django\core\handlers\exception.py", line 34, in inner
    response = get_response(request)
  File "C:\Python372\mecheck\lib\site-packages\django\core\handlers\base.py", line 126, in _get_response
    response = self.process_exception_by_middleware(e, request)
  File "C:\Python372\mecheck\lib\site-packages\django\core\handlers\base.py", line 124, in _get_response
    response = wrapped_callback(request, *callback_args, **callback_kwargs)
  File "C:\djangoproject\Reliability_Row_data\TestPlanSW\views.py", line 202, in TestPlanSW_summary
    CRTsum = TestPlanSW.objects.filter(Projectinfo=check_dic).aggregate(Sum('ConfigRetestTime'))
  File "C:\Python372\mecheck\lib\site-packages\django\db\models\manager.py", line 82, in manager_method
    return getattr(self.get_queryset(), name)(*args, **kwargs)
  File "C:\Python372\mecheck\lib\site-packages\django\db\models\query.py", line 844, in filter
    return self._filter_or_exclude(False, *args, **kwargs)
  File "C:\Python372\mecheck\lib\site-packages\django\db\models\query.py", line 862, in _filter_or_exclude
    clone.query.add_q(Q(*args, **kwargs))
  File "C:\Python372\mecheck\lib\site-packages\django\db\models\sql\query.py", line 1263, in add_q
    clause, _ = self._add_q(q_object, self.used_aliases)
  File "C:\Python372\mecheck\lib\site-packages\django\db\models\sql\query.py", line 1287, in _add_q
    split_subq=split_subq,
  File "C:\Python372\mecheck\lib\site-packages\django\db\models\sql\query.py", line 1225, in build_filter
    condition = self.build_lookup(lookups, col, value)
  File "C:\Python372\mecheck\lib\site-packages\django\db\models\sql\query.py", line 1096, in build_lookup
    lookup = lookup_class(lhs, rhs)
  File "C:\Python372\mecheck\lib\site-packages\django\db\models\lookups.py", line 20, in __init__
    self.rhs = self.get_prep_lookup()
  File "C:\Python372\mecheck\lib\site-packages\django\db\models\fields\related_lookups.py", line 115, in get_prep_lookup
    self.rhs = target_field.get_prep_value(self.rhs)
  File "C:\Python372\mecheck\lib\site-packages\django\db\models\fields\__init__.py", line 965, in get_prep_value
    return int(value)
TypeError: int() argument must be a string, a bytes-like object or a number, not 'dict'
[2020-05-11 14:20:14,500] [basehttp.py:154] [basehttp:log_message] [ERROR]- "POST /TestPlanSW/TestPlanSW-summary/ HTTP/1.1" 500 129471
[2020-05-11 16:26:02,420] [log.py:228] [log:log_response] [ERROR]- Internal Server Error: /TestPlanSW/TestPlanSW-summary/
Traceback (most recent call last):
  File "C:\Python372\mecheck\lib\site-packages\django\core\handlers\exception.py", line 34, in inner
    response = get_response(request)
  File "C:\Python372\mecheck\lib\site-packages\django\core\handlers\base.py", line 126, in _get_response
    response = self.process_exception_by_middleware(e, request)
  File "C:\Python372\mecheck\lib\site-packages\django\core\handlers\base.py", line 124, in _get_response
    response = wrapped_callback(request, *callback_args, **callback_kwargs)
  File "C:\djangoproject\Reliability_Row_data\TestPlanSW\views.py", line 267, in TestPlanSW_summary
    FFRTByRD.objects.filter(**check_dic_Pro).first().create(**createFFRT)
AttributeError: 'NoneType' object has no attribute 'create'
[2020-05-11 16:26:02,425] [basehttp.py:154] [basehttp:log_message] [ERROR]- "POST /TestPlanSW/TestPlanSW-summary/ HTTP/1.1" 500 76034
[2020-05-11 16:26:04,363] [log.py:228] [log:log_response] [ERROR]- Internal Server Error: /TestPlanSW/TestPlanSW-summary/
Traceback (most recent call last):
  File "C:\Python372\mecheck\lib\site-packages\django\core\handlers\exception.py", line 34, in inner
    response = get_response(request)
  File "C:\Python372\mecheck\lib\site-packages\django\core\handlers\base.py", line 126, in _get_response
    response = self.process_exception_by_middleware(e, request)
  File "C:\Python372\mecheck\lib\site-packages\django\core\handlers\base.py", line 124, in _get_response
    response = wrapped_callback(request, *callback_args, **callback_kwargs)
  File "C:\djangoproject\Reliability_Row_data\TestPlanSW\views.py", line 308, in TestPlanSW_summary
    {"Functionteam":"EC","Quantity":FFRTByRDinfo.EC},
AttributeError: 'NoneType' object has no attribute 'EC'
[2020-05-11 16:26:04,366] [basehttp.py:154] [basehttp:log_message] [ERROR]- "POST /TestPlanSW/TestPlanSW-summary/ HTTP/1.1" 500 76523
[2020-05-11 16:30:45,891] [log.py:228] [log:log_response] [ERROR]- Internal Server Error: /TestPlanSW/TestPlanSW-summary/
Traceback (most recent call last):
  File "C:\Python372\mecheck\lib\site-packages\django\core\handlers\exception.py", line 34, in inner
    response = get_response(request)
  File "C:\Python372\mecheck\lib\site-packages\django\core\handlers\base.py", line 126, in _get_response
    response = self.process_exception_by_middleware(e, request)
  File "C:\Python372\mecheck\lib\site-packages\django\core\handlers\base.py", line 124, in _get_response
    response = wrapped_callback(request, *callback_args, **callback_kwargs)
  File "C:\djangoproject\Reliability_Row_data\TestPlanSW\views.py", line 267, in TestPlanSW_summary
    FFRTByRD.objects.get(**check_dic_Pro).create(**createFFRT)
  File "C:\Python372\mecheck\lib\site-packages\django\db\models\manager.py", line 82, in manager_method
    return getattr(self.get_queryset(), name)(*args, **kwargs)
  File "C:\Python372\mecheck\lib\site-packages\django\db\models\query.py", line 399, in get
    self.model._meta.object_name
TestPlanSW.models.FFRTByRD.DoesNotExist: FFRTByRD matching query does not exist.
[2020-05-11 16:30:45,899] [basehttp.py:154] [basehttp:log_message] [ERROR]- "POST /TestPlanSW/TestPlanSW-summary/ HTTP/1.1" 500 84410
[2020-05-11 16:31:23,488] [log.py:228] [log:log_response] [ERROR]- Internal Server Error: /TestPlanSW/TestPlanSW-summary/
Traceback (most recent call last):
  File "C:\Python372\mecheck\lib\site-packages\django\core\handlers\exception.py", line 34, in inner
    response = get_response(request)
  File "C:\Python372\mecheck\lib\site-packages\django\core\handlers\base.py", line 126, in _get_response
    response = self.process_exception_by_middleware(e, request)
  File "C:\Python372\mecheck\lib\site-packages\django\core\handlers\base.py", line 124, in _get_response
    response = wrapped_callback(request, *callback_args, **callback_kwargs)
  File "C:\djangoproject\Reliability_Row_data\TestPlanSW\views.py", line 267, in TestPlanSW_summary
    FFRTByRD.objects.create(**createFFRT)
  File "C:\Python372\mecheck\lib\site-packages\django\db\models\manager.py", line 82, in manager_method
    return getattr(self.get_queryset(), name)(*args, **kwargs)
  File "C:\Python372\mecheck\lib\site-packages\django\db\models\query.py", line 411, in create
    obj = self.model(**kwargs)
  File "C:\Python372\mecheck\lib\site-packages\django\db\models\base.py", line 485, in __init__
    raise TypeError("'%s' is an invalid keyword argument for this function" % kwarg)
TypeError: 'Thermal' is an invalid keyword argument for this function
[2020-05-11 16:31:23,495] [basehttp.py:154] [basehttp:log_message] [ERROR]- "POST /TestPlanSW/TestPlanSW-summary/ HTTP/1.1" 500 90680
[2020-05-11 16:34:32,381] [log.py:228] [log:log_response] [ERROR]- Internal Server Error: /TestPlanSW/TestPlanSW-summary/
Traceback (most recent call last):
  File "C:\Python372\mecheck\lib\site-packages\django\core\handlers\exception.py", line 34, in inner
    response = get_response(request)
  File "C:\Python372\mecheck\lib\site-packages\django\core\handlers\base.py", line 126, in _get_response
    response = self.process_exception_by_middleware(e, request)
  File "C:\Python372\mecheck\lib\site-packages\django\core\handlers\base.py", line 124, in _get_response
    response = wrapped_callback(request, *callback_args, **callback_kwargs)
  File "C:\djangoproject\Reliability_Row_data\TestPlanSW\views.py", line 278, in TestPlanSW_summary
    {"Functionteam": "Thermal", "Quantity": FFRTByRDinfo.Themal},
AttributeError: 'FFRTByRD' object has no attribute 'Themal'
[2020-05-11 16:34:32,390] [basehttp.py:154] [basehttp:log_message] [ERROR]- "POST /TestPlanSW/TestPlanSW-summary/ HTTP/1.1" 500 76255
[2020-05-11 16:35:16,307] [log.py:228] [log:log_response] [ERROR]- Internal Server Error: /TestPlanSW/TestPlanSW-summary/
Traceback (most recent call last):
  File "C:\Python372\mecheck\lib\site-packages\django\core\handlers\exception.py", line 34, in inner
    response = get_response(request)
  File "C:\Python372\mecheck\lib\site-packages\django\core\handlers\base.py", line 126, in _get_response
    response = self.process_exception_by_middleware(e, request)
  File "C:\Python372\mecheck\lib\site-packages\django\core\handlers\base.py", line 124, in _get_response
    response = wrapped_callback(request, *callback_args, **callback_kwargs)
  File "C:\djangoproject\Reliability_Row_data\TestPlanSW\views.py", line 304, in TestPlanSW_summary
    FFRTByRD.objects.filter(**check_dic_Pro).first().update(**updatedic)
AttributeError: 'FFRTByRD' object has no attribute 'update'
[2020-05-11 16:35:16,311] [basehttp.py:154] [basehttp:log_message] [ERROR]- "POST /TestPlanSW/TestPlanSW-summary/ HTTP/1.1" 500 76132
[2020-05-11 16:36:16,313] [log.py:228] [log:log_response] [ERROR]- Internal Server Error: /TestPlanSW/TestPlanSW-summary/
Traceback (most recent call last):
  File "C:\Python372\mecheck\lib\site-packages\django\core\handlers\exception.py", line 34, in inner
    response = get_response(request)
  File "C:\Python372\mecheck\lib\site-packages\django\core\handlers\base.py", line 126, in _get_response
    response = self.process_exception_by_middleware(e, request)
  File "C:\Python372\mecheck\lib\site-packages\django\core\handlers\base.py", line 124, in _get_response
    response = wrapped_callback(request, *callback_args, **callback_kwargs)
  File "C:\djangoproject\Reliability_Row_data\TestPlanSW\views.py", line 304, in TestPlanSW_summary
    FFRTByRD.objects.get(**check_dic_Pro).update(**updatedic)
AttributeError: 'FFRTByRD' object has no attribute 'update'
[2020-05-11 16:36:16,317] [basehttp.py:154] [basehttp:log_message] [ERROR]- "POST /TestPlanSW/TestPlanSW-summary/ HTTP/1.1" 500 76110
[2020-05-11 16:38:08,923] [log.py:228] [log:log_response] [ERROR]- Internal Server Error: /TestPlanSW/TestPlanSW-summary/
Traceback (most recent call last):
  File "C:\Python372\mecheck\lib\site-packages\django\core\handlers\exception.py", line 34, in inner
    response = get_response(request)
  File "C:\Python372\mecheck\lib\site-packages\django\core\handlers\base.py", line 126, in _get_response
    response = self.process_exception_by_middleware(e, request)
  File "C:\Python372\mecheck\lib\site-packages\django\core\handlers\base.py", line 124, in _get_response
    response = wrapped_callback(request, *callback_args, **callback_kwargs)
  File "C:\djangoproject\Reliability_Row_data\TestPlanSW\views.py", line 219, in TestPlanSW_summary
    "Themal": FFRTByRDinfo.Themal, "Power": FFRTByRDinfo.Power, "SED": FFRTByRDinfo.SED,}
AttributeError: 'FFRTByRD' object has no attribute 'Themal'
[2020-05-11 16:38:08,927] [basehttp.py:154] [basehttp:log_message] [ERROR]- "POST /TestPlanSW/TestPlanSW-summary/ HTTP/1.1" 500 77124
