[2021-02-26 08:51:55,411] [log.py:228] [log:log_response] [ERROR]- Internal Server Error: /AdapterPowerCode/M_edit/
Traceback (most recent call last):
  File "C:\Python372\mecheck\lib\site-packages\django\core\handlers\exception.py", line 34, in inner
    response = get_response(request)
  File "C:\Python372\mecheck\lib\site-packages\django\core\handlers\base.py", line 126, in _get_response
    response = self.process_exception_by_middleware(e, request)
  File "C:\Python372\mecheck\lib\site-packages\django\core\handlers\base.py", line 124, in _get_response
    response = wrapped_callback(request, *callback_args, **callback_kwargs)
  File "C:\Python372\mecheck\lib\site-packages\django\views\decorators\csrf.py", line 54, in wrapped_view
    return view_func(*args, **kwargs)
  File "C:\djangoproject\DMS\AdapterPowerCode\views.py", line 792, in M_edit
    return HttpResponse(json.dumps(data), content_type="application/json")
  File "C:\Python372\lib\json\__init__.py", line 231, in dumps
    return _default_encoder.encode(obj)
  File "C:\Python372\lib\json\encoder.py", line 199, in encode
    chunks = self.iterencode(o, _one_shot=True)
  File "C:\Python372\lib\json\encoder.py", line 257, in iterencode
    return _iterencode(o, 0)
  File "C:\Python372\lib\json\encoder.py", line 179, in default
    raise TypeError(f'Object of type {o.__class__.__name__} '
TypeError: Object of type date is not JSON serializable
[2021-02-26 08:51:55,413] [basehttp.py:154] [basehttp:log_message] [ERROR]- "POST /AdapterPowerCode/M_edit/ HTTP/1.1" 500 136557
[2021-02-26 10:08:12,403] [log.py:228] [log:log_response] [ERROR]- Internal Server Error: /AdapterPowerCode/M_edit/
Traceback (most recent call last):
  File "C:\Python372\mecheck\lib\site-packages\django\core\handlers\exception.py", line 34, in inner
    response = get_response(request)
  File "C:\Python372\mecheck\lib\site-packages\django\core\handlers\base.py", line 126, in _get_response
    response = self.process_exception_by_middleware(e, request)
  File "C:\Python372\mecheck\lib\site-packages\django\core\handlers\base.py", line 124, in _get_response
    response = wrapped_callback(request, *callback_args, **callback_kwargs)
  File "C:\Python372\mecheck\lib\site-packages\django\views\decorators\csrf.py", line 54, in wrapped_view
    return view_func(*args, **kwargs)
  File "C:\djangoproject\DMS\AdapterPowerCode\views.py", line 661, in M_edit
    AdapterPowerCode.objects.filter(id=id).update(**updatedic)
  File "C:\Python372\mecheck\lib\site-packages\django\db\models\manager.py", line 82, in manager_method
    return getattr(self.get_queryset(), name)(*args, **kwargs)
  File "C:\Python372\mecheck\lib\site-packages\django\db\models\query.py", line 844, in filter
    return self._filter_or_exclude(False, *args, **kwargs)
  File "C:\Python372\mecheck\lib\site-packages\django\db\models\query.py", line 862, in _filter_or_exclude
    clone.query.add_q(Q(*args, **kwargs))
  File "C:\Python372\mecheck\lib\site-packages\django\db\models\sql\query.py", line 1263, in add_q
    clause, _ = self._add_q(q_object, self.used_aliases)
  File "C:\Python372\mecheck\lib\site-packages\django\db\models\sql\query.py", line 1287, in _add_q
    split_subq=split_subq,
  File "C:\Python372\mecheck\lib\site-packages\django\db\models\sql\query.py", line 1225, in build_filter
    condition = self.build_lookup(lookups, col, value)
  File "C:\Python372\mecheck\lib\site-packages\django\db\models\sql\query.py", line 1096, in build_lookup
    lookup = lookup_class(lhs, rhs)
  File "C:\Python372\mecheck\lib\site-packages\django\db\models\lookups.py", line 20, in __init__
    self.rhs = self.get_prep_lookup()
  File "C:\Python372\mecheck\lib\site-packages\django\db\models\lookups.py", line 70, in get_prep_lookup
    return self.lhs.output_field.get_prep_value(self.rhs)
  File "C:\Python372\mecheck\lib\site-packages\django\db\models\fields\__init__.py", line 965, in get_prep_value
    return int(value)
ValueError: invalid literal for int() with base 10: ''
[2021-02-26 10:08:12,406] [basehttp.py:154] [basehttp:log_message] [ERROR]- "POST /AdapterPowerCode/M_edit/ HTTP/1.1" 500 139806
[2021-02-26 10:17:17,669] [log.py:228] [log:log_response] [ERROR]- Internal Server Error: /AdapterPowerCode/M_edit/
Traceback (most recent call last):
  File "C:\Python372\mecheck\lib\site-packages\django\core\handlers\exception.py", line 34, in inner
    response = get_response(request)
  File "C:\Python372\mecheck\lib\site-packages\django\core\handlers\base.py", line 126, in _get_response
    response = self.process_exception_by_middleware(e, request)
  File "C:\Python372\mecheck\lib\site-packages\django\core\handlers\base.py", line 124, in _get_response
    response = wrapped_callback(request, *callback_args, **callback_kwargs)
  File "C:\Python372\mecheck\lib\site-packages\django\views\decorators\csrf.py", line 54, in wrapped_view
    return view_func(*args, **kwargs)
  File "C:\djangoproject\DMS\AdapterPowerCode\views.py", line 664, in M_edit
    AdapterPowerCode.objects.filter(id=id).update(**updatedic)
  File "C:\Python372\mecheck\lib\site-packages\django\db\models\query.py", line 693, in update
    rows = query.get_compiler(self.db).execute_sql(CURSOR)
  File "C:\Python372\mecheck\lib\site-packages\django\db\models\sql\compiler.py", line 1383, in execute_sql
    cursor = super().execute_sql(result_type)
  File "C:\Python372\mecheck\lib\site-packages\django\db\models\sql\compiler.py", line 1052, in execute_sql
    sql, params = self.as_sql()
  File "C:\Python372\mecheck\lib\site-packages\django\db\models\sql\compiler.py", line 1349, in as_sql
    val = field.get_db_prep_save(val, connection=self.connection)
  File "C:\Python372\mecheck\lib\site-packages\django\db\models\fields\__init__.py", line 790, in get_db_prep_save
    return self.get_db_prep_value(value, connection=connection, prepared=False)
  File "C:\Python372\mecheck\lib\site-packages\django\db\models\fields\__init__.py", line 1273, in get_db_prep_value
    value = self.get_prep_value(value)
  File "C:\Python372\mecheck\lib\site-packages\django\db\models\fields\__init__.py", line 1268, in get_prep_value
    return self.to_python(value)
  File "C:\Python372\mecheck\lib\site-packages\django\db\models\fields\__init__.py", line 1243, in to_python
    params={'value': value},
django.core.exceptions.ValidationError: ['’‘ 必须为合法的日期格式，请使用 YYYY-MM-DD 格式。']
[2021-02-26 10:17:17,672] [basehttp.py:154] [basehttp:log_message] [ERROR]- "POST /AdapterPowerCode/M_edit/ HTTP/1.1" 500 125309
[2021-02-26 10:20:41,876] [log.py:228] [log:log_response] [ERROR]- Internal Server Error: /AdapterPowerCode/M_edit/
Traceback (most recent call last):
  File "C:\Python372\mecheck\lib\site-packages\django\core\handlers\exception.py", line 34, in inner
    response = get_response(request)
  File "C:\Python372\mecheck\lib\site-packages\django\core\handlers\base.py", line 126, in _get_response
    response = self.process_exception_by_middleware(e, request)
  File "C:\Python372\mecheck\lib\site-packages\django\core\handlers\base.py", line 124, in _get_response
    response = wrapped_callback(request, *callback_args, **callback_kwargs)
  File "C:\Python372\mecheck\lib\site-packages\django\views\decorators\csrf.py", line 54, in wrapped_view
    return view_func(*args, **kwargs)
  File "C:\djangoproject\DMS\AdapterPowerCode\views.py", line 664, in M_edit
    AdapterPowerCode.objects.filter(id=id).update(**updatedic)
  File "C:\Python372\mecheck\lib\site-packages\django\db\models\query.py", line 693, in update
    rows = query.get_compiler(self.db).execute_sql(CURSOR)
  File "C:\Python372\mecheck\lib\site-packages\django\db\models\sql\compiler.py", line 1383, in execute_sql
    cursor = super().execute_sql(result_type)
  File "C:\Python372\mecheck\lib\site-packages\django\db\models\sql\compiler.py", line 1052, in execute_sql
    sql, params = self.as_sql()
  File "C:\Python372\mecheck\lib\site-packages\django\db\models\sql\compiler.py", line 1349, in as_sql
    val = field.get_db_prep_save(val, connection=self.connection)
  File "C:\Python372\mecheck\lib\site-packages\django\db\models\fields\__init__.py", line 790, in get_db_prep_save
    return self.get_db_prep_value(value, connection=connection, prepared=False)
  File "C:\Python372\mecheck\lib\site-packages\django\db\models\fields\__init__.py", line 1273, in get_db_prep_value
    value = self.get_prep_value(value)
  File "C:\Python372\mecheck\lib\site-packages\django\db\models\fields\__init__.py", line 1268, in get_prep_value
    return self.to_python(value)
  File "C:\Python372\mecheck\lib\site-packages\django\db\models\fields\__init__.py", line 1243, in to_python
    params={'value': value},
django.core.exceptions.ValidationError: ['’‘ 必须为合法的日期格式，请使用 YYYY-MM-DD 格式。']
[2021-02-26 10:20:41,877] [basehttp.py:154] [basehttp:log_message] [ERROR]- "POST /AdapterPowerCode/M_edit/ HTTP/1.1" 500 125309
[2021-02-26 10:30:10,500] [log.py:228] [log:log_response] [ERROR]- Internal Server Error: /AdapterPowerCode/M_edit/
Traceback (most recent call last):
  File "C:\Python372\mecheck\lib\site-packages\django\core\handlers\exception.py", line 34, in inner
    response = get_response(request)
  File "C:\Python372\mecheck\lib\site-packages\django\core\handlers\base.py", line 126, in _get_response
    response = self.process_exception_by_middleware(e, request)
  File "C:\Python372\mecheck\lib\site-packages\django\core\handlers\base.py", line 124, in _get_response
    response = wrapped_callback(request, *callback_args, **callback_kwargs)
  File "C:\Python372\mecheck\lib\site-packages\django\views\decorators\csrf.py", line 54, in wrapped_view
    return view_func(*args, **kwargs)
  File "C:\djangoproject\DMS\AdapterPowerCode\views.py", line 668, in M_edit
    AdapterPowerCode.objects.filter(id=id).update(**updatedic)
  File "C:\Python372\mecheck\lib\site-packages\django\db\models\query.py", line 693, in update
    rows = query.get_compiler(self.db).execute_sql(CURSOR)
  File "C:\Python372\mecheck\lib\site-packages\django\db\models\sql\compiler.py", line 1383, in execute_sql
    cursor = super().execute_sql(result_type)
  File "C:\Python372\mecheck\lib\site-packages\django\db\models\sql\compiler.py", line 1052, in execute_sql
    sql, params = self.as_sql()
  File "C:\Python372\mecheck\lib\site-packages\django\db\models\sql\compiler.py", line 1349, in as_sql
    val = field.get_db_prep_save(val, connection=self.connection)
  File "C:\Python372\mecheck\lib\site-packages\django\db\models\fields\__init__.py", line 790, in get_db_prep_save
    return self.get_db_prep_value(value, connection=connection, prepared=False)
  File "C:\Python372\mecheck\lib\site-packages\django\db\models\fields\__init__.py", line 1273, in get_db_prep_value
    value = self.get_prep_value(value)
  File "C:\Python372\mecheck\lib\site-packages\django\db\models\fields\__init__.py", line 1268, in get_prep_value
    return self.to_python(value)
  File "C:\Python372\mecheck\lib\site-packages\django\db\models\fields\__init__.py", line 1243, in to_python
    params={'value': value},
django.core.exceptions.ValidationError: ['’‘ 必须为合法的日期格式，请使用 YYYY-MM-DD 格式。']
[2021-02-26 10:30:10,503] [basehttp.py:154] [basehttp:log_message] [ERROR]- "POST /AdapterPowerCode/M_edit/ HTTP/1.1" 500 125293
[2021-02-26 10:32:32,886] [log.py:228] [log:log_response] [ERROR]- Internal Server Error: /AdapterPowerCode/M_edit/
Traceback (most recent call last):
  File "C:\Python372\mecheck\lib\site-packages\django\core\handlers\exception.py", line 34, in inner
    response = get_response(request)
  File "C:\Python372\mecheck\lib\site-packages\django\core\handlers\base.py", line 126, in _get_response
    response = self.process_exception_by_middleware(e, request)
  File "C:\Python372\mecheck\lib\site-packages\django\core\handlers\base.py", line 124, in _get_response
    response = wrapped_callback(request, *callback_args, **callback_kwargs)
  File "C:\Python372\mecheck\lib\site-packages\django\views\decorators\csrf.py", line 54, in wrapped_view
    return view_func(*args, **kwargs)
  File "C:\djangoproject\DMS\AdapterPowerCode\views.py", line 668, in M_edit
    AdapterPowerCode.objects.filter(id=id).update(**updatedic)
  File "C:\Python372\mecheck\lib\site-packages\django\db\models\query.py", line 693, in update
    rows = query.get_compiler(self.db).execute_sql(CURSOR)
  File "C:\Python372\mecheck\lib\site-packages\django\db\models\sql\compiler.py", line 1383, in execute_sql
    cursor = super().execute_sql(result_type)
  File "C:\Python372\mecheck\lib\site-packages\django\db\models\sql\compiler.py", line 1052, in execute_sql
    sql, params = self.as_sql()
  File "C:\Python372\mecheck\lib\site-packages\django\db\models\sql\compiler.py", line 1349, in as_sql
    val = field.get_db_prep_save(val, connection=self.connection)
  File "C:\Python372\mecheck\lib\site-packages\django\db\models\fields\__init__.py", line 790, in get_db_prep_save
    return self.get_db_prep_value(value, connection=connection, prepared=False)
  File "C:\Python372\mecheck\lib\site-packages\django\db\models\fields\__init__.py", line 1273, in get_db_prep_value
    value = self.get_prep_value(value)
  File "C:\Python372\mecheck\lib\site-packages\django\db\models\fields\__init__.py", line 1268, in get_prep_value
    return self.to_python(value)
  File "C:\Python372\mecheck\lib\site-packages\django\db\models\fields\__init__.py", line 1243, in to_python
    params={'value': value},
django.core.exceptions.ValidationError: ['’‘ 必须为合法的日期格式，请使用 YYYY-MM-DD 格式。']
[2021-02-26 10:32:32,889] [basehttp.py:154] [basehttp:log_message] [ERROR]- "POST /AdapterPowerCode/M_edit/ HTTP/1.1" 500 125287
[2021-02-26 10:33:19,350] [log.py:228] [log:log_response] [ERROR]- Internal Server Error: /AdapterPowerCode/M_edit/
Traceback (most recent call last):
  File "C:\Python372\mecheck\lib\site-packages\django\core\handlers\exception.py", line 34, in inner
    response = get_response(request)
  File "C:\Python372\mecheck\lib\site-packages\django\core\handlers\base.py", line 126, in _get_response
    response = self.process_exception_by_middleware(e, request)
  File "C:\Python372\mecheck\lib\site-packages\django\core\handlers\base.py", line 124, in _get_response
    response = wrapped_callback(request, *callback_args, **callback_kwargs)
  File "C:\Python372\mecheck\lib\site-packages\django\views\decorators\csrf.py", line 54, in wrapped_view
    return view_func(*args, **kwargs)
  File "C:\djangoproject\DMS\AdapterPowerCode\views.py", line 668, in M_edit
    AdapterPowerCode.objects.filter(id=id).update(**updatedic)
  File "C:\Python372\mecheck\lib\site-packages\django\db\models\query.py", line 693, in update
    rows = query.get_compiler(self.db).execute_sql(CURSOR)
  File "C:\Python372\mecheck\lib\site-packages\django\db\models\sql\compiler.py", line 1383, in execute_sql
    cursor = super().execute_sql(result_type)
  File "C:\Python372\mecheck\lib\site-packages\django\db\models\sql\compiler.py", line 1052, in execute_sql
    sql, params = self.as_sql()
  File "C:\Python372\mecheck\lib\site-packages\django\db\models\sql\compiler.py", line 1349, in as_sql
    val = field.get_db_prep_save(val, connection=self.connection)
  File "C:\Python372\mecheck\lib\site-packages\django\db\models\fields\__init__.py", line 790, in get_db_prep_save
    return self.get_db_prep_value(value, connection=connection, prepared=False)
  File "C:\Python372\mecheck\lib\site-packages\django\db\models\fields\__init__.py", line 1273, in get_db_prep_value
    value = self.get_prep_value(value)
  File "C:\Python372\mecheck\lib\site-packages\django\db\models\fields\__init__.py", line 1268, in get_prep_value
    return self.to_python(value)
  File "C:\Python372\mecheck\lib\site-packages\django\db\models\fields\__init__.py", line 1243, in to_python
    params={'value': value},
django.core.exceptions.ValidationError: ['’‘ 必须为合法的日期格式，请使用 YYYY-MM-DD 格式。']
[2021-02-26 10:33:19,351] [basehttp.py:154] [basehttp:log_message] [ERROR]- "POST /AdapterPowerCode/M_edit/ HTTP/1.1" 500 125287
[2021-02-26 10:44:05,431] [log.py:228] [log:log_response] [ERROR]- Internal Server Error: /AdapterPowerCode/M_edit/
Traceback (most recent call last):
  File "C:\Python372\mecheck\lib\site-packages\django\core\handlers\exception.py", line 34, in inner
    response = get_response(request)
  File "C:\Python372\mecheck\lib\site-packages\django\core\handlers\base.py", line 126, in _get_response
    response = self.process_exception_by_middleware(e, request)
  File "C:\Python372\mecheck\lib\site-packages\django\core\handlers\base.py", line 124, in _get_response
    response = wrapped_callback(request, *callback_args, **callback_kwargs)
  File "C:\Python372\mecheck\lib\site-packages\django\views\decorators\csrf.py", line 54, in wrapped_view
    return view_func(*args, **kwargs)
  File "C:\djangoproject\DMS\AdapterPowerCode\views.py", line 674, in M_edit
    AdapterPowerCode.objects.filter(id=id).update(**updatedic)
  File "C:\Python372\mecheck\lib\site-packages\django\db\models\query.py", line 693, in update
    rows = query.get_compiler(self.db).execute_sql(CURSOR)
  File "C:\Python372\mecheck\lib\site-packages\django\db\models\sql\compiler.py", line 1383, in execute_sql
    cursor = super().execute_sql(result_type)
  File "C:\Python372\mecheck\lib\site-packages\django\db\models\sql\compiler.py", line 1052, in execute_sql
    sql, params = self.as_sql()
  File "C:\Python372\mecheck\lib\site-packages\django\db\models\sql\compiler.py", line 1349, in as_sql
    val = field.get_db_prep_save(val, connection=self.connection)
  File "C:\Python372\mecheck\lib\site-packages\django\db\models\fields\__init__.py", line 790, in get_db_prep_save
    return self.get_db_prep_value(value, connection=connection, prepared=False)
  File "C:\Python372\mecheck\lib\site-packages\django\db\models\fields\__init__.py", line 1273, in get_db_prep_value
    value = self.get_prep_value(value)
  File "C:\Python372\mecheck\lib\site-packages\django\db\models\fields\__init__.py", line 1268, in get_prep_value
    return self.to_python(value)
  File "C:\Python372\mecheck\lib\site-packages\django\db\models\fields\__init__.py", line 1243, in to_python
    params={'value': value},
django.core.exceptions.ValidationError: ['’‘ 必须为合法的日期格式，请使用 YYYY-MM-DD 格式。']
[2021-02-26 10:44:05,434] [basehttp.py:154] [basehttp:log_message] [ERROR]- "POST /AdapterPowerCode/M_edit/ HTTP/1.1" 500 125616
[2021-02-26 10:45:11,798] [log.py:228] [log:log_response] [ERROR]- Internal Server Error: /AdapterPowerCode/M_edit/
Traceback (most recent call last):
  File "C:\Python372\mecheck\lib\site-packages\django\core\handlers\exception.py", line 34, in inner
    response = get_response(request)
  File "C:\Python372\mecheck\lib\site-packages\django\core\handlers\base.py", line 126, in _get_response
    response = self.process_exception_by_middleware(e, request)
  File "C:\Python372\mecheck\lib\site-packages\django\core\handlers\base.py", line 124, in _get_response
    response = wrapped_callback(request, *callback_args, **callback_kwargs)
  File "C:\Python372\mecheck\lib\site-packages\django\views\decorators\csrf.py", line 54, in wrapped_view
    return view_func(*args, **kwargs)
  File "C:\djangoproject\DMS\AdapterPowerCode\views.py", line 676, in M_edit
    AdapterPowerCode.objects.filter(id=id).update(**updatedic)
  File "C:\Python372\mecheck\lib\site-packages\django\db\models\query.py", line 693, in update
    rows = query.get_compiler(self.db).execute_sql(CURSOR)
  File "C:\Python372\mecheck\lib\site-packages\django\db\models\sql\compiler.py", line 1383, in execute_sql
    cursor = super().execute_sql(result_type)
  File "C:\Python372\mecheck\lib\site-packages\django\db\models\sql\compiler.py", line 1052, in execute_sql
    sql, params = self.as_sql()
  File "C:\Python372\mecheck\lib\site-packages\django\db\models\sql\compiler.py", line 1349, in as_sql
    val = field.get_db_prep_save(val, connection=self.connection)
  File "C:\Python372\mecheck\lib\site-packages\django\db\models\fields\__init__.py", line 790, in get_db_prep_save
    return self.get_db_prep_value(value, connection=connection, prepared=False)
  File "C:\Python372\mecheck\lib\site-packages\django\db\models\fields\__init__.py", line 1273, in get_db_prep_value
    value = self.get_prep_value(value)
  File "C:\Python372\mecheck\lib\site-packages\django\db\models\fields\__init__.py", line 1268, in get_prep_value
    return self.to_python(value)
  File "C:\Python372\mecheck\lib\site-packages\django\db\models\fields\__init__.py", line 1243, in to_python
    params={'value': value},
django.core.exceptions.ValidationError: ['’‘ 必须为合法的日期格式，请使用 YYYY-MM-DD 格式。']
[2021-02-26 10:45:11,800] [basehttp.py:154] [basehttp:log_message] [ERROR]- "POST /AdapterPowerCode/M_edit/ HTTP/1.1" 500 125681
[2021-02-26 10:45:51,696] [log.py:228] [log:log_response] [ERROR]- Internal Server Error: /AdapterPowerCode/M_edit/
Traceback (most recent call last):
  File "C:\Python372\mecheck\lib\site-packages\django\core\handlers\exception.py", line 34, in inner
    response = get_response(request)
  File "C:\Python372\mecheck\lib\site-packages\django\core\handlers\base.py", line 126, in _get_response
    response = self.process_exception_by_middleware(e, request)
  File "C:\Python372\mecheck\lib\site-packages\django\core\handlers\base.py", line 124, in _get_response
    response = wrapped_callback(request, *callback_args, **callback_kwargs)
  File "C:\Python372\mecheck\lib\site-packages\django\views\decorators\csrf.py", line 54, in wrapped_view
    return view_func(*args, **kwargs)
  File "C:\djangoproject\DMS\AdapterPowerCode\views.py", line 676, in M_edit
    AdapterPowerCode.objects.filter(id=id).update(**updatedic)
  File "C:\Python372\mecheck\lib\site-packages\django\db\models\query.py", line 693, in update
    rows = query.get_compiler(self.db).execute_sql(CURSOR)
  File "C:\Python372\mecheck\lib\site-packages\django\db\models\sql\compiler.py", line 1383, in execute_sql
    cursor = super().execute_sql(result_type)
  File "C:\Python372\mecheck\lib\site-packages\django\db\models\sql\compiler.py", line 1052, in execute_sql
    sql, params = self.as_sql()
  File "C:\Python372\mecheck\lib\site-packages\django\db\models\sql\compiler.py", line 1349, in as_sql
    val = field.get_db_prep_save(val, connection=self.connection)
  File "C:\Python372\mecheck\lib\site-packages\django\db\models\fields\__init__.py", line 790, in get_db_prep_save
    return self.get_db_prep_value(value, connection=connection, prepared=False)
  File "C:\Python372\mecheck\lib\site-packages\django\db\models\fields\__init__.py", line 1273, in get_db_prep_value
    value = self.get_prep_value(value)
  File "C:\Python372\mecheck\lib\site-packages\django\db\models\fields\__init__.py", line 1268, in get_prep_value
    return self.to_python(value)
  File "C:\Python372\mecheck\lib\site-packages\django\db\models\fields\__init__.py", line 1243, in to_python
    params={'value': value},
django.core.exceptions.ValidationError: ['’‘ 必须为合法的日期格式，请使用 YYYY-MM-DD 格式。']
[2021-02-26 10:45:51,701] [basehttp.py:154] [basehttp:log_message] [ERROR]- "POST /AdapterPowerCode/M_edit/ HTTP/1.1" 500 125745
[2021-02-26 10:46:59,246] [log.py:228] [log:log_response] [ERROR]- Internal Server Error: /AdapterPowerCode/M_edit/
Traceback (most recent call last):
  File "C:\Python372\mecheck\lib\site-packages\django\core\handlers\exception.py", line 34, in inner
    response = get_response(request)
  File "C:\Python372\mecheck\lib\site-packages\django\core\handlers\base.py", line 126, in _get_response
    response = self.process_exception_by_middleware(e, request)
  File "C:\Python372\mecheck\lib\site-packages\django\core\handlers\base.py", line 124, in _get_response
    response = wrapped_callback(request, *callback_args, **callback_kwargs)
  File "C:\Python372\mecheck\lib\site-packages\django\views\decorators\csrf.py", line 54, in wrapped_view
    return view_func(*args, **kwargs)
  File "C:\djangoproject\DMS\AdapterPowerCode\views.py", line 674, in M_edit
    AdapterPowerCode.objects.filter(id=id).update(**updatedic)
  File "C:\Python372\mecheck\lib\site-packages\django\db\models\query.py", line 693, in update
    rows = query.get_compiler(self.db).execute_sql(CURSOR)
  File "C:\Python372\mecheck\lib\site-packages\django\db\models\sql\compiler.py", line 1383, in execute_sql
    cursor = super().execute_sql(result_type)
  File "C:\Python372\mecheck\lib\site-packages\django\db\models\sql\compiler.py", line 1052, in execute_sql
    sql, params = self.as_sql()
  File "C:\Python372\mecheck\lib\site-packages\django\db\models\sql\compiler.py", line 1349, in as_sql
    val = field.get_db_prep_save(val, connection=self.connection)
  File "C:\Python372\mecheck\lib\site-packages\django\db\models\fields\__init__.py", line 790, in get_db_prep_save
    return self.get_db_prep_value(value, connection=connection, prepared=False)
  File "C:\Python372\mecheck\lib\site-packages\django\db\models\fields\__init__.py", line 1273, in get_db_prep_value
    value = self.get_prep_value(value)
  File "C:\Python372\mecheck\lib\site-packages\django\db\models\fields\__init__.py", line 1268, in get_prep_value
    return self.to_python(value)
  File "C:\Python372\mecheck\lib\site-packages\django\db\models\fields\__init__.py", line 1243, in to_python
    params={'value': value},
django.core.exceptions.ValidationError: ['’‘ 必须为合法的日期格式，请使用 YYYY-MM-DD 格式。']
[2021-02-26 10:46:59,249] [basehttp.py:154] [basehttp:log_message] [ERROR]- "POST /AdapterPowerCode/M_edit/ HTTP/1.1" 500 125809
[2021-02-26 10:58:38,888] [log.py:228] [log:log_response] [ERROR]- Internal Server Error: /AdapterPowerCode/M_edit/
Traceback (most recent call last):
  File "C:\Python372\mecheck\lib\site-packages\django\core\handlers\exception.py", line 34, in inner
    response = get_response(request)
  File "C:\Python372\mecheck\lib\site-packages\django\core\handlers\base.py", line 126, in _get_response
    response = self.process_exception_by_middleware(e, request)
  File "C:\Python372\mecheck\lib\site-packages\django\core\handlers\base.py", line 124, in _get_response
    response = wrapped_callback(request, *callback_args, **callback_kwargs)
  File "C:\Python372\mecheck\lib\site-packages\django\views\decorators\csrf.py", line 54, in wrapped_view
    return view_func(*args, **kwargs)
  File "C:\djangoproject\DMS\AdapterPowerCode\views.py", line 677, in M_edit
    AdapterPowerCode.objects.filter(id=id).first().Photo.d
AttributeError: 'ManyRelatedManager' object has no attribute 'd'
[2021-02-26 10:58:38,890] [basehttp.py:154] [basehttp:log_message] [ERROR]- "POST /AdapterPowerCode/M_edit/ HTTP/1.1" 500 89758
[2021-02-26 12:13:44,261] [log.py:228] [log:log_response] [ERROR]- Internal Server Error: /AdapterPowerCode/M_edit/
Traceback (most recent call last):
  File "C:\Python372\mecheck\lib\site-packages\django\core\handlers\exception.py", line 34, in inner
    response = get_response(request)
  File "C:\Python372\mecheck\lib\site-packages\django\core\handlers\base.py", line 126, in _get_response
    response = self.process_exception_by_middleware(e, request)
  File "C:\Python372\mecheck\lib\site-packages\django\core\handlers\base.py", line 124, in _get_response
    response = wrapped_callback(request, *callback_args, **callback_kwargs)
  File "C:\Python372\mecheck\lib\site-packages\django\views\decorators\csrf.py", line 54, in wrapped_view
    return view_func(*args, **kwargs)
  File "C:\djangoproject\DMS\AdapterPowerCode\views.py", line 440, in M_edit
    customerchajialist.append({{"Changjia": j["Changjia"]}})
TypeError: unhashable type: 'dict'
[2021-02-26 12:13:44,263] [basehttp.py:154] [basehttp:log_message] [ERROR]- "GET /AdapterPowerCode/M_edit/ HTTP/1.1" 500 80813
[2021-02-26 13:22:52,829] [log.py:228] [log:log_response] [ERROR]- Internal Server Error: /AdapterPowerCode/M_edit/
Traceback (most recent call last):
  File "C:\Python372\mecheck\lib\site-packages\django\core\handlers\exception.py", line 34, in inner
    response = get_response(request)
  File "C:\Python372\mecheck\lib\site-packages\django\core\handlers\base.py", line 126, in _get_response
    response = self.process_exception_by_middleware(e, request)
  File "C:\Python372\mecheck\lib\site-packages\django\core\handlers\base.py", line 124, in _get_response
    response = wrapped_callback(request, *callback_args, **callback_kwargs)
  File "C:\Python372\mecheck\lib\site-packages\django\views\decorators\csrf.py", line 54, in wrapped_view
    return view_func(*args, **kwargs)
  File "C:\djangoproject\DMS\AdapterPowerCode\views.py", line 440, in M_edit
    customerchajialist.append({{"Changjia": j["Changjia"]}})
TypeError: unhashable type: 'dict'
[2021-02-26 13:22:52,831] [basehttp.py:154] [basehttp:log_message] [ERROR]- "GET /AdapterPowerCode/M_edit/ HTTP/1.1" 500 80286
[2021-02-26 14:42:22,464] [log.py:228] [log:log_response] [ERROR]- Internal Server Error: /AdapterPowerCode/M_edit/
Traceback (most recent call last):
  File "C:\Python372\mecheck\lib\site-packages\django\core\handlers\exception.py", line 34, in inner
    response = get_response(request)
  File "C:\Python372\mecheck\lib\site-packages\django\core\handlers\base.py", line 126, in _get_response
    response = self.process_exception_by_middleware(e, request)
  File "C:\Python372\mecheck\lib\site-packages\django\core\handlers\base.py", line 124, in _get_response
    response = wrapped_callback(request, *callback_args, **callback_kwargs)
  File "C:\Python372\mecheck\lib\site-packages\django\views\decorators\csrf.py", line 54, in wrapped_view
    return view_func(*args, **kwargs)
  File "C:\djangoproject\DMS\AdapterPowerCode\views.py", line 603, in M_edit
    print(params[0])
IndexError: list index out of range
[2021-02-26 14:42:22,467] [basehttp.py:154] [basehttp:log_message] [ERROR]- "POST /AdapterPowerCode/M_edit/ HTTP/1.1" 500 85086
[2021-02-26 16:51:52,820] [log.py:228] [log:log_response] [ERROR]- Internal Server Error: /AdapterPowerCode/BorrowedAdapter/
Traceback (most recent call last):
  File "C:\Python372\mecheck\lib\site-packages\django\core\handlers\exception.py", line 34, in inner
    response = get_response(request)
  File "C:\Python372\mecheck\lib\site-packages\django\core\handlers\base.py", line 126, in _get_response
    response = self.process_exception_by_middleware(e, request)
  File "C:\Python372\mecheck\lib\site-packages\django\core\handlers\base.py", line 124, in _get_response
    response = wrapped_callback(request, *callback_args, **callback_kwargs)
  File "C:\Python372\mecheck\lib\site-packages\django\views\decorators\csrf.py", line 54, in wrapped_view
    return view_func(*args, **kwargs)
  File "C:\djangoproject\DMS\AdapterPowerCode\views.py", line 169, in BorrowedAdapter
    mock_datalist = AdapterPowerCode.objects.filter(**checkAdaPow)
  File "C:\Python372\mecheck\lib\site-packages\django\db\models\manager.py", line 82, in manager_method
    return getattr(self.get_queryset(), name)(*args, **kwargs)
  File "C:\Python372\mecheck\lib\site-packages\django\db\models\query.py", line 844, in filter
    return self._filter_or_exclude(False, *args, **kwargs)
  File "C:\Python372\mecheck\lib\site-packages\django\db\models\query.py", line 862, in _filter_or_exclude
    clone.query.add_q(Q(*args, **kwargs))
  File "C:\Python372\mecheck\lib\site-packages\django\db\models\sql\query.py", line 1263, in add_q
    clause, _ = self._add_q(q_object, self.used_aliases)
  File "C:\Python372\mecheck\lib\site-packages\django\db\models\sql\query.py", line 1287, in _add_q
    split_subq=split_subq,
  File "C:\Python372\mecheck\lib\site-packages\django\db\models\sql\query.py", line 1164, in build_filter
    lookups, parts, reffed_expression = self.solve_lookup_type(arg)
  File "C:\Python372\mecheck\lib\site-packages\django\db\models\sql\query.py", line 1028, in solve_lookup_type
    _, field, _, lookup_parts = self.names_to_path(lookup_splitted, self.get_meta())
  File "C:\Python372\mecheck\lib\site-packages\django\db\models\sql\query.py", line 1389, in names_to_path
    "Choices are: %s" % (name, ", ".join(available)))
django.core.exceptions.FieldError: Cannot resolve keyword 'PN' into field. Choices are: BR_Status, BR_per, Borrow_date, Changjia, Customer, Description, Device_Status, Last_BR_per, Last_Borrow_date, Last_Return_date, Location, MaterialPN, Number, OAP, Phase, Photo, Power, Predict_return, Project_Code, Return_date, id
[2021-02-26 16:51:52,822] [basehttp.py:154] [basehttp:log_message] [ERROR]- "POST /AdapterPowerCode/BorrowedAdapter/ HTTP/1.1" 500 128249
[2021-02-26 16:52:15,786] [log.py:228] [log:log_response] [ERROR]- Internal Server Error: /AdapterPowerCode/BorrowedAdapter/
Traceback (most recent call last):
  File "C:\Python372\mecheck\lib\site-packages\django\core\handlers\exception.py", line 34, in inner
    response = get_response(request)
  File "C:\Python372\mecheck\lib\site-packages\django\core\handlers\base.py", line 126, in _get_response
    response = self.process_exception_by_middleware(e, request)
  File "C:\Python372\mecheck\lib\site-packages\django\core\handlers\base.py", line 124, in _get_response
    response = wrapped_callback(request, *callback_args, **callback_kwargs)
  File "C:\Python372\mecheck\lib\site-packages\django\views\decorators\csrf.py", line 54, in wrapped_view
    return view_func(*args, **kwargs)
  File "C:\djangoproject\DMS\AdapterPowerCode\views.py", line 169, in BorrowedAdapter
    mock_datalist = AdapterPowerCode.objects.filter(**checkAdaPow)
  File "C:\Python372\mecheck\lib\site-packages\django\db\models\manager.py", line 82, in manager_method
    return getattr(self.get_queryset(), name)(*args, **kwargs)
  File "C:\Python372\mecheck\lib\site-packages\django\db\models\query.py", line 844, in filter
    return self._filter_or_exclude(False, *args, **kwargs)
  File "C:\Python372\mecheck\lib\site-packages\django\db\models\query.py", line 862, in _filter_or_exclude
    clone.query.add_q(Q(*args, **kwargs))
  File "C:\Python372\mecheck\lib\site-packages\django\db\models\sql\query.py", line 1263, in add_q
    clause, _ = self._add_q(q_object, self.used_aliases)
  File "C:\Python372\mecheck\lib\site-packages\django\db\models\sql\query.py", line 1287, in _add_q
    split_subq=split_subq,
  File "C:\Python372\mecheck\lib\site-packages\django\db\models\sql\query.py", line 1164, in build_filter
    lookups, parts, reffed_expression = self.solve_lookup_type(arg)
  File "C:\Python372\mecheck\lib\site-packages\django\db\models\sql\query.py", line 1028, in solve_lookup_type
    _, field, _, lookup_parts = self.names_to_path(lookup_splitted, self.get_meta())
  File "C:\Python372\mecheck\lib\site-packages\django\db\models\sql\query.py", line 1389, in names_to_path
    "Choices are: %s" % (name, ", ".join(available)))
django.core.exceptions.FieldError: Cannot resolve keyword 'PN' into field. Choices are: BR_Status, BR_per, Borrow_date, Changjia, Customer, Description, Device_Status, Last_BR_per, Last_Borrow_date, Last_Return_date, Location, MaterialPN, Number, OAP, Phase, Photo, Power, Predict_return, Project_Code, Return_date, id
[2021-02-26 16:52:15,787] [basehttp.py:154] [basehttp:log_message] [ERROR]- "POST /AdapterPowerCode/BorrowedAdapter/ HTTP/1.1" 500 128249
