[2022-02-10 13:53:19,093] [log.py:228] [log:log_response] [ERROR]- Internal Server Error: /ComputerMS/R_Borrowed/
Traceback (most recent call last):
  File "C:\Python372\mecheck\lib\site-packages\django\core\handlers\exception.py", line 34, in inner
    response = get_response(request)
  File "C:\Python372\mecheck\lib\site-packages\django\core\handlers\base.py", line 126, in _get_response
    response = self.process_exception_by_middleware(e, request)
  File "C:\Python372\mecheck\lib\site-packages\django\core\handlers\base.py", line 124, in _get_response
    response = wrapped_callback(request, *callback_args, **callback_kwargs)
  File "C:\Python372\mecheck\lib\site-packages\django\views\decorators\csrf.py", line 54, in wrapped_view
    return view_func(*args, **kwargs)
  File "C:\djangoproject\DMS\ComputerMS\views.py", line 372, in R_Borrowed
    if i.Plandate and i.Btime and not i.Rtime:
AttributeError: 'ComputerLNV' object has no attribute 'Plandate'
[2022-02-10 13:53:19,096] [UserIP.py:89] [UserIP:process_response] [CRITICAL]- 系统错误
[2022-02-10 13:53:19,097] [basehttp.py:154] [basehttp:log_message] [ERROR]- "POST /ComputerMS/R_Borrowed/ HTTP/1.1" 500 81063
[2022-02-10 14:00:46,054] [log.py:228] [log:log_response] [ERROR]- Internal Server Error: /ComputerMS/R_Borrowed/
Traceback (most recent call last):
  File "C:\Python372\mecheck\lib\site-packages\django\core\handlers\exception.py", line 34, in inner
    response = get_response(request)
  File "C:\Python372\mecheck\lib\site-packages\django\core\handlers\base.py", line 126, in _get_response
    response = self.process_exception_by_middleware(e, request)
  File "C:\Python372\mecheck\lib\site-packages\django\core\handlers\base.py", line 124, in _get_response
    response = wrapped_callback(request, *callback_args, **callback_kwargs)
  File "C:\Python372\mecheck\lib\site-packages\django\views\decorators\csrf.py", line 54, in wrapped_view
    return view_func(*args, **kwargs)
  File "C:\djangoproject\DMS\ComputerMS\views.py", line 774, in R_Borrowed
    "IntfCtgryOptions5": IntfCtgryOptions5,
NameError: name 'IntfCtgryOptions5' is not defined
[2022-02-10 14:00:46,056] [UserIP.py:89] [UserIP:process_response] [CRITICAL]- 系统错误
[2022-02-10 14:00:46,057] [basehttp.py:154] [basehttp:log_message] [ERROR]- "POST /ComputerMS/R_Borrowed/ HTTP/1.1" 500 82383
[2022-02-10 15:18:32,348] [log.py:228] [log:log_response] [ERROR]- Internal Server Error: /ComputerMS/R_Return/
Traceback (most recent call last):
  File "C:\Python372\mecheck\lib\site-packages\django\core\handlers\exception.py", line 34, in inner
    response = get_response(request)
  File "C:\Python372\mecheck\lib\site-packages\django\core\handlers\base.py", line 126, in _get_response
    response = self.process_exception_by_middleware(e, request)
  File "C:\Python372\mecheck\lib\site-packages\django\core\handlers\base.py", line 124, in _get_response
    response = wrapped_callback(request, *callback_args, **callback_kwargs)
  File "C:\Python372\mecheck\lib\site-packages\django\views\decorators\csrf.py", line 54, in wrapped_view
    return view_func(*args, **kwargs)
  File "C:\djangoproject\DMS\ComputerMS\views.py", line 937, in R_Return
    if i.Plandate and i.Btime and not i.Rtime:
AttributeError: 'ComputerLNV' object has no attribute 'Plandate'
[2022-02-10 15:18:32,351] [UserIP.py:89] [UserIP:process_response] [CRITICAL]- 系统错误
[2022-02-10 15:18:32,351] [basehttp.py:154] [basehttp:log_message] [ERROR]- "POST /ComputerMS/R_Return/ HTTP/1.1" 500 81025
[2022-02-10 15:23:50,099] [log.py:228] [log:log_response] [ERROR]- Internal Server Error: /ComputerMS/R_Return/
Traceback (most recent call last):
  File "C:\Python372\mecheck\lib\site-packages\django\core\handlers\exception.py", line 34, in inner
    response = get_response(request)
  File "C:\Python372\mecheck\lib\site-packages\django\core\handlers\base.py", line 126, in _get_response
    response = self.process_exception_by_middleware(e, request)
  File "C:\Python372\mecheck\lib\site-packages\django\core\handlers\base.py", line 124, in _get_response
    response = wrapped_callback(request, *callback_args, **callback_kwargs)
  File "C:\Python372\mecheck\lib\site-packages\django\views\decorators\csrf.py", line 54, in wrapped_view
    return view_func(*args, **kwargs)
  File "C:\djangoproject\DMS\ComputerMS\views.py", line 1163, in R_Return
    "IntfCtgryOptions5": IntfCtgryOptions5,
NameError: name 'IntfCtgryOptions5' is not defined
[2022-02-10 15:23:50,102] [UserIP.py:89] [UserIP:process_response] [CRITICAL]- 系统错误
[2022-02-10 15:23:50,102] [basehttp.py:154] [basehttp:log_message] [ERROR]- "POST /ComputerMS/R_Return/ HTTP/1.1" 500 81271
[2022-02-10 15:26:07,633] [log.py:228] [log:log_response] [ERROR]- Internal Server Error: /ComputerMS/R_Return/
Traceback (most recent call last):
  File "C:\Python372\mecheck\lib\site-packages\django\core\handlers\exception.py", line 34, in inner
    response = get_response(request)
  File "C:\Python372\mecheck\lib\site-packages\django\core\handlers\base.py", line 126, in _get_response
    response = self.process_exception_by_middleware(e, request)
  File "C:\Python372\mecheck\lib\site-packages\django\core\handlers\base.py", line 124, in _get_response
    response = wrapped_callback(request, *callback_args, **callback_kwargs)
  File "C:\Python372\mecheck\lib\site-packages\django\views\decorators\csrf.py", line 54, in wrapped_view
    return view_func(*args, **kwargs)
  File "C:\djangoproject\DMS\ComputerMS\views.py", line 920, in R_Return
    for i in responseData['ReturnId']:
KeyError: 'ReturnId'
[2022-02-10 15:26:07,636] [UserIP.py:89] [UserIP:process_response] [CRITICAL]- 系统错误
[2022-02-10 15:26:07,637] [basehttp.py:154] [basehttp:log_message] [ERROR]- "POST /ComputerMS/R_Return/ HTTP/1.1" 500 79096
[2022-02-10 16:05:13,051] [log.py:228] [log:log_response] [ERROR]- Internal Server Error: /ComputerMS/R_Destine/
Traceback (most recent call last):
  File "C:\Python372\mecheck\lib\site-packages\django\core\handlers\exception.py", line 34, in inner
    response = get_response(request)
  File "C:\Python372\mecheck\lib\site-packages\django\core\handlers\base.py", line 126, in _get_response
    response = self.process_exception_by_middleware(e, request)
  File "C:\Python372\mecheck\lib\site-packages\django\core\handlers\base.py", line 124, in _get_response
    response = wrapped_callback(request, *callback_args, **callback_kwargs)
  File "C:\Python372\mecheck\lib\site-packages\django\views\decorators\csrf.py", line 54, in wrapped_view
    return view_func(*args, **kwargs)
  File "C:\djangoproject\DMS\ComputerMS\views.py", line 1200, in R_Destine
    "IntfCtgryOptions5": IntfCtgryOptions5,
NameError: name 'IntfCtgryOptions5' is not defined
[2022-02-10 16:05:13,053] [UserIP.py:89] [UserIP:process_response] [CRITICAL]- 系统错误
[2022-02-10 16:05:13,054] [basehttp.py:154] [basehttp:log_message] [ERROR]- "POST /ComputerMS/R_Destine/ HTTP/1.1" 500 81085
[2022-02-10 16:05:26,094] [log.py:228] [log:log_response] [ERROR]- Internal Server Error: /ComputerMS/R_Destine/
Traceback (most recent call last):
  File "C:\Python372\mecheck\lib\site-packages\django\core\handlers\exception.py", line 34, in inner
    response = get_response(request)
  File "C:\Python372\mecheck\lib\site-packages\django\core\handlers\base.py", line 126, in _get_response
    response = self.process_exception_by_middleware(e, request)
  File "C:\Python372\mecheck\lib\site-packages\django\core\handlers\base.py", line 124, in _get_response
    response = wrapped_callback(request, *callback_args, **callback_kwargs)
  File "C:\Python372\mecheck\lib\site-packages\django\views\decorators\csrf.py", line 54, in wrapped_view
    return view_func(*args, **kwargs)
  File "C:\djangoproject\DMS\ComputerMS\views.py", line 1200, in R_Destine
    "IntfCtgryOptions5": IntfCtgryOptions5,
NameError: name 'IntfCtgryOptions5' is not defined
[2022-02-10 16:05:26,098] [UserIP.py:89] [UserIP:process_response] [CRITICAL]- 系统错误
[2022-02-10 16:05:26,099] [basehttp.py:154] [basehttp:log_message] [ERROR]- "POST /ComputerMS/R_Destine/ HTTP/1.1" 500 81085
[2022-02-10 16:06:33,112] [log.py:228] [log:log_response] [ERROR]- Internal Server Error: /ComputerMS/R_Destine/
Traceback (most recent call last):
  File "C:\Python372\mecheck\lib\site-packages\django\core\handlers\exception.py", line 34, in inner
    response = get_response(request)
  File "C:\Python372\mecheck\lib\site-packages\django\core\handlers\base.py", line 126, in _get_response
    response = self.process_exception_by_middleware(e, request)
  File "C:\Python372\mecheck\lib\site-packages\django\core\handlers\base.py", line 124, in _get_response
    response = wrapped_callback(request, *callback_args, **callback_kwargs)
  File "C:\Python372\mecheck\lib\site-packages\django\views\decorators\csrf.py", line 54, in wrapped_view
    return view_func(*args, **kwargs)
  File "C:\djangoproject\DMS\ComputerMS\views.py", line 1200, in R_Destine
    "IntfCtgryOptions5": IntfCtgryOptions5,
NameError: name 'IntfCtgryOptions5' is not defined
[2022-02-10 16:06:33,115] [UserIP.py:89] [UserIP:process_response] [CRITICAL]- 系统错误
[2022-02-10 16:06:33,117] [basehttp.py:154] [basehttp:log_message] [ERROR]- "POST /ComputerMS/R_Destine/ HTTP/1.1" 500 81085
[2022-02-10 16:07:34,892] [log.py:228] [log:log_response] [ERROR]- Internal Server Error: /ComputerMS/R_Destine/
Traceback (most recent call last):
  File "C:\Python372\mecheck\lib\site-packages\django\core\handlers\exception.py", line 34, in inner
    response = get_response(request)
  File "C:\Python372\mecheck\lib\site-packages\django\core\handlers\base.py", line 126, in _get_response
    response = self.process_exception_by_middleware(e, request)
  File "C:\Python372\mecheck\lib\site-packages\django\core\handlers\base.py", line 124, in _get_response
    response = wrapped_callback(request, *callback_args, **callback_kwargs)
  File "C:\Python372\mecheck\lib\site-packages\django\views\decorators\csrf.py", line 54, in wrapped_view
    return view_func(*args, **kwargs)
  File "C:\djangoproject\DMS\ComputerMS\views.py", line 1200, in R_Destine
    "IntfCtgryOptions5": IntfCtgryOptions5,
NameError: name 'IntfCtgryOptions5' is not defined
[2022-02-10 16:07:34,895] [UserIP.py:89] [UserIP:process_response] [CRITICAL]- 系统错误
[2022-02-10 16:07:34,895] [basehttp.py:154] [basehttp:log_message] [ERROR]- "POST /ComputerMS/R_Destine/ HTTP/1.1" 500 81085
[2022-02-10 16:24:03,677] [log.py:228] [log:log_response] [ERROR]- Internal Server Error: /ComputerMS/R_Destine/
Traceback (most recent call last):
  File "C:\Python372\mecheck\lib\site-packages\django\core\handlers\exception.py", line 34, in inner
    response = get_response(request)
  File "C:\Python372\mecheck\lib\site-packages\django\core\handlers\base.py", line 126, in _get_response
    response = self.process_exception_by_middleware(e, request)
  File "C:\Python372\mecheck\lib\site-packages\django\core\handlers\base.py", line 124, in _get_response
    response = wrapped_callback(request, *callback_args, **callback_kwargs)
  File "C:\Python372\mecheck\lib\site-packages\django\views\decorators\csrf.py", line 54, in wrapped_view
    return view_func(*args, **kwargs)
  File "C:\djangoproject\DMS\ComputerMS\views.py", line 1062, in R_Destine
    for i in responseData['BookId']:
KeyError: 'BookId'
[2022-02-10 16:24:03,679] [UserIP.py:89] [UserIP:process_response] [CRITICAL]- 系统错误
[2022-02-10 16:24:03,679] [basehttp.py:154] [basehttp:log_message] [ERROR]- "POST /ComputerMS/R_Destine/ HTTP/1.1" 500 79358
[2022-02-11 10:25:53,490] [UserIP.py:89] [UserIP:process_response] [CRITICAL]- 系统错误
[2022-02-14 08:32:45,867] [UserIP.py:89] [UserIP:process_response] [CRITICAL]- 系统错误
