[2023-09-25 08:48:30,788] [UserIP.py:89] [UserIP:process_response] [CRITICAL]- 系统错误
[2023-09-25 08:48:54,317] [UserIP.py:89] [UserIP:process_response] [CRITICAL]- 系统错误
[2023-09-25 08:55:59,134] [UserIP.py:89] [UserIP:process_response] [CRITICAL]- 系统错误
[2023-09-25 09:50:49,101] [log.py:228] [log:log_response] [ERROR]- Internal Server Error: /Summary/
Traceback (most recent call last):
  File "C:\Python372\mecheck\lib\site-packages\django\core\handlers\exception.py", line 34, in inner
    response = get_response(request)
  File "C:\Python372\mecheck\lib\site-packages\django\core\handlers\base.py", line 126, in _get_response
    response = self.process_exception_by_middleware(e, request)
  File "C:\Python372\mecheck\lib\site-packages\django\core\handlers\base.py", line 124, in _get_response
    response = wrapped_callback(request, *callback_args, **callback_kwargs)
  File "C:\Python372\mecheck\lib\site-packages\django\views\decorators\csrf.py", line 54, in wrapped_view
    return view_func(*args, **kwargs)
  File "C:\djangoproject\DMS\app01\views.py", line 588, in Summary
    tasks.GetTumdata()
  File "C:\djangoproject\DMS\app01\tasks.py", line 34, in GetTumdata
    print(df_MateriaOTST)
UnboundLocalError: local variable 'df_MateriaOTST' referenced before assignment
[2023-09-25 09:50:49,105] [UserIP.py:89] [UserIP:process_response] [CRITICAL]- 系统错误
[2023-09-25 09:50:49,106] [basehttp.py:154] [basehttp:log_message] [ERROR]- "POST /Summary/ HTTP/1.1" 500 92029
[2023-09-25 11:03:55,391] [log.py:228] [log:log_response] [ERROR]- Internal Server Error: /Summary/
Traceback (most recent call last):
  File "C:\Python372\mecheck\lib\site-packages\django\core\handlers\exception.py", line 34, in inner
    response = get_response(request)
  File "C:\Python372\mecheck\lib\site-packages\django\core\handlers\base.py", line 126, in _get_response
    response = self.process_exception_by_middleware(e, request)
  File "C:\Python372\mecheck\lib\site-packages\django\core\handlers\base.py", line 124, in _get_response
    response = wrapped_callback(request, *callback_args, **callback_kwargs)
  File "C:\Python372\mecheck\lib\site-packages\django\views\decorators\csrf.py", line 54, in wrapped_view
    return view_func(*args, **kwargs)
  File "C:\djangoproject\DMS\app01\views.py", line 588, in Summary
    tasks.GetTumdata()
  File "C:\djangoproject\DMS\app01\tasks.py", line 90, in GetTumdata
    MateriaInDQA_Tum.objects.create(**modeldata)
  File "C:\Python372\mecheck\lib\site-packages\django\db\models\manager.py", line 82, in manager_method
    return getattr(self.get_queryset(), name)(*args, **kwargs)
  File "C:\Python372\mecheck\lib\site-packages\django\db\models\query.py", line 413, in create
    obj.save(force_insert=True, using=self.db)
  File "C:\Python372\mecheck\lib\site-packages\django\db\models\base.py", line 718, in save
    force_update=force_update, update_fields=update_fields)
  File "C:\Python372\mecheck\lib\site-packages\django\db\models\base.py", line 748, in save_base
    updated = self._save_table(raw, cls, force_insert, force_update, using, update_fields)
  File "C:\Python372\mecheck\lib\site-packages\django\db\models\base.py", line 831, in _save_table
    result = self._do_insert(cls._base_manager, using, fields, update_pk, raw)
  File "C:\Python372\mecheck\lib\site-packages\django\db\models\base.py", line 869, in _do_insert
    using=using, raw=raw)
  File "C:\Python372\mecheck\lib\site-packages\django\db\models\manager.py", line 82, in manager_method
    return getattr(self.get_queryset(), name)(*args, **kwargs)
  File "C:\Python372\mecheck\lib\site-packages\django\db\models\query.py", line 1136, in _insert
    return query.get_compiler(using=using).execute_sql(return_id)
  File "C:\Python372\mecheck\lib\site-packages\django\db\models\sql\compiler.py", line 1288, in execute_sql
    for sql, params in self.as_sql():
  File "C:\Python372\mecheck\lib\site-packages\django\db\models\sql\compiler.py", line 1241, in as_sql
    for obj in self.query.objs
  File "C:\Python372\mecheck\lib\site-packages\django\db\models\sql\compiler.py", line 1241, in <listcomp>
    for obj in self.query.objs
  File "C:\Python372\mecheck\lib\site-packages\django\db\models\sql\compiler.py", line 1240, in <listcomp>
    [self.prepare_value(field, self.pre_save_val(field, obj)) for field in fields]
  File "C:\Python372\mecheck\lib\site-packages\django\db\models\sql\compiler.py", line 1182, in prepare_value
    value = field.get_db_prep_save(value, connection=self.connection)
  File "C:\Python372\mecheck\lib\site-packages\django\db\models\fields\__init__.py", line 790, in get_db_prep_save
    return self.get_db_prep_value(value, connection=connection, prepared=False)
  File "C:\Python372\mecheck\lib\site-packages\django\db\models\fields\__init__.py", line 1273, in get_db_prep_value
    value = self.get_prep_value(value)
  File "C:\Python372\mecheck\lib\site-packages\django\db\models\fields\__init__.py", line 1268, in get_prep_value
    return self.to_python(value)
  File "C:\Python372\mecheck\lib\site-packages\django\db\models\fields\__init__.py", line 1243, in to_python
    params={'value': value},
django.core.exceptions.ValidationError: ['’‘ 必须为合法的日期格式，请使用 YYYY-MM-DD 格式。']
[2023-09-25 11:03:55,401] [UserIP.py:89] [UserIP:process_response] [CRITICAL]- 系统错误
[2023-09-25 11:03:55,402] [basehttp.py:154] [basehttp:log_message] [ERROR]- "POST /Summary/ HTTP/1.1" 500 212626
[2023-09-25 11:16:11,878] [log.py:228] [log:log_response] [ERROR]- Internal Server Error: /Summary/
Traceback (most recent call last):
  File "C:\Python372\mecheck\lib\site-packages\django\db\backends\utils.py", line 85, in _execute
    return self.cursor.execute(sql, params)
  File "C:\Python372\mecheck\lib\site-packages\django\db\backends\mysql\base.py", line 71, in execute
    return self.cursor.execute(query, args)
  File "C:\Python372\mecheck\lib\site-packages\pymysql\cursors.py", line 170, in execute
    result = self._query(query)
  File "C:\Python372\mecheck\lib\site-packages\pymysql\cursors.py", line 328, in _query
    conn.query(q)
  File "C:\Python372\mecheck\lib\site-packages\pymysql\connections.py", line 517, in query
    self._affected_rows = self._read_query_result(unbuffered=unbuffered)
  File "C:\Python372\mecheck\lib\site-packages\pymysql\connections.py", line 732, in _read_query_result
    result.read()
  File "C:\Python372\mecheck\lib\site-packages\pymysql\connections.py", line 1075, in read
    first_packet = self.connection._read_packet()
  File "C:\Python372\mecheck\lib\site-packages\pymysql\connections.py", line 684, in _read_packet
    packet.check_error()
  File "C:\Python372\mecheck\lib\site-packages\pymysql\protocol.py", line 220, in check_error
    err.raise_mysql_exception(self._data)
  File "C:\Python372\mecheck\lib\site-packages\pymysql\err.py", line 109, in raise_mysql_exception
    raise errorclass(errno, errval)
pymysql.err.DataError: (1406, "Data too long for column 'ApplyReason' at row 1")

The above exception was the direct cause of the following exception:

Traceback (most recent call last):
  File "C:\Python372\mecheck\lib\site-packages\django\core\handlers\exception.py", line 34, in inner
    response = get_response(request)
  File "C:\Python372\mecheck\lib\site-packages\django\core\handlers\base.py", line 126, in _get_response
    response = self.process_exception_by_middleware(e, request)
  File "C:\Python372\mecheck\lib\site-packages\django\core\handlers\base.py", line 124, in _get_response
    response = wrapped_callback(request, *callback_args, **callback_kwargs)
  File "C:\Python372\mecheck\lib\site-packages\django\views\decorators\csrf.py", line 54, in wrapped_view
    return view_func(*args, **kwargs)
  File "C:\djangoproject\DMS\app01\views.py", line 588, in Summary
    tasks.GetTumdata()
  File "C:\djangoproject\DMS\app01\tasks.py", line 96, in GetTumdata
    MateriaInDQA_Tum.objects.create(**modeldata)
  File "C:\Python372\mecheck\lib\site-packages\django\db\models\manager.py", line 82, in manager_method
    return getattr(self.get_queryset(), name)(*args, **kwargs)
  File "C:\Python372\mecheck\lib\site-packages\django\db\models\query.py", line 413, in create
    obj.save(force_insert=True, using=self.db)
  File "C:\Python372\mecheck\lib\site-packages\django\db\models\base.py", line 718, in save
    force_update=force_update, update_fields=update_fields)
  File "C:\Python372\mecheck\lib\site-packages\django\db\models\base.py", line 748, in save_base
    updated = self._save_table(raw, cls, force_insert, force_update, using, update_fields)
  File "C:\Python372\mecheck\lib\site-packages\django\db\models\base.py", line 831, in _save_table
    result = self._do_insert(cls._base_manager, using, fields, update_pk, raw)
  File "C:\Python372\mecheck\lib\site-packages\django\db\models\base.py", line 869, in _do_insert
    using=using, raw=raw)
  File "C:\Python372\mecheck\lib\site-packages\django\db\models\manager.py", line 82, in manager_method
    return getattr(self.get_queryset(), name)(*args, **kwargs)
  File "C:\Python372\mecheck\lib\site-packages\django\db\models\query.py", line 1136, in _insert
    return query.get_compiler(using=using).execute_sql(return_id)
  File "C:\Python372\mecheck\lib\site-packages\django\db\models\sql\compiler.py", line 1289, in execute_sql
    cursor.execute(sql, params)
  File "C:\Python372\mecheck\lib\site-packages\django\db\backends\utils.py", line 100, in execute
    return super().execute(sql, params)
  File "C:\Python372\mecheck\lib\site-packages\django\db\backends\utils.py", line 68, in execute
    return self._execute_with_wrappers(sql, params, many=False, executor=self._execute)
  File "C:\Python372\mecheck\lib\site-packages\django\db\backends\utils.py", line 77, in _execute_with_wrappers
    return executor(sql, params, many, context)
  File "C:\Python372\mecheck\lib\site-packages\django\db\backends\utils.py", line 85, in _execute
    return self.cursor.execute(sql, params)
  File "C:\Python372\mecheck\lib\site-packages\django\db\utils.py", line 89, in __exit__
    raise dj_exc_value.with_traceback(traceback) from exc_value
  File "C:\Python372\mecheck\lib\site-packages\django\db\backends\utils.py", line 85, in _execute
    return self.cursor.execute(sql, params)
  File "C:\Python372\mecheck\lib\site-packages\django\db\backends\mysql\base.py", line 71, in execute
    return self.cursor.execute(query, args)
  File "C:\Python372\mecheck\lib\site-packages\pymysql\cursors.py", line 170, in execute
    result = self._query(query)
  File "C:\Python372\mecheck\lib\site-packages\pymysql\cursors.py", line 328, in _query
    conn.query(q)
  File "C:\Python372\mecheck\lib\site-packages\pymysql\connections.py", line 517, in query
    self._affected_rows = self._read_query_result(unbuffered=unbuffered)
  File "C:\Python372\mecheck\lib\site-packages\pymysql\connections.py", line 732, in _read_query_result
    result.read()
  File "C:\Python372\mecheck\lib\site-packages\pymysql\connections.py", line 1075, in read
    first_packet = self.connection._read_packet()
  File "C:\Python372\mecheck\lib\site-packages\pymysql\connections.py", line 684, in _read_packet
    packet.check_error()
  File "C:\Python372\mecheck\lib\site-packages\pymysql\protocol.py", line 220, in check_error
    err.raise_mysql_exception(self._data)
  File "C:\Python372\mecheck\lib\site-packages\pymysql\err.py", line 109, in raise_mysql_exception
    raise errorclass(errno, errval)
django.db.utils.DataError: (1406, "Data too long for column 'ApplyReason' at row 1")
[2023-09-25 11:16:11,891] [UserIP.py:89] [UserIP:process_response] [CRITICAL]- 系统错误
[2023-09-25 11:16:11,892] [basehttp.py:154] [basehttp:log_message] [ERROR]- "POST /Summary/ HTTP/1.1" 500 296371
[2023-09-25 13:48:58,491] [UserIP.py:89] [UserIP:process_response] [CRITICAL]- 系统错误
[2023-09-25 13:49:36,299] [log.py:228] [log:log_response] [ERROR]- Internal Server Error: /Summary/
Traceback (most recent call last):
  File "C:\Python372\mecheck\lib\site-packages\django\core\handlers\exception.py", line 34, in inner
    response = get_response(request)
  File "C:\Python372\mecheck\lib\site-packages\django\core\handlers\base.py", line 126, in _get_response
    response = self.process_exception_by_middleware(e, request)
  File "C:\Python372\mecheck\lib\site-packages\django\core\handlers\base.py", line 124, in _get_response
    response = wrapped_callback(request, *callback_args, **callback_kwargs)
  File "C:\Python372\mecheck\lib\site-packages\django\views\decorators\csrf.py", line 54, in wrapped_view
    return view_func(*args, **kwargs)
  File "C:\djangoproject\DMS\app01\views.py", line 588, in Summary
    tasks.GetTumdata()
  File "C:\djangoproject\DMS\app01\tasks.py", line 79, in GetTumdata
    Result_UnitOTST_fun = pool.submit(UnitOTST_fun, UnitOTST_dict)
  File "C:\Python372\lib\concurrent\futures\thread.py", line 153, in submit
    raise RuntimeError('cannot schedule new futures after '
RuntimeError: cannot schedule new futures after interpreter shutdown
[2023-09-25 13:49:36,303] [UserIP.py:89] [UserIP:process_response] [CRITICAL]- 系统错误
[2023-09-25 13:49:36,303] [basehttp.py:154] [basehttp:log_message] [ERROR]- "POST /Summary/ HTTP/1.1" 500 112272
[2023-09-25 14:19:38,591] [log.py:228] [log:log_response] [ERROR]- Internal Server Error: /Summary/
Traceback (most recent call last):
  File "C:\Python372\mecheck\lib\site-packages\django\core\handlers\exception.py", line 34, in inner
    response = get_response(request)
  File "C:\Python372\mecheck\lib\site-packages\django\core\handlers\base.py", line 126, in _get_response
    response = self.process_exception_by_middleware(e, request)
  File "C:\Python372\mecheck\lib\site-packages\django\core\handlers\base.py", line 124, in _get_response
    response = wrapped_callback(request, *callback_args, **callback_kwargs)
  File "C:\Python372\mecheck\lib\site-packages\django\views\decorators\csrf.py", line 54, in wrapped_view
    return view_func(*args, **kwargs)
  File "C:\djangoproject\DMS\app01\views.py", line 588, in Summary
    tasks.GetTumdata()
  File "C:\djangoproject\DMS\app01\tasks.py", line 79, in GetTumdata
    Result_UnitOTST_fun = pool.submit(UnitOTST_fun, UnitOTST_dict)
  File "C:\Python372\lib\concurrent\futures\thread.py", line 153, in submit
    raise RuntimeError('cannot schedule new futures after '
RuntimeError: cannot schedule new futures after interpreter shutdown
[2023-09-25 14:19:38,594] [UserIP.py:89] [UserIP:process_response] [CRITICAL]- 系统错误
[2023-09-25 14:19:38,595] [basehttp.py:154] [basehttp:log_message] [ERROR]- "POST /Summary/ HTTP/1.1" 500 112272
[2023-09-25 14:36:35,578] [basehttp.py:154] [basehttp:log_message] [ERROR]- "GET /admin/ HTTP/1.1" 500 59
[2023-09-25 14:36:36,370] [basehttp.py:154] [basehttp:log_message] [ERROR]- "GET /admin/login/?next=/admin/ HTTP/1.1" 500 59
[2023-09-25 14:36:37,043] [basehttp.py:154] [basehttp:log_message] [ERROR]- "GET /admin/login/?next=/admin/ HTTP/1.1" 500 59
[2023-09-25 14:36:42,178] [UserIP.py:89] [UserIP:process_response] [CRITICAL]- 系统错误
[2023-09-25 16:45:28,380] [basehttp.py:154] [basehttp:log_message] [ERROR]- "GET /admin/TUMHistory/dqamateria_tumhistory/ HTTP/1.1" 500 59
[2023-09-25 16:47:15,658] [log.py:228] [log:log_response] [ERROR]- Internal Server Error: /Summary/
Traceback (most recent call last):
  File "C:\Python372\mecheck\lib\site-packages\pymysql\connections.py", line 691, in _read_bytes
    data = self._rfile.read(num_bytes)
  File "C:\Python372\lib\socket.py", line 589, in readinto
    return self._sock.recv_into(b)
ConnectionAbortedError: [WinError 10053] 你的主机中的软件中止了一个已建立的连接。

During handling of the above exception, another exception occurred:

Traceback (most recent call last):
  File "C:\Python372\mecheck\lib\site-packages\django\db\backends\utils.py", line 85, in _execute
    return self.cursor.execute(sql, params)
  File "C:\Python372\mecheck\lib\site-packages\django\db\backends\mysql\base.py", line 71, in execute
    return self.cursor.execute(query, args)
  File "C:\Python372\mecheck\lib\site-packages\pymysql\cursors.py", line 170, in execute
    result = self._query(query)
  File "C:\Python372\mecheck\lib\site-packages\pymysql\cursors.py", line 328, in _query
    conn.query(q)
  File "C:\Python372\mecheck\lib\site-packages\pymysql\connections.py", line 517, in query
    self._affected_rows = self._read_query_result(unbuffered=unbuffered)
  File "C:\Python372\mecheck\lib\site-packages\pymysql\connections.py", line 732, in _read_query_result
    result.read()
  File "C:\Python372\mecheck\lib\site-packages\pymysql\connections.py", line 1075, in read
    first_packet = self.connection._read_packet()
  File "C:\Python372\mecheck\lib\site-packages\pymysql\connections.py", line 657, in _read_packet
    packet_header = self._read_bytes(4)
  File "C:\Python372\mecheck\lib\site-packages\pymysql\connections.py", line 699, in _read_bytes
    "Lost connection to MySQL server during query (%s)" % (e,))
pymysql.err.OperationalError: (2013, 'Lost connection to MySQL server during query ([WinError 10053] 你的主机中的软件中止了一个已建立的连接。)')

The above exception was the direct cause of the following exception:

Traceback (most recent call last):
  File "C:\djangoproject\DMS\app01\tasks.py", line 206, in UnitRT_fun
    DQAUnit_TUMHistory.objects.bulk_create(update_list)
  File "C:\Python372\mecheck\lib\site-packages\django\db\models\manager.py", line 82, in manager_method
    return getattr(self.get_queryset(), name)(*args, **kwargs)
  File "C:\Python372\mecheck\lib\site-packages\django\db\models\query.py", line 465, in bulk_create
    ids = self._batched_insert(objs_without_pk, fields, batch_size)
  File "C:\Python372\mecheck\lib\site-packages\django\db\models\query.py", line 1155, in _batched_insert
    self._insert(item, fields=fields, using=self.db)
  File "C:\Python372\mecheck\lib\site-packages\django\db\models\query.py", line 1136, in _insert
    return query.get_compiler(using=using).execute_sql(return_id)
  File "C:\Python372\mecheck\lib\site-packages\django\db\models\sql\compiler.py", line 1289, in execute_sql
    cursor.execute(sql, params)
  File "C:\Python372\mecheck\lib\site-packages\django\db\backends\utils.py", line 100, in execute
    return super().execute(sql, params)
  File "C:\Python372\mecheck\lib\site-packages\django\db\backends\utils.py", line 68, in execute
    return self._execute_with_wrappers(sql, params, many=False, executor=self._execute)
  File "C:\Python372\mecheck\lib\site-packages\django\db\backends\utils.py", line 77, in _execute_with_wrappers
    return executor(sql, params, many, context)
  File "C:\Python372\mecheck\lib\site-packages\django\db\backends\utils.py", line 85, in _execute
    return self.cursor.execute(sql, params)
  File "C:\Python372\mecheck\lib\site-packages\django\db\utils.py", line 89, in __exit__
    raise dj_exc_value.with_traceback(traceback) from exc_value
  File "C:\Python372\mecheck\lib\site-packages\django\db\backends\utils.py", line 85, in _execute
    return self.cursor.execute(sql, params)
  File "C:\Python372\mecheck\lib\site-packages\django\db\backends\mysql\base.py", line 71, in execute
    return self.cursor.execute(query, args)
  File "C:\Python372\mecheck\lib\site-packages\pymysql\cursors.py", line 170, in execute
    result = self._query(query)
  File "C:\Python372\mecheck\lib\site-packages\pymysql\cursors.py", line 328, in _query
    conn.query(q)
  File "C:\Python372\mecheck\lib\site-packages\pymysql\connections.py", line 517, in query
    self._affected_rows = self._read_query_result(unbuffered=unbuffered)
  File "C:\Python372\mecheck\lib\site-packages\pymysql\connections.py", line 732, in _read_query_result
    result.read()
  File "C:\Python372\mecheck\lib\site-packages\pymysql\connections.py", line 1075, in read
    first_packet = self.connection._read_packet()
  File "C:\Python372\mecheck\lib\site-packages\pymysql\connections.py", line 657, in _read_packet
    packet_header = self._read_bytes(4)
  File "C:\Python372\mecheck\lib\site-packages\pymysql\connections.py", line 699, in _read_bytes
    "Lost connection to MySQL server during query (%s)" % (e,))
django.db.utils.OperationalError: (2013, 'Lost connection to MySQL server during query ([WinError 10053] 你的主机中的软件中止了一个已建立的连接。)')

During handling of the above exception, another exception occurred:

Traceback (most recent call last):
  File "C:\Python372\mecheck\lib\site-packages\django\core\handlers\exception.py", line 34, in inner
    response = get_response(request)
  File "C:\Python372\mecheck\lib\site-packages\django\core\handlers\base.py", line 126, in _get_response
    response = self.process_exception_by_middleware(e, request)
  File "C:\Python372\mecheck\lib\site-packages\django\core\handlers\base.py", line 124, in _get_response
    response = wrapped_callback(request, *callback_args, **callback_kwargs)
  File "C:\Python372\mecheck\lib\site-packages\django\views\decorators\csrf.py", line 54, in wrapped_view
    return view_func(*args, **kwargs)
  File "C:\djangoproject\DMS\app01\views.py", line 588, in Summary
    tasks.GetTumdata()
  File "C:\djangoproject\DMS\app01\tasks.py", line 90, in GetTumdata
    all_result.append(Result_UnitRT_fun.result())
  File "C:\Python372\lib\concurrent\futures\_base.py", line 432, in result
    return self.__get_result()
  File "C:\Python372\lib\concurrent\futures\_base.py", line 384, in __get_result
    raise self._exception
  File "C:\Python372\lib\concurrent\futures\thread.py", line 57, in run
    result = self.fn(*self.args, **self.kwargs)
  File "C:\djangoproject\DMS\app01\tasks.py", line 210, in UnitRT_fun
    logger.info("DDMS_Task-InputTumInfo: UnitRT_fun->" + e)
TypeError: can only concatenate str (not "OperationalError") to str
[2023-09-25 16:47:15,703] [UserIP.py:89] [UserIP:process_response] [CRITICAL]- 系统错误
[2023-09-25 16:47:15,707] [basehttp.py:154] [basehttp:log_message] [ERROR]- "POST /Summary/ HTTP/1.1" 500 485931
[2023-09-25 16:50:39,726] [log.py:228] [log:log_response] [ERROR]- Internal Server Error: /Summary/
Traceback (most recent call last):
  File "C:\Python372\mecheck\lib\site-packages\django\db\backends\utils.py", line 85, in _execute
    return self.cursor.execute(sql, params)
  File "C:\Python372\mecheck\lib\site-packages\django\db\backends\mysql\base.py", line 71, in execute
    return self.cursor.execute(query, args)
  File "C:\Python372\mecheck\lib\site-packages\pymysql\cursors.py", line 170, in execute
    result = self._query(query)
  File "C:\Python372\mecheck\lib\site-packages\pymysql\cursors.py", line 328, in _query
    conn.query(q)
  File "C:\Python372\mecheck\lib\site-packages\pymysql\connections.py", line 517, in query
    self._affected_rows = self._read_query_result(unbuffered=unbuffered)
  File "C:\Python372\mecheck\lib\site-packages\pymysql\connections.py", line 732, in _read_query_result
    result.read()
  File "C:\Python372\mecheck\lib\site-packages\pymysql\connections.py", line 1075, in read
    first_packet = self.connection._read_packet()
  File "C:\Python372\mecheck\lib\site-packages\pymysql\connections.py", line 684, in _read_packet
    packet.check_error()
  File "C:\Python372\mecheck\lib\site-packages\pymysql\protocol.py", line 220, in check_error
    err.raise_mysql_exception(self._data)
  File "C:\Python372\mecheck\lib\site-packages\pymysql\err.py", line 109, in raise_mysql_exception
    raise errorclass(errno, errval)
pymysql.err.InternalError: (1153, "Got a packet bigger than 'max_allowed_packet' bytes")

The above exception was the direct cause of the following exception:

Traceback (most recent call last):
  File "C:\djangoproject\DMS\app01\tasks.py", line 206, in UnitRT_fun
    DQAUnit_TUMHistory.objects.bulk_create(update_list)
  File "C:\Python372\mecheck\lib\site-packages\django\db\models\manager.py", line 82, in manager_method
    return getattr(self.get_queryset(), name)(*args, **kwargs)
  File "C:\Python372\mecheck\lib\site-packages\django\db\models\query.py", line 465, in bulk_create
    ids = self._batched_insert(objs_without_pk, fields, batch_size)
  File "C:\Python372\mecheck\lib\site-packages\django\db\models\query.py", line 1155, in _batched_insert
    self._insert(item, fields=fields, using=self.db)
  File "C:\Python372\mecheck\lib\site-packages\django\db\models\query.py", line 1136, in _insert
    return query.get_compiler(using=using).execute_sql(return_id)
  File "C:\Python372\mecheck\lib\site-packages\django\db\models\sql\compiler.py", line 1289, in execute_sql
    cursor.execute(sql, params)
  File "C:\Python372\mecheck\lib\site-packages\django\db\backends\utils.py", line 100, in execute
    return super().execute(sql, params)
  File "C:\Python372\mecheck\lib\site-packages\django\db\backends\utils.py", line 68, in execute
    return self._execute_with_wrappers(sql, params, many=False, executor=self._execute)
  File "C:\Python372\mecheck\lib\site-packages\django\db\backends\utils.py", line 77, in _execute_with_wrappers
    return executor(sql, params, many, context)
  File "C:\Python372\mecheck\lib\site-packages\django\db\backends\utils.py", line 85, in _execute
    return self.cursor.execute(sql, params)
  File "C:\Python372\mecheck\lib\site-packages\django\db\utils.py", line 89, in __exit__
    raise dj_exc_value.with_traceback(traceback) from exc_value
  File "C:\Python372\mecheck\lib\site-packages\django\db\backends\utils.py", line 85, in _execute
    return self.cursor.execute(sql, params)
  File "C:\Python372\mecheck\lib\site-packages\django\db\backends\mysql\base.py", line 71, in execute
    return self.cursor.execute(query, args)
  File "C:\Python372\mecheck\lib\site-packages\pymysql\cursors.py", line 170, in execute
    result = self._query(query)
  File "C:\Python372\mecheck\lib\site-packages\pymysql\cursors.py", line 328, in _query
    conn.query(q)
  File "C:\Python372\mecheck\lib\site-packages\pymysql\connections.py", line 517, in query
    self._affected_rows = self._read_query_result(unbuffered=unbuffered)
  File "C:\Python372\mecheck\lib\site-packages\pymysql\connections.py", line 732, in _read_query_result
    result.read()
  File "C:\Python372\mecheck\lib\site-packages\pymysql\connections.py", line 1075, in read
    first_packet = self.connection._read_packet()
  File "C:\Python372\mecheck\lib\site-packages\pymysql\connections.py", line 684, in _read_packet
    packet.check_error()
  File "C:\Python372\mecheck\lib\site-packages\pymysql\protocol.py", line 220, in check_error
    err.raise_mysql_exception(self._data)
  File "C:\Python372\mecheck\lib\site-packages\pymysql\err.py", line 109, in raise_mysql_exception
    raise errorclass(errno, errval)
django.db.utils.InternalError: (1153, "Got a packet bigger than 'max_allowed_packet' bytes")

During handling of the above exception, another exception occurred:

Traceback (most recent call last):
  File "C:\Python372\mecheck\lib\site-packages\django\core\handlers\exception.py", line 34, in inner
    response = get_response(request)
  File "C:\Python372\mecheck\lib\site-packages\django\core\handlers\base.py", line 126, in _get_response
    response = self.process_exception_by_middleware(e, request)
  File "C:\Python372\mecheck\lib\site-packages\django\core\handlers\base.py", line 124, in _get_response
    response = wrapped_callback(request, *callback_args, **callback_kwargs)
  File "C:\Python372\mecheck\lib\site-packages\django\views\decorators\csrf.py", line 54, in wrapped_view
    return view_func(*args, **kwargs)
  File "C:\djangoproject\DMS\app01\views.py", line 588, in Summary
    tasks.GetTumdata()
  File "C:\djangoproject\DMS\app01\tasks.py", line 90, in GetTumdata
    all_result.append(Result_UnitRT_fun.result())
  File "C:\Python372\lib\concurrent\futures\_base.py", line 432, in result
    return self.__get_result()
  File "C:\Python372\lib\concurrent\futures\_base.py", line 384, in __get_result
    raise self._exception
  File "C:\Python372\lib\concurrent\futures\thread.py", line 57, in run
    result = self.fn(*self.args, **self.kwargs)
  File "C:\djangoproject\DMS\app01\tasks.py", line 210, in UnitRT_fun
    logger.info("DDMS_Task-InputTumInfo: UnitRT_fun->" + e)
TypeError: can only concatenate str (not "InternalError") to str
[2023-09-25 16:50:39,748] [UserIP.py:89] [UserIP:process_response] [CRITICAL]- 系统错误
[2023-09-25 16:50:39,749] [basehttp.py:154] [basehttp:log_message] [ERROR]- "POST /Summary/ HTTP/1.1" 500 486398
[2023-09-26 07:57:51,794] [UserIP.py:89] [UserIP:process_response] [CRITICAL]- 系统错误
