[2021-08-11 08:30:21,372] [UserIP.py:89] [UserIP:process_response] [CRITICAL]- 系统错误
[2021-08-11 08:36:24,699] [UserIP.py:89] [UserIP:process_response] [CRITICAL]- 系统错误
[2021-08-11 08:39:28,368] [UserIP.py:89] [UserIP:process_response] [CRITICAL]- 系统错误
[2021-08-11 08:40:43,887] [UserIP.py:89] [UserIP:process_response] [CRITICAL]- 系统错误
[2021-08-11 08:47:58,000] [UserIP.py:89] [UserIP:process_response] [CRITICAL]- 系统错误
[2021-08-11 08:53:33,772] [UserIP.py:89] [UserIP:process_response] [CRITICAL]- 系统错误
[2021-08-11 11:01:20,984] [UserIP.py:89] [UserIP:process_response] [CRITICAL]- 系统错误
[2021-08-11 11:04:45,323] [UserIP.py:89] [UserIP:process_response] [CRITICAL]- 系统错误
[2021-08-11 11:06:00,920] [UserIP.py:89] [UserIP:process_response] [CRITICAL]- 系统错误
[2021-08-11 11:10:18,050] [log.py:228] [log:log_response] [ERROR]- Internal Server Error: /DeviceLNV/BorrowedDevice/
Traceback (most recent call last):
  File "C:\Python372\mecheck\lib\site-packages\django\db\models\sql\query.py", line 1735, in add_fields
    join_info = self.setup_joins(name.split(LOOKUP_SEP), opts, alias, allow_many=allow_m2m)
  File "C:\Python372\mecheck\lib\site-packages\django\db\models\sql\query.py", line 1473, in setup_joins
    names[:pivot], opts, allow_many, fail_on_missing=True,
  File "C:\Python372\mecheck\lib\site-packages\django\db\models\sql\query.py", line 1389, in names_to_path
    "Choices are: %s" % (name, ", ".join(available)))
django.core.exceptions.FieldError: Cannot resolve keyword 'Changjia' into field. Choices are: ApplicationNo, AssetNum, BR_per_code, BrwStatus, Btime, Comment, Customer, Declaration, DeclarationNo, DevCtgry, DevDescription, DevID, DevModel, DevName, DevPrice, DevStatus, DevVendor, Devproperties, Devsize, FWVer, HWVer, IntfCtgry, LSTA, Last_BR_per, Last_BR_per_code, Last_Borrow_date, Last_Predict_return, Last_Return_date, NID, PN, Pchsdate, PckgIncludes, Phase, Photo, Plandate, Plant, ProjectCode, Rtime, Source, UsrTimes, Usrname, addnewdate, addnewname, expirdate, id, uscyc, useday

During handling of the above exception, another exception occurred:

Traceback (most recent call last):
  File "C:\Python372\mecheck\lib\site-packages\django\core\handlers\exception.py", line 34, in inner
    response = get_response(request)
  File "C:\Python372\mecheck\lib\site-packages\django\core\handlers\base.py", line 126, in _get_response
    response = self.process_exception_by_middleware(e, request)
  File "C:\Python372\mecheck\lib\site-packages\django\core\handlers\base.py", line 124, in _get_response
    response = wrapped_callback(request, *callback_args, **callback_kwargs)
  File "C:\Python372\mecheck\lib\site-packages\django\views\decorators\csrf.py", line 54, in wrapped_view
    return view_func(*args, **kwargs)
  File "C:\djangoproject\DMS\DeviceLNV\views.py", line 103, in BorrowedDeviceLNV
    for j in DeviceLNV.objects.filter(Customer=i["Customer"]).values("Changjia").distinct().order_by(
  File "C:\Python372\mecheck\lib\site-packages\django\db\models\query.py", line 750, in values
    clone = self._values(*fields, **expressions)
  File "C:\Python372\mecheck\lib\site-packages\django\db\models\query.py", line 745, in _values
    clone.query.set_values(fields)
  File "C:\Python372\mecheck\lib\site-packages\django\db\models\sql\query.py", line 1987, in set_values
    self.add_fields(field_names, True)
  File "C:\Python372\mecheck\lib\site-packages\django\db\models\sql\query.py", line 1758, in add_fields
    "Choices are: %s" % (name, ", ".join(names)))
django.core.exceptions.FieldError: Cannot resolve keyword 'Changjia' into field. Choices are: ApplicationNo, AssetNum, BR_per_code, BrwStatus, Btime, Comment, Customer, Declaration, DeclarationNo, DevCtgry, DevDescription, DevID, DevModel, DevName, DevPrice, DevStatus, DevVendor, Devproperties, Devsize, FWVer, HWVer, IntfCtgry, LSTA, Last_BR_per, Last_BR_per_code, Last_Borrow_date, Last_Predict_return, Last_Return_date, NID, PN, Pchsdate, PckgIncludes, Phase, Photo, Plandate, Plant, ProjectCode, Rtime, Source, UsrTimes, Usrname, addnewdate, addnewname, expirdate, id, uscyc, useday
[2021-08-11 11:10:18,053] [basehttp.py:154] [basehttp:log_message] [ERROR]- "GET /DeviceLNV/BorrowedDevice/ HTTP/1.1" 500 121064
