[2021-10-15 10:32:19,363] [UserIP.py:89] [UserIP:process_response] [CRITICAL]- 系统错误
[2021-10-15 10:38:42,143] [UserIP.py:89] [UserIP:process_response] [CRITICAL]- 系统错误
[2021-10-15 10:38:48,205] [UserIP.py:89] [UserIP:process_response] [CRITICAL]- 系统错误
[2021-10-15 10:38:55,338] [UserIP.py:89] [UserIP:process_response] [CRITICAL]- 系统错误
[2021-10-15 10:39:02,216] [UserIP.py:89] [UserIP:process_response] [CRITICAL]- 系统错误
[2021-10-15 10:39:07,810] [UserIP.py:89] [UserIP:process_response] [CRITICAL]- 系统错误
[2021-10-15 10:39:57,887] [basehttp.py:154] [basehttp:log_message] [ERROR]- "POST /AdapterPowerCode/Summary/ HTTP/1.1" 500 59
[2021-10-15 10:40:29,842] [log.py:228] [log:log_response] [ERROR]- Internal Server Error: /AdapterPowerCode/M_edit/
Traceback (most recent call last):
  File "C:\Python372\mecheck\lib\site-packages\django\core\handlers\exception.py", line 34, in inner
    response = get_response(request)
  File "C:\Python372\mecheck\lib\site-packages\django\core\handlers\base.py", line 126, in _get_response
    response = self.process_exception_by_middleware(e, request)
  File "C:\Python372\mecheck\lib\site-packages\django\core\handlers\base.py", line 124, in _get_response
    response = wrapped_callback(request, *callback_args, **callback_kwargs)
  File "C:\Python372\mecheck\lib\site-packages\django\views\decorators\csrf.py", line 54, in wrapped_view
    return view_func(*args, **kwargs)
  File "C:\djangoproject\DMS\AdapterPowerCode\views.py", line 3420, in M_edit
    value.split("/")[0] + "-" + \
IndexError: list index out of range
[2021-10-15 10:40:29,844] [UserIP.py:89] [UserIP:process_response] [CRITICAL]- 系统错误
[2021-10-15 10:40:29,845] [basehttp.py:154] [basehttp:log_message] [ERROR]- "POST /AdapterPowerCode/M_edit/ HTTP/1.1" 500 110806
[2021-10-15 10:41:20,150] [log.py:228] [log:log_response] [ERROR]- Internal Server Error: /AdapterPowerCode/M_edit/
Traceback (most recent call last):
  File "C:\Python372\mecheck\lib\site-packages\django\core\handlers\exception.py", line 34, in inner
    response = get_response(request)
  File "C:\Python372\mecheck\lib\site-packages\django\core\handlers\base.py", line 126, in _get_response
    response = self.process_exception_by_middleware(e, request)
  File "C:\Python372\mecheck\lib\site-packages\django\core\handlers\base.py", line 124, in _get_response
    response = wrapped_callback(request, *callback_args, **callback_kwargs)
  File "C:\Python372\mecheck\lib\site-packages\django\views\decorators\csrf.py", line 54, in wrapped_view
    return view_func(*args, **kwargs)
  File "C:\djangoproject\DMS\AdapterPowerCode\views.py", line 3436, in M_edit
    AdapterPowerCodeBR.objects.create(**modeldata)
  File "C:\Python372\mecheck\lib\site-packages\django\db\models\manager.py", line 82, in manager_method
    return getattr(self.get_queryset(), name)(*args, **kwargs)
  File "C:\Python372\mecheck\lib\site-packages\django\db\models\query.py", line 413, in create
    obj.save(force_insert=True, using=self.db)
  File "C:\Python372\mecheck\lib\site-packages\django\db\models\base.py", line 718, in save
    force_update=force_update, update_fields=update_fields)
  File "C:\Python372\mecheck\lib\site-packages\django\db\models\base.py", line 748, in save_base
    updated = self._save_table(raw, cls, force_insert, force_update, using, update_fields)
  File "C:\Python372\mecheck\lib\site-packages\django\db\models\base.py", line 831, in _save_table
    result = self._do_insert(cls._base_manager, using, fields, update_pk, raw)
  File "C:\Python372\mecheck\lib\site-packages\django\db\models\base.py", line 869, in _do_insert
    using=using, raw=raw)
  File "C:\Python372\mecheck\lib\site-packages\django\db\models\manager.py", line 82, in manager_method
    return getattr(self.get_queryset(), name)(*args, **kwargs)
  File "C:\Python372\mecheck\lib\site-packages\django\db\models\query.py", line 1136, in _insert
    return query.get_compiler(using=using).execute_sql(return_id)
  File "C:\Python372\mecheck\lib\site-packages\django\db\models\sql\compiler.py", line 1288, in execute_sql
    for sql, params in self.as_sql():
  File "C:\Python372\mecheck\lib\site-packages\django\db\models\sql\compiler.py", line 1241, in as_sql
    for obj in self.query.objs
  File "C:\Python372\mecheck\lib\site-packages\django\db\models\sql\compiler.py", line 1241, in <listcomp>
    for obj in self.query.objs
  File "C:\Python372\mecheck\lib\site-packages\django\db\models\sql\compiler.py", line 1240, in <listcomp>
    [self.prepare_value(field, self.pre_save_val(field, obj)) for field in fields]
  File "C:\Python372\mecheck\lib\site-packages\django\db\models\sql\compiler.py", line 1182, in prepare_value
    value = field.get_db_prep_save(value, connection=self.connection)
  File "C:\Python372\mecheck\lib\site-packages\django\db\models\fields\__init__.py", line 790, in get_db_prep_save
    return self.get_db_prep_value(value, connection=connection, prepared=False)
  File "C:\Python372\mecheck\lib\site-packages\django\db\models\fields\__init__.py", line 1273, in get_db_prep_value
    value = self.get_prep_value(value)
  File "C:\Python372\mecheck\lib\site-packages\django\db\models\fields\__init__.py", line 1268, in get_prep_value
    return self.to_python(value)
  File "C:\Python372\mecheck\lib\site-packages\django\db\models\fields\__init__.py", line 1243, in to_python
    params={'value': value},
django.core.exceptions.ValidationError: ['’28-2022-2‘ 必须为合法的日期格式，请使用 YYYY-MM-DD 格式。']
[2021-10-15 10:41:20,155] [UserIP.py:89] [UserIP:process_response] [CRITICAL]- 系统错误
[2021-10-15 10:41:20,157] [basehttp.py:154] [basehttp:log_message] [ERROR]- "POST /AdapterPowerCode/M_edit/ HTTP/1.1" 500 202786
[2021-10-15 10:58:31,180] [log.py:228] [log:log_response] [ERROR]- Internal Server Error: /AdapterPowerCode/M_edit/
Traceback (most recent call last):
  File "C:\Python372\mecheck\lib\site-packages\django\core\handlers\exception.py", line 34, in inner
    response = get_response(request)
  File "C:\Python372\mecheck\lib\site-packages\django\core\handlers\base.py", line 126, in _get_response
    response = self.process_exception_by_middleware(e, request)
  File "C:\Python372\mecheck\lib\site-packages\django\core\handlers\base.py", line 124, in _get_response
    response = wrapped_callback(request, *callback_args, **callback_kwargs)
  File "C:\Python372\mecheck\lib\site-packages\django\views\decorators\csrf.py", line 54, in wrapped_view
    return view_func(*args, **kwargs)
  File "C:\djangoproject\DMS\AdapterPowerCode\views.py", line 3436, in M_edit
    AdapterPowerCodeBR.objects.create(**modeldata)
  File "C:\Python372\mecheck\lib\site-packages\django\db\models\manager.py", line 82, in manager_method
    return getattr(self.get_queryset(), name)(*args, **kwargs)
  File "C:\Python372\mecheck\lib\site-packages\django\db\models\query.py", line 413, in create
    obj.save(force_insert=True, using=self.db)
  File "C:\Python372\mecheck\lib\site-packages\django\db\models\base.py", line 718, in save
    force_update=force_update, update_fields=update_fields)
  File "C:\Python372\mecheck\lib\site-packages\django\db\models\base.py", line 748, in save_base
    updated = self._save_table(raw, cls, force_insert, force_update, using, update_fields)
  File "C:\Python372\mecheck\lib\site-packages\django\db\models\base.py", line 831, in _save_table
    result = self._do_insert(cls._base_manager, using, fields, update_pk, raw)
  File "C:\Python372\mecheck\lib\site-packages\django\db\models\base.py", line 869, in _do_insert
    using=using, raw=raw)
  File "C:\Python372\mecheck\lib\site-packages\django\db\models\manager.py", line 82, in manager_method
    return getattr(self.get_queryset(), name)(*args, **kwargs)
  File "C:\Python372\mecheck\lib\site-packages\django\db\models\query.py", line 1136, in _insert
    return query.get_compiler(using=using).execute_sql(return_id)
  File "C:\Python372\mecheck\lib\site-packages\django\db\models\sql\compiler.py", line 1288, in execute_sql
    for sql, params in self.as_sql():
  File "C:\Python372\mecheck\lib\site-packages\django\db\models\sql\compiler.py", line 1241, in as_sql
    for obj in self.query.objs
  File "C:\Python372\mecheck\lib\site-packages\django\db\models\sql\compiler.py", line 1241, in <listcomp>
    for obj in self.query.objs
  File "C:\Python372\mecheck\lib\site-packages\django\db\models\sql\compiler.py", line 1240, in <listcomp>
    [self.prepare_value(field, self.pre_save_val(field, obj)) for field in fields]
  File "C:\Python372\mecheck\lib\site-packages\django\db\models\sql\compiler.py", line 1182, in prepare_value
    value = field.get_db_prep_save(value, connection=self.connection)
  File "C:\Python372\mecheck\lib\site-packages\django\db\models\fields\__init__.py", line 790, in get_db_prep_save
    return self.get_db_prep_value(value, connection=connection, prepared=False)
  File "C:\Python372\mecheck\lib\site-packages\django\db\models\fields\__init__.py", line 1273, in get_db_prep_value
    value = self.get_prep_value(value)
  File "C:\Python372\mecheck\lib\site-packages\django\db\models\fields\__init__.py", line 1268, in get_prep_value
    return self.to_python(value)
  File "C:\Python372\mecheck\lib\site-packages\django\db\models\fields\__init__.py", line 1243, in to_python
    params={'value': value},
django.core.exceptions.ValidationError: ['’28-2022-2‘ 必须为合法的日期格式，请使用 YYYY-MM-DD 格式。']
[2021-10-15 10:58:31,182] [UserIP.py:89] [UserIP:process_response] [CRITICAL]- 系统错误
[2021-10-15 10:58:31,183] [basehttp.py:154] [basehttp:log_message] [ERROR]- "POST /AdapterPowerCode/M_edit/ HTTP/1.1" 500 205010
[2021-10-15 11:04:21,419] [log.py:228] [log:log_response] [ERROR]- Internal Server Error: /AdapterPowerCode/M_edit/
Traceback (most recent call last):
  File "C:\Python372\mecheck\lib\site-packages\django\core\handlers\exception.py", line 34, in inner
    response = get_response(request)
  File "C:\Python372\mecheck\lib\site-packages\django\core\handlers\base.py", line 126, in _get_response
    response = self.process_exception_by_middleware(e, request)
  File "C:\Python372\mecheck\lib\site-packages\django\core\handlers\base.py", line 124, in _get_response
    response = wrapped_callback(request, *callback_args, **callback_kwargs)
  File "C:\Python372\mecheck\lib\site-packages\django\views\decorators\csrf.py", line 54, in wrapped_view
    return view_func(*args, **kwargs)
  File "C:\djangoproject\DMS\AdapterPowerCode\views.py", line 3436, in M_edit
    AdapterPowerCodeBR.objects.create(**modeldata)
  File "C:\Python372\mecheck\lib\site-packages\django\db\models\manager.py", line 82, in manager_method
    return getattr(self.get_queryset(), name)(*args, **kwargs)
  File "C:\Python372\mecheck\lib\site-packages\django\db\models\query.py", line 413, in create
    obj.save(force_insert=True, using=self.db)
  File "C:\Python372\mecheck\lib\site-packages\django\db\models\base.py", line 718, in save
    force_update=force_update, update_fields=update_fields)
  File "C:\Python372\mecheck\lib\site-packages\django\db\models\base.py", line 748, in save_base
    updated = self._save_table(raw, cls, force_insert, force_update, using, update_fields)
  File "C:\Python372\mecheck\lib\site-packages\django\db\models\base.py", line 831, in _save_table
    result = self._do_insert(cls._base_manager, using, fields, update_pk, raw)
  File "C:\Python372\mecheck\lib\site-packages\django\db\models\base.py", line 869, in _do_insert
    using=using, raw=raw)
  File "C:\Python372\mecheck\lib\site-packages\django\db\models\manager.py", line 82, in manager_method
    return getattr(self.get_queryset(), name)(*args, **kwargs)
  File "C:\Python372\mecheck\lib\site-packages\django\db\models\query.py", line 1136, in _insert
    return query.get_compiler(using=using).execute_sql(return_id)
  File "C:\Python372\mecheck\lib\site-packages\django\db\models\sql\compiler.py", line 1288, in execute_sql
    for sql, params in self.as_sql():
  File "C:\Python372\mecheck\lib\site-packages\django\db\models\sql\compiler.py", line 1241, in as_sql
    for obj in self.query.objs
  File "C:\Python372\mecheck\lib\site-packages\django\db\models\sql\compiler.py", line 1241, in <listcomp>
    for obj in self.query.objs
  File "C:\Python372\mecheck\lib\site-packages\django\db\models\sql\compiler.py", line 1240, in <listcomp>
    [self.prepare_value(field, self.pre_save_val(field, obj)) for field in fields]
  File "C:\Python372\mecheck\lib\site-packages\django\db\models\sql\compiler.py", line 1182, in prepare_value
    value = field.get_db_prep_save(value, connection=self.connection)
  File "C:\Python372\mecheck\lib\site-packages\django\db\models\fields\__init__.py", line 790, in get_db_prep_save
    return self.get_db_prep_value(value, connection=connection, prepared=False)
  File "C:\Python372\mecheck\lib\site-packages\django\db\models\fields\__init__.py", line 1273, in get_db_prep_value
    value = self.get_prep_value(value)
  File "C:\Python372\mecheck\lib\site-packages\django\db\models\fields\__init__.py", line 1268, in get_prep_value
    return self.to_python(value)
  File "C:\Python372\mecheck\lib\site-packages\django\db\models\fields\__init__.py", line 1243, in to_python
    params={'value': value},
django.core.exceptions.ValidationError: ['’28-2022-2‘ 必须为合法的日期格式，请使用 YYYY-MM-DD 格式。']
[2021-10-15 11:04:21,421] [UserIP.py:89] [UserIP:process_response] [CRITICAL]- 系统错误
[2021-10-15 11:04:21,422] [basehttp.py:154] [basehttp:log_message] [ERROR]- "POST /AdapterPowerCode/M_edit/ HTTP/1.1" 500 205010
[2021-10-15 11:05:24,115] [log.py:228] [log:log_response] [ERROR]- Internal Server Error: /AdapterPowerCode/M_edit/
Traceback (most recent call last):
  File "C:\Python372\mecheck\lib\site-packages\django\core\handlers\exception.py", line 34, in inner
    response = get_response(request)
  File "C:\Python372\mecheck\lib\site-packages\django\core\handlers\base.py", line 126, in _get_response
    response = self.process_exception_by_middleware(e, request)
  File "C:\Python372\mecheck\lib\site-packages\django\core\handlers\base.py", line 124, in _get_response
    response = wrapped_callback(request, *callback_args, **callback_kwargs)
  File "C:\Python372\mecheck\lib\site-packages\django\views\decorators\csrf.py", line 54, in wrapped_view
    return view_func(*args, **kwargs)
  File "C:\djangoproject\DMS\AdapterPowerCode\views.py", line 3439, in M_edit
    AdapterPowerCodeBR.objects.create(**modeldata)
  File "C:\Python372\mecheck\lib\site-packages\django\db\models\manager.py", line 82, in manager_method
    return getattr(self.get_queryset(), name)(*args, **kwargs)
  File "C:\Python372\mecheck\lib\site-packages\django\db\models\query.py", line 413, in create
    obj.save(force_insert=True, using=self.db)
  File "C:\Python372\mecheck\lib\site-packages\django\db\models\base.py", line 718, in save
    force_update=force_update, update_fields=update_fields)
  File "C:\Python372\mecheck\lib\site-packages\django\db\models\base.py", line 748, in save_base
    updated = self._save_table(raw, cls, force_insert, force_update, using, update_fields)
  File "C:\Python372\mecheck\lib\site-packages\django\db\models\base.py", line 831, in _save_table
    result = self._do_insert(cls._base_manager, using, fields, update_pk, raw)
  File "C:\Python372\mecheck\lib\site-packages\django\db\models\base.py", line 869, in _do_insert
    using=using, raw=raw)
  File "C:\Python372\mecheck\lib\site-packages\django\db\models\manager.py", line 82, in manager_method
    return getattr(self.get_queryset(), name)(*args, **kwargs)
  File "C:\Python372\mecheck\lib\site-packages\django\db\models\query.py", line 1136, in _insert
    return query.get_compiler(using=using).execute_sql(return_id)
  File "C:\Python372\mecheck\lib\site-packages\django\db\models\sql\compiler.py", line 1288, in execute_sql
    for sql, params in self.as_sql():
  File "C:\Python372\mecheck\lib\site-packages\django\db\models\sql\compiler.py", line 1241, in as_sql
    for obj in self.query.objs
  File "C:\Python372\mecheck\lib\site-packages\django\db\models\sql\compiler.py", line 1241, in <listcomp>
    for obj in self.query.objs
  File "C:\Python372\mecheck\lib\site-packages\django\db\models\sql\compiler.py", line 1240, in <listcomp>
    [self.prepare_value(field, self.pre_save_val(field, obj)) for field in fields]
  File "C:\Python372\mecheck\lib\site-packages\django\db\models\sql\compiler.py", line 1182, in prepare_value
    value = field.get_db_prep_save(value, connection=self.connection)
  File "C:\Python372\mecheck\lib\site-packages\django\db\models\fields\__init__.py", line 790, in get_db_prep_save
    return self.get_db_prep_value(value, connection=connection, prepared=False)
  File "C:\Python372\mecheck\lib\site-packages\django\db\models\fields\__init__.py", line 1273, in get_db_prep_value
    value = self.get_prep_value(value)
  File "C:\Python372\mecheck\lib\site-packages\django\db\models\fields\__init__.py", line 1268, in get_prep_value
    return self.to_python(value)
  File "C:\Python372\mecheck\lib\site-packages\django\db\models\fields\__init__.py", line 1243, in to_python
    params={'value': value},
django.core.exceptions.ValidationError: ['’28-2022-2‘ 必须为合法的日期格式，请使用 YYYY-MM-DD 格式。']
[2021-10-15 11:05:24,123] [UserIP.py:89] [UserIP:process_response] [CRITICAL]- 系统错误
[2021-10-15 11:05:24,124] [basehttp.py:154] [basehttp:log_message] [ERROR]- "POST /AdapterPowerCode/M_edit/ HTTP/1.1" 500 205164
[2021-10-15 11:05:41,047] [log.py:228] [log:log_response] [ERROR]- Internal Server Error: /AdapterPowerCode/M_edit/
Traceback (most recent call last):
  File "C:\Python372\mecheck\lib\site-packages\django\core\handlers\exception.py", line 34, in inner
    response = get_response(request)
  File "C:\Python372\mecheck\lib\site-packages\django\core\handlers\base.py", line 126, in _get_response
    response = self.process_exception_by_middleware(e, request)
  File "C:\Python372\mecheck\lib\site-packages\django\core\handlers\base.py", line 124, in _get_response
    response = wrapped_callback(request, *callback_args, **callback_kwargs)
  File "C:\Python372\mecheck\lib\site-packages\django\views\decorators\csrf.py", line 54, in wrapped_view
    return view_func(*args, **kwargs)
  File "C:\djangoproject\DMS\AdapterPowerCode\views.py", line 3422, in M_edit
    value.split("/")[0] + "-" + \
AttributeError: 'int' object has no attribute 'split'
[2021-10-15 11:05:41,049] [UserIP.py:89] [UserIP:process_response] [CRITICAL]- 系统错误
[2021-10-15 11:05:41,049] [basehttp.py:154] [basehttp:log_message] [ERROR]- "POST /AdapterPowerCode/M_edit/ HTTP/1.1" 500 113232
[2021-10-15 11:06:40,711] [log.py:228] [log:log_response] [ERROR]- Internal Server Error: /AdapterPowerCode/M_edit/
Traceback (most recent call last):
  File "C:\Python372\mecheck\lib\site-packages\django\core\handlers\exception.py", line 34, in inner
    response = get_response(request)
  File "C:\Python372\mecheck\lib\site-packages\django\core\handlers\base.py", line 126, in _get_response
    response = self.process_exception_by_middleware(e, request)
  File "C:\Python372\mecheck\lib\site-packages\django\core\handlers\base.py", line 124, in _get_response
    response = wrapped_callback(request, *callback_args, **callback_kwargs)
  File "C:\Python372\mecheck\lib\site-packages\django\views\decorators\csrf.py", line 54, in wrapped_view
    return view_func(*args, **kwargs)
  File "C:\djangoproject\DMS\AdapterPowerCode\views.py", line 3422, in M_edit
    value.split("/")[0] + "-" + \
AttributeError: 'int' object has no attribute 'split'
[2021-10-15 11:06:40,714] [UserIP.py:89] [UserIP:process_response] [CRITICAL]- 系统错误
[2021-10-15 11:06:40,715] [basehttp.py:154] [basehttp:log_message] [ERROR]- "POST /AdapterPowerCode/M_edit/ HTTP/1.1" 500 113232
[2021-10-15 11:08:37,567] [log.py:228] [log:log_response] [ERROR]- Internal Server Error: /AdapterPowerCode/M_edit/
Traceback (most recent call last):
  File "C:\Python372\mecheck\lib\site-packages\django\core\handlers\exception.py", line 34, in inner
    response = get_response(request)
  File "C:\Python372\mecheck\lib\site-packages\django\core\handlers\base.py", line 126, in _get_response
    response = self.process_exception_by_middleware(e, request)
  File "C:\Python372\mecheck\lib\site-packages\django\core\handlers\base.py", line 124, in _get_response
    response = wrapped_callback(request, *callback_args, **callback_kwargs)
  File "C:\Python372\mecheck\lib\site-packages\django\views\decorators\csrf.py", line 54, in wrapped_view
    return view_func(*args, **kwargs)
  File "C:\djangoproject\DMS\AdapterPowerCode\views.py", line 3422, in M_edit
    value.split("/")[0] + "-" + \
IndexError: list index out of range
[2021-10-15 11:08:37,569] [UserIP.py:89] [UserIP:process_response] [CRITICAL]- 系统错误
[2021-10-15 11:08:37,569] [basehttp.py:154] [basehttp:log_message] [ERROR]- "POST /AdapterPowerCode/M_edit/ HTTP/1.1" 500 113502
[2021-10-15 11:09:43,206] [log.py:228] [log:log_response] [ERROR]- Internal Server Error: /AdapterPowerCode/M_edit/
Traceback (most recent call last):
  File "C:\Python372\mecheck\lib\site-packages\django\core\handlers\exception.py", line 34, in inner
    response = get_response(request)
  File "C:\Python372\mecheck\lib\site-packages\django\core\handlers\base.py", line 126, in _get_response
    response = self.process_exception_by_middleware(e, request)
  File "C:\Python372\mecheck\lib\site-packages\django\core\handlers\base.py", line 124, in _get_response
    response = wrapped_callback(request, *callback_args, **callback_kwargs)
  File "C:\Python372\mecheck\lib\site-packages\django\views\decorators\csrf.py", line 54, in wrapped_view
    return view_func(*args, **kwargs)
  File "C:\djangoproject\DMS\AdapterPowerCode\views.py", line 3423, in M_edit
    value.split("/")[0] + "-" + \
IndexError: list index out of range
[2021-10-15 11:09:43,209] [UserIP.py:89] [UserIP:process_response] [CRITICAL]- 系统错误
[2021-10-15 11:09:43,210] [basehttp.py:154] [basehttp:log_message] [ERROR]- "POST /AdapterPowerCode/M_edit/ HTTP/1.1" 500 115718
[2021-10-15 11:10:37,021] [log.py:228] [log:log_response] [ERROR]- Internal Server Error: /AdapterPowerCode/M_edit/
Traceback (most recent call last):
  File "C:\Python372\mecheck\lib\site-packages\django\core\handlers\exception.py", line 34, in inner
    response = get_response(request)
  File "C:\Python372\mecheck\lib\site-packages\django\core\handlers\base.py", line 126, in _get_response
    response = self.process_exception_by_middleware(e, request)
  File "C:\Python372\mecheck\lib\site-packages\django\core\handlers\base.py", line 124, in _get_response
    response = wrapped_callback(request, *callback_args, **callback_kwargs)
  File "C:\Python372\mecheck\lib\site-packages\django\views\decorators\csrf.py", line 54, in wrapped_view
    return view_func(*args, **kwargs)
  File "C:\djangoproject\DMS\AdapterPowerCode\views.py", line 3423, in M_edit
    value.split("/")[0] + "-" + \
IndexError: list index out of range
[2021-10-15 11:10:37,023] [UserIP.py:89] [UserIP:process_response] [CRITICAL]- 系统错误
[2021-10-15 11:10:37,023] [basehttp.py:154] [basehttp:log_message] [ERROR]- "POST /AdapterPowerCode/M_edit/ HTTP/1.1" 500 115651
[2021-10-15 11:13:02,152] [log.py:228] [log:log_response] [ERROR]- Internal Server Error: /AdapterPowerCode/M_edit/
Traceback (most recent call last):
  File "C:\Python372\mecheck\lib\site-packages\django\core\handlers\exception.py", line 34, in inner
    response = get_response(request)
  File "C:\Python372\mecheck\lib\site-packages\django\core\handlers\base.py", line 126, in _get_response
    response = self.process_exception_by_middleware(e, request)
  File "C:\Python372\mecheck\lib\site-packages\django\core\handlers\base.py", line 124, in _get_response
    response = wrapped_callback(request, *callback_args, **callback_kwargs)
  File "C:\Python372\mecheck\lib\site-packages\django\views\decorators\csrf.py", line 54, in wrapped_view
    return view_func(*args, **kwargs)
  File "C:\djangoproject\DMS\AdapterPowerCode\views.py", line 3438, in M_edit
    **Check_dic).update(**modeldata)
  File "C:\Python372\mecheck\lib\site-packages\django\db\models\query.py", line 693, in update
    rows = query.get_compiler(self.db).execute_sql(CURSOR)
  File "C:\Python372\mecheck\lib\site-packages\django\db\models\sql\compiler.py", line 1383, in execute_sql
    cursor = super().execute_sql(result_type)
  File "C:\Python372\mecheck\lib\site-packages\django\db\models\sql\compiler.py", line 1052, in execute_sql
    sql, params = self.as_sql()
  File "C:\Python372\mecheck\lib\site-packages\django\db\models\sql\compiler.py", line 1349, in as_sql
    val = field.get_db_prep_save(val, connection=self.connection)
  File "C:\Python372\mecheck\lib\site-packages\django\db\models\fields\__init__.py", line 790, in get_db_prep_save
    return self.get_db_prep_value(value, connection=connection, prepared=False)
  File "C:\Python372\mecheck\lib\site-packages\django\db\models\fields\__init__.py", line 1273, in get_db_prep_value
    value = self.get_prep_value(value)
  File "C:\Python372\mecheck\lib\site-packages\django\db\models\fields\__init__.py", line 1268, in get_prep_value
    return self.to_python(value)
  File "C:\Python372\mecheck\lib\site-packages\django\db\models\fields\__init__.py", line 1243, in to_python
    params={'value': value},
django.core.exceptions.ValidationError: ['’28-2022-2‘ 必须为合法的日期格式，请使用 YYYY-MM-DD 格式。']
[2021-10-15 11:13:02,154] [UserIP.py:89] [UserIP:process_response] [CRITICAL]- 系统错误
[2021-10-15 11:13:02,156] [basehttp.py:154] [basehttp:log_message] [ERROR]- "POST /AdapterPowerCode/M_edit/ HTTP/1.1" 500 153112
[2021-10-18 16:47:41,632] [UserIP.py:89] [UserIP:process_response] [CRITICAL]- 系统错误
[2021-10-19 08:49:22,799] [UserIP.py:89] [UserIP:process_response] [CRITICAL]- 系统错误
[2021-10-19 11:49:57,688] [UserIP.py:89] [UserIP:process_response] [CRITICAL]- 系统错误
[2021-10-19 11:51:32,460] [UserIP.py:89] [UserIP:process_response] [CRITICAL]- 系统错误
