[2020-12-31 08:54:04,768] [log.py:228] [log:log_response] [ERROR]- Internal Server Error: /PersonalInfo/Infos-upload/
Traceback (most recent call last):
  File "C:\Python372\mecheck\lib\site-packages\django\core\handlers\exception.py", line 34, in inner
    response = get_response(request)
  File "C:\Python372\mecheck\lib\site-packages\django\core\handlers\base.py", line 126, in _get_response
    response = self.process_exception_by_middleware(e, request)
  File "C:\Python372\mecheck\lib\site-packages\django\core\handlers\base.py", line 124, in _get_response
    response = wrapped_callback(request, *callback_args, **callback_kwargs)
  File "C:\Python372\mecheck\lib\site-packages\django\views\decorators\csrf.py", line 54, in wrapped_view
    return view_func(*args, **kwargs)
  File "C:\djangoproject\Reliability_Row_data\PersonalInfo\views.py", line 198, in Infos_upload
    Check_dic = {"Year": modeldata['Year'],
KeyError: 'Year'
[2020-12-31 08:54:04,773] [basehttp.py:154] [basehttp:log_message] [ERROR]- "POST /PersonalInfo/Infos-upload/ HTTP/1.1" 500 22339
[2020-12-31 10:32:02,470] [log.py:228] [log:log_response] [ERROR]- Internal Server Error: /PersonalInfo/Infos-upload/
Traceback (most recent call last):
  File "C:\Python372\mecheck\lib\site-packages\django\core\handlers\exception.py", line 34, in inner
    response = get_response(request)
  File "C:\Python372\mecheck\lib\site-packages\django\core\handlers\base.py", line 126, in _get_response
    response = self.process_exception_by_middleware(e, request)
  File "C:\Python372\mecheck\lib\site-packages\django\core\handlers\base.py", line 124, in _get_response
    response = wrapped_callback(request, *callback_args, **callback_kwargs)
  File "C:\Python372\mecheck\lib\site-packages\django\views\decorators\csrf.py", line 54, in wrapped_view
    return view_func(*args, **kwargs)
  File "C:\djangoproject\Reliability_Row_data\PersonalInfo\views.py", line 297, in Infos_upload
    Check_dics)
NameError: name 'Check_dics' is not defined
[2020-12-31 10:32:02,474] [basehttp.py:154] [basehttp:log_message] [ERROR]- "POST /PersonalInfo/Infos-upload/ HTTP/1.1" 500 206438
[2020-12-31 10:42:47,194] [log.py:228] [log:log_response] [ERROR]- Internal Server Error: /PersonalInfo/Infos-upload/
Traceback (most recent call last):
  File "C:\Python372\mecheck\lib\site-packages\django\core\handlers\exception.py", line 34, in inner
    response = get_response(request)
  File "C:\Python372\mecheck\lib\site-packages\django\core\handlers\base.py", line 126, in _get_response
    response = self.process_exception_by_middleware(e, request)
  File "C:\Python372\mecheck\lib\site-packages\django\core\handlers\base.py", line 124, in _get_response
    response = wrapped_callback(request, *callback_args, **callback_kwargs)
  File "C:\Python372\mecheck\lib\site-packages\django\views\decorators\csrf.py", line 54, in wrapped_view
    return view_func(*args, **kwargs)
  File "C:\djangoproject\Reliability_Row_data\PersonalInfo\views.py", line 142, in Infos_upload
    modeldata[headermodel_Positions[key]] = value
KeyError: '公司別'
[2020-12-31 10:42:47,198] [basehttp.py:154] [basehttp:log_message] [ERROR]- "POST /PersonalInfo/Infos-upload/ HTTP/1.1" 500 19760
[2020-12-31 10:43:02,986] [log.py:228] [log:log_response] [ERROR]- Internal Server Error: /PersonalInfo/Infos-upload/
Traceback (most recent call last):
  File "C:\Python372\mecheck\lib\site-packages\django\core\handlers\exception.py", line 34, in inner
    response = get_response(request)
  File "C:\Python372\mecheck\lib\site-packages\django\core\handlers\base.py", line 126, in _get_response
    response = self.process_exception_by_middleware(e, request)
  File "C:\Python372\mecheck\lib\site-packages\django\core\handlers\base.py", line 124, in _get_response
    response = wrapped_callback(request, *callback_args, **callback_kwargs)
  File "C:\Python372\mecheck\lib\site-packages\django\views\decorators\csrf.py", line 54, in wrapped_view
    return view_func(*args, **kwargs)
  File "C:\djangoproject\Reliability_Row_data\PersonalInfo\views.py", line 233, in Infos_upload
    modeldata[headermodel_MajorIfo[key]] = value
KeyError: '職等'
[2020-12-31 10:43:02,987] [basehttp.py:154] [basehttp:log_message] [ERROR]- "POST /PersonalInfo/Infos-upload/ HTTP/1.1" 500 22340
[2020-12-31 10:43:07,066] [log.py:228] [log:log_response] [ERROR]- Internal Server Error: /PersonalInfo/Infos-upload/
Traceback (most recent call last):
  File "C:\Python372\mecheck\lib\site-packages\django\core\handlers\exception.py", line 34, in inner
    response = get_response(request)
  File "C:\Python372\mecheck\lib\site-packages\django\core\handlers\base.py", line 126, in _get_response
    response = self.process_exception_by_middleware(e, request)
  File "C:\Python372\mecheck\lib\site-packages\django\core\handlers\base.py", line 124, in _get_response
    response = wrapped_callback(request, *callback_args, **callback_kwargs)
  File "C:\Python372\mecheck\lib\site-packages\django\views\decorators\csrf.py", line 54, in wrapped_view
    return view_func(*args, **kwargs)
  File "C:\djangoproject\Reliability_Row_data\PersonalInfo\views.py", line 233, in Infos_upload
    modeldata[headermodel_MajorIfo[key]] = value
KeyError: '職等'
[2020-12-31 10:43:07,067] [basehttp.py:154] [basehttp:log_message] [ERROR]- "POST /PersonalInfo/Infos-upload/ HTTP/1.1" 500 22340
[2020-12-31 10:43:35,566] [log.py:228] [log:log_response] [ERROR]- Internal Server Error: /PersonalInfo/Infos-upload/
Traceback (most recent call last):
  File "C:\Python372\mecheck\lib\site-packages\django\core\handlers\exception.py", line 34, in inner
    response = get_response(request)
  File "C:\Python372\mecheck\lib\site-packages\django\core\handlers\base.py", line 126, in _get_response
    response = self.process_exception_by_middleware(e, request)
  File "C:\Python372\mecheck\lib\site-packages\django\core\handlers\base.py", line 124, in _get_response
    response = wrapped_callback(request, *callback_args, **callback_kwargs)
  File "C:\Python372\mecheck\lib\site-packages\django\views\decorators\csrf.py", line 54, in wrapped_view
    return view_func(*args, **kwargs)
  File "C:\djangoproject\Reliability_Row_data\PersonalInfo\views.py", line 142, in Infos_upload
    modeldata[headermodel_Positions[key]] = value
KeyError: '學歷'
[2020-12-31 10:43:35,567] [basehttp.py:154] [basehttp:log_message] [ERROR]- "POST /PersonalInfo/Infos-upload/ HTTP/1.1" 500 206510
[2020-12-31 11:17:05,101] [log.py:228] [log:log_response] [ERROR]- Internal Server Error: /PersonalInfo/Infos-upload/
Traceback (most recent call last):
  File "C:\Python372\mecheck\lib\site-packages\django\core\handlers\exception.py", line 34, in inner
    response = get_response(request)
  File "C:\Python372\mecheck\lib\site-packages\django\core\handlers\base.py", line 126, in _get_response
    response = self.process_exception_by_middleware(e, request)
  File "C:\Python372\mecheck\lib\site-packages\django\core\handlers\base.py", line 124, in _get_response
    response = wrapped_callback(request, *callback_args, **callback_kwargs)
  File "C:\Python372\mecheck\lib\site-packages\django\views\decorators\csrf.py", line 54, in wrapped_view
    return view_func(*args, **kwargs)
  File "C:\djangoproject\Reliability_Row_data\PersonalInfo\views.py", line 231, in Infos_upload
    modeldata[headermodel_MajorIfo[key]] = value
KeyError: '職等'
[2020-12-31 11:17:05,104] [basehttp.py:154] [basehttp:log_message] [ERROR]- "POST /PersonalInfo/Infos-upload/ HTTP/1.1" 500 22340
[2020-12-31 11:23:12,232] [log.py:228] [log:log_response] [ERROR]- Internal Server Error: /PersonalInfo/Infos-upload/
Traceback (most recent call last):
  File "C:\Python372\mecheck\lib\site-packages\django\core\handlers\exception.py", line 34, in inner
    response = get_response(request)
  File "C:\Python372\mecheck\lib\site-packages\django\core\handlers\base.py", line 126, in _get_response
    response = self.process_exception_by_middleware(e, request)
  File "C:\Python372\mecheck\lib\site-packages\django\core\handlers\base.py", line 124, in _get_response
    response = wrapped_callback(request, *callback_args, **callback_kwargs)
  File "C:\Python372\mecheck\lib\site-packages\django\views\decorators\csrf.py", line 54, in wrapped_view
    return view_func(*args, **kwargs)
  File "C:\djangoproject\Reliability_Row_data\PersonalInfo\views.py", line 321, in Infos_upload
    modeldata[headermodel_WorkOvertime[key]] = value
KeyError: '學歷'
[2020-12-31 11:23:12,233] [basehttp.py:154] [basehttp:log_message] [ERROR]- "POST /PersonalInfo/Infos-upload/ HTTP/1.1" 500 206513
[2020-12-31 11:23:34,958] [log.py:228] [log:log_response] [ERROR]- Internal Server Error: /PersonalInfo/Infos-upload/
Traceback (most recent call last):
  File "C:\Python372\mecheck\lib\site-packages\django\core\handlers\exception.py", line 34, in inner
    response = get_response(request)
  File "C:\Python372\mecheck\lib\site-packages\django\core\handlers\base.py", line 126, in _get_response
    response = self.process_exception_by_middleware(e, request)
  File "C:\Python372\mecheck\lib\site-packages\django\core\handlers\base.py", line 124, in _get_response
    response = wrapped_callback(request, *callback_args, **callback_kwargs)
  File "C:\Python372\mecheck\lib\site-packages\django\views\decorators\csrf.py", line 54, in wrapped_view
    return view_func(*args, **kwargs)
  File "C:\djangoproject\Reliability_Row_data\PersonalInfo\views.py", line 392, in Infos_upload
    modeldata[headermodel_LeaveInfo[key]] = value
KeyError: '計薪區間'
[2020-12-31 11:23:34,958] [basehttp.py:154] [basehttp:log_message] [ERROR]- "POST /PersonalInfo/Infos-upload/ HTTP/1.1" 500 20982
[2020-12-31 11:30:06,177] [log.py:228] [log:log_response] [ERROR]- Internal Server Error: /PersonalInfo/Infos-upload/
Traceback (most recent call last):
  File "C:\Python372\mecheck\lib\site-packages\django\core\handlers\exception.py", line 34, in inner
    response = get_response(request)
  File "C:\Python372\mecheck\lib\site-packages\django\core\handlers\base.py", line 126, in _get_response
    response = self.process_exception_by_middleware(e, request)
  File "C:\Python372\mecheck\lib\site-packages\django\core\handlers\base.py", line 124, in _get_response
    response = wrapped_callback(request, *callback_args, **callback_kwargs)
  File "C:\Python372\mecheck\lib\site-packages\django\views\decorators\csrf.py", line 54, in wrapped_view
    return view_func(*args, **kwargs)
  File "C:\djangoproject\Reliability_Row_data\PersonalInfo\views.py", line 321, in Infos_upload
    modeldata[headermodel_WorkOvertime[key]] = value
KeyError: '請假人工號'
[2020-12-31 11:30:06,178] [basehttp.py:154] [basehttp:log_message] [ERROR]- "POST /PersonalInfo/Infos-upload/ HTTP/1.1" 500 19982
[2020-12-31 11:30:17,301] [log.py:228] [log:log_response] [ERROR]- Internal Server Error: /PersonalInfo/Infos-upload/
Traceback (most recent call last):
  File "C:\Python372\mecheck\lib\site-packages\django\core\handlers\exception.py", line 34, in inner
    response = get_response(request)
  File "C:\Python372\mecheck\lib\site-packages\django\core\handlers\base.py", line 126, in _get_response
    response = self.process_exception_by_middleware(e, request)
  File "C:\Python372\mecheck\lib\site-packages\django\core\handlers\base.py", line 124, in _get_response
    response = wrapped_callback(request, *callback_args, **callback_kwargs)
  File "C:\Python372\mecheck\lib\site-packages\django\views\decorators\csrf.py", line 54, in wrapped_view
    return view_func(*args, **kwargs)
  File "C:\djangoproject\Reliability_Row_data\PersonalInfo\views.py", line 321, in Infos_upload
    modeldata[headermodel_WorkOvertime[key]] = value
KeyError: '請假人工號'
[2020-12-31 11:30:17,302] [basehttp.py:154] [basehttp:log_message] [ERROR]- "POST /PersonalInfo/Infos-upload/ HTTP/1.1" 500 19982
[2020-12-31 11:30:24,268] [log.py:228] [log:log_response] [ERROR]- Internal Server Error: /PersonalInfo/Infos-upload/
Traceback (most recent call last):
  File "C:\Python372\mecheck\lib\site-packages\django\core\handlers\exception.py", line 34, in inner
    response = get_response(request)
  File "C:\Python372\mecheck\lib\site-packages\django\core\handlers\base.py", line 126, in _get_response
    response = self.process_exception_by_middleware(e, request)
  File "C:\Python372\mecheck\lib\site-packages\django\core\handlers\base.py", line 124, in _get_response
    response = wrapped_callback(request, *callback_args, **callback_kwargs)
  File "C:\Python372\mecheck\lib\site-packages\django\views\decorators\csrf.py", line 54, in wrapped_view
    return view_func(*args, **kwargs)
  File "C:\djangoproject\Reliability_Row_data\PersonalInfo\views.py", line 321, in Infos_upload
    modeldata[headermodel_WorkOvertime[key]] = value
KeyError: '請假人工號'
[2020-12-31 11:30:24,269] [basehttp.py:154] [basehttp:log_message] [ERROR]- "POST /PersonalInfo/Infos-upload/ HTTP/1.1" 500 19982
[2020-12-31 11:30:32,876] [log.py:228] [log:log_response] [ERROR]- Internal Server Error: /PersonalInfo/Infos-upload/
Traceback (most recent call last):
  File "C:\Python372\mecheck\lib\site-packages\django\core\handlers\exception.py", line 34, in inner
    response = get_response(request)
  File "C:\Python372\mecheck\lib\site-packages\django\core\handlers\base.py", line 126, in _get_response
    response = self.process_exception_by_middleware(e, request)
  File "C:\Python372\mecheck\lib\site-packages\django\core\handlers\base.py", line 124, in _get_response
    response = wrapped_callback(request, *callback_args, **callback_kwargs)
  File "C:\Python372\mecheck\lib\site-packages\django\views\decorators\csrf.py", line 54, in wrapped_view
    return view_func(*args, **kwargs)
  File "C:\djangoproject\Reliability_Row_data\PersonalInfo\views.py", line 321, in Infos_upload
    modeldata[headermodel_WorkOvertime[key]] = value
KeyError: '請假人工號'
[2020-12-31 11:30:32,877] [basehttp.py:154] [basehttp:log_message] [ERROR]- "POST /PersonalInfo/Infos-upload/ HTTP/1.1" 500 19982
