[2021-01-22 10:30:53,184] [log.py:228] [log:log_response] [ERROR]- Internal Server Error: /PersonalInfo/Summary1/
Traceback (most recent call last):
  File "C:\Python372\mecheck\lib\site-packages\django\core\handlers\exception.py", line 34, in inner
    response = get_response(request)
  File "C:\Python372\mecheck\lib\site-packages\django\core\handlers\base.py", line 126, in _get_response
    response = self.process_exception_by_middleware(e, request)
  File "C:\Python372\mecheck\lib\site-packages\django\core\handlers\base.py", line 124, in _get_response
    response = wrapped_callback(request, *callback_args, **callback_kwargs)
  File "C:\Python372\mecheck\lib\site-packages\django\views\decorators\csrf.py", line 54, in wrapped_view
    return view_func(*args, **kwargs)
  File "C:\djangoproject\Reliability_Row_data\PersonalInfo\views.py", line 3991, in Summary1
    professionTableData = {"daLei": MajorIfo.objects.filter(MajorForExcel=i["MajorAscription"]).first.Categories, "Profession": i["MajorAscription"]}
AttributeError: 'function' object has no attribute 'Categories'
[2021-01-22 10:30:53,190] [basehttp.py:154] [basehttp:log_message] [ERROR]- "POST /PersonalInfo/Summary1/ HTTP/1.1" 500 103355
[2021-01-22 10:37:25,910] [log.py:228] [log:log_response] [ERROR]- Internal Server Error: /PersonalInfo/Summary1/
Traceback (most recent call last):
  File "C:\Python372\mecheck\lib\site-packages\django\core\handlers\exception.py", line 34, in inner
    response = get_response(request)
  File "C:\Python372\mecheck\lib\site-packages\django\core\handlers\base.py", line 126, in _get_response
    response = self.process_exception_by_middleware(e, request)
  File "C:\Python372\mecheck\lib\site-packages\django\core\handlers\base.py", line 124, in _get_response
    response = wrapped_callback(request, *callback_args, **callback_kwargs)
  File "C:\Python372\mecheck\lib\site-packages\django\views\decorators\csrf.py", line 54, in wrapped_view
    return view_func(*args, **kwargs)
  File "C:\djangoproject\Reliability_Row_data\PersonalInfo\views.py", line 4015, in Summary1
    for i in key:
TypeError: 'function' object is not iterable
[2021-01-22 10:37:25,917] [basehttp.py:154] [basehttp:log_message] [ERROR]- "POST /PersonalInfo/Summary1/ HTTP/1.1" 500 107637
[2021-01-22 10:39:40,792] [log.py:228] [log:log_response] [ERROR]- Internal Server Error: /PersonalInfo/Summary1/
Traceback (most recent call last):
  File "C:\Python372\mecheck\lib\site-packages\django\core\handlers\exception.py", line 34, in inner
    response = get_response(request)
  File "C:\Python372\mecheck\lib\site-packages\django\core\handlers\base.py", line 126, in _get_response
    response = self.process_exception_by_middleware(e, request)
  File "C:\Python372\mecheck\lib\site-packages\django\core\handlers\base.py", line 124, in _get_response
    response = wrapped_callback(request, *callback_args, **callback_kwargs)
  File "C:\Python372\mecheck\lib\site-packages\django\views\decorators\csrf.py", line 54, in wrapped_view
    return view_func(*args, **kwargs)
  File "C:\djangoproject\Reliability_Row_data\PersonalInfo\views.py", line 4016, in Summary1
    print(key(professionTable))
  File "C:\djangoproject\Reliability_Row_data\PersonalInfo\views.py", line 4014, in <lambda>
    key = lambda e: e.__getitem__('daLei')
TypeError: list indices must be integers or slices, not str
[2021-01-22 10:39:40,804] [basehttp.py:154] [basehttp:log_message] [ERROR]- "POST /PersonalInfo/Summary1/ HTTP/1.1" 500 115813
[2021-01-22 10:40:02,802] [log.py:228] [log:log_response] [ERROR]- Internal Server Error: /PersonalInfo/Summary1/
Traceback (most recent call last):
  File "C:\Python372\mecheck\lib\site-packages\django\core\handlers\exception.py", line 34, in inner
    response = get_response(request)
  File "C:\Python372\mecheck\lib\site-packages\django\core\handlers\base.py", line 126, in _get_response
    response = self.process_exception_by_middleware(e, request)
  File "C:\Python372\mecheck\lib\site-packages\django\core\handlers\base.py", line 124, in _get_response
    response = wrapped_callback(request, *callback_args, **callback_kwargs)
  File "C:\Python372\mecheck\lib\site-packages\django\views\decorators\csrf.py", line 54, in wrapped_view
    return view_func(*args, **kwargs)
  File "C:\djangoproject\Reliability_Row_data\PersonalInfo\views.py", line 4016, in Summary1
    print(key(**professionTable))
TypeError: <lambda>() argument after ** must be a mapping, not list
[2021-01-22 10:40:02,811] [basehttp.py:154] [basehttp:log_message] [ERROR]- "POST /PersonalInfo/Summary1/ HTTP/1.1" 500 107644
[2021-01-22 11:00:22,319] [log.py:228] [log:log_response] [ERROR]- Internal Server Error: /PersonalInfo/Summary1/
Traceback (most recent call last):
  File "C:\Python372\mecheck\lib\site-packages\django\core\handlers\exception.py", line 34, in inner
    response = get_response(request)
  File "C:\Python372\mecheck\lib\site-packages\django\core\handlers\base.py", line 126, in _get_response
    response = self.process_exception_by_middleware(e, request)
  File "C:\Python372\mecheck\lib\site-packages\django\core\handlers\base.py", line 124, in _get_response
    response = wrapped_callback(request, *callback_args, **callback_kwargs)
  File "C:\Python372\mecheck\lib\site-packages\django\views\decorators\csrf.py", line 54, in wrapped_view
    return view_func(*args, **kwargs)
  File "C:\djangoproject\Reliability_Row_data\PersonalInfo\views.py", line 4016, in Summary1
    professionTablenew.append(professionTable["daLei"])
TypeError: list indices must be integers or slices, not str
[2021-01-22 11:00:22,325] [basehttp.py:154] [basehttp:log_message] [ERROR]- "POST /PersonalInfo/Summary1/ HTTP/1.1" 500 107789
[2021-01-22 12:12:51,588] [log.py:228] [log:log_response] [ERROR]- Internal Server Error: /PersonalInfo/Summary1/
Traceback (most recent call last):
  File "C:\Python372\mecheck\lib\site-packages\django\core\handlers\exception.py", line 34, in inner
    response = get_response(request)
  File "C:\Python372\mecheck\lib\site-packages\django\core\handlers\base.py", line 126, in _get_response
    response = self.process_exception_by_middleware(e, request)
  File "C:\Python372\mecheck\lib\site-packages\django\core\handlers\base.py", line 124, in _get_response
    response = wrapped_callback(request, *callback_args, **callback_kwargs)
  File "C:\Python372\mecheck\lib\site-packages\django\views\decorators\csrf.py", line 54, in wrapped_view
    return view_func(*args, **kwargs)
  File "C:\djangoproject\Reliability_Row_data\PersonalInfo\views.py", line 3631, in Summary1
    regionsTable.sorted(regionsTable, key=lambda x: x.__getitem__(regionsSummary), reverse=True)
AttributeError: 'list' object has no attribute 'sorted'
[2021-01-22 12:12:51,596] [basehttp.py:154] [basehttp:log_message] [ERROR]- "POST /PersonalInfo/Summary1/ HTTP/1.1" 500 111518
[2021-01-22 12:14:49,927] [log.py:228] [log:log_response] [ERROR]- Internal Server Error: /PersonalInfo/Summary1/
Traceback (most recent call last):
  File "C:\Python372\mecheck\lib\site-packages\django\core\handlers\exception.py", line 34, in inner
    response = get_response(request)
  File "C:\Python372\mecheck\lib\site-packages\django\core\handlers\base.py", line 126, in _get_response
    response = self.process_exception_by_middleware(e, request)
  File "C:\Python372\mecheck\lib\site-packages\django\core\handlers\base.py", line 124, in _get_response
    response = wrapped_callback(request, *callback_args, **callback_kwargs)
  File "C:\Python372\mecheck\lib\site-packages\django\views\decorators\csrf.py", line 54, in wrapped_view
    return view_func(*args, **kwargs)
  File "C:\djangoproject\Reliability_Row_data\PersonalInfo\views.py", line 3631, in Summary1
    regionsTable = sorted(regionsTable, key=lambda x: x.__getitem__(regionsSummary), reverse=True)
  File "C:\djangoproject\Reliability_Row_data\PersonalInfo\views.py", line 3631, in <lambda>
    regionsTable = sorted(regionsTable, key=lambda x: x.__getitem__(regionsSummary), reverse=True)
KeyError: 2
[2021-01-22 12:14:49,933] [basehttp.py:154] [basehttp:log_message] [ERROR]- "POST /PersonalInfo/Summary1/ HTTP/1.1" 500 115599
[2021-01-22 12:16:37,274] [log.py:228] [log:log_response] [ERROR]- Internal Server Error: /PersonalInfo/Summary1/
Traceback (most recent call last):
  File "C:\Python372\mecheck\lib\site-packages\django\core\handlers\exception.py", line 34, in inner
    response = get_response(request)
  File "C:\Python372\mecheck\lib\site-packages\django\core\handlers\base.py", line 126, in _get_response
    response = self.process_exception_by_middleware(e, request)
  File "C:\Python372\mecheck\lib\site-packages\django\core\handlers\base.py", line 124, in _get_response
    response = wrapped_callback(request, *callback_args, **callback_kwargs)
  File "C:\Python372\mecheck\lib\site-packages\django\views\decorators\csrf.py", line 54, in wrapped_view
    return view_func(*args, **kwargs)
  File "C:\djangoproject\Reliability_Row_data\PersonalInfo\views.py", line 4054, in Summary1
    "educationDiagramname": educationDiagramname,
UnboundLocalError: local variable 'educationDiagramname' referenced before assignment
[2021-01-22 12:16:37,281] [basehttp.py:154] [basehttp:log_message] [ERROR]- "POST /PersonalInfo/Summary1/ HTTP/1.1" 500 95808
[2021-01-22 14:08:19,381] [log.py:228] [log:log_response] [ERROR]- Internal Server Error: /PersonalInfo/Summary1/
Traceback (most recent call last):
  File "C:\Python372\mecheck\lib\site-packages\django\core\handlers\exception.py", line 34, in inner
    response = get_response(request)
  File "C:\Python372\mecheck\lib\site-packages\django\core\handlers\base.py", line 137, in _get_response
    "returned None instead." % (callback.__module__, view_name)
ValueError: The view PersonalInfo.views.Summary1 didn't return an HttpResponse object. It returned None instead.
[2021-01-22 14:08:19,382] [basehttp.py:154] [basehttp:log_message] [ERROR]- "GET /PersonalInfo/Summary1/ HTTP/1.1" 500 66604
