[2020-03-10 09:46:34,671] [log.py:228] [log:log_response] [ERROR]- Internal Server Error: /TestPlanSW/TestPlanSW-edit/
Traceback (most recent call last):
  File "C:\Python372\mecheck\lib\site-packages\django\core\handlers\exception.py", line 34, in inner
    response = get_response(request)
  File "C:\Python372\mecheck\lib\site-packages\django\core\handlers\base.py", line 126, in _get_response
    response = self.process_exception_by_middleware(e, request)
  File "C:\Python372\mecheck\lib\site-packages\django\core\handlers\base.py", line 124, in _get_response
    response = wrapped_callback(request, *callback_args, **callback_kwargs)
  File "C:\djangoproject\Reliability_Row_data\TestPlanSW\views.py", line 1166, in TestPlanSW_Edit
    RetestItemSW.objects.create(**adddic)
  File "C:\Python372\mecheck\lib\site-packages\django\db\models\manager.py", line 82, in manager_method
    return getattr(self.get_queryset(), name)(*args, **kwargs)
  File "C:\Python372\mecheck\lib\site-packages\django\db\models\query.py", line 411, in create
    obj = self.model(**kwargs)
  File "C:\Python372\mecheck\lib\site-packages\django\db\models\base.py", line 467, in __init__
    _setattr(self, field.name, rel_obj)
  File "C:\Python372\mecheck\lib\site-packages\django\db\models\fields\related_descriptors.py", line 210, in __set__
    self.field.remote_field.model._meta.object_name,
ValueError: Cannot assign "<QuerySet []>": "RetestItemSW.Projectinfo" must be a "TestProjectSW" instance.
[2020-03-10 09:46:34,752] [basehttp.py:154] [basehttp:log_message] [ERROR]- "POST /TestPlanSW/TestPlanSW-edit/ HTTP/1.1" 500 27
[2020-03-10 09:50:24,594] [log.py:228] [log:log_response] [ERROR]- Internal Server Error: /TestPlanSW/TestPlanSW-edit/
Traceback (most recent call last):
  File "C:\Python372\mecheck\lib\site-packages\django\core\handlers\exception.py", line 34, in inner
    response = get_response(request)
  File "C:\Python372\mecheck\lib\site-packages\django\core\handlers\base.py", line 126, in _get_response
    response = self.process_exception_by_middleware(e, request)
  File "C:\Python372\mecheck\lib\site-packages\django\core\handlers\base.py", line 124, in _get_response
    response = wrapped_callback(request, *callback_args, **callback_kwargs)
  File "C:\djangoproject\Reliability_Row_data\TestPlanSW\views.py", line 1133, in TestPlanSW_Edit
    adddic['Projectinfo'] = TestProjectSW.objects.get(**projctcheck)
  File "C:\Python372\mecheck\lib\site-packages\django\db\models\manager.py", line 82, in manager_method
    return getattr(self.get_queryset(), name)(*args, **kwargs)
  File "C:\Python372\mecheck\lib\site-packages\django\db\models\query.py", line 399, in get
    self.model._meta.object_name
TestPlanSW.models.TestProjectSW.DoesNotExist: TestProjectSW matching query does not exist.
[2020-03-10 09:50:24,602] [basehttp.py:154] [basehttp:log_message] [ERROR]- "POST /TestPlanSW/TestPlanSW-edit/ HTTP/1.1" 500 27
[2020-03-10 10:01:24,223] [log.py:228] [log:log_response] [ERROR]- Internal Server Error: /TestPlanSW/TestPlanSW-edit/
Traceback (most recent call last):
  File "C:\Python372\mecheck\lib\site-packages\django\core\handlers\exception.py", line 34, in inner
    response = get_response(request)
  File "C:\Python372\mecheck\lib\site-packages\django\core\handlers\base.py", line 126, in _get_response
    response = self.process_exception_by_middleware(e, request)
  File "C:\Python372\mecheck\lib\site-packages\django\core\handlers\base.py", line 124, in _get_response
    response = wrapped_callback(request, *callback_args, **callback_kwargs)
  File "C:\djangoproject\Reliability_Row_data\TestPlanSW\views.py", line 1134, in TestPlanSW_Edit
    adddic['Projectinfo'] = TestProjectSW.objects.get(**projctcheck)
  File "C:\Python372\mecheck\lib\site-packages\django\db\models\manager.py", line 82, in manager_method
    return getattr(self.get_queryset(), name)(*args, **kwargs)
  File "C:\Python372\mecheck\lib\site-packages\django\db\models\query.py", line 399, in get
    self.model._meta.object_name
TestPlanSW.models.TestProjectSW.DoesNotExist: TestProjectSW matching query does not exist.
[2020-03-10 10:01:24,228] [basehttp.py:154] [basehttp:log_message] [ERROR]- "POST /TestPlanSW/TestPlanSW-edit/ HTTP/1.1" 500 27
[2020-03-10 10:02:49,534] [log.py:228] [log:log_response] [ERROR]- Internal Server Error: /TestPlanSW/TestPlanSW-edit/
Traceback (most recent call last):
  File "C:\Python372\mecheck\lib\site-packages\django\core\handlers\exception.py", line 34, in inner
    response = get_response(request)
  File "C:\Python372\mecheck\lib\site-packages\django\core\handlers\base.py", line 126, in _get_response
    response = self.process_exception_by_middleware(e, request)
  File "C:\Python372\mecheck\lib\site-packages\django\core\handlers\base.py", line 124, in _get_response
    response = wrapped_callback(request, *callback_args, **callback_kwargs)
  File "C:\djangoproject\Reliability_Row_data\TestPlanSW\views.py", line 1134, in TestPlanSW_Edit
    adddic['Projectinfo'] = TestProjectSW.objects.get(**projctcheck)
  File "C:\Python372\mecheck\lib\site-packages\django\db\models\manager.py", line 82, in manager_method
    return getattr(self.get_queryset(), name)(*args, **kwargs)
  File "C:\Python372\mecheck\lib\site-packages\django\db\models\query.py", line 399, in get
    self.model._meta.object_name
TestPlanSW.models.TestProjectSW.DoesNotExist: TestProjectSW matching query does not exist.
[2020-03-10 10:02:49,541] [basehttp.py:154] [basehttp:log_message] [ERROR]- "POST /TestPlanSW/TestPlanSW-edit/ HTTP/1.1" 500 27
[2020-03-10 10:04:34,939] [log.py:228] [log:log_response] [ERROR]- Internal Server Error: /TestPlanSW/TestPlanSW-edit/
Traceback (most recent call last):
  File "C:\Python372\mecheck\lib\site-packages\django\core\handlers\exception.py", line 34, in inner
    response = get_response(request)
  File "C:\Python372\mecheck\lib\site-packages\django\core\handlers\base.py", line 126, in _get_response
    response = self.process_exception_by_middleware(e, request)
  File "C:\Python372\mecheck\lib\site-packages\django\core\handlers\base.py", line 124, in _get_response
    response = wrapped_callback(request, *callback_args, **callback_kwargs)
  File "C:\djangoproject\Reliability_Row_data\TestPlanSW\views.py", line 1134, in TestPlanSW_Edit
    adddic['Projectinfo'] = TestProjectSW.objects.get(**projctcheck)
  File "C:\Python372\mecheck\lib\site-packages\django\db\models\manager.py", line 82, in manager_method
    return getattr(self.get_queryset(), name)(*args, **kwargs)
  File "C:\Python372\mecheck\lib\site-packages\django\db\models\query.py", line 399, in get
    self.model._meta.object_name
TestPlanSW.models.TestProjectSW.DoesNotExist: TestProjectSW matching query does not exist.
[2020-03-10 10:04:34,945] [basehttp.py:154] [basehttp:log_message] [ERROR]- "POST /TestPlanSW/TestPlanSW-edit/ HTTP/1.1" 500 27
[2020-03-10 10:05:34,054] [log.py:228] [log:log_response] [ERROR]- Internal Server Error: /TestPlanSW/TestPlanSW-edit/
Traceback (most recent call last):
  File "C:\Python372\mecheck\lib\site-packages\django\core\handlers\exception.py", line 34, in inner
    response = get_response(request)
  File "C:\Python372\mecheck\lib\site-packages\django\core\handlers\base.py", line 126, in _get_response
    response = self.process_exception_by_middleware(e, request)
  File "C:\Python372\mecheck\lib\site-packages\django\core\handlers\base.py", line 124, in _get_response
    response = wrapped_callback(request, *callback_args, **callback_kwargs)
  File "C:\djangoproject\Reliability_Row_data\TestPlanSW\views.py", line 1134, in TestPlanSW_Edit
    adddic['Projectinfo'] = TestProjectSW.objects.get(**projctcheck)
  File "C:\Python372\mecheck\lib\site-packages\django\db\models\manager.py", line 82, in manager_method
    return getattr(self.get_queryset(), name)(*args, **kwargs)
  File "C:\Python372\mecheck\lib\site-packages\django\db\models\query.py", line 399, in get
    self.model._meta.object_name
TestPlanSW.models.TestProjectSW.DoesNotExist: TestProjectSW matching query does not exist.
[2020-03-10 10:05:34,059] [basehttp.py:154] [basehttp:log_message] [ERROR]- "POST /TestPlanSW/TestPlanSW-edit/ HTTP/1.1" 500 27
[2020-03-10 10:09:18,579] [log.py:228] [log:log_response] [ERROR]- Internal Server Error: /TestPlanSW/TestPlanSW-edit/
Traceback (most recent call last):
  File "C:\Python372\mecheck\lib\site-packages\django\core\handlers\exception.py", line 34, in inner
    response = get_response(request)
  File "C:\Python372\mecheck\lib\site-packages\django\core\handlers\base.py", line 126, in _get_response
    response = self.process_exception_by_middleware(e, request)
  File "C:\Python372\mecheck\lib\site-packages\django\core\handlers\base.py", line 124, in _get_response
    response = wrapped_callback(request, *callback_args, **callback_kwargs)
  File "C:\djangoproject\Reliability_Row_data\TestPlanSW\views.py", line 1134, in TestPlanSW_Edit
    adddic['Projectinfo'] = TestProjectSW.objects.get(**projctcheck)
  File "C:\Python372\mecheck\lib\site-packages\django\db\models\manager.py", line 82, in manager_method
    return getattr(self.get_queryset(), name)(*args, **kwargs)
  File "C:\Python372\mecheck\lib\site-packages\django\db\models\query.py", line 399, in get
    self.model._meta.object_name
TestPlanSW.models.TestProjectSW.DoesNotExist: TestProjectSW matching query does not exist.
[2020-03-10 10:09:18,584] [basehttp.py:154] [basehttp:log_message] [ERROR]- "POST /TestPlanSW/TestPlanSW-edit/ HTTP/1.1" 500 27
[2020-03-10 10:10:07,756] [log.py:228] [log:log_response] [ERROR]- Internal Server Error: /TestPlanSW/TestPlanSW-edit/
Traceback (most recent call last):
  File "C:\Python372\mecheck\lib\site-packages\django\core\handlers\exception.py", line 34, in inner
    response = get_response(request)
  File "C:\Python372\mecheck\lib\site-packages\django\core\handlers\base.py", line 126, in _get_response
    response = self.process_exception_by_middleware(e, request)
  File "C:\Python372\mecheck\lib\site-packages\django\core\handlers\base.py", line 124, in _get_response
    response = wrapped_callback(request, *callback_args, **callback_kwargs)
  File "C:\djangoproject\Reliability_Row_data\TestPlanSW\views.py", line 1167, in TestPlanSW_Edit
    RetestItemSW.objects.create(**adddic)
  File "C:\Python372\mecheck\lib\site-packages\django\db\models\manager.py", line 82, in manager_method
    return getattr(self.get_queryset(), name)(*args, **kwargs)
  File "C:\Python372\mecheck\lib\site-packages\django\db\models\query.py", line 413, in create
    obj.save(force_insert=True, using=self.db)
  File "C:\Python372\mecheck\lib\site-packages\django\db\models\base.py", line 718, in save
    force_update=force_update, update_fields=update_fields)
  File "C:\Python372\mecheck\lib\site-packages\django\db\models\base.py", line 748, in save_base
    updated = self._save_table(raw, cls, force_insert, force_update, using, update_fields)
  File "C:\Python372\mecheck\lib\site-packages\django\db\models\base.py", line 831, in _save_table
    result = self._do_insert(cls._base_manager, using, fields, update_pk, raw)
  File "C:\Python372\mecheck\lib\site-packages\django\db\models\base.py", line 869, in _do_insert
    using=using, raw=raw)
  File "C:\Python372\mecheck\lib\site-packages\django\db\models\manager.py", line 82, in manager_method
    return getattr(self.get_queryset(), name)(*args, **kwargs)
  File "C:\Python372\mecheck\lib\site-packages\django\db\models\query.py", line 1136, in _insert
    return query.get_compiler(using=using).execute_sql(return_id)
  File "C:\Python372\mecheck\lib\site-packages\django\db\models\sql\compiler.py", line 1288, in execute_sql
    for sql, params in self.as_sql():
  File "C:\Python372\mecheck\lib\site-packages\django\db\models\sql\compiler.py", line 1241, in as_sql
    for obj in self.query.objs
  File "C:\Python372\mecheck\lib\site-packages\django\db\models\sql\compiler.py", line 1241, in <listcomp>
    for obj in self.query.objs
  File "C:\Python372\mecheck\lib\site-packages\django\db\models\sql\compiler.py", line 1240, in <listcomp>
    [self.prepare_value(field, self.pre_save_val(field, obj)) for field in fields]
  File "C:\Python372\mecheck\lib\site-packages\django\db\models\sql\compiler.py", line 1182, in prepare_value
    value = field.get_db_prep_save(value, connection=self.connection)
  File "C:\Python372\mecheck\lib\site-packages\django\db\models\fields\__init__.py", line 790, in get_db_prep_save
    return self.get_db_prep_value(value, connection=connection, prepared=False)
  File "C:\Python372\mecheck\lib\site-packages\django\db\models\fields\__init__.py", line 785, in get_db_prep_value
    value = self.get_prep_value(value)
  File "C:\Python372\mecheck\lib\site-packages\django\db\models\fields\__init__.py", line 1737, in get_prep_value
    return float(value)
ValueError: could not convert string to float: 
[2020-03-10 10:10:07,775] [basehttp.py:154] [basehttp:log_message] [ERROR]- "POST /TestPlanSW/TestPlanSW-edit/ HTTP/1.1" 500 27
[2020-03-10 10:19:35,988] [log.py:228] [log:log_response] [ERROR]- Internal Server Error: /TestPlanSW/TestPlanSW-edit/
Traceback (most recent call last):
  File "C:\Python372\mecheck\lib\site-packages\django\core\handlers\exception.py", line 34, in inner
    response = get_response(request)
  File "C:\Python372\mecheck\lib\site-packages\django\core\handlers\base.py", line 126, in _get_response
    response = self.process_exception_by_middleware(e, request)
  File "C:\Python372\mecheck\lib\site-packages\django\core\handlers\base.py", line 124, in _get_response
    response = wrapped_callback(request, *callback_args, **callback_kwargs)
  File "C:\djangoproject\Reliability_Row_data\TestPlanSW\views.py", line 1124, in TestPlanSW_Edit
    adddic['TDMSUnattendedTime'] = float(request.POST.get('unattendedtime'))
ValueError: could not convert string to float: 
[2020-03-10 10:19:35,992] [basehttp.py:154] [basehttp:log_message] [ERROR]- "POST /TestPlanSW/TestPlanSW-edit/ HTTP/1.1" 500 27
[2020-03-10 10:20:33,536] [log.py:228] [log:log_response] [ERROR]- Internal Server Error: /TestPlanSW/TestPlanSW-edit/
Traceback (most recent call last):
  File "C:\Python372\mecheck\lib\site-packages\django\core\handlers\exception.py", line 34, in inner
    response = get_response(request)
  File "C:\Python372\mecheck\lib\site-packages\django\core\handlers\base.py", line 126, in _get_response
    response = self.process_exception_by_middleware(e, request)
  File "C:\Python372\mecheck\lib\site-packages\django\core\handlers\base.py", line 124, in _get_response
    response = wrapped_callback(request, *callback_args, **callback_kwargs)
  File "C:\djangoproject\Reliability_Row_data\TestPlanSW\views.py", line 1139, in TestPlanSW_Edit
    adddic['ProjectTestSKUfollowMatrix'] = float(request.POST.get('starttime'))
ValueError: could not convert string to float: 
[2020-03-10 10:20:33,537] [basehttp.py:154] [basehttp:log_message] [ERROR]- "POST /TestPlanSW/TestPlanSW-edit/ HTTP/1.1" 500 27
[2020-03-10 10:20:56,817] [log.py:228] [log:log_response] [ERROR]- Internal Server Error: /TestPlanSW/TestPlanSW-edit/
Traceback (most recent call last):
  File "C:\Python372\mecheck\lib\site-packages\django\core\handlers\exception.py", line 34, in inner
    response = get_response(request)
  File "C:\Python372\mecheck\lib\site-packages\django\core\handlers\base.py", line 126, in _get_response
    response = self.process_exception_by_middleware(e, request)
  File "C:\Python372\mecheck\lib\site-packages\django\core\handlers\base.py", line 124, in _get_response
    response = wrapped_callback(request, *callback_args, **callback_kwargs)
  File "C:\djangoproject\Reliability_Row_data\TestPlanSW\views.py", line 1152, in TestPlanSW_Edit
    adddic['ConfigRetestCycle'] = float(request.POST.get('CRC'))
ValueError: could not convert string to float: 
[2020-03-10 10:20:56,819] [basehttp.py:154] [basehttp:log_message] [ERROR]- "POST /TestPlanSW/TestPlanSW-edit/ HTTP/1.1" 500 27
[2020-03-10 13:14:24,793] [basehttp.py:154] [basehttp:log_message] [ERROR]- "GET /static/src/blue.jpg HTTP/1.1" 500 59
[2020-03-10 18:24:57,382] [log.py:228] [log:log_response] [ERROR]- Internal Server Error: /login/
Traceback (most recent call last):
  File "C:\Python372\mecheck\lib\site-packages\django\db\backends\utils.py", line 85, in _execute
    return self.cursor.execute(sql, params)
  File "C:\Python372\mecheck\lib\site-packages\django\db\backends\mysql\base.py", line 71, in execute
    return self.cursor.execute(query, args)
  File "C:\Python372\mecheck\lib\site-packages\pymysql\cursors.py", line 170, in execute
    result = self._query(query)
  File "C:\Python372\mecheck\lib\site-packages\pymysql\cursors.py", line 328, in _query
    conn.query(q)
  File "C:\Python372\mecheck\lib\site-packages\pymysql\connections.py", line 517, in query
    self._affected_rows = self._read_query_result(unbuffered=unbuffered)
  File "C:\Python372\mecheck\lib\site-packages\pymysql\connections.py", line 732, in _read_query_result
    result.read()
  File "C:\Python372\mecheck\lib\site-packages\pymysql\connections.py", line 1075, in read
    first_packet = self.connection._read_packet()
  File "C:\Python372\mecheck\lib\site-packages\pymysql\connections.py", line 684, in _read_packet
    packet.check_error()
  File "C:\Python372\mecheck\lib\site-packages\pymysql\protocol.py", line 220, in check_error
    err.raise_mysql_exception(self._data)
  File "C:\Python372\mecheck\lib\site-packages\pymysql\err.py", line 109, in raise_mysql_exception
    raise errorclass(errno, errval)
pymysql.err.ProgrammingError: (1146, "Table 'reliabilityrowdata.app01_userinfo' doesn't exist")

The above exception was the direct cause of the following exception:

Traceback (most recent call last):
  File "C:\Python372\mecheck\lib\site-packages\django\core\handlers\exception.py", line 34, in inner
    response = get_response(request)
  File "C:\Python372\mecheck\lib\site-packages\django\core\handlers\base.py", line 126, in _get_response
    response = self.process_exception_by_middleware(e, request)
  File "C:\Python372\mecheck\lib\site-packages\django\core\handlers\base.py", line 124, in _get_response
    response = wrapped_callback(request, *callback_args, **callback_kwargs)
  File "C:\Python372\mecheck\lib\site-packages\django\views\decorators\csrf.py", line 54, in wrapped_view
    return view_func(*args, **kwargs)
  File "C:\djangoproject\Reliability_Row_data\app01\views.py", line 53, in login
    user_obj = UserInfo.objects.filter(account=Account, password=Password).first()
  File "C:\Python372\mecheck\lib\site-packages\django\db\models\query.py", line 605, in first
    for obj in (self if self.ordered else self.order_by('pk'))[:1]:
  File "C:\Python372\mecheck\lib\site-packages\django\db\models\query.py", line 268, in __iter__
    self._fetch_all()
  File "C:\Python372\mecheck\lib\site-packages\django\db\models\query.py", line 1186, in _fetch_all
    self._result_cache = list(self._iterable_class(self))
  File "C:\Python372\mecheck\lib\site-packages\django\db\models\query.py", line 54, in __iter__
    results = compiler.execute_sql(chunked_fetch=self.chunked_fetch, chunk_size=self.chunk_size)
  File "C:\Python372\mecheck\lib\site-packages\django\db\models\sql\compiler.py", line 1065, in execute_sql
    cursor.execute(sql, params)
  File "C:\Python372\mecheck\lib\site-packages\django\db\backends\utils.py", line 68, in execute
    return self._execute_with_wrappers(sql, params, many=False, executor=self._execute)
  File "C:\Python372\mecheck\lib\site-packages\django\db\backends\utils.py", line 77, in _execute_with_wrappers
    return executor(sql, params, many, context)
  File "C:\Python372\mecheck\lib\site-packages\django\db\backends\utils.py", line 85, in _execute
    return self.cursor.execute(sql, params)
  File "C:\Python372\mecheck\lib\site-packages\django\db\utils.py", line 89, in __exit__
    raise dj_exc_value.with_traceback(traceback) from exc_value
  File "C:\Python372\mecheck\lib\site-packages\django\db\backends\utils.py", line 85, in _execute
    return self.cursor.execute(sql, params)
  File "C:\Python372\mecheck\lib\site-packages\django\db\backends\mysql\base.py", line 71, in execute
    return self.cursor.execute(query, args)
  File "C:\Python372\mecheck\lib\site-packages\pymysql\cursors.py", line 170, in execute
    result = self._query(query)
  File "C:\Python372\mecheck\lib\site-packages\pymysql\cursors.py", line 328, in _query
    conn.query(q)
  File "C:\Python372\mecheck\lib\site-packages\pymysql\connections.py", line 517, in query
    self._affected_rows = self._read_query_result(unbuffered=unbuffered)
  File "C:\Python372\mecheck\lib\site-packages\pymysql\connections.py", line 732, in _read_query_result
    result.read()
  File "C:\Python372\mecheck\lib\site-packages\pymysql\connections.py", line 1075, in read
    first_packet = self.connection._read_packet()
  File "C:\Python372\mecheck\lib\site-packages\pymysql\connections.py", line 684, in _read_packet
    packet.check_error()
  File "C:\Python372\mecheck\lib\site-packages\pymysql\protocol.py", line 220, in check_error
    err.raise_mysql_exception(self._data)
  File "C:\Python372\mecheck\lib\site-packages\pymysql\err.py", line 109, in raise_mysql_exception
    raise errorclass(errno, errval)
django.db.utils.ProgrammingError: (1146, "Table 'reliabilityrowdata.app01_userinfo' doesn't exist")
[2020-03-10 18:24:57,414] [basehttp.py:154] [basehttp:log_message] [ERROR]- "POST /login/ HTTP/1.1" 500 27
[2020-03-10 18:25:09,051] [log.py:228] [log:log_response] [ERROR]- Internal Server Error: /login/
Traceback (most recent call last):
  File "C:\Python372\mecheck\lib\site-packages\django\db\backends\utils.py", line 85, in _execute
    return self.cursor.execute(sql, params)
  File "C:\Python372\mecheck\lib\site-packages\django\db\backends\mysql\base.py", line 71, in execute
    return self.cursor.execute(query, args)
  File "C:\Python372\mecheck\lib\site-packages\pymysql\cursors.py", line 170, in execute
    result = self._query(query)
  File "C:\Python372\mecheck\lib\site-packages\pymysql\cursors.py", line 328, in _query
    conn.query(q)
  File "C:\Python372\mecheck\lib\site-packages\pymysql\connections.py", line 517, in query
    self._affected_rows = self._read_query_result(unbuffered=unbuffered)
  File "C:\Python372\mecheck\lib\site-packages\pymysql\connections.py", line 732, in _read_query_result
    result.read()
  File "C:\Python372\mecheck\lib\site-packages\pymysql\connections.py", line 1075, in read
    first_packet = self.connection._read_packet()
  File "C:\Python372\mecheck\lib\site-packages\pymysql\connections.py", line 684, in _read_packet
    packet.check_error()
  File "C:\Python372\mecheck\lib\site-packages\pymysql\protocol.py", line 220, in check_error
    err.raise_mysql_exception(self._data)
  File "C:\Python372\mecheck\lib\site-packages\pymysql\err.py", line 109, in raise_mysql_exception
    raise errorclass(errno, errval)
pymysql.err.ProgrammingError: (1146, "Table 'reliabilityrowdata.app01_userinfo' doesn't exist")

The above exception was the direct cause of the following exception:

Traceback (most recent call last):
  File "C:\Python372\mecheck\lib\site-packages\django\core\handlers\exception.py", line 34, in inner
    response = get_response(request)
  File "C:\Python372\mecheck\lib\site-packages\django\core\handlers\base.py", line 126, in _get_response
    response = self.process_exception_by_middleware(e, request)
  File "C:\Python372\mecheck\lib\site-packages\django\core\handlers\base.py", line 124, in _get_response
    response = wrapped_callback(request, *callback_args, **callback_kwargs)
  File "C:\Python372\mecheck\lib\site-packages\django\views\decorators\csrf.py", line 54, in wrapped_view
    return view_func(*args, **kwargs)
  File "C:\djangoproject\Reliability_Row_data\app01\views.py", line 53, in login
    user_obj = UserInfo.objects.filter(account=Account, password=Password).first()
  File "C:\Python372\mecheck\lib\site-packages\django\db\models\query.py", line 605, in first
    for obj in (self if self.ordered else self.order_by('pk'))[:1]:
  File "C:\Python372\mecheck\lib\site-packages\django\db\models\query.py", line 268, in __iter__
    self._fetch_all()
  File "C:\Python372\mecheck\lib\site-packages\django\db\models\query.py", line 1186, in _fetch_all
    self._result_cache = list(self._iterable_class(self))
  File "C:\Python372\mecheck\lib\site-packages\django\db\models\query.py", line 54, in __iter__
    results = compiler.execute_sql(chunked_fetch=self.chunked_fetch, chunk_size=self.chunk_size)
  File "C:\Python372\mecheck\lib\site-packages\django\db\models\sql\compiler.py", line 1065, in execute_sql
    cursor.execute(sql, params)
  File "C:\Python372\mecheck\lib\site-packages\django\db\backends\utils.py", line 68, in execute
    return self._execute_with_wrappers(sql, params, many=False, executor=self._execute)
  File "C:\Python372\mecheck\lib\site-packages\django\db\backends\utils.py", line 77, in _execute_with_wrappers
    return executor(sql, params, many, context)
  File "C:\Python372\mecheck\lib\site-packages\django\db\backends\utils.py", line 85, in _execute
    return self.cursor.execute(sql, params)
  File "C:\Python372\mecheck\lib\site-packages\django\db\utils.py", line 89, in __exit__
    raise dj_exc_value.with_traceback(traceback) from exc_value
  File "C:\Python372\mecheck\lib\site-packages\django\db\backends\utils.py", line 85, in _execute
    return self.cursor.execute(sql, params)
  File "C:\Python372\mecheck\lib\site-packages\django\db\backends\mysql\base.py", line 71, in execute
    return self.cursor.execute(query, args)
  File "C:\Python372\mecheck\lib\site-packages\pymysql\cursors.py", line 170, in execute
    result = self._query(query)
  File "C:\Python372\mecheck\lib\site-packages\pymysql\cursors.py", line 328, in _query
    conn.query(q)
  File "C:\Python372\mecheck\lib\site-packages\pymysql\connections.py", line 517, in query
    self._affected_rows = self._read_query_result(unbuffered=unbuffered)
  File "C:\Python372\mecheck\lib\site-packages\pymysql\connections.py", line 732, in _read_query_result
    result.read()
  File "C:\Python372\mecheck\lib\site-packages\pymysql\connections.py", line 1075, in read
    first_packet = self.connection._read_packet()
  File "C:\Python372\mecheck\lib\site-packages\pymysql\connections.py", line 684, in _read_packet
    packet.check_error()
  File "C:\Python372\mecheck\lib\site-packages\pymysql\protocol.py", line 220, in check_error
    err.raise_mysql_exception(self._data)
  File "C:\Python372\mecheck\lib\site-packages\pymysql\err.py", line 109, in raise_mysql_exception
    raise errorclass(errno, errval)
django.db.utils.ProgrammingError: (1146, "Table 'reliabilityrowdata.app01_userinfo' doesn't exist")
[2020-03-10 18:25:09,083] [basehttp.py:154] [basehttp:log_message] [ERROR]- "POST /login/ HTTP/1.1" 500 27
[2020-03-10 19:37:00,821] [log.py:228] [log:log_response] [ERROR]- Internal Server Error: /admin/app01/menu/29/change/
Traceback (most recent call last):
  File "C:\Python372\mecheck\lib\site-packages\django\db\models\fields\related_descriptors.py", line 163, in __get__
    rel_obj = self.field.get_cached_value(instance)
  File "C:\Python372\mecheck\lib\site-packages\django\db\models\fields\mixins.py", line 13, in get_cached_value
    return instance._state.fields_cache[cache_name]
KeyError: 'parent'

During handling of the above exception, another exception occurred:

Traceback (most recent call last):
  File "C:\Python372\mecheck\lib\site-packages\django\core\handlers\exception.py", line 34, in inner
    response = get_response(request)
  File "C:\Python372\mecheck\lib\site-packages\django\core\handlers\base.py", line 156, in _get_response
    response = self.process_exception_by_middleware(e, request)
  File "C:\Python372\mecheck\lib\site-packages\django\core\handlers\base.py", line 154, in _get_response
    response = response.render()
  File "C:\Python372\mecheck\lib\site-packages\django\template\response.py", line 106, in render
    self.content = self.rendered_content
  File "C:\Python372\mecheck\lib\site-packages\django\template\response.py", line 83, in rendered_content
    content = template.render(context, self._request)
  File "C:\Python372\mecheck\lib\site-packages\django\template\backends\django.py", line 61, in render
    return self.template.render(context)
  File "C:\Python372\mecheck\lib\site-packages\django\template\base.py", line 171, in render
    return self._render(context)
  File "C:\Python372\mecheck\lib\site-packages\django\template\base.py", line 163, in _render
    return self.nodelist.render(context)
  File "C:\Python372\mecheck\lib\site-packages\django\template\base.py", line 937, in render
    bit = node.render_annotated(context)
  File "C:\Python372\mecheck\lib\site-packages\django\template\base.py", line 904, in render_annotated
    return self.render(context)
  File "C:\Python372\mecheck\lib\site-packages\django\template\loader_tags.py", line 150, in render
    return compiled_parent._render(context)
  File "C:\Python372\mecheck\lib\site-packages\django\template\base.py", line 163, in _render
    return self.nodelist.render(context)
  File "C:\Python372\mecheck\lib\site-packages\django\template\base.py", line 937, in render
    bit = node.render_annotated(context)
  File "C:\Python372\mecheck\lib\site-packages\django\template\base.py", line 904, in render_annotated
    return self.render(context)
  File "C:\Python372\mecheck\lib\site-packages\django\template\loader_tags.py", line 150, in render
    return compiled_parent._render(context)
  File "C:\Python372\mecheck\lib\site-packages\django\template\base.py", line 163, in _render
    return self.nodelist.render(context)
  File "C:\Python372\mecheck\lib\site-packages\django\template\base.py", line 937, in render
    bit = node.render_annotated(context)
  File "C:\Python372\mecheck\lib\site-packages\django\template\base.py", line 904, in render_annotated
    return self.render(context)
  File "C:\Python372\mecheck\lib\site-packages\django\template\defaulttags.py", line 309, in render
    return nodelist.render(context)
  File "C:\Python372\mecheck\lib\site-packages\django\template\base.py", line 937, in render
    bit = node.render_annotated(context)
  File "C:\Python372\mecheck\lib\site-packages\django\template\base.py", line 904, in render_annotated
    return self.render(context)
  File "C:\Python372\mecheck\lib\site-packages\django\template\loader_tags.py", line 62, in render
    result = block.nodelist.render(context)
  File "C:\Python372\mecheck\lib\site-packages\django\template\base.py", line 937, in render
    bit = node.render_annotated(context)
  File "C:\Python372\mecheck\lib\site-packages\django\template\base.py", line 904, in render_annotated
    return self.render(context)
  File "C:\Python372\mecheck\lib\site-packages\django\template\defaulttags.py", line 309, in render
    return nodelist.render(context)
  File "C:\Python372\mecheck\lib\site-packages\django\template\base.py", line 937, in render
    bit = node.render_annotated(context)
  File "C:\Python372\mecheck\lib\site-packages\django\template\base.py", line 904, in render_annotated
    return self.render(context)
  File "C:\Python372\mecheck\lib\site-packages\django\template\base.py", line 987, in render
    output = self.filter_expression.resolve(context)
  File "C:\Python372\mecheck\lib\site-packages\django\template\base.py", line 698, in resolve
    new_obj = func(obj, *arg_vals)
  File "C:\Python372\mecheck\lib\site-packages\django\template\defaultfilters.py", line 42, in _dec
    args[0] = str(args[0])
  File "C:\djangoproject\Reliability_Row_data\app01\models.py", line 70, in __str__
    p = self.parent
  File "C:\Python372\mecheck\lib\site-packages\django\db\models\fields\related_descriptors.py", line 177, in __get__
    rel_obj = self.get_object(instance)
  File "C:\Python372\mecheck\lib\site-packages\django\db\models\fields\related_descriptors.py", line 144, in get_object
    return qs.get(self.field.get_reverse_related_filter(instance))
  File "C:\Python372\mecheck\lib\site-packages\django\db\models\query.py", line 399, in get
    self.model._meta.object_name
app01.models.Menu.DoesNotExist: Menu matching query does not exist.
[2020-03-10 19:37:00,853] [basehttp.py:154] [basehttp:log_message] [ERROR]- "GET /admin/app01/menu/29/change/ HTTP/1.1" 500 27
[2020-03-10 19:38:09,050] [log.py:228] [log:log_response] [ERROR]- Internal Server Error: /admin/app01/menu/51/change/
Traceback (most recent call last):
  File "C:\Python372\mecheck\lib\site-packages\django\db\models\fields\related_descriptors.py", line 163, in __get__
    rel_obj = self.field.get_cached_value(instance)
  File "C:\Python372\mecheck\lib\site-packages\django\db\models\fields\mixins.py", line 13, in get_cached_value
    return instance._state.fields_cache[cache_name]
KeyError: 'parent'

During handling of the above exception, another exception occurred:

Traceback (most recent call last):
  File "C:\Python372\mecheck\lib\site-packages\django\core\handlers\exception.py", line 34, in inner
    response = get_response(request)
  File "C:\Python372\mecheck\lib\site-packages\django\core\handlers\base.py", line 156, in _get_response
    response = self.process_exception_by_middleware(e, request)
  File "C:\Python372\mecheck\lib\site-packages\django\core\handlers\base.py", line 154, in _get_response
    response = response.render()
  File "C:\Python372\mecheck\lib\site-packages\django\template\response.py", line 106, in render
    self.content = self.rendered_content
  File "C:\Python372\mecheck\lib\site-packages\django\template\response.py", line 83, in rendered_content
    content = template.render(context, self._request)
  File "C:\Python372\mecheck\lib\site-packages\django\template\backends\django.py", line 61, in render
    return self.template.render(context)
  File "C:\Python372\mecheck\lib\site-packages\django\template\base.py", line 171, in render
    return self._render(context)
  File "C:\Python372\mecheck\lib\site-packages\django\template\base.py", line 163, in _render
    return self.nodelist.render(context)
  File "C:\Python372\mecheck\lib\site-packages\django\template\base.py", line 937, in render
    bit = node.render_annotated(context)
  File "C:\Python372\mecheck\lib\site-packages\django\template\base.py", line 904, in render_annotated
    return self.render(context)
  File "C:\Python372\mecheck\lib\site-packages\django\template\loader_tags.py", line 150, in render
    return compiled_parent._render(context)
  File "C:\Python372\mecheck\lib\site-packages\django\template\base.py", line 163, in _render
    return self.nodelist.render(context)
  File "C:\Python372\mecheck\lib\site-packages\django\template\base.py", line 937, in render
    bit = node.render_annotated(context)
  File "C:\Python372\mecheck\lib\site-packages\django\template\base.py", line 904, in render_annotated
    return self.render(context)
  File "C:\Python372\mecheck\lib\site-packages\django\template\loader_tags.py", line 150, in render
    return compiled_parent._render(context)
  File "C:\Python372\mecheck\lib\site-packages\django\template\base.py", line 163, in _render
    return self.nodelist.render(context)
  File "C:\Python372\mecheck\lib\site-packages\django\template\base.py", line 937, in render
    bit = node.render_annotated(context)
  File "C:\Python372\mecheck\lib\site-packages\django\template\base.py", line 904, in render_annotated
    return self.render(context)
  File "C:\Python372\mecheck\lib\site-packages\django\template\defaulttags.py", line 309, in render
    return nodelist.render(context)
  File "C:\Python372\mecheck\lib\site-packages\django\template\base.py", line 937, in render
    bit = node.render_annotated(context)
  File "C:\Python372\mecheck\lib\site-packages\django\template\base.py", line 904, in render_annotated
    return self.render(context)
  File "C:\Python372\mecheck\lib\site-packages\django\template\loader_tags.py", line 62, in render
    result = block.nodelist.render(context)
  File "C:\Python372\mecheck\lib\site-packages\django\template\base.py", line 937, in render
    bit = node.render_annotated(context)
  File "C:\Python372\mecheck\lib\site-packages\django\template\base.py", line 904, in render_annotated
    return self.render(context)
  File "C:\Python372\mecheck\lib\site-packages\django\template\defaulttags.py", line 309, in render
    return nodelist.render(context)
  File "C:\Python372\mecheck\lib\site-packages\django\template\base.py", line 937, in render
    bit = node.render_annotated(context)
  File "C:\Python372\mecheck\lib\site-packages\django\template\base.py", line 904, in render_annotated
    return self.render(context)
  File "C:\Python372\mecheck\lib\site-packages\django\template\base.py", line 987, in render
    output = self.filter_expression.resolve(context)
  File "C:\Python372\mecheck\lib\site-packages\django\template\base.py", line 698, in resolve
    new_obj = func(obj, *arg_vals)
  File "C:\Python372\mecheck\lib\site-packages\django\template\defaultfilters.py", line 42, in _dec
    args[0] = str(args[0])
  File "C:\djangoproject\Reliability_Row_data\app01\models.py", line 73, in __str__
    p = p.parent
  File "C:\Python372\mecheck\lib\site-packages\django\db\models\fields\related_descriptors.py", line 177, in __get__
    rel_obj = self.get_object(instance)
  File "C:\Python372\mecheck\lib\site-packages\django\db\models\fields\related_descriptors.py", line 144, in get_object
    return qs.get(self.field.get_reverse_related_filter(instance))
  File "C:\Python372\mecheck\lib\site-packages\django\db\models\query.py", line 399, in get
    self.model._meta.object_name
app01.models.Menu.DoesNotExist: Menu matching query does not exist.
[2020-03-10 19:38:09,066] [basehttp.py:154] [basehttp:log_message] [ERROR]- "GET /admin/app01/menu/51/change/ HTTP/1.1" 500 27
[2020-03-10 19:38:19,183] [log.py:228] [log:log_response] [ERROR]- Internal Server Error: /admin/app01/menu/add/
Traceback (most recent call last):
  File "C:\Python372\mecheck\lib\site-packages\django\db\models\fields\related_descriptors.py", line 163, in __get__
    rel_obj = self.field.get_cached_value(instance)
  File "C:\Python372\mecheck\lib\site-packages\django\db\models\fields\mixins.py", line 13, in get_cached_value
    return instance._state.fields_cache[cache_name]
KeyError: 'parent'

During handling of the above exception, another exception occurred:

Traceback (most recent call last):
  File "C:\Python372\mecheck\lib\site-packages\django\core\handlers\exception.py", line 34, in inner
    response = get_response(request)
  File "C:\Python372\mecheck\lib\site-packages\django\core\handlers\base.py", line 156, in _get_response
    response = self.process_exception_by_middleware(e, request)
  File "C:\Python372\mecheck\lib\site-packages\django\core\handlers\base.py", line 154, in _get_response
    response = response.render()
  File "C:\Python372\mecheck\lib\site-packages\django\template\response.py", line 106, in render
    self.content = self.rendered_content
  File "C:\Python372\mecheck\lib\site-packages\django\template\response.py", line 83, in rendered_content
    content = template.render(context, self._request)
  File "C:\Python372\mecheck\lib\site-packages\django\template\backends\django.py", line 61, in render
    return self.template.render(context)
  File "C:\Python372\mecheck\lib\site-packages\django\template\base.py", line 171, in render
    return self._render(context)
  File "C:\Python372\mecheck\lib\site-packages\django\template\base.py", line 163, in _render
    return self.nodelist.render(context)
  File "C:\Python372\mecheck\lib\site-packages\django\template\base.py", line 937, in render
    bit = node.render_annotated(context)
  File "C:\Python372\mecheck\lib\site-packages\django\template\base.py", line 904, in render_annotated
    return self.render(context)
  File "C:\Python372\mecheck\lib\site-packages\django\template\loader_tags.py", line 150, in render
    return compiled_parent._render(context)
  File "C:\Python372\mecheck\lib\site-packages\django\template\base.py", line 163, in _render
    return self.nodelist.render(context)
  File "C:\Python372\mecheck\lib\site-packages\django\template\base.py", line 937, in render
    bit = node.render_annotated(context)
  File "C:\Python372\mecheck\lib\site-packages\django\template\base.py", line 904, in render_annotated
    return self.render(context)
  File "C:\Python372\mecheck\lib\site-packages\django\template\loader_tags.py", line 150, in render
    return compiled_parent._render(context)
  File "C:\Python372\mecheck\lib\site-packages\django\template\base.py", line 163, in _render
    return self.nodelist.render(context)
  File "C:\Python372\mecheck\lib\site-packages\django\template\base.py", line 937, in render
    bit = node.render_annotated(context)
  File "C:\Python372\mecheck\lib\site-packages\django\template\base.py", line 904, in render_annotated
    return self.render(context)
  File "C:\Python372\mecheck\lib\site-packages\django\template\loader_tags.py", line 62, in render
    result = block.nodelist.render(context)
  File "C:\Python372\mecheck\lib\site-packages\django\template\base.py", line 937, in render
    bit = node.render_annotated(context)
  File "C:\Python372\mecheck\lib\site-packages\django\template\base.py", line 904, in render_annotated
    return self.render(context)
  File "C:\Python372\mecheck\lib\site-packages\django\template\loader_tags.py", line 62, in render
    result = block.nodelist.render(context)
  File "C:\Python372\mecheck\lib\site-packages\django\template\base.py", line 937, in render
    bit = node.render_annotated(context)
  File "C:\Python372\mecheck\lib\site-packages\django\template\base.py", line 904, in render_annotated
    return self.render(context)
  File "C:\Python372\mecheck\lib\site-packages\django\template\defaulttags.py", line 209, in render
    nodelist.append(node.render_annotated(context))
  File "C:\Python372\mecheck\lib\site-packages\django\template\base.py", line 904, in render_annotated
    return self.render(context)
  File "C:\Python372\mecheck\lib\site-packages\django\template\loader_tags.py", line 188, in render
    return template.render(context)
  File "C:\Python372\mecheck\lib\site-packages\django\template\base.py", line 173, in render
    return self._render(context)
  File "C:\Python372\mecheck\lib\site-packages\django\template\base.py", line 163, in _render
    return self.nodelist.render(context)
  File "C:\Python372\mecheck\lib\site-packages\django\template\base.py", line 937, in render
    bit = node.render_annotated(context)
  File "C:\Python372\mecheck\lib\site-packages\django\template\base.py", line 904, in render_annotated
    return self.render(context)
  File "C:\Python372\mecheck\lib\site-packages\django\template\defaulttags.py", line 209, in render
    nodelist.append(node.render_annotated(context))
  File "C:\Python372\mecheck\lib\site-packages\django\template\base.py", line 904, in render_annotated
    return self.render(context)
  File "C:\Python372\mecheck\lib\site-packages\django\template\defaulttags.py", line 209, in render
    nodelist.append(node.render_annotated(context))
  File "C:\Python372\mecheck\lib\site-packages\django\template\base.py", line 904, in render_annotated
    return self.render(context)
  File "C:\Python372\mecheck\lib\site-packages\django\template\defaulttags.py", line 309, in render
    return nodelist.render(context)
  File "C:\Python372\mecheck\lib\site-packages\django\template\base.py", line 937, in render
    bit = node.render_annotated(context)
  File "C:\Python372\mecheck\lib\site-packages\django\template\base.py", line 904, in render_annotated
    return self.render(context)
  File "C:\Python372\mecheck\lib\site-packages\django\template\defaulttags.py", line 309, in render
    return nodelist.render(context)
  File "C:\Python372\mecheck\lib\site-packages\django\template\base.py", line 937, in render
    bit = node.render_annotated(context)
  File "C:\Python372\mecheck\lib\site-packages\django\template\base.py", line 904, in render_annotated
    return self.render(context)
  File "C:\Python372\mecheck\lib\site-packages\django\template\base.py", line 993, in render
    return render_value_in_context(output, context)
  File "C:\Python372\mecheck\lib\site-packages\django\template\base.py", line 972, in render_value_in_context
    value = str(value)
  File "C:\Python372\mecheck\lib\site-packages\django\utils\html.py", line 397, in <lambda>
    klass.__str__ = lambda self: mark_safe(klass_str(self))
  File "C:\Python372\mecheck\lib\site-packages\django\forms\boundfield.py", line 33, in __str__
    return self.as_widget()
  File "C:\Python372\mecheck\lib\site-packages\django\forms\boundfield.py", line 93, in as_widget
    renderer=self.form.renderer,
  File "C:\Python372\mecheck\lib\site-packages\django\forms\widgets.py", line 229, in render
    context = self.get_context(name, value, attrs)
  File "C:\Python372\mecheck\lib\site-packages\django\contrib\admin\widgets.py", line 293, in get_context
    'rendered_widget': self.widget.render(name, value, attrs),
  File "C:\Python372\mecheck\lib\site-packages\django\forms\widgets.py", line 229, in render
    context = self.get_context(name, value, attrs)
  File "C:\Python372\mecheck\lib\site-packages\django\forms\widgets.py", line 668, in get_context
    context = super().get_context(name, value, attrs)
  File "C:\Python372\mecheck\lib\site-packages\django\forms\widgets.py", line 629, in get_context
    context['widget']['optgroups'] = self.optgroups(name, context['widget']['value'], attrs)
  File "C:\Python372\mecheck\lib\site-packages\django\forms\widgets.py", line 577, in optgroups
    for index, (option_value, option_label) in enumerate(self.choices):
  File "C:\Python372\mecheck\lib\site-packages\django\forms\models.py", line 1140, in __iter__
    yield self.choice(obj)
  File "C:\Python372\mecheck\lib\site-packages\django\forms\models.py", line 1152, in choice
    return (self.field.prepare_value(obj), self.field.label_from_instance(obj))
  File "C:\Python372\mecheck\lib\site-packages\django\forms\models.py", line 1218, in label_from_instance
    return str(obj)
  File "C:\djangoproject\Reliability_Row_data\app01\models.py", line 70, in __str__
    p = self.parent
  File "C:\Python372\mecheck\lib\site-packages\django\db\models\fields\related_descriptors.py", line 177, in __get__
    rel_obj = self.get_object(instance)
  File "C:\Python372\mecheck\lib\site-packages\django\db\models\fields\related_descriptors.py", line 144, in get_object
    return qs.get(self.field.get_reverse_related_filter(instance))
  File "C:\Python372\mecheck\lib\site-packages\django\db\models\query.py", line 399, in get
    self.model._meta.object_name
app01.models.Menu.DoesNotExist: Menu matching query does not exist.
[2020-03-10 19:38:19,199] [basehttp.py:154] [basehttp:log_message] [ERROR]- "GET /admin/app01/menu/add/ HTTP/1.1" 500 27
[2020-03-10 19:39:03,758] [log.py:228] [log:log_response] [ERROR]- Internal Server Error: /admin/app01/permission/31/change/
Traceback (most recent call last):
  File "C:\Python372\mecheck\lib\site-packages\django\db\models\fields\related_descriptors.py", line 163, in __get__
    rel_obj = self.field.get_cached_value(instance)
  File "C:\Python372\mecheck\lib\site-packages\django\db\models\fields\mixins.py", line 13, in get_cached_value
    return instance._state.fields_cache[cache_name]
KeyError: 'parent'

During handling of the above exception, another exception occurred:

Traceback (most recent call last):
  File "C:\Python372\mecheck\lib\site-packages\django\core\handlers\exception.py", line 34, in inner
    response = get_response(request)
  File "C:\Python372\mecheck\lib\site-packages\django\core\handlers\base.py", line 156, in _get_response
    response = self.process_exception_by_middleware(e, request)
  File "C:\Python372\mecheck\lib\site-packages\django\core\handlers\base.py", line 154, in _get_response
    response = response.render()
  File "C:\Python372\mecheck\lib\site-packages\django\template\response.py", line 106, in render
    self.content = self.rendered_content
  File "C:\Python372\mecheck\lib\site-packages\django\template\response.py", line 83, in rendered_content
    content = template.render(context, self._request)
  File "C:\Python372\mecheck\lib\site-packages\django\template\backends\django.py", line 61, in render
    return self.template.render(context)
  File "C:\Python372\mecheck\lib\site-packages\django\template\base.py", line 171, in render
    return self._render(context)
  File "C:\Python372\mecheck\lib\site-packages\django\template\base.py", line 163, in _render
    return self.nodelist.render(context)
  File "C:\Python372\mecheck\lib\site-packages\django\template\base.py", line 937, in render
    bit = node.render_annotated(context)
  File "C:\Python372\mecheck\lib\site-packages\django\template\base.py", line 904, in render_annotated
    return self.render(context)
  File "C:\Python372\mecheck\lib\site-packages\django\template\loader_tags.py", line 150, in render
    return compiled_parent._render(context)
  File "C:\Python372\mecheck\lib\site-packages\django\template\base.py", line 163, in _render
    return self.nodelist.render(context)
  File "C:\Python372\mecheck\lib\site-packages\django\template\base.py", line 937, in render
    bit = node.render_annotated(context)
  File "C:\Python372\mecheck\lib\site-packages\django\template\base.py", line 904, in render_annotated
    return self.render(context)
  File "C:\Python372\mecheck\lib\site-packages\django\template\loader_tags.py", line 150, in render
    return compiled_parent._render(context)
  File "C:\Python372\mecheck\lib\site-packages\django\template\base.py", line 163, in _render
    return self.nodelist.render(context)
  File "C:\Python372\mecheck\lib\site-packages\django\template\base.py", line 937, in render
    bit = node.render_annotated(context)
  File "C:\Python372\mecheck\lib\site-packages\django\template\base.py", line 904, in render_annotated
    return self.render(context)
  File "C:\Python372\mecheck\lib\site-packages\django\template\defaulttags.py", line 309, in render
    return nodelist.render(context)
  File "C:\Python372\mecheck\lib\site-packages\django\template\base.py", line 937, in render
    bit = node.render_annotated(context)
  File "C:\Python372\mecheck\lib\site-packages\django\template\base.py", line 904, in render_annotated
    return self.render(context)
  File "C:\Python372\mecheck\lib\site-packages\django\template\loader_tags.py", line 62, in render
    result = block.nodelist.render(context)
  File "C:\Python372\mecheck\lib\site-packages\django\template\base.py", line 937, in render
    bit = node.render_annotated(context)
  File "C:\Python372\mecheck\lib\site-packages\django\template\base.py", line 904, in render_annotated
    return self.render(context)
  File "C:\Python372\mecheck\lib\site-packages\django\template\defaulttags.py", line 309, in render
    return nodelist.render(context)
  File "C:\Python372\mecheck\lib\site-packages\django\template\base.py", line 937, in render
    bit = node.render_annotated(context)
  File "C:\Python372\mecheck\lib\site-packages\django\template\base.py", line 904, in render_annotated
    return self.render(context)
  File "C:\Python372\mecheck\lib\site-packages\django\template\base.py", line 987, in render
    output = self.filter_expression.resolve(context)
  File "C:\Python372\mecheck\lib\site-packages\django\template\base.py", line 698, in resolve
    new_obj = func(obj, *arg_vals)
  File "C:\Python372\mecheck\lib\site-packages\django\template\defaultfilters.py", line 42, in _dec
    args[0] = str(args[0])
  File "C:\djangoproject\Reliability_Row_data\app01\models.py", line 53, in __str__
    return '{menu}---{permission}'.format(menu=self.menu, permission=self.Menu_title)
  File "C:\djangoproject\Reliability_Row_data\app01\models.py", line 73, in __str__
    p = p.parent
  File "C:\Python372\mecheck\lib\site-packages\django\db\models\fields\related_descriptors.py", line 177, in __get__
    rel_obj = self.get_object(instance)
  File "C:\Python372\mecheck\lib\site-packages\django\db\models\fields\related_descriptors.py", line 144, in get_object
    return qs.get(self.field.get_reverse_related_filter(instance))
  File "C:\Python372\mecheck\lib\site-packages\django\db\models\query.py", line 399, in get
    self.model._meta.object_name
app01.models.Menu.DoesNotExist: Menu matching query does not exist.
[2020-03-10 19:39:03,774] [basehttp.py:154] [basehttp:log_message] [ERROR]- "GET /admin/app01/permission/31/change/ HTTP/1.1" 500 27
[2020-03-10 19:40:40,007] [log.py:228] [log:log_response] [ERROR]- Internal Server Error: /admin/app01/permission/31/change/
Traceback (most recent call last):
  File "C:\Python372\mecheck\lib\site-packages\django\db\models\fields\related_descriptors.py", line 163, in __get__
    rel_obj = self.field.get_cached_value(instance)
  File "C:\Python372\mecheck\lib\site-packages\django\db\models\fields\mixins.py", line 13, in get_cached_value
    return instance._state.fields_cache[cache_name]
KeyError: 'parent'

During handling of the above exception, another exception occurred:

Traceback (most recent call last):
  File "C:\Python372\mecheck\lib\site-packages\django\core\handlers\exception.py", line 34, in inner
    response = get_response(request)
  File "C:\Python372\mecheck\lib\site-packages\django\core\handlers\base.py", line 156, in _get_response
    response = self.process_exception_by_middleware(e, request)
  File "C:\Python372\mecheck\lib\site-packages\django\core\handlers\base.py", line 154, in _get_response
    response = response.render()
  File "C:\Python372\mecheck\lib\site-packages\django\template\response.py", line 106, in render
    self.content = self.rendered_content
  File "C:\Python372\mecheck\lib\site-packages\django\template\response.py", line 83, in rendered_content
    content = template.render(context, self._request)
  File "C:\Python372\mecheck\lib\site-packages\django\template\backends\django.py", line 61, in render
    return self.template.render(context)
  File "C:\Python372\mecheck\lib\site-packages\django\template\base.py", line 171, in render
    return self._render(context)
  File "C:\Python372\mecheck\lib\site-packages\django\template\base.py", line 163, in _render
    return self.nodelist.render(context)
  File "C:\Python372\mecheck\lib\site-packages\django\template\base.py", line 937, in render
    bit = node.render_annotated(context)
  File "C:\Python372\mecheck\lib\site-packages\django\template\base.py", line 904, in render_annotated
    return self.render(context)
  File "C:\Python372\mecheck\lib\site-packages\django\template\loader_tags.py", line 150, in render
    return compiled_parent._render(context)
  File "C:\Python372\mecheck\lib\site-packages\django\template\base.py", line 163, in _render
    return self.nodelist.render(context)
  File "C:\Python372\mecheck\lib\site-packages\django\template\base.py", line 937, in render
    bit = node.render_annotated(context)
  File "C:\Python372\mecheck\lib\site-packages\django\template\base.py", line 904, in render_annotated
    return self.render(context)
  File "C:\Python372\mecheck\lib\site-packages\django\template\loader_tags.py", line 150, in render
    return compiled_parent._render(context)
  File "C:\Python372\mecheck\lib\site-packages\django\template\base.py", line 163, in _render
    return self.nodelist.render(context)
  File "C:\Python372\mecheck\lib\site-packages\django\template\base.py", line 937, in render
    bit = node.render_annotated(context)
  File "C:\Python372\mecheck\lib\site-packages\django\template\base.py", line 904, in render_annotated
    return self.render(context)
  File "C:\Python372\mecheck\lib\site-packages\django\template\defaulttags.py", line 309, in render
    return nodelist.render(context)
  File "C:\Python372\mecheck\lib\site-packages\django\template\base.py", line 937, in render
    bit = node.render_annotated(context)
  File "C:\Python372\mecheck\lib\site-packages\django\template\base.py", line 904, in render_annotated
    return self.render(context)
  File "C:\Python372\mecheck\lib\site-packages\django\template\loader_tags.py", line 62, in render
    result = block.nodelist.render(context)
  File "C:\Python372\mecheck\lib\site-packages\django\template\base.py", line 937, in render
    bit = node.render_annotated(context)
  File "C:\Python372\mecheck\lib\site-packages\django\template\base.py", line 904, in render_annotated
    return self.render(context)
  File "C:\Python372\mecheck\lib\site-packages\django\template\defaulttags.py", line 309, in render
    return nodelist.render(context)
  File "C:\Python372\mecheck\lib\site-packages\django\template\base.py", line 937, in render
    bit = node.render_annotated(context)
  File "C:\Python372\mecheck\lib\site-packages\django\template\base.py", line 904, in render_annotated
    return self.render(context)
  File "C:\Python372\mecheck\lib\site-packages\django\template\base.py", line 987, in render
    output = self.filter_expression.resolve(context)
  File "C:\Python372\mecheck\lib\site-packages\django\template\base.py", line 698, in resolve
    new_obj = func(obj, *arg_vals)
  File "C:\Python372\mecheck\lib\site-packages\django\template\defaultfilters.py", line 42, in _dec
    args[0] = str(args[0])
  File "C:\djangoproject\Reliability_Row_data\app01\models.py", line 53, in __str__
    return '{menu}---{permission}'.format(menu=self.menu, permission=self.Menu_title)
  File "C:\djangoproject\Reliability_Row_data\app01\models.py", line 73, in __str__
    p = p.parent
  File "C:\Python372\mecheck\lib\site-packages\django\db\models\fields\related_descriptors.py", line 177, in __get__
    rel_obj = self.get_object(instance)
  File "C:\Python372\mecheck\lib\site-packages\django\db\models\fields\related_descriptors.py", line 144, in get_object
    return qs.get(self.field.get_reverse_related_filter(instance))
  File "C:\Python372\mecheck\lib\site-packages\django\db\models\query.py", line 399, in get
    self.model._meta.object_name
app01.models.Menu.DoesNotExist: Menu matching query does not exist.
[2020-03-10 19:40:40,023] [basehttp.py:154] [basehttp:log_message] [ERROR]- "GET /admin/app01/permission/31/change/ HTTP/1.1" 500 228339
[2020-03-10 19:41:33,173] [log.py:228] [log:log_response] [ERROR]- Internal Server Error: /admin/app01/menu/add/
Traceback (most recent call last):
  File "C:\Python372\mecheck\lib\site-packages\django\db\models\fields\related_descriptors.py", line 163, in __get__
    rel_obj = self.field.get_cached_value(instance)
  File "C:\Python372\mecheck\lib\site-packages\django\db\models\fields\mixins.py", line 13, in get_cached_value
    return instance._state.fields_cache[cache_name]
KeyError: 'parent'

During handling of the above exception, another exception occurred:

Traceback (most recent call last):
  File "C:\Python372\mecheck\lib\site-packages\django\core\handlers\exception.py", line 34, in inner
    response = get_response(request)
  File "C:\Python372\mecheck\lib\site-packages\django\core\handlers\base.py", line 156, in _get_response
    response = self.process_exception_by_middleware(e, request)
  File "C:\Python372\mecheck\lib\site-packages\django\core\handlers\base.py", line 154, in _get_response
    response = response.render()
  File "C:\Python372\mecheck\lib\site-packages\django\template\response.py", line 106, in render
    self.content = self.rendered_content
  File "C:\Python372\mecheck\lib\site-packages\django\template\response.py", line 83, in rendered_content
    content = template.render(context, self._request)
  File "C:\Python372\mecheck\lib\site-packages\django\template\backends\django.py", line 61, in render
    return self.template.render(context)
  File "C:\Python372\mecheck\lib\site-packages\django\template\base.py", line 171, in render
    return self._render(context)
  File "C:\Python372\mecheck\lib\site-packages\django\template\base.py", line 163, in _render
    return self.nodelist.render(context)
  File "C:\Python372\mecheck\lib\site-packages\django\template\base.py", line 937, in render
    bit = node.render_annotated(context)
  File "C:\Python372\mecheck\lib\site-packages\django\template\base.py", line 904, in render_annotated
    return self.render(context)
  File "C:\Python372\mecheck\lib\site-packages\django\template\loader_tags.py", line 150, in render
    return compiled_parent._render(context)
  File "C:\Python372\mecheck\lib\site-packages\django\template\base.py", line 163, in _render
    return self.nodelist.render(context)
  File "C:\Python372\mecheck\lib\site-packages\django\template\base.py", line 937, in render
    bit = node.render_annotated(context)
  File "C:\Python372\mecheck\lib\site-packages\django\template\base.py", line 904, in render_annotated
    return self.render(context)
  File "C:\Python372\mecheck\lib\site-packages\django\template\loader_tags.py", line 150, in render
    return compiled_parent._render(context)
  File "C:\Python372\mecheck\lib\site-packages\django\template\base.py", line 163, in _render
    return self.nodelist.render(context)
  File "C:\Python372\mecheck\lib\site-packages\django\template\base.py", line 937, in render
    bit = node.render_annotated(context)
  File "C:\Python372\mecheck\lib\site-packages\django\template\base.py", line 904, in render_annotated
    return self.render(context)
  File "C:\Python372\mecheck\lib\site-packages\django\template\loader_tags.py", line 62, in render
    result = block.nodelist.render(context)
  File "C:\Python372\mecheck\lib\site-packages\django\template\base.py", line 937, in render
    bit = node.render_annotated(context)
  File "C:\Python372\mecheck\lib\site-packages\django\template\base.py", line 904, in render_annotated
    return self.render(context)
  File "C:\Python372\mecheck\lib\site-packages\django\template\loader_tags.py", line 62, in render
    result = block.nodelist.render(context)
  File "C:\Python372\mecheck\lib\site-packages\django\template\base.py", line 937, in render
    bit = node.render_annotated(context)
  File "C:\Python372\mecheck\lib\site-packages\django\template\base.py", line 904, in render_annotated
    return self.render(context)
  File "C:\Python372\mecheck\lib\site-packages\django\template\defaulttags.py", line 209, in render
    nodelist.append(node.render_annotated(context))
  File "C:\Python372\mecheck\lib\site-packages\django\template\base.py", line 904, in render_annotated
    return self.render(context)
  File "C:\Python372\mecheck\lib\site-packages\django\template\loader_tags.py", line 188, in render
    return template.render(context)
  File "C:\Python372\mecheck\lib\site-packages\django\template\base.py", line 173, in render
    return self._render(context)
  File "C:\Python372\mecheck\lib\site-packages\django\template\base.py", line 163, in _render
    return self.nodelist.render(context)
  File "C:\Python372\mecheck\lib\site-packages\django\template\base.py", line 937, in render
    bit = node.render_annotated(context)
  File "C:\Python372\mecheck\lib\site-packages\django\template\base.py", line 904, in render_annotated
    return self.render(context)
  File "C:\Python372\mecheck\lib\site-packages\django\template\defaulttags.py", line 209, in render
    nodelist.append(node.render_annotated(context))
  File "C:\Python372\mecheck\lib\site-packages\django\template\base.py", line 904, in render_annotated
    return self.render(context)
  File "C:\Python372\mecheck\lib\site-packages\django\template\defaulttags.py", line 209, in render
    nodelist.append(node.render_annotated(context))
  File "C:\Python372\mecheck\lib\site-packages\django\template\base.py", line 904, in render_annotated
    return self.render(context)
  File "C:\Python372\mecheck\lib\site-packages\django\template\defaulttags.py", line 309, in render
    return nodelist.render(context)
  File "C:\Python372\mecheck\lib\site-packages\django\template\base.py", line 937, in render
    bit = node.render_annotated(context)
  File "C:\Python372\mecheck\lib\site-packages\django\template\base.py", line 904, in render_annotated
    return self.render(context)
  File "C:\Python372\mecheck\lib\site-packages\django\template\defaulttags.py", line 309, in render
    return nodelist.render(context)
  File "C:\Python372\mecheck\lib\site-packages\django\template\base.py", line 937, in render
    bit = node.render_annotated(context)
  File "C:\Python372\mecheck\lib\site-packages\django\template\base.py", line 904, in render_annotated
    return self.render(context)
  File "C:\Python372\mecheck\lib\site-packages\django\template\base.py", line 993, in render
    return render_value_in_context(output, context)
  File "C:\Python372\mecheck\lib\site-packages\django\template\base.py", line 972, in render_value_in_context
    value = str(value)
  File "C:\Python372\mecheck\lib\site-packages\django\utils\html.py", line 397, in <lambda>
    klass.__str__ = lambda self: mark_safe(klass_str(self))
  File "C:\Python372\mecheck\lib\site-packages\django\forms\boundfield.py", line 33, in __str__
    return self.as_widget()
  File "C:\Python372\mecheck\lib\site-packages\django\forms\boundfield.py", line 93, in as_widget
    renderer=self.form.renderer,
  File "C:\Python372\mecheck\lib\site-packages\django\forms\widgets.py", line 229, in render
    context = self.get_context(name, value, attrs)
  File "C:\Python372\mecheck\lib\site-packages\django\contrib\admin\widgets.py", line 293, in get_context
    'rendered_widget': self.widget.render(name, value, attrs),
  File "C:\Python372\mecheck\lib\site-packages\django\forms\widgets.py", line 229, in render
    context = self.get_context(name, value, attrs)
  File "C:\Python372\mecheck\lib\site-packages\django\forms\widgets.py", line 668, in get_context
    context = super().get_context(name, value, attrs)
  File "C:\Python372\mecheck\lib\site-packages\django\forms\widgets.py", line 629, in get_context
    context['widget']['optgroups'] = self.optgroups(name, context['widget']['value'], attrs)
  File "C:\Python372\mecheck\lib\site-packages\django\forms\widgets.py", line 577, in optgroups
    for index, (option_value, option_label) in enumerate(self.choices):
  File "C:\Python372\mecheck\lib\site-packages\django\forms\models.py", line 1140, in __iter__
    yield self.choice(obj)
  File "C:\Python372\mecheck\lib\site-packages\django\forms\models.py", line 1152, in choice
    return (self.field.prepare_value(obj), self.field.label_from_instance(obj))
  File "C:\Python372\mecheck\lib\site-packages\django\forms\models.py", line 1218, in label_from_instance
    return str(obj)
  File "C:\djangoproject\Reliability_Row_data\app01\models.py", line 70, in __str__
    p = self.parent
  File "C:\Python372\mecheck\lib\site-packages\django\db\models\fields\related_descriptors.py", line 177, in __get__
    rel_obj = self.get_object(instance)
  File "C:\Python372\mecheck\lib\site-packages\django\db\models\fields\related_descriptors.py", line 144, in get_object
    return qs.get(self.field.get_reverse_related_filter(instance))
  File "C:\Python372\mecheck\lib\site-packages\django\db\models\query.py", line 399, in get
    self.model._meta.object_name
app01.models.Menu.DoesNotExist: Menu matching query does not exist.
[2020-03-10 19:41:33,189] [basehttp.py:154] [basehttp:log_message] [ERROR]- "GET /admin/app01/menu/add/ HTTP/1.1" 500 584569
[2020-03-10 19:42:40,826] [log.py:228] [log:log_response] [ERROR]- Internal Server Error: /admin/app01/menu/49/change/
Traceback (most recent call last):
  File "C:\Python372\mecheck\lib\site-packages\django\db\models\fields\related_descriptors.py", line 163, in __get__
    rel_obj = self.field.get_cached_value(instance)
  File "C:\Python372\mecheck\lib\site-packages\django\db\models\fields\mixins.py", line 13, in get_cached_value
    return instance._state.fields_cache[cache_name]
KeyError: 'parent'

During handling of the above exception, another exception occurred:

Traceback (most recent call last):
  File "C:\Python372\mecheck\lib\site-packages\django\core\handlers\exception.py", line 34, in inner
    response = get_response(request)
  File "C:\Python372\mecheck\lib\site-packages\django\core\handlers\base.py", line 156, in _get_response
    response = self.process_exception_by_middleware(e, request)
  File "C:\Python372\mecheck\lib\site-packages\django\core\handlers\base.py", line 154, in _get_response
    response = response.render()
  File "C:\Python372\mecheck\lib\site-packages\django\template\response.py", line 106, in render
    self.content = self.rendered_content
  File "C:\Python372\mecheck\lib\site-packages\django\template\response.py", line 83, in rendered_content
    content = template.render(context, self._request)
  File "C:\Python372\mecheck\lib\site-packages\django\template\backends\django.py", line 61, in render
    return self.template.render(context)
  File "C:\Python372\mecheck\lib\site-packages\django\template\base.py", line 171, in render
    return self._render(context)
  File "C:\Python372\mecheck\lib\site-packages\django\template\base.py", line 163, in _render
    return self.nodelist.render(context)
  File "C:\Python372\mecheck\lib\site-packages\django\template\base.py", line 937, in render
    bit = node.render_annotated(context)
  File "C:\Python372\mecheck\lib\site-packages\django\template\base.py", line 904, in render_annotated
    return self.render(context)
  File "C:\Python372\mecheck\lib\site-packages\django\template\loader_tags.py", line 150, in render
    return compiled_parent._render(context)
  File "C:\Python372\mecheck\lib\site-packages\django\template\base.py", line 163, in _render
    return self.nodelist.render(context)
  File "C:\Python372\mecheck\lib\site-packages\django\template\base.py", line 937, in render
    bit = node.render_annotated(context)
  File "C:\Python372\mecheck\lib\site-packages\django\template\base.py", line 904, in render_annotated
    return self.render(context)
  File "C:\Python372\mecheck\lib\site-packages\django\template\loader_tags.py", line 150, in render
    return compiled_parent._render(context)
  File "C:\Python372\mecheck\lib\site-packages\django\template\base.py", line 163, in _render
    return self.nodelist.render(context)
  File "C:\Python372\mecheck\lib\site-packages\django\template\base.py", line 937, in render
    bit = node.render_annotated(context)
  File "C:\Python372\mecheck\lib\site-packages\django\template\base.py", line 904, in render_annotated
    return self.render(context)
  File "C:\Python372\mecheck\lib\site-packages\django\template\defaulttags.py", line 309, in render
    return nodelist.render(context)
  File "C:\Python372\mecheck\lib\site-packages\django\template\base.py", line 937, in render
    bit = node.render_annotated(context)
  File "C:\Python372\mecheck\lib\site-packages\django\template\base.py", line 904, in render_annotated
    return self.render(context)
  File "C:\Python372\mecheck\lib\site-packages\django\template\loader_tags.py", line 62, in render
    result = block.nodelist.render(context)
  File "C:\Python372\mecheck\lib\site-packages\django\template\base.py", line 937, in render
    bit = node.render_annotated(context)
  File "C:\Python372\mecheck\lib\site-packages\django\template\base.py", line 904, in render_annotated
    return self.render(context)
  File "C:\Python372\mecheck\lib\site-packages\django\template\defaulttags.py", line 309, in render
    return nodelist.render(context)
  File "C:\Python372\mecheck\lib\site-packages\django\template\base.py", line 937, in render
    bit = node.render_annotated(context)
  File "C:\Python372\mecheck\lib\site-packages\django\template\base.py", line 904, in render_annotated
    return self.render(context)
  File "C:\Python372\mecheck\lib\site-packages\django\template\base.py", line 987, in render
    output = self.filter_expression.resolve(context)
  File "C:\Python372\mecheck\lib\site-packages\django\template\base.py", line 698, in resolve
    new_obj = func(obj, *arg_vals)
  File "C:\Python372\mecheck\lib\site-packages\django\template\defaultfilters.py", line 42, in _dec
    args[0] = str(args[0])
  File "C:\djangoproject\Reliability_Row_data\app01\models.py", line 70, in __str__
    p = self.parent
  File "C:\Python372\mecheck\lib\site-packages\django\db\models\fields\related_descriptors.py", line 177, in __get__
    rel_obj = self.get_object(instance)
  File "C:\Python372\mecheck\lib\site-packages\django\db\models\fields\related_descriptors.py", line 144, in get_object
    return qs.get(self.field.get_reverse_related_filter(instance))
  File "C:\Python372\mecheck\lib\site-packages\django\db\models\query.py", line 399, in get
    self.model._meta.object_name
app01.models.Menu.DoesNotExist: Menu matching query does not exist.
[2020-03-10 19:42:40,842] [basehttp.py:154] [basehttp:log_message] [ERROR]- "GET /admin/app01/menu/49/change/ HTTP/1.1" 500 224178
[2020-03-10 19:42:46,441] [log.py:228] [log:log_response] [ERROR]- Internal Server Error: /admin/app01/menu/16/change/
Traceback (most recent call last):
  File "C:\Python372\mecheck\lib\site-packages\django\db\models\fields\related_descriptors.py", line 163, in __get__
    rel_obj = self.field.get_cached_value(instance)
  File "C:\Python372\mecheck\lib\site-packages\django\db\models\fields\mixins.py", line 13, in get_cached_value
    return instance._state.fields_cache[cache_name]
KeyError: 'parent'

During handling of the above exception, another exception occurred:

Traceback (most recent call last):
  File "C:\Python372\mecheck\lib\site-packages\django\core\handlers\exception.py", line 34, in inner
    response = get_response(request)
  File "C:\Python372\mecheck\lib\site-packages\django\core\handlers\base.py", line 156, in _get_response
    response = self.process_exception_by_middleware(e, request)
  File "C:\Python372\mecheck\lib\site-packages\django\core\handlers\base.py", line 154, in _get_response
    response = response.render()
  File "C:\Python372\mecheck\lib\site-packages\django\template\response.py", line 106, in render
    self.content = self.rendered_content
  File "C:\Python372\mecheck\lib\site-packages\django\template\response.py", line 83, in rendered_content
    content = template.render(context, self._request)
  File "C:\Python372\mecheck\lib\site-packages\django\template\backends\django.py", line 61, in render
    return self.template.render(context)
  File "C:\Python372\mecheck\lib\site-packages\django\template\base.py", line 171, in render
    return self._render(context)
  File "C:\Python372\mecheck\lib\site-packages\django\template\base.py", line 163, in _render
    return self.nodelist.render(context)
  File "C:\Python372\mecheck\lib\site-packages\django\template\base.py", line 937, in render
    bit = node.render_annotated(context)
  File "C:\Python372\mecheck\lib\site-packages\django\template\base.py", line 904, in render_annotated
    return self.render(context)
  File "C:\Python372\mecheck\lib\site-packages\django\template\loader_tags.py", line 150, in render
    return compiled_parent._render(context)
  File "C:\Python372\mecheck\lib\site-packages\django\template\base.py", line 163, in _render
    return self.nodelist.render(context)
  File "C:\Python372\mecheck\lib\site-packages\django\template\base.py", line 937, in render
    bit = node.render_annotated(context)
  File "C:\Python372\mecheck\lib\site-packages\django\template\base.py", line 904, in render_annotated
    return self.render(context)
  File "C:\Python372\mecheck\lib\site-packages\django\template\loader_tags.py", line 150, in render
    return compiled_parent._render(context)
  File "C:\Python372\mecheck\lib\site-packages\django\template\base.py", line 163, in _render
    return self.nodelist.render(context)
  File "C:\Python372\mecheck\lib\site-packages\django\template\base.py", line 937, in render
    bit = node.render_annotated(context)
  File "C:\Python372\mecheck\lib\site-packages\django\template\base.py", line 904, in render_annotated
    return self.render(context)
  File "C:\Python372\mecheck\lib\site-packages\django\template\defaulttags.py", line 309, in render
    return nodelist.render(context)
  File "C:\Python372\mecheck\lib\site-packages\django\template\base.py", line 937, in render
    bit = node.render_annotated(context)
  File "C:\Python372\mecheck\lib\site-packages\django\template\base.py", line 904, in render_annotated
    return self.render(context)
  File "C:\Python372\mecheck\lib\site-packages\django\template\loader_tags.py", line 62, in render
    result = block.nodelist.render(context)
  File "C:\Python372\mecheck\lib\site-packages\django\template\base.py", line 937, in render
    bit = node.render_annotated(context)
  File "C:\Python372\mecheck\lib\site-packages\django\template\base.py", line 904, in render_annotated
    return self.render(context)
  File "C:\Python372\mecheck\lib\site-packages\django\template\defaulttags.py", line 309, in render
    return nodelist.render(context)
  File "C:\Python372\mecheck\lib\site-packages\django\template\base.py", line 937, in render
    bit = node.render_annotated(context)
  File "C:\Python372\mecheck\lib\site-packages\django\template\base.py", line 904, in render_annotated
    return self.render(context)
  File "C:\Python372\mecheck\lib\site-packages\django\template\base.py", line 987, in render
    output = self.filter_expression.resolve(context)
  File "C:\Python372\mecheck\lib\site-packages\django\template\base.py", line 698, in resolve
    new_obj = func(obj, *arg_vals)
  File "C:\Python372\mecheck\lib\site-packages\django\template\defaultfilters.py", line 42, in _dec
    args[0] = str(args[0])
  File "C:\djangoproject\Reliability_Row_data\app01\models.py", line 70, in __str__
    p = self.parent
  File "C:\Python372\mecheck\lib\site-packages\django\db\models\fields\related_descriptors.py", line 177, in __get__
    rel_obj = self.get_object(instance)
  File "C:\Python372\mecheck\lib\site-packages\django\db\models\fields\related_descriptors.py", line 144, in get_object
    return qs.get(self.field.get_reverse_related_filter(instance))
  File "C:\Python372\mecheck\lib\site-packages\django\db\models\query.py", line 399, in get
    self.model._meta.object_name
app01.models.Menu.DoesNotExist: Menu matching query does not exist.
[2020-03-10 19:42:46,457] [basehttp.py:154] [basehttp:log_message] [ERROR]- "GET /admin/app01/menu/16/change/ HTTP/1.1" 500 224191
[2020-03-10 19:43:40,994] [log.py:228] [log:log_response] [ERROR]- Internal Server Error: /admin/app01/menu/
Traceback (most recent call last):
  File "C:\Python372\mecheck\lib\site-packages\django\core\handlers\exception.py", line 34, in inner
    response = get_response(request)
  File "C:\Python372\mecheck\lib\site-packages\django\core\handlers\base.py", line 126, in _get_response
    response = self.process_exception_by_middleware(e, request)
  File "C:\Python372\mecheck\lib\site-packages\django\core\handlers\base.py", line 124, in _get_response
    response = wrapped_callback(request, *callback_args, **callback_kwargs)
  File "C:\Python372\mecheck\lib\site-packages\django\contrib\admin\options.py", line 604, in wrapper
    return self.admin_site.admin_view(view)(*args, **kwargs)
  File "C:\Python372\mecheck\lib\site-packages\django\utils\decorators.py", line 142, in _wrapped_view
    response = view_func(request, *args, **kwargs)
  File "C:\Python372\mecheck\lib\site-packages\django\views\decorators\cache.py", line 44, in _wrapped_view_func
    response = view_func(request, *args, **kwargs)
  File "C:\Python372\mecheck\lib\site-packages\django\contrib\admin\sites.py", line 223, in inner
    return view(request, *args, **kwargs)
  File "C:\Python372\mecheck\lib\site-packages\django\utils\decorators.py", line 45, in _wrapper
    return bound_method(*args, **kwargs)
  File "C:\Python372\mecheck\lib\site-packages\django\utils\decorators.py", line 142, in _wrapped_view
    response = view_func(request, *args, **kwargs)
  File "C:\Python372\mecheck\lib\site-packages\django\contrib\admin\options.py", line 1701, in changelist_view
    response = self.response_action(request, queryset=cl.get_queryset(request))
  File "C:\Python372\mecheck\lib\site-packages\django\contrib\admin\options.py", line 1400, in response_action
    response = func(self, request, queryset)
  File "C:\Python372\mecheck\lib\site-packages\django\contrib\admin\actions.py", line 28, in delete_selected
    deletable_objects, model_count, perms_needed, protected = modeladmin.get_deleted_objects(queryset, request)
  File "C:\Python372\mecheck\lib\site-packages\django\contrib\admin\options.py", line 1823, in get_deleted_objects
    return get_deleted_objects(objs, request, self.admin_site)
  File "C:\Python372\mecheck\lib\site-packages\django\contrib\admin\utils.py", line 134, in get_deleted_objects
    collector.collect(objs)
  File "C:\Python372\mecheck\lib\site-packages\django\contrib\admin\utils.py", line 197, in collect
    return super().collect(objs, source_attr=source_attr, **kwargs)
  File "C:\Python372\mecheck\lib\site-packages\django\db\models\deletion.py", line 221, in collect
    field.remote_field.on_delete(self, field, sub_objs, self.using)
TypeError: 'bool' object is not callable
[2020-03-10 19:43:40,994] [basehttp.py:154] [basehttp:log_message] [ERROR]- "POST /admin/app01/menu/ HTTP/1.1" 500 132791
[2020-03-10 19:43:48,921] [log.py:228] [log:log_response] [ERROR]- Internal Server Error: /admin/app01/menu/
Traceback (most recent call last):
  File "C:\Python372\mecheck\lib\site-packages\django\core\handlers\exception.py", line 34, in inner
    response = get_response(request)
  File "C:\Python372\mecheck\lib\site-packages\django\core\handlers\base.py", line 126, in _get_response
    response = self.process_exception_by_middleware(e, request)
  File "C:\Python372\mecheck\lib\site-packages\django\core\handlers\base.py", line 124, in _get_response
    response = wrapped_callback(request, *callback_args, **callback_kwargs)
  File "C:\Python372\mecheck\lib\site-packages\django\contrib\admin\options.py", line 604, in wrapper
    return self.admin_site.admin_view(view)(*args, **kwargs)
  File "C:\Python372\mecheck\lib\site-packages\django\utils\decorators.py", line 142, in _wrapped_view
    response = view_func(request, *args, **kwargs)
  File "C:\Python372\mecheck\lib\site-packages\django\views\decorators\cache.py", line 44, in _wrapped_view_func
    response = view_func(request, *args, **kwargs)
  File "C:\Python372\mecheck\lib\site-packages\django\contrib\admin\sites.py", line 223, in inner
    return view(request, *args, **kwargs)
  File "C:\Python372\mecheck\lib\site-packages\django\utils\decorators.py", line 45, in _wrapper
    return bound_method(*args, **kwargs)
  File "C:\Python372\mecheck\lib\site-packages\django\utils\decorators.py", line 142, in _wrapped_view
    response = view_func(request, *args, **kwargs)
  File "C:\Python372\mecheck\lib\site-packages\django\contrib\admin\options.py", line 1701, in changelist_view
    response = self.response_action(request, queryset=cl.get_queryset(request))
  File "C:\Python372\mecheck\lib\site-packages\django\contrib\admin\options.py", line 1400, in response_action
    response = func(self, request, queryset)
  File "C:\Python372\mecheck\lib\site-packages\django\contrib\admin\actions.py", line 28, in delete_selected
    deletable_objects, model_count, perms_needed, protected = modeladmin.get_deleted_objects(queryset, request)
  File "C:\Python372\mecheck\lib\site-packages\django\contrib\admin\options.py", line 1823, in get_deleted_objects
    return get_deleted_objects(objs, request, self.admin_site)
  File "C:\Python372\mecheck\lib\site-packages\django\contrib\admin\utils.py", line 134, in get_deleted_objects
    collector.collect(objs)
  File "C:\Python372\mecheck\lib\site-packages\django\contrib\admin\utils.py", line 197, in collect
    return super().collect(objs, source_attr=source_attr, **kwargs)
  File "C:\Python372\mecheck\lib\site-packages\django\db\models\deletion.py", line 221, in collect
    field.remote_field.on_delete(self, field, sub_objs, self.using)
TypeError: 'bool' object is not callable
[2020-03-10 19:43:48,921] [basehttp.py:154] [basehttp:log_message] [ERROR]- "POST /admin/app01/menu/ HTTP/1.1" 500 132791
[2020-03-10 19:44:05,382] [log.py:228] [log:log_response] [ERROR]- Internal Server Error: /admin/app01/menu/29/change/
Traceback (most recent call last):
  File "C:\Python372\mecheck\lib\site-packages\django\db\models\fields\related_descriptors.py", line 163, in __get__
    rel_obj = self.field.get_cached_value(instance)
  File "C:\Python372\mecheck\lib\site-packages\django\db\models\fields\mixins.py", line 13, in get_cached_value
    return instance._state.fields_cache[cache_name]
KeyError: 'parent'

During handling of the above exception, another exception occurred:

Traceback (most recent call last):
  File "C:\Python372\mecheck\lib\site-packages\django\core\handlers\exception.py", line 34, in inner
    response = get_response(request)
  File "C:\Python372\mecheck\lib\site-packages\django\core\handlers\base.py", line 156, in _get_response
    response = self.process_exception_by_middleware(e, request)
  File "C:\Python372\mecheck\lib\site-packages\django\core\handlers\base.py", line 154, in _get_response
    response = response.render()
  File "C:\Python372\mecheck\lib\site-packages\django\template\response.py", line 106, in render
    self.content = self.rendered_content
  File "C:\Python372\mecheck\lib\site-packages\django\template\response.py", line 83, in rendered_content
    content = template.render(context, self._request)
  File "C:\Python372\mecheck\lib\site-packages\django\template\backends\django.py", line 61, in render
    return self.template.render(context)
  File "C:\Python372\mecheck\lib\site-packages\django\template\base.py", line 171, in render
    return self._render(context)
  File "C:\Python372\mecheck\lib\site-packages\django\template\base.py", line 163, in _render
    return self.nodelist.render(context)
  File "C:\Python372\mecheck\lib\site-packages\django\template\base.py", line 937, in render
    bit = node.render_annotated(context)
  File "C:\Python372\mecheck\lib\site-packages\django\template\base.py", line 904, in render_annotated
    return self.render(context)
  File "C:\Python372\mecheck\lib\site-packages\django\template\loader_tags.py", line 150, in render
    return compiled_parent._render(context)
  File "C:\Python372\mecheck\lib\site-packages\django\template\base.py", line 163, in _render
    return self.nodelist.render(context)
  File "C:\Python372\mecheck\lib\site-packages\django\template\base.py", line 937, in render
    bit = node.render_annotated(context)
  File "C:\Python372\mecheck\lib\site-packages\django\template\base.py", line 904, in render_annotated
    return self.render(context)
  File "C:\Python372\mecheck\lib\site-packages\django\template\loader_tags.py", line 150, in render
    return compiled_parent._render(context)
  File "C:\Python372\mecheck\lib\site-packages\django\template\base.py", line 163, in _render
    return self.nodelist.render(context)
  File "C:\Python372\mecheck\lib\site-packages\django\template\base.py", line 937, in render
    bit = node.render_annotated(context)
  File "C:\Python372\mecheck\lib\site-packages\django\template\base.py", line 904, in render_annotated
    return self.render(context)
  File "C:\Python372\mecheck\lib\site-packages\django\template\defaulttags.py", line 309, in render
    return nodelist.render(context)
  File "C:\Python372\mecheck\lib\site-packages\django\template\base.py", line 937, in render
    bit = node.render_annotated(context)
  File "C:\Python372\mecheck\lib\site-packages\django\template\base.py", line 904, in render_annotated
    return self.render(context)
  File "C:\Python372\mecheck\lib\site-packages\django\template\loader_tags.py", line 62, in render
    result = block.nodelist.render(context)
  File "C:\Python372\mecheck\lib\site-packages\django\template\base.py", line 937, in render
    bit = node.render_annotated(context)
  File "C:\Python372\mecheck\lib\site-packages\django\template\base.py", line 904, in render_annotated
    return self.render(context)
  File "C:\Python372\mecheck\lib\site-packages\django\template\defaulttags.py", line 309, in render
    return nodelist.render(context)
  File "C:\Python372\mecheck\lib\site-packages\django\template\base.py", line 937, in render
    bit = node.render_annotated(context)
  File "C:\Python372\mecheck\lib\site-packages\django\template\base.py", line 904, in render_annotated
    return self.render(context)
  File "C:\Python372\mecheck\lib\site-packages\django\template\base.py", line 987, in render
    output = self.filter_expression.resolve(context)
  File "C:\Python372\mecheck\lib\site-packages\django\template\base.py", line 698, in resolve
    new_obj = func(obj, *arg_vals)
  File "C:\Python372\mecheck\lib\site-packages\django\template\defaultfilters.py", line 42, in _dec
    args[0] = str(args[0])
  File "C:\djangoproject\Reliability_Row_data\app01\models.py", line 70, in __str__
    p = self.parent
  File "C:\Python372\mecheck\lib\site-packages\django\db\models\fields\related_descriptors.py", line 177, in __get__
    rel_obj = self.get_object(instance)
  File "C:\Python372\mecheck\lib\site-packages\django\db\models\fields\related_descriptors.py", line 144, in get_object
    return qs.get(self.field.get_reverse_related_filter(instance))
  File "C:\Python372\mecheck\lib\site-packages\django\db\models\query.py", line 399, in get
    self.model._meta.object_name
app01.models.Menu.DoesNotExist: Menu matching query does not exist.
[2020-03-10 19:44:05,397] [basehttp.py:154] [basehttp:log_message] [ERROR]- "GET /admin/app01/menu/29/change/ HTTP/1.1" 500 224173
[2020-03-10 19:44:13,731] [log.py:228] [log:log_response] [ERROR]- Internal Server Error: /admin/app01/menu/
Traceback (most recent call last):
  File "C:\Python372\mecheck\lib\site-packages\django\core\handlers\exception.py", line 34, in inner
    response = get_response(request)
  File "C:\Python372\mecheck\lib\site-packages\django\core\handlers\base.py", line 126, in _get_response
    response = self.process_exception_by_middleware(e, request)
  File "C:\Python372\mecheck\lib\site-packages\django\core\handlers\base.py", line 124, in _get_response
    response = wrapped_callback(request, *callback_args, **callback_kwargs)
  File "C:\Python372\mecheck\lib\site-packages\django\contrib\admin\options.py", line 604, in wrapper
    return self.admin_site.admin_view(view)(*args, **kwargs)
  File "C:\Python372\mecheck\lib\site-packages\django\utils\decorators.py", line 142, in _wrapped_view
    response = view_func(request, *args, **kwargs)
  File "C:\Python372\mecheck\lib\site-packages\django\views\decorators\cache.py", line 44, in _wrapped_view_func
    response = view_func(request, *args, **kwargs)
  File "C:\Python372\mecheck\lib\site-packages\django\contrib\admin\sites.py", line 223, in inner
    return view(request, *args, **kwargs)
  File "C:\Python372\mecheck\lib\site-packages\django\utils\decorators.py", line 45, in _wrapper
    return bound_method(*args, **kwargs)
  File "C:\Python372\mecheck\lib\site-packages\django\utils\decorators.py", line 142, in _wrapped_view
    response = view_func(request, *args, **kwargs)
  File "C:\Python372\mecheck\lib\site-packages\django\contrib\admin\options.py", line 1701, in changelist_view
    response = self.response_action(request, queryset=cl.get_queryset(request))
  File "C:\Python372\mecheck\lib\site-packages\django\contrib\admin\options.py", line 1400, in response_action
    response = func(self, request, queryset)
  File "C:\Python372\mecheck\lib\site-packages\django\contrib\admin\actions.py", line 28, in delete_selected
    deletable_objects, model_count, perms_needed, protected = modeladmin.get_deleted_objects(queryset, request)
  File "C:\Python372\mecheck\lib\site-packages\django\contrib\admin\options.py", line 1823, in get_deleted_objects
    return get_deleted_objects(objs, request, self.admin_site)
  File "C:\Python372\mecheck\lib\site-packages\django\contrib\admin\utils.py", line 134, in get_deleted_objects
    collector.collect(objs)
  File "C:\Python372\mecheck\lib\site-packages\django\contrib\admin\utils.py", line 197, in collect
    return super().collect(objs, source_attr=source_attr, **kwargs)
  File "C:\Python372\mecheck\lib\site-packages\django\db\models\deletion.py", line 221, in collect
    field.remote_field.on_delete(self, field, sub_objs, self.using)
TypeError: 'bool' object is not callable
[2020-03-10 19:44:13,731] [basehttp.py:154] [basehttp:log_message] [ERROR]- "POST /admin/app01/menu/ HTTP/1.1" 500 132341
[2020-03-10 19:44:18,962] [log.py:228] [log:log_response] [ERROR]- Internal Server Error: /admin/app01/role/2/change/
Traceback (most recent call last):
  File "C:\Python372\mecheck\lib\site-packages\django\db\models\fields\related_descriptors.py", line 163, in __get__
    rel_obj = self.field.get_cached_value(instance)
  File "C:\Python372\mecheck\lib\site-packages\django\db\models\fields\mixins.py", line 13, in get_cached_value
    return instance._state.fields_cache[cache_name]
KeyError: 'parent'

During handling of the above exception, another exception occurred:

Traceback (most recent call last):
  File "C:\Python372\mecheck\lib\site-packages\django\core\handlers\exception.py", line 34, in inner
    response = get_response(request)
  File "C:\Python372\mecheck\lib\site-packages\django\core\handlers\base.py", line 156, in _get_response
    response = self.process_exception_by_middleware(e, request)
  File "C:\Python372\mecheck\lib\site-packages\django\core\handlers\base.py", line 154, in _get_response
    response = response.render()
  File "C:\Python372\mecheck\lib\site-packages\django\template\response.py", line 106, in render
    self.content = self.rendered_content
  File "C:\Python372\mecheck\lib\site-packages\django\template\response.py", line 83, in rendered_content
    content = template.render(context, self._request)
  File "C:\Python372\mecheck\lib\site-packages\django\template\backends\django.py", line 61, in render
    return self.template.render(context)
  File "C:\Python372\mecheck\lib\site-packages\django\template\base.py", line 171, in render
    return self._render(context)
  File "C:\Python372\mecheck\lib\site-packages\django\template\base.py", line 163, in _render
    return self.nodelist.render(context)
  File "C:\Python372\mecheck\lib\site-packages\django\template\base.py", line 937, in render
    bit = node.render_annotated(context)
  File "C:\Python372\mecheck\lib\site-packages\django\template\base.py", line 904, in render_annotated
    return self.render(context)
  File "C:\Python372\mecheck\lib\site-packages\django\template\loader_tags.py", line 150, in render
    return compiled_parent._render(context)
  File "C:\Python372\mecheck\lib\site-packages\django\template\base.py", line 163, in _render
    return self.nodelist.render(context)
  File "C:\Python372\mecheck\lib\site-packages\django\template\base.py", line 937, in render
    bit = node.render_annotated(context)
  File "C:\Python372\mecheck\lib\site-packages\django\template\base.py", line 904, in render_annotated
    return self.render(context)
  File "C:\Python372\mecheck\lib\site-packages\django\template\loader_tags.py", line 150, in render
    return compiled_parent._render(context)
  File "C:\Python372\mecheck\lib\site-packages\django\template\base.py", line 163, in _render
    return self.nodelist.render(context)
  File "C:\Python372\mecheck\lib\site-packages\django\template\base.py", line 937, in render
    bit = node.render_annotated(context)
  File "C:\Python372\mecheck\lib\site-packages\django\template\base.py", line 904, in render_annotated
    return self.render(context)
  File "C:\Python372\mecheck\lib\site-packages\django\template\loader_tags.py", line 62, in render
    result = block.nodelist.render(context)
  File "C:\Python372\mecheck\lib\site-packages\django\template\base.py", line 937, in render
    bit = node.render_annotated(context)
  File "C:\Python372\mecheck\lib\site-packages\django\template\base.py", line 904, in render_annotated
    return self.render(context)
  File "C:\Python372\mecheck\lib\site-packages\django\template\loader_tags.py", line 62, in render
    result = block.nodelist.render(context)
  File "C:\Python372\mecheck\lib\site-packages\django\template\base.py", line 937, in render
    bit = node.render_annotated(context)
  File "C:\Python372\mecheck\lib\site-packages\django\template\base.py", line 904, in render_annotated
    return self.render(context)
  File "C:\Python372\mecheck\lib\site-packages\django\template\defaulttags.py", line 209, in render
    nodelist.append(node.render_annotated(context))
  File "C:\Python372\mecheck\lib\site-packages\django\template\base.py", line 904, in render_annotated
    return self.render(context)
  File "C:\Python372\mecheck\lib\site-packages\django\template\loader_tags.py", line 188, in render
    return template.render(context)
  File "C:\Python372\mecheck\lib\site-packages\django\template\base.py", line 173, in render
    return self._render(context)
  File "C:\Python372\mecheck\lib\site-packages\django\template\base.py", line 163, in _render
    return self.nodelist.render(context)
  File "C:\Python372\mecheck\lib\site-packages\django\template\base.py", line 937, in render
    bit = node.render_annotated(context)
  File "C:\Python372\mecheck\lib\site-packages\django\template\base.py", line 904, in render_annotated
    return self.render(context)
  File "C:\Python372\mecheck\lib\site-packages\django\template\defaulttags.py", line 209, in render
    nodelist.append(node.render_annotated(context))
  File "C:\Python372\mecheck\lib\site-packages\django\template\base.py", line 904, in render_annotated
    return self.render(context)
  File "C:\Python372\mecheck\lib\site-packages\django\template\defaulttags.py", line 209, in render
    nodelist.append(node.render_annotated(context))
  File "C:\Python372\mecheck\lib\site-packages\django\template\base.py", line 904, in render_annotated
    return self.render(context)
  File "C:\Python372\mecheck\lib\site-packages\django\template\defaulttags.py", line 309, in render
    return nodelist.render(context)
  File "C:\Python372\mecheck\lib\site-packages\django\template\base.py", line 937, in render
    bit = node.render_annotated(context)
  File "C:\Python372\mecheck\lib\site-packages\django\template\base.py", line 904, in render_annotated
    return self.render(context)
  File "C:\Python372\mecheck\lib\site-packages\django\template\defaulttags.py", line 309, in render
    return nodelist.render(context)
  File "C:\Python372\mecheck\lib\site-packages\django\template\base.py", line 937, in render
    bit = node.render_annotated(context)
  File "C:\Python372\mecheck\lib\site-packages\django\template\base.py", line 904, in render_annotated
    return self.render(context)
  File "C:\Python372\mecheck\lib\site-packages\django\template\base.py", line 993, in render
    return render_value_in_context(output, context)
  File "C:\Python372\mecheck\lib\site-packages\django\template\base.py", line 972, in render_value_in_context
    value = str(value)
  File "C:\Python372\mecheck\lib\site-packages\django\utils\html.py", line 397, in <lambda>
    klass.__str__ = lambda self: mark_safe(klass_str(self))
  File "C:\Python372\mecheck\lib\site-packages\django\forms\boundfield.py", line 33, in __str__
    return self.as_widget()
  File "C:\Python372\mecheck\lib\site-packages\django\forms\boundfield.py", line 93, in as_widget
    renderer=self.form.renderer,
  File "C:\Python372\mecheck\lib\site-packages\django\forms\widgets.py", line 229, in render
    context = self.get_context(name, value, attrs)
  File "C:\Python372\mecheck\lib\site-packages\django\contrib\admin\widgets.py", line 293, in get_context
    'rendered_widget': self.widget.render(name, value, attrs),
  File "C:\Python372\mecheck\lib\site-packages\django\forms\widgets.py", line 229, in render
    context = self.get_context(name, value, attrs)
  File "C:\Python372\mecheck\lib\site-packages\django\forms\widgets.py", line 668, in get_context
    context = super().get_context(name, value, attrs)
  File "C:\Python372\mecheck\lib\site-packages\django\forms\widgets.py", line 629, in get_context
    context['widget']['optgroups'] = self.optgroups(name, context['widget']['value'], attrs)
  File "C:\Python372\mecheck\lib\site-packages\django\forms\widgets.py", line 577, in optgroups
    for index, (option_value, option_label) in enumerate(self.choices):
  File "C:\Python372\mecheck\lib\site-packages\django\forms\models.py", line 1140, in __iter__
    yield self.choice(obj)
  File "C:\Python372\mecheck\lib\site-packages\django\forms\models.py", line 1152, in choice
    return (self.field.prepare_value(obj), self.field.label_from_instance(obj))
  File "C:\Python372\mecheck\lib\site-packages\django\forms\models.py", line 1218, in label_from_instance
    return str(obj)
  File "C:\djangoproject\Reliability_Row_data\app01\models.py", line 53, in __str__
    return '{menu}---{permission}'.format(menu=self.menu, permission=self.Menu_title)
  File "C:\djangoproject\Reliability_Row_data\app01\models.py", line 73, in __str__
    p = p.parent
  File "C:\Python372\mecheck\lib\site-packages\django\db\models\fields\related_descriptors.py", line 177, in __get__
    rel_obj = self.get_object(instance)
  File "C:\Python372\mecheck\lib\site-packages\django\db\models\fields\related_descriptors.py", line 144, in get_object
    return qs.get(self.field.get_reverse_related_filter(instance))
  File "C:\Python372\mecheck\lib\site-packages\django\db\models\query.py", line 399, in get
    self.model._meta.object_name
app01.models.Menu.DoesNotExist: Menu matching query does not exist.
[2020-03-10 19:44:18,978] [basehttp.py:154] [basehttp:log_message] [ERROR]- "GET /admin/app01/role/2/change/ HTTP/1.1" 500 587067
[2020-03-10 19:49:51,333] [log.py:228] [log:log_response] [ERROR]- Internal Server Error: /admin/app01/menu/29/change/
Traceback (most recent call last):
  File "C:\Python372\mecheck\lib\site-packages\django\db\models\fields\related_descriptors.py", line 163, in __get__
    rel_obj = self.field.get_cached_value(instance)
  File "C:\Python372\mecheck\lib\site-packages\django\db\models\fields\mixins.py", line 13, in get_cached_value
    return instance._state.fields_cache[cache_name]
KeyError: 'parent'

During handling of the above exception, another exception occurred:

Traceback (most recent call last):
  File "C:\Python372\mecheck\lib\site-packages\django\core\handlers\exception.py", line 34, in inner
    response = get_response(request)
  File "C:\Python372\mecheck\lib\site-packages\django\core\handlers\base.py", line 156, in _get_response
    response = self.process_exception_by_middleware(e, request)
  File "C:\Python372\mecheck\lib\site-packages\django\core\handlers\base.py", line 154, in _get_response
    response = response.render()
  File "C:\Python372\mecheck\lib\site-packages\django\template\response.py", line 106, in render
    self.content = self.rendered_content
  File "C:\Python372\mecheck\lib\site-packages\django\template\response.py", line 83, in rendered_content
    content = template.render(context, self._request)
  File "C:\Python372\mecheck\lib\site-packages\django\template\backends\django.py", line 61, in render
    return self.template.render(context)
  File "C:\Python372\mecheck\lib\site-packages\django\template\base.py", line 171, in render
    return self._render(context)
  File "C:\Python372\mecheck\lib\site-packages\django\template\base.py", line 163, in _render
    return self.nodelist.render(context)
  File "C:\Python372\mecheck\lib\site-packages\django\template\base.py", line 937, in render
    bit = node.render_annotated(context)
  File "C:\Python372\mecheck\lib\site-packages\django\template\base.py", line 904, in render_annotated
    return self.render(context)
  File "C:\Python372\mecheck\lib\site-packages\django\template\loader_tags.py", line 150, in render
    return compiled_parent._render(context)
  File "C:\Python372\mecheck\lib\site-packages\django\template\base.py", line 163, in _render
    return self.nodelist.render(context)
  File "C:\Python372\mecheck\lib\site-packages\django\template\base.py", line 937, in render
    bit = node.render_annotated(context)
  File "C:\Python372\mecheck\lib\site-packages\django\template\base.py", line 904, in render_annotated
    return self.render(context)
  File "C:\Python372\mecheck\lib\site-packages\django\template\loader_tags.py", line 150, in render
    return compiled_parent._render(context)
  File "C:\Python372\mecheck\lib\site-packages\django\template\base.py", line 163, in _render
    return self.nodelist.render(context)
  File "C:\Python372\mecheck\lib\site-packages\django\template\base.py", line 937, in render
    bit = node.render_annotated(context)
  File "C:\Python372\mecheck\lib\site-packages\django\template\base.py", line 904, in render_annotated
    return self.render(context)
  File "C:\Python372\mecheck\lib\site-packages\django\template\defaulttags.py", line 309, in render
    return nodelist.render(context)
  File "C:\Python372\mecheck\lib\site-packages\django\template\base.py", line 937, in render
    bit = node.render_annotated(context)
  File "C:\Python372\mecheck\lib\site-packages\django\template\base.py", line 904, in render_annotated
    return self.render(context)
  File "C:\Python372\mecheck\lib\site-packages\django\template\loader_tags.py", line 62, in render
    result = block.nodelist.render(context)
  File "C:\Python372\mecheck\lib\site-packages\django\template\base.py", line 937, in render
    bit = node.render_annotated(context)
  File "C:\Python372\mecheck\lib\site-packages\django\template\base.py", line 904, in render_annotated
    return self.render(context)
  File "C:\Python372\mecheck\lib\site-packages\django\template\defaulttags.py", line 309, in render
    return nodelist.render(context)
  File "C:\Python372\mecheck\lib\site-packages\django\template\base.py", line 937, in render
    bit = node.render_annotated(context)
  File "C:\Python372\mecheck\lib\site-packages\django\template\base.py", line 904, in render_annotated
    return self.render(context)
  File "C:\Python372\mecheck\lib\site-packages\django\template\base.py", line 987, in render
    output = self.filter_expression.resolve(context)
  File "C:\Python372\mecheck\lib\site-packages\django\template\base.py", line 698, in resolve
    new_obj = func(obj, *arg_vals)
  File "C:\Python372\mecheck\lib\site-packages\django\template\defaultfilters.py", line 42, in _dec
    args[0] = str(args[0])
  File "C:\djangoproject\Reliability_Row_data\app01\models.py", line 70, in __str__
    p = self.parent
  File "C:\Python372\mecheck\lib\site-packages\django\db\models\fields\related_descriptors.py", line 177, in __get__
    rel_obj = self.get_object(instance)
  File "C:\Python372\mecheck\lib\site-packages\django\db\models\fields\related_descriptors.py", line 144, in get_object
    return qs.get(self.field.get_reverse_related_filter(instance))
  File "C:\Python372\mecheck\lib\site-packages\django\db\models\query.py", line 399, in get
    self.model._meta.object_name
app01.models.Menu.DoesNotExist: Menu matching query does not exist.
[2020-03-10 19:49:51,348] [basehttp.py:154] [basehttp:log_message] [ERROR]- "GET /admin/app01/menu/29/change/ HTTP/1.1" 500 224173
[2020-03-10 19:50:09,499] [log.py:228] [log:log_response] [ERROR]- Internal Server Error: /admin/app01/menu/29/change/
Traceback (most recent call last):
  File "C:\Python372\mecheck\lib\site-packages\django\db\models\fields\related_descriptors.py", line 163, in __get__
    rel_obj = self.field.get_cached_value(instance)
  File "C:\Python372\mecheck\lib\site-packages\django\db\models\fields\mixins.py", line 13, in get_cached_value
    return instance._state.fields_cache[cache_name]
KeyError: 'parent'

During handling of the above exception, another exception occurred:

Traceback (most recent call last):
  File "C:\Python372\mecheck\lib\site-packages\django\core\handlers\exception.py", line 34, in inner
    response = get_response(request)
  File "C:\Python372\mecheck\lib\site-packages\django\core\handlers\base.py", line 156, in _get_response
    response = self.process_exception_by_middleware(e, request)
  File "C:\Python372\mecheck\lib\site-packages\django\core\handlers\base.py", line 154, in _get_response
    response = response.render()
  File "C:\Python372\mecheck\lib\site-packages\django\template\response.py", line 106, in render
    self.content = self.rendered_content
  File "C:\Python372\mecheck\lib\site-packages\django\template\response.py", line 83, in rendered_content
    content = template.render(context, self._request)
  File "C:\Python372\mecheck\lib\site-packages\django\template\backends\django.py", line 61, in render
    return self.template.render(context)
  File "C:\Python372\mecheck\lib\site-packages\django\template\base.py", line 171, in render
    return self._render(context)
  File "C:\Python372\mecheck\lib\site-packages\django\template\base.py", line 163, in _render
    return self.nodelist.render(context)
  File "C:\Python372\mecheck\lib\site-packages\django\template\base.py", line 937, in render
    bit = node.render_annotated(context)
  File "C:\Python372\mecheck\lib\site-packages\django\template\base.py", line 904, in render_annotated
    return self.render(context)
  File "C:\Python372\mecheck\lib\site-packages\django\template\loader_tags.py", line 150, in render
    return compiled_parent._render(context)
  File "C:\Python372\mecheck\lib\site-packages\django\template\base.py", line 163, in _render
    return self.nodelist.render(context)
  File "C:\Python372\mecheck\lib\site-packages\django\template\base.py", line 937, in render
    bit = node.render_annotated(context)
  File "C:\Python372\mecheck\lib\site-packages\django\template\base.py", line 904, in render_annotated
    return self.render(context)
  File "C:\Python372\mecheck\lib\site-packages\django\template\loader_tags.py", line 150, in render
    return compiled_parent._render(context)
  File "C:\Python372\mecheck\lib\site-packages\django\template\base.py", line 163, in _render
    return self.nodelist.render(context)
  File "C:\Python372\mecheck\lib\site-packages\django\template\base.py", line 937, in render
    bit = node.render_annotated(context)
  File "C:\Python372\mecheck\lib\site-packages\django\template\base.py", line 904, in render_annotated
    return self.render(context)
  File "C:\Python372\mecheck\lib\site-packages\django\template\defaulttags.py", line 309, in render
    return nodelist.render(context)
  File "C:\Python372\mecheck\lib\site-packages\django\template\base.py", line 937, in render
    bit = node.render_annotated(context)
  File "C:\Python372\mecheck\lib\site-packages\django\template\base.py", line 904, in render_annotated
    return self.render(context)
  File "C:\Python372\mecheck\lib\site-packages\django\template\loader_tags.py", line 62, in render
    result = block.nodelist.render(context)
  File "C:\Python372\mecheck\lib\site-packages\django\template\base.py", line 937, in render
    bit = node.render_annotated(context)
  File "C:\Python372\mecheck\lib\site-packages\django\template\base.py", line 904, in render_annotated
    return self.render(context)
  File "C:\Python372\mecheck\lib\site-packages\django\template\defaulttags.py", line 309, in render
    return nodelist.render(context)
  File "C:\Python372\mecheck\lib\site-packages\django\template\base.py", line 937, in render
    bit = node.render_annotated(context)
  File "C:\Python372\mecheck\lib\site-packages\django\template\base.py", line 904, in render_annotated
    return self.render(context)
  File "C:\Python372\mecheck\lib\site-packages\django\template\base.py", line 987, in render
    output = self.filter_expression.resolve(context)
  File "C:\Python372\mecheck\lib\site-packages\django\template\base.py", line 698, in resolve
    new_obj = func(obj, *arg_vals)
  File "C:\Python372\mecheck\lib\site-packages\django\template\defaultfilters.py", line 42, in _dec
    args[0] = str(args[0])
  File "C:\djangoproject\Reliability_Row_data\app01\models.py", line 70, in __str__
    p = self.parent
  File "C:\Python372\mecheck\lib\site-packages\django\db\models\fields\related_descriptors.py", line 177, in __get__
    rel_obj = self.get_object(instance)
  File "C:\Python372\mecheck\lib\site-packages\django\db\models\fields\related_descriptors.py", line 144, in get_object
    return qs.get(self.field.get_reverse_related_filter(instance))
  File "C:\Python372\mecheck\lib\site-packages\django\db\models\query.py", line 399, in get
    self.model._meta.object_name
app01.models.Menu.DoesNotExist: Menu matching query does not exist.
[2020-03-10 19:50:09,515] [basehttp.py:154] [basehttp:log_message] [ERROR]- "GET /admin/app01/menu/29/change/ HTTP/1.1" 500 224173
[2020-03-10 19:50:56,587] [log.py:228] [log:log_response] [ERROR]- Internal Server Error: /admin/app01/menu/29/change/
Traceback (most recent call last):
  File "C:\Python372\mecheck\lib\site-packages\django\db\models\fields\related_descriptors.py", line 163, in __get__
    rel_obj = self.field.get_cached_value(instance)
  File "C:\Python372\mecheck\lib\site-packages\django\db\models\fields\mixins.py", line 13, in get_cached_value
    return instance._state.fields_cache[cache_name]
KeyError: 'parent'

During handling of the above exception, another exception occurred:

Traceback (most recent call last):
  File "C:\Python372\mecheck\lib\site-packages\django\core\handlers\exception.py", line 34, in inner
    response = get_response(request)
  File "C:\Python372\mecheck\lib\site-packages\django\core\handlers\base.py", line 156, in _get_response
    response = self.process_exception_by_middleware(e, request)
  File "C:\Python372\mecheck\lib\site-packages\django\core\handlers\base.py", line 154, in _get_response
    response = response.render()
  File "C:\Python372\mecheck\lib\site-packages\django\template\response.py", line 106, in render
    self.content = self.rendered_content
  File "C:\Python372\mecheck\lib\site-packages\django\template\response.py", line 83, in rendered_content
    content = template.render(context, self._request)
  File "C:\Python372\mecheck\lib\site-packages\django\template\backends\django.py", line 61, in render
    return self.template.render(context)
  File "C:\Python372\mecheck\lib\site-packages\django\template\base.py", line 171, in render
    return self._render(context)
  File "C:\Python372\mecheck\lib\site-packages\django\template\base.py", line 163, in _render
    return self.nodelist.render(context)
  File "C:\Python372\mecheck\lib\site-packages\django\template\base.py", line 937, in render
    bit = node.render_annotated(context)
  File "C:\Python372\mecheck\lib\site-packages\django\template\base.py", line 904, in render_annotated
    return self.render(context)
  File "C:\Python372\mecheck\lib\site-packages\django\template\loader_tags.py", line 150, in render
    return compiled_parent._render(context)
  File "C:\Python372\mecheck\lib\site-packages\django\template\base.py", line 163, in _render
    return self.nodelist.render(context)
  File "C:\Python372\mecheck\lib\site-packages\django\template\base.py", line 937, in render
    bit = node.render_annotated(context)
  File "C:\Python372\mecheck\lib\site-packages\django\template\base.py", line 904, in render_annotated
    return self.render(context)
  File "C:\Python372\mecheck\lib\site-packages\django\template\loader_tags.py", line 150, in render
    return compiled_parent._render(context)
  File "C:\Python372\mecheck\lib\site-packages\django\template\base.py", line 163, in _render
    return self.nodelist.render(context)
  File "C:\Python372\mecheck\lib\site-packages\django\template\base.py", line 937, in render
    bit = node.render_annotated(context)
  File "C:\Python372\mecheck\lib\site-packages\django\template\base.py", line 904, in render_annotated
    return self.render(context)
  File "C:\Python372\mecheck\lib\site-packages\django\template\defaulttags.py", line 309, in render
    return nodelist.render(context)
  File "C:\Python372\mecheck\lib\site-packages\django\template\base.py", line 937, in render
    bit = node.render_annotated(context)
  File "C:\Python372\mecheck\lib\site-packages\django\template\base.py", line 904, in render_annotated
    return self.render(context)
  File "C:\Python372\mecheck\lib\site-packages\django\template\loader_tags.py", line 62, in render
    result = block.nodelist.render(context)
  File "C:\Python372\mecheck\lib\site-packages\django\template\base.py", line 937, in render
    bit = node.render_annotated(context)
  File "C:\Python372\mecheck\lib\site-packages\django\template\base.py", line 904, in render_annotated
    return self.render(context)
  File "C:\Python372\mecheck\lib\site-packages\django\template\defaulttags.py", line 309, in render
    return nodelist.render(context)
  File "C:\Python372\mecheck\lib\site-packages\django\template\base.py", line 937, in render
    bit = node.render_annotated(context)
  File "C:\Python372\mecheck\lib\site-packages\django\template\base.py", line 904, in render_annotated
    return self.render(context)
  File "C:\Python372\mecheck\lib\site-packages\django\template\base.py", line 987, in render
    output = self.filter_expression.resolve(context)
  File "C:\Python372\mecheck\lib\site-packages\django\template\base.py", line 698, in resolve
    new_obj = func(obj, *arg_vals)
  File "C:\Python372\mecheck\lib\site-packages\django\template\defaultfilters.py", line 42, in _dec
    args[0] = str(args[0])
  File "C:\djangoproject\Reliability_Row_data\app01\models.py", line 70, in __str__
    p = self.parent
  File "C:\Python372\mecheck\lib\site-packages\django\db\models\fields\related_descriptors.py", line 177, in __get__
    rel_obj = self.get_object(instance)
  File "C:\Python372\mecheck\lib\site-packages\django\db\models\fields\related_descriptors.py", line 144, in get_object
    return qs.get(self.field.get_reverse_related_filter(instance))
  File "C:\Python372\mecheck\lib\site-packages\django\db\models\query.py", line 399, in get
    self.model._meta.object_name
app01.models.Menu.DoesNotExist: Menu matching query does not exist.
[2020-03-10 19:50:56,602] [basehttp.py:154] [basehttp:log_message] [ERROR]- "GET /admin/app01/menu/29/change/ HTTP/1.1" 500 224173
[2020-03-10 19:51:04,327] [log.py:228] [log:log_response] [ERROR]- Internal Server Error: /admin/app01/menu/49/change/
Traceback (most recent call last):
  File "C:\Python372\mecheck\lib\site-packages\django\db\models\fields\related_descriptors.py", line 163, in __get__
    rel_obj = self.field.get_cached_value(instance)
  File "C:\Python372\mecheck\lib\site-packages\django\db\models\fields\mixins.py", line 13, in get_cached_value
    return instance._state.fields_cache[cache_name]
KeyError: 'parent'

During handling of the above exception, another exception occurred:

Traceback (most recent call last):
  File "C:\Python372\mecheck\lib\site-packages\django\core\handlers\exception.py", line 34, in inner
    response = get_response(request)
  File "C:\Python372\mecheck\lib\site-packages\django\core\handlers\base.py", line 156, in _get_response
    response = self.process_exception_by_middleware(e, request)
  File "C:\Python372\mecheck\lib\site-packages\django\core\handlers\base.py", line 154, in _get_response
    response = response.render()
  File "C:\Python372\mecheck\lib\site-packages\django\template\response.py", line 106, in render
    self.content = self.rendered_content
  File "C:\Python372\mecheck\lib\site-packages\django\template\response.py", line 83, in rendered_content
    content = template.render(context, self._request)
  File "C:\Python372\mecheck\lib\site-packages\django\template\backends\django.py", line 61, in render
    return self.template.render(context)
  File "C:\Python372\mecheck\lib\site-packages\django\template\base.py", line 171, in render
    return self._render(context)
  File "C:\Python372\mecheck\lib\site-packages\django\template\base.py", line 163, in _render
    return self.nodelist.render(context)
  File "C:\Python372\mecheck\lib\site-packages\django\template\base.py", line 937, in render
    bit = node.render_annotated(context)
  File "C:\Python372\mecheck\lib\site-packages\django\template\base.py", line 904, in render_annotated
    return self.render(context)
  File "C:\Python372\mecheck\lib\site-packages\django\template\loader_tags.py", line 150, in render
    return compiled_parent._render(context)
  File "C:\Python372\mecheck\lib\site-packages\django\template\base.py", line 163, in _render
    return self.nodelist.render(context)
  File "C:\Python372\mecheck\lib\site-packages\django\template\base.py", line 937, in render
    bit = node.render_annotated(context)
  File "C:\Python372\mecheck\lib\site-packages\django\template\base.py", line 904, in render_annotated
    return self.render(context)
  File "C:\Python372\mecheck\lib\site-packages\django\template\loader_tags.py", line 150, in render
    return compiled_parent._render(context)
  File "C:\Python372\mecheck\lib\site-packages\django\template\base.py", line 163, in _render
    return self.nodelist.render(context)
  File "C:\Python372\mecheck\lib\site-packages\django\template\base.py", line 937, in render
    bit = node.render_annotated(context)
  File "C:\Python372\mecheck\lib\site-packages\django\template\base.py", line 904, in render_annotated
    return self.render(context)
  File "C:\Python372\mecheck\lib\site-packages\django\template\defaulttags.py", line 309, in render
    return nodelist.render(context)
  File "C:\Python372\mecheck\lib\site-packages\django\template\base.py", line 937, in render
    bit = node.render_annotated(context)
  File "C:\Python372\mecheck\lib\site-packages\django\template\base.py", line 904, in render_annotated
    return self.render(context)
  File "C:\Python372\mecheck\lib\site-packages\django\template\loader_tags.py", line 62, in render
    result = block.nodelist.render(context)
  File "C:\Python372\mecheck\lib\site-packages\django\template\base.py", line 937, in render
    bit = node.render_annotated(context)
  File "C:\Python372\mecheck\lib\site-packages\django\template\base.py", line 904, in render_annotated
    return self.render(context)
  File "C:\Python372\mecheck\lib\site-packages\django\template\defaulttags.py", line 309, in render
    return nodelist.render(context)
  File "C:\Python372\mecheck\lib\site-packages\django\template\base.py", line 937, in render
    bit = node.render_annotated(context)
  File "C:\Python372\mecheck\lib\site-packages\django\template\base.py", line 904, in render_annotated
    return self.render(context)
  File "C:\Python372\mecheck\lib\site-packages\django\template\base.py", line 987, in render
    output = self.filter_expression.resolve(context)
  File "C:\Python372\mecheck\lib\site-packages\django\template\base.py", line 698, in resolve
    new_obj = func(obj, *arg_vals)
  File "C:\Python372\mecheck\lib\site-packages\django\template\defaultfilters.py", line 42, in _dec
    args[0] = str(args[0])
  File "C:\djangoproject\Reliability_Row_data\app01\models.py", line 70, in __str__
    p = self.parent
  File "C:\Python372\mecheck\lib\site-packages\django\db\models\fields\related_descriptors.py", line 177, in __get__
    rel_obj = self.get_object(instance)
  File "C:\Python372\mecheck\lib\site-packages\django\db\models\fields\related_descriptors.py", line 144, in get_object
    return qs.get(self.field.get_reverse_related_filter(instance))
  File "C:\Python372\mecheck\lib\site-packages\django\db\models\query.py", line 399, in get
    self.model._meta.object_name
app01.models.Menu.DoesNotExist: Menu matching query does not exist.
[2020-03-10 19:51:04,343] [basehttp.py:154] [basehttp:log_message] [ERROR]- "GET /admin/app01/menu/49/change/ HTTP/1.1" 500 224178
[2020-03-10 19:51:07,643] [log.py:228] [log:log_response] [ERROR]- Internal Server Error: /admin/app01/menu/16/change/
Traceback (most recent call last):
  File "C:\Python372\mecheck\lib\site-packages\django\db\models\fields\related_descriptors.py", line 163, in __get__
    rel_obj = self.field.get_cached_value(instance)
  File "C:\Python372\mecheck\lib\site-packages\django\db\models\fields\mixins.py", line 13, in get_cached_value
    return instance._state.fields_cache[cache_name]
KeyError: 'parent'

During handling of the above exception, another exception occurred:

Traceback (most recent call last):
  File "C:\Python372\mecheck\lib\site-packages\django\core\handlers\exception.py", line 34, in inner
    response = get_response(request)
  File "C:\Python372\mecheck\lib\site-packages\django\core\handlers\base.py", line 156, in _get_response
    response = self.process_exception_by_middleware(e, request)
  File "C:\Python372\mecheck\lib\site-packages\django\core\handlers\base.py", line 154, in _get_response
    response = response.render()
  File "C:\Python372\mecheck\lib\site-packages\django\template\response.py", line 106, in render
    self.content = self.rendered_content
  File "C:\Python372\mecheck\lib\site-packages\django\template\response.py", line 83, in rendered_content
    content = template.render(context, self._request)
  File "C:\Python372\mecheck\lib\site-packages\django\template\backends\django.py", line 61, in render
    return self.template.render(context)
  File "C:\Python372\mecheck\lib\site-packages\django\template\base.py", line 171, in render
    return self._render(context)
  File "C:\Python372\mecheck\lib\site-packages\django\template\base.py", line 163, in _render
    return self.nodelist.render(context)
  File "C:\Python372\mecheck\lib\site-packages\django\template\base.py", line 937, in render
    bit = node.render_annotated(context)
  File "C:\Python372\mecheck\lib\site-packages\django\template\base.py", line 904, in render_annotated
    return self.render(context)
  File "C:\Python372\mecheck\lib\site-packages\django\template\loader_tags.py", line 150, in render
    return compiled_parent._render(context)
  File "C:\Python372\mecheck\lib\site-packages\django\template\base.py", line 163, in _render
    return self.nodelist.render(context)
  File "C:\Python372\mecheck\lib\site-packages\django\template\base.py", line 937, in render
    bit = node.render_annotated(context)
  File "C:\Python372\mecheck\lib\site-packages\django\template\base.py", line 904, in render_annotated
    return self.render(context)
  File "C:\Python372\mecheck\lib\site-packages\django\template\loader_tags.py", line 150, in render
    return compiled_parent._render(context)
  File "C:\Python372\mecheck\lib\site-packages\django\template\base.py", line 163, in _render
    return self.nodelist.render(context)
  File "C:\Python372\mecheck\lib\site-packages\django\template\base.py", line 937, in render
    bit = node.render_annotated(context)
  File "C:\Python372\mecheck\lib\site-packages\django\template\base.py", line 904, in render_annotated
    return self.render(context)
  File "C:\Python372\mecheck\lib\site-packages\django\template\defaulttags.py", line 309, in render
    return nodelist.render(context)
  File "C:\Python372\mecheck\lib\site-packages\django\template\base.py", line 937, in render
    bit = node.render_annotated(context)
  File "C:\Python372\mecheck\lib\site-packages\django\template\base.py", line 904, in render_annotated
    return self.render(context)
  File "C:\Python372\mecheck\lib\site-packages\django\template\loader_tags.py", line 62, in render
    result = block.nodelist.render(context)
  File "C:\Python372\mecheck\lib\site-packages\django\template\base.py", line 937, in render
    bit = node.render_annotated(context)
  File "C:\Python372\mecheck\lib\site-packages\django\template\base.py", line 904, in render_annotated
    return self.render(context)
  File "C:\Python372\mecheck\lib\site-packages\django\template\defaulttags.py", line 309, in render
    return nodelist.render(context)
  File "C:\Python372\mecheck\lib\site-packages\django\template\base.py", line 937, in render
    bit = node.render_annotated(context)
  File "C:\Python372\mecheck\lib\site-packages\django\template\base.py", line 904, in render_annotated
    return self.render(context)
  File "C:\Python372\mecheck\lib\site-packages\django\template\base.py", line 987, in render
    output = self.filter_expression.resolve(context)
  File "C:\Python372\mecheck\lib\site-packages\django\template\base.py", line 698, in resolve
    new_obj = func(obj, *arg_vals)
  File "C:\Python372\mecheck\lib\site-packages\django\template\defaultfilters.py", line 42, in _dec
    args[0] = str(args[0])
  File "C:\djangoproject\Reliability_Row_data\app01\models.py", line 70, in __str__
    p = self.parent
  File "C:\Python372\mecheck\lib\site-packages\django\db\models\fields\related_descriptors.py", line 177, in __get__
    rel_obj = self.get_object(instance)
  File "C:\Python372\mecheck\lib\site-packages\django\db\models\fields\related_descriptors.py", line 144, in get_object
    return qs.get(self.field.get_reverse_related_filter(instance))
  File "C:\Python372\mecheck\lib\site-packages\django\db\models\query.py", line 399, in get
    self.model._meta.object_name
app01.models.Menu.DoesNotExist: Menu matching query does not exist.
[2020-03-10 19:51:07,659] [basehttp.py:154] [basehttp:log_message] [ERROR]- "GET /admin/app01/menu/16/change/ HTTP/1.1" 500 224191
[2020-03-10 19:51:15,242] [log.py:228] [log:log_response] [ERROR]- Internal Server Error: /admin/app01/menu/3/change/
Traceback (most recent call last):
  File "C:\Python372\mecheck\lib\site-packages\django\db\models\fields\related_descriptors.py", line 163, in __get__
    rel_obj = self.field.get_cached_value(instance)
  File "C:\Python372\mecheck\lib\site-packages\django\db\models\fields\mixins.py", line 13, in get_cached_value
    return instance._state.fields_cache[cache_name]
KeyError: 'parent'

During handling of the above exception, another exception occurred:

Traceback (most recent call last):
  File "C:\Python372\mecheck\lib\site-packages\django\core\handlers\exception.py", line 34, in inner
    response = get_response(request)
  File "C:\Python372\mecheck\lib\site-packages\django\core\handlers\base.py", line 156, in _get_response
    response = self.process_exception_by_middleware(e, request)
  File "C:\Python372\mecheck\lib\site-packages\django\core\handlers\base.py", line 154, in _get_response
    response = response.render()
  File "C:\Python372\mecheck\lib\site-packages\django\template\response.py", line 106, in render
    self.content = self.rendered_content
  File "C:\Python372\mecheck\lib\site-packages\django\template\response.py", line 83, in rendered_content
    content = template.render(context, self._request)
  File "C:\Python372\mecheck\lib\site-packages\django\template\backends\django.py", line 61, in render
    return self.template.render(context)
  File "C:\Python372\mecheck\lib\site-packages\django\template\base.py", line 171, in render
    return self._render(context)
  File "C:\Python372\mecheck\lib\site-packages\django\template\base.py", line 163, in _render
    return self.nodelist.render(context)
  File "C:\Python372\mecheck\lib\site-packages\django\template\base.py", line 937, in render
    bit = node.render_annotated(context)
  File "C:\Python372\mecheck\lib\site-packages\django\template\base.py", line 904, in render_annotated
    return self.render(context)
  File "C:\Python372\mecheck\lib\site-packages\django\template\loader_tags.py", line 150, in render
    return compiled_parent._render(context)
  File "C:\Python372\mecheck\lib\site-packages\django\template\base.py", line 163, in _render
    return self.nodelist.render(context)
  File "C:\Python372\mecheck\lib\site-packages\django\template\base.py", line 937, in render
    bit = node.render_annotated(context)
  File "C:\Python372\mecheck\lib\site-packages\django\template\base.py", line 904, in render_annotated
    return self.render(context)
  File "C:\Python372\mecheck\lib\site-packages\django\template\loader_tags.py", line 150, in render
    return compiled_parent._render(context)
  File "C:\Python372\mecheck\lib\site-packages\django\template\base.py", line 163, in _render
    return self.nodelist.render(context)
  File "C:\Python372\mecheck\lib\site-packages\django\template\base.py", line 937, in render
    bit = node.render_annotated(context)
  File "C:\Python372\mecheck\lib\site-packages\django\template\base.py", line 904, in render_annotated
    return self.render(context)
  File "C:\Python372\mecheck\lib\site-packages\django\template\defaulttags.py", line 309, in render
    return nodelist.render(context)
  File "C:\Python372\mecheck\lib\site-packages\django\template\base.py", line 937, in render
    bit = node.render_annotated(context)
  File "C:\Python372\mecheck\lib\site-packages\django\template\base.py", line 904, in render_annotated
    return self.render(context)
  File "C:\Python372\mecheck\lib\site-packages\django\template\loader_tags.py", line 62, in render
    result = block.nodelist.render(context)
  File "C:\Python372\mecheck\lib\site-packages\django\template\base.py", line 937, in render
    bit = node.render_annotated(context)
  File "C:\Python372\mecheck\lib\site-packages\django\template\base.py", line 904, in render_annotated
    return self.render(context)
  File "C:\Python372\mecheck\lib\site-packages\django\template\defaulttags.py", line 309, in render
    return nodelist.render(context)
  File "C:\Python372\mecheck\lib\site-packages\django\template\base.py", line 937, in render
    bit = node.render_annotated(context)
  File "C:\Python372\mecheck\lib\site-packages\django\template\base.py", line 904, in render_annotated
    return self.render(context)
  File "C:\Python372\mecheck\lib\site-packages\django\template\base.py", line 987, in render
    output = self.filter_expression.resolve(context)
  File "C:\Python372\mecheck\lib\site-packages\django\template\base.py", line 698, in resolve
    new_obj = func(obj, *arg_vals)
  File "C:\Python372\mecheck\lib\site-packages\django\template\defaultfilters.py", line 42, in _dec
    args[0] = str(args[0])
  File "C:\djangoproject\Reliability_Row_data\app01\models.py", line 70, in __str__
    p = self.parent
  File "C:\Python372\mecheck\lib\site-packages\django\db\models\fields\related_descriptors.py", line 177, in __get__
    rel_obj = self.get_object(instance)
  File "C:\Python372\mecheck\lib\site-packages\django\db\models\fields\related_descriptors.py", line 144, in get_object
    return qs.get(self.field.get_reverse_related_filter(instance))
  File "C:\Python372\mecheck\lib\site-packages\django\db\models\query.py", line 399, in get
    self.model._meta.object_name
app01.models.Menu.DoesNotExist: Menu matching query does not exist.
[2020-03-10 19:51:15,258] [basehttp.py:154] [basehttp:log_message] [ERROR]- "GET /admin/app01/menu/3/change/ HTTP/1.1" 500 224167
[2020-03-10 20:09:09,985] [log.py:228] [log:log_response] [ERROR]- Internal Server Error: /admin/app01/menu/
Traceback (most recent call last):
  File "C:\Python372\mecheck\lib\site-packages\django\core\handlers\exception.py", line 34, in inner
    response = get_response(request)
  File "C:\Python372\mecheck\lib\site-packages\django\core\handlers\base.py", line 126, in _get_response
    response = self.process_exception_by_middleware(e, request)
  File "C:\Python372\mecheck\lib\site-packages\django\core\handlers\base.py", line 124, in _get_response
    response = wrapped_callback(request, *callback_args, **callback_kwargs)
  File "C:\Python372\mecheck\lib\site-packages\django\contrib\admin\options.py", line 604, in wrapper
    return self.admin_site.admin_view(view)(*args, **kwargs)
  File "C:\Python372\mecheck\lib\site-packages\django\utils\decorators.py", line 142, in _wrapped_view
    response = view_func(request, *args, **kwargs)
  File "C:\Python372\mecheck\lib\site-packages\django\views\decorators\cache.py", line 44, in _wrapped_view_func
    response = view_func(request, *args, **kwargs)
  File "C:\Python372\mecheck\lib\site-packages\django\contrib\admin\sites.py", line 223, in inner
    return view(request, *args, **kwargs)
  File "C:\Python372\mecheck\lib\site-packages\django\utils\decorators.py", line 45, in _wrapper
    return bound_method(*args, **kwargs)
  File "C:\Python372\mecheck\lib\site-packages\django\utils\decorators.py", line 142, in _wrapped_view
    response = view_func(request, *args, **kwargs)
  File "C:\Python372\mecheck\lib\site-packages\django\contrib\admin\options.py", line 1701, in changelist_view
    response = self.response_action(request, queryset=cl.get_queryset(request))
  File "C:\Python372\mecheck\lib\site-packages\django\contrib\admin\options.py", line 1400, in response_action
    response = func(self, request, queryset)
  File "C:\Python372\mecheck\lib\site-packages\django\contrib\admin\actions.py", line 28, in delete_selected
    deletable_objects, model_count, perms_needed, protected = modeladmin.get_deleted_objects(queryset, request)
  File "C:\Python372\mecheck\lib\site-packages\django\contrib\admin\options.py", line 1823, in get_deleted_objects
    return get_deleted_objects(objs, request, self.admin_site)
  File "C:\Python372\mecheck\lib\site-packages\django\contrib\admin\utils.py", line 134, in get_deleted_objects
    collector.collect(objs)
  File "C:\Python372\mecheck\lib\site-packages\django\contrib\admin\utils.py", line 197, in collect
    return super().collect(objs, source_attr=source_attr, **kwargs)
  File "C:\Python372\mecheck\lib\site-packages\django\db\models\deletion.py", line 221, in collect
    field.remote_field.on_delete(self, field, sub_objs, self.using)
TypeError: 'bool' object is not callable
[2020-03-10 20:09:09,985] [basehttp.py:154] [basehttp:log_message] [ERROR]- "POST /admin/app01/menu/ HTTP/1.1" 500 138150
[2020-03-10 20:09:21,375] [log.py:228] [log:log_response] [ERROR]- Internal Server Error: /admin/app01/menu/
Traceback (most recent call last):
  File "C:\Python372\mecheck\lib\site-packages\django\core\handlers\exception.py", line 34, in inner
    response = get_response(request)
  File "C:\Python372\mecheck\lib\site-packages\django\core\handlers\base.py", line 126, in _get_response
    response = self.process_exception_by_middleware(e, request)
  File "C:\Python372\mecheck\lib\site-packages\django\core\handlers\base.py", line 124, in _get_response
    response = wrapped_callback(request, *callback_args, **callback_kwargs)
  File "C:\Python372\mecheck\lib\site-packages\django\contrib\admin\options.py", line 604, in wrapper
    return self.admin_site.admin_view(view)(*args, **kwargs)
  File "C:\Python372\mecheck\lib\site-packages\django\utils\decorators.py", line 142, in _wrapped_view
    response = view_func(request, *args, **kwargs)
  File "C:\Python372\mecheck\lib\site-packages\django\views\decorators\cache.py", line 44, in _wrapped_view_func
    response = view_func(request, *args, **kwargs)
  File "C:\Python372\mecheck\lib\site-packages\django\contrib\admin\sites.py", line 223, in inner
    return view(request, *args, **kwargs)
  File "C:\Python372\mecheck\lib\site-packages\django\utils\decorators.py", line 45, in _wrapper
    return bound_method(*args, **kwargs)
  File "C:\Python372\mecheck\lib\site-packages\django\utils\decorators.py", line 142, in _wrapped_view
    response = view_func(request, *args, **kwargs)
  File "C:\Python372\mecheck\lib\site-packages\django\contrib\admin\options.py", line 1701, in changelist_view
    response = self.response_action(request, queryset=cl.get_queryset(request))
  File "C:\Python372\mecheck\lib\site-packages\django\contrib\admin\options.py", line 1400, in response_action
    response = func(self, request, queryset)
  File "C:\Python372\mecheck\lib\site-packages\django\contrib\admin\actions.py", line 28, in delete_selected
    deletable_objects, model_count, perms_needed, protected = modeladmin.get_deleted_objects(queryset, request)
  File "C:\Python372\mecheck\lib\site-packages\django\contrib\admin\options.py", line 1823, in get_deleted_objects
    return get_deleted_objects(objs, request, self.admin_site)
  File "C:\Python372\mecheck\lib\site-packages\django\contrib\admin\utils.py", line 134, in get_deleted_objects
    collector.collect(objs)
  File "C:\Python372\mecheck\lib\site-packages\django\contrib\admin\utils.py", line 197, in collect
    return super().collect(objs, source_attr=source_attr, **kwargs)
  File "C:\Python372\mecheck\lib\site-packages\django\db\models\deletion.py", line 221, in collect
    field.remote_field.on_delete(self, field, sub_objs, self.using)
TypeError: 'bool' object is not callable
[2020-03-10 20:09:21,375] [basehttp.py:154] [basehttp:log_message] [ERROR]- "POST /admin/app01/menu/ HTTP/1.1" 500 132069
