[2021-06-24 09:31:22,063] [log.py:228] [log:log_response] [ERROR]- Internal Server Error: /DeviceLNV/M_edit/
Traceback (most recent call last):
  File "C:\Python372\mecheck\lib\site-packages\django\core\handlers\exception.py", line 34, in inner
    response = get_response(request)
  File "C:\Python372\mecheck\lib\site-packages\django\core\handlers\base.py", line 126, in _get_response
    response = self.process_exception_by_middleware(e, request)
  File "C:\Python372\mecheck\lib\site-packages\django\core\handlers\base.py", line 124, in _get_response
    response = wrapped_callback(request, *callback_args, **callback_kwargs)
  File "C:\Python372\mecheck\lib\site-packages\django\views\decorators\csrf.py", line 54, in wrapped_view
    return view_func(*args, **kwargs)
  File "C:\djangoproject\DMS\DeviceLNV\views.py", line 2733, in M_edit
    Lent = mock_datalist.filter(BR_Status="已借出").count()  # 已借出
  File "C:\Python372\mecheck\lib\site-packages\django\db\models\query.py", line 844, in filter
    return self._filter_or_exclude(False, *args, **kwargs)
  File "C:\Python372\mecheck\lib\site-packages\django\db\models\query.py", line 862, in _filter_or_exclude
    clone.query.add_q(Q(*args, **kwargs))
  File "C:\Python372\mecheck\lib\site-packages\django\db\models\sql\query.py", line 1263, in add_q
    clause, _ = self._add_q(q_object, self.used_aliases)
  File "C:\Python372\mecheck\lib\site-packages\django\db\models\sql\query.py", line 1287, in _add_q
    split_subq=split_subq,
  File "C:\Python372\mecheck\lib\site-packages\django\db\models\sql\query.py", line 1164, in build_filter
    lookups, parts, reffed_expression = self.solve_lookup_type(arg)
  File "C:\Python372\mecheck\lib\site-packages\django\db\models\sql\query.py", line 1028, in solve_lookup_type
    _, field, _, lookup_parts = self.names_to_path(lookup_splitted, self.get_meta())
  File "C:\Python372\mecheck\lib\site-packages\django\db\models\sql\query.py", line 1389, in names_to_path
    "Choices are: %s" % (name, ", ".join(available)))
django.core.exceptions.FieldError: Cannot resolve keyword 'BR_Status' into field. Choices are: ApplicationNo, AssetNum, BR_per_code, BrwStatus, Btime, Comment, Customer, Declaration, DeclarationNo, DevCtgry, DevDescription, DevID, DevModel, DevName, DevPrice, DevStatus, DevVendor, Devproperties, Devsize, FWVer, HWVer, IntfCtgry, LSTA, Last_BR_per, Last_BR_per_code, Last_Borrow_date, Last_Predict_return, Last_Return_date, NID, PN, Pchsdate, PckgIncludes, Phase, Photo, Plandate, Plant, ProjectCode, Rtime, Source, UsrTimes, Usrname, addnewdate, addnewname, expirdate, id, uscyc, useday
[2021-06-24 09:31:22,066] [basehttp.py:154] [basehttp:log_message] [ERROR]- "POST /DeviceLNV/M_edit/ HTTP/1.1" 500 126551
[2021-06-24 09:44:17,060] [exception.py:77] [exception:response_for_exception] [ERROR]- Request body exceeded settings.DATA_UPLOAD_MAX_MEMORY_SIZE.
[2021-06-24 09:44:57,791] [exception.py:77] [exception:response_for_exception] [ERROR]- Request body exceeded settings.DATA_UPLOAD_MAX_MEMORY_SIZE.
[2021-06-24 10:03:29,169] [log.py:228] [log:log_response] [ERROR]- Internal Server Error: /DeviceLNV/M_edit/
Traceback (most recent call last):
  File "C:\Python372\mecheck\lib\site-packages\django\core\handlers\exception.py", line 34, in inner
    response = get_response(request)
  File "C:\Python372\mecheck\lib\site-packages\django\core\handlers\base.py", line 126, in _get_response
    response = self.process_exception_by_middleware(e, request)
  File "C:\Python372\mecheck\lib\site-packages\django\core\handlers\base.py", line 124, in _get_response
    response = wrapped_callback(request, *callback_args, **callback_kwargs)
  File "C:\Python372\mecheck\lib\site-packages\django\views\decorators\csrf.py", line 54, in wrapped_view
    return view_func(*args, **kwargs)
  File "C:\djangoproject\DMS\DeviceLNV\views.py", line 3380, in M_edit
    Lent = mock_datalist.filter(BR_Status="已借出").count()  # 已借出
  File "C:\Python372\mecheck\lib\site-packages\django\db\models\query.py", line 844, in filter
    return self._filter_or_exclude(False, *args, **kwargs)
  File "C:\Python372\mecheck\lib\site-packages\django\db\models\query.py", line 862, in _filter_or_exclude
    clone.query.add_q(Q(*args, **kwargs))
  File "C:\Python372\mecheck\lib\site-packages\django\db\models\sql\query.py", line 1263, in add_q
    clause, _ = self._add_q(q_object, self.used_aliases)
  File "C:\Python372\mecheck\lib\site-packages\django\db\models\sql\query.py", line 1287, in _add_q
    split_subq=split_subq,
  File "C:\Python372\mecheck\lib\site-packages\django\db\models\sql\query.py", line 1164, in build_filter
    lookups, parts, reffed_expression = self.solve_lookup_type(arg)
  File "C:\Python372\mecheck\lib\site-packages\django\db\models\sql\query.py", line 1028, in solve_lookup_type
    _, field, _, lookup_parts = self.names_to_path(lookup_splitted, self.get_meta())
  File "C:\Python372\mecheck\lib\site-packages\django\db\models\sql\query.py", line 1389, in names_to_path
    "Choices are: %s" % (name, ", ".join(available)))
django.core.exceptions.FieldError: Cannot resolve keyword 'BR_Status' into field. Choices are: ApplicationNo, AssetNum, BR_per_code, BrwStatus, Btime, Comment, Customer, Declaration, DeclarationNo, DevCtgry, DevDescription, DevID, DevModel, DevName, DevPrice, DevStatus, DevVendor, Devproperties, Devsize, FWVer, HWVer, IntfCtgry, LSTA, Last_BR_per, Last_BR_per_code, Last_Borrow_date, Last_Predict_return, Last_Return_date, NID, PN, Pchsdate, PckgIncludes, Phase, Photo, Plandate, Plant, ProjectCode, Rtime, Source, UsrTimes, Usrname, addnewdate, addnewname, expirdate, id, uscyc, useday
[2021-06-24 10:03:29,172] [basehttp.py:154] [basehttp:log_message] [ERROR]- "POST /DeviceLNV/M_edit/ HTTP/1.1" 500 146278
[2021-06-24 10:10:13,920] [log.py:228] [log:log_response] [ERROR]- Internal Server Error: /DeviceLNV/M_edit/
Traceback (most recent call last):
  File "C:\Python372\mecheck\lib\site-packages\django\core\handlers\exception.py", line 34, in inner
    response = get_response(request)
  File "C:\Python372\mecheck\lib\site-packages\django\core\handlers\base.py", line 126, in _get_response
    response = self.process_exception_by_middleware(e, request)
  File "C:\Python372\mecheck\lib\site-packages\django\core\handlers\base.py", line 124, in _get_response
    response = wrapped_callback(request, *callback_args, **callback_kwargs)
  File "C:\Python372\mecheck\lib\site-packages\django\views\decorators\csrf.py", line 54, in wrapped_view
    return view_func(*args, **kwargs)
  File "C:\djangoproject\DMS\DeviceLNV\views.py", line 3380, in M_edit
    Lent = mock_datalist.filter(BR_Status="已借出").count()  # 已借出
  File "C:\Python372\mecheck\lib\site-packages\django\db\models\query.py", line 844, in filter
    return self._filter_or_exclude(False, *args, **kwargs)
  File "C:\Python372\mecheck\lib\site-packages\django\db\models\query.py", line 862, in _filter_or_exclude
    clone.query.add_q(Q(*args, **kwargs))
  File "C:\Python372\mecheck\lib\site-packages\django\db\models\sql\query.py", line 1263, in add_q
    clause, _ = self._add_q(q_object, self.used_aliases)
  File "C:\Python372\mecheck\lib\site-packages\django\db\models\sql\query.py", line 1287, in _add_q
    split_subq=split_subq,
  File "C:\Python372\mecheck\lib\site-packages\django\db\models\sql\query.py", line 1164, in build_filter
    lookups, parts, reffed_expression = self.solve_lookup_type(arg)
  File "C:\Python372\mecheck\lib\site-packages\django\db\models\sql\query.py", line 1028, in solve_lookup_type
    _, field, _, lookup_parts = self.names_to_path(lookup_splitted, self.get_meta())
  File "C:\Python372\mecheck\lib\site-packages\django\db\models\sql\query.py", line 1389, in names_to_path
    "Choices are: %s" % (name, ", ".join(available)))
django.core.exceptions.FieldError: Cannot resolve keyword 'BR_Status' into field. Choices are: ApplicationNo, AssetNum, BR_per_code, BrwStatus, Btime, Comment, Customer, Declaration, DeclarationNo, DevCtgry, DevDescription, DevID, DevModel, DevName, DevPrice, DevStatus, DevVendor, Devproperties, Devsize, FWVer, HWVer, IntfCtgry, LSTA, Last_BR_per, Last_BR_per_code, Last_Borrow_date, Last_Predict_return, Last_Return_date, NID, PN, Pchsdate, PckgIncludes, Phase, Photo, Plandate, Plant, ProjectCode, Rtime, Source, UsrTimes, Usrname, addnewdate, addnewname, expirdate, id, uscyc, useday
[2021-06-24 10:10:13,921] [basehttp.py:154] [basehttp:log_message] [ERROR]- "POST /DeviceLNV/M_edit/ HTTP/1.1" 500 143467
[2021-06-24 10:19:41,557] [log.py:228] [log:log_response] [ERROR]- Internal Server Error: /DeviceLNV/M_edit/
Traceback (most recent call last):
  File "C:\Python372\mecheck\lib\site-packages\django\core\handlers\exception.py", line 34, in inner
    response = get_response(request)
  File "C:\Python372\mecheck\lib\site-packages\django\core\handlers\base.py", line 126, in _get_response
    response = self.process_exception_by_middleware(e, request)
  File "C:\Python372\mecheck\lib\site-packages\django\core\handlers\base.py", line 124, in _get_response
    response = wrapped_callback(request, *callback_args, **callback_kwargs)
  File "C:\Python372\mecheck\lib\site-packages\django\views\decorators\csrf.py", line 54, in wrapped_view
    return view_func(*args, **kwargs)
  File "C:\djangoproject\DMS\DeviceLNV\views.py", line 3296, in M_edit
    'Number': modeldata['Number'],
KeyError: 'Number'
[2021-06-24 10:19:41,559] [basehttp.py:154] [basehttp:log_message] [ERROR]- "POST /DeviceLNV/M_edit/ HTTP/1.1" 500 98208
[2021-06-24 10:24:08,495] [log.py:228] [log:log_response] [ERROR]- Internal Server Error: /DeviceLNV/M_edit/
Traceback (most recent call last):
  File "C:\Python372\mecheck\lib\site-packages\django\core\handlers\exception.py", line 34, in inner
    response = get_response(request)
  File "C:\Python372\mecheck\lib\site-packages\django\core\handlers\base.py", line 126, in _get_response
    response = self.process_exception_by_middleware(e, request)
  File "C:\Python372\mecheck\lib\site-packages\django\core\handlers\base.py", line 124, in _get_response
    response = wrapped_callback(request, *callback_args, **callback_kwargs)
  File "C:\Python372\mecheck\lib\site-packages\django\views\decorators\csrf.py", line 54, in wrapped_view
    return view_func(*args, **kwargs)
  File "C:\djangoproject\DMS\DeviceLNV\views.py", line 3304, in M_edit
    DeviceLNV.objects.create(**modeldata)
  File "C:\Python372\mecheck\lib\site-packages\django\db\models\manager.py", line 82, in manager_method
    return getattr(self.get_queryset(), name)(*args, **kwargs)
  File "C:\Python372\mecheck\lib\site-packages\django\db\models\query.py", line 413, in create
    obj.save(force_insert=True, using=self.db)
  File "C:\Python372\mecheck\lib\site-packages\django\db\models\base.py", line 718, in save
    force_update=force_update, update_fields=update_fields)
  File "C:\Python372\mecheck\lib\site-packages\django\db\models\base.py", line 748, in save_base
    updated = self._save_table(raw, cls, force_insert, force_update, using, update_fields)
  File "C:\Python372\mecheck\lib\site-packages\django\db\models\base.py", line 831, in _save_table
    result = self._do_insert(cls._base_manager, using, fields, update_pk, raw)
  File "C:\Python372\mecheck\lib\site-packages\django\db\models\base.py", line 869, in _do_insert
    using=using, raw=raw)
  File "C:\Python372\mecheck\lib\site-packages\django\db\models\manager.py", line 82, in manager_method
    return getattr(self.get_queryset(), name)(*args, **kwargs)
  File "C:\Python372\mecheck\lib\site-packages\django\db\models\query.py", line 1136, in _insert
    return query.get_compiler(using=using).execute_sql(return_id)
  File "C:\Python372\mecheck\lib\site-packages\django\db\models\sql\compiler.py", line 1288, in execute_sql
    for sql, params in self.as_sql():
  File "C:\Python372\mecheck\lib\site-packages\django\db\models\sql\compiler.py", line 1241, in as_sql
    for obj in self.query.objs
  File "C:\Python372\mecheck\lib\site-packages\django\db\models\sql\compiler.py", line 1241, in <listcomp>
    for obj in self.query.objs
  File "C:\Python372\mecheck\lib\site-packages\django\db\models\sql\compiler.py", line 1240, in <listcomp>
    [self.prepare_value(field, self.pre_save_val(field, obj)) for field in fields]
  File "C:\Python372\mecheck\lib\site-packages\django\db\models\sql\compiler.py", line 1182, in prepare_value
    value = field.get_db_prep_save(value, connection=self.connection)
  File "C:\Python372\mecheck\lib\site-packages\django\db\models\fields\__init__.py", line 790, in get_db_prep_save
    return self.get_db_prep_value(value, connection=connection, prepared=False)
  File "C:\Python372\mecheck\lib\site-packages\django\db\models\fields\__init__.py", line 1273, in get_db_prep_value
    value = self.get_prep_value(value)
  File "C:\Python372\mecheck\lib\site-packages\django\db\models\fields\__init__.py", line 1268, in get_prep_value
    return self.to_python(value)
  File "C:\Python372\mecheck\lib\site-packages\django\db\models\fields\__init__.py", line 1243, in to_python
    params={'value': value},
django.core.exceptions.ValidationError: ['’2020/1/25‘ 必须为合法的日期格式，请使用 YYYY-MM-DD 格式。']
[2021-06-24 10:24:08,499] [basehttp.py:154] [basehttp:log_message] [ERROR]- "POST /DeviceLNV/M_edit/ HTTP/1.1" 500 194960
[2021-06-24 10:25:34,190] [log.py:228] [log:log_response] [ERROR]- Internal Server Error: /DeviceLNV/M_edit/
Traceback (most recent call last):
  File "C:\Python372\mecheck\lib\site-packages\django\core\handlers\exception.py", line 34, in inner
    response = get_response(request)
  File "C:\Python372\mecheck\lib\site-packages\django\core\handlers\base.py", line 126, in _get_response
    response = self.process_exception_by_middleware(e, request)
  File "C:\Python372\mecheck\lib\site-packages\django\core\handlers\base.py", line 124, in _get_response
    response = wrapped_callback(request, *callback_args, **callback_kwargs)
  File "C:\Python372\mecheck\lib\site-packages\django\views\decorators\csrf.py", line 54, in wrapped_view
    return view_func(*args, **kwargs)
  File "C:\djangoproject\DMS\DeviceLNV\views.py", line 3304, in M_edit
    DeviceLNV.objects.create(**modeldata)
  File "C:\Python372\mecheck\lib\site-packages\django\db\models\manager.py", line 82, in manager_method
    return getattr(self.get_queryset(), name)(*args, **kwargs)
  File "C:\Python372\mecheck\lib\site-packages\django\db\models\query.py", line 413, in create
    obj.save(force_insert=True, using=self.db)
  File "C:\Python372\mecheck\lib\site-packages\django\db\models\base.py", line 718, in save
    force_update=force_update, update_fields=update_fields)
  File "C:\Python372\mecheck\lib\site-packages\django\db\models\base.py", line 748, in save_base
    updated = self._save_table(raw, cls, force_insert, force_update, using, update_fields)
  File "C:\Python372\mecheck\lib\site-packages\django\db\models\base.py", line 831, in _save_table
    result = self._do_insert(cls._base_manager, using, fields, update_pk, raw)
  File "C:\Python372\mecheck\lib\site-packages\django\db\models\base.py", line 869, in _do_insert
    using=using, raw=raw)
  File "C:\Python372\mecheck\lib\site-packages\django\db\models\manager.py", line 82, in manager_method
    return getattr(self.get_queryset(), name)(*args, **kwargs)
  File "C:\Python372\mecheck\lib\site-packages\django\db\models\query.py", line 1136, in _insert
    return query.get_compiler(using=using).execute_sql(return_id)
  File "C:\Python372\mecheck\lib\site-packages\django\db\models\sql\compiler.py", line 1288, in execute_sql
    for sql, params in self.as_sql():
  File "C:\Python372\mecheck\lib\site-packages\django\db\models\sql\compiler.py", line 1241, in as_sql
    for obj in self.query.objs
  File "C:\Python372\mecheck\lib\site-packages\django\db\models\sql\compiler.py", line 1241, in <listcomp>
    for obj in self.query.objs
  File "C:\Python372\mecheck\lib\site-packages\django\db\models\sql\compiler.py", line 1240, in <listcomp>
    [self.prepare_value(field, self.pre_save_val(field, obj)) for field in fields]
  File "C:\Python372\mecheck\lib\site-packages\django\db\models\sql\compiler.py", line 1182, in prepare_value
    value = field.get_db_prep_save(value, connection=self.connection)
  File "C:\Python372\mecheck\lib\site-packages\django\db\models\fields\__init__.py", line 790, in get_db_prep_save
    return self.get_db_prep_value(value, connection=connection, prepared=False)
  File "C:\Python372\mecheck\lib\site-packages\django\db\models\fields\__init__.py", line 1273, in get_db_prep_value
    value = self.get_prep_value(value)
  File "C:\Python372\mecheck\lib\site-packages\django\db\models\fields\__init__.py", line 1268, in get_prep_value
    return self.to_python(value)
  File "C:\Python372\mecheck\lib\site-packages\django\db\models\fields\__init__.py", line 1243, in to_python
    params={'value': value},
django.core.exceptions.ValidationError: ['’2020/1/25‘ 必须为合法的日期格式，请使用 YYYY-MM-DD 格式。']
[2021-06-24 10:25:34,193] [basehttp.py:154] [basehttp:log_message] [ERROR]- "POST /DeviceLNV/M_edit/ HTTP/1.1" 500 194960
[2021-06-24 10:32:09,955] [log.py:228] [log:log_response] [ERROR]- Internal Server Error: /DeviceLNV/M_edit/
Traceback (most recent call last):
  File "C:\Python372\mecheck\lib\site-packages\django\core\handlers\exception.py", line 34, in inner
    response = get_response(request)
  File "C:\Python372\mecheck\lib\site-packages\django\core\handlers\base.py", line 126, in _get_response
    response = self.process_exception_by_middleware(e, request)
  File "C:\Python372\mecheck\lib\site-packages\django\core\handlers\base.py", line 124, in _get_response
    response = wrapped_callback(request, *callback_args, **callback_kwargs)
  File "C:\Python372\mecheck\lib\site-packages\django\views\decorators\csrf.py", line 54, in wrapped_view
    return view_func(*args, **kwargs)
  File "C:\djangoproject\DMS\DeviceLNV\views.py", line 3309, in M_edit
    DeviceLNV.objects.create(**modeldata)
  File "C:\Python372\mecheck\lib\site-packages\django\db\models\manager.py", line 82, in manager_method
    return getattr(self.get_queryset(), name)(*args, **kwargs)
  File "C:\Python372\mecheck\lib\site-packages\django\db\models\query.py", line 413, in create
    obj.save(force_insert=True, using=self.db)
  File "C:\Python372\mecheck\lib\site-packages\django\db\models\base.py", line 718, in save
    force_update=force_update, update_fields=update_fields)
  File "C:\Python372\mecheck\lib\site-packages\django\db\models\base.py", line 748, in save_base
    updated = self._save_table(raw, cls, force_insert, force_update, using, update_fields)
  File "C:\Python372\mecheck\lib\site-packages\django\db\models\base.py", line 831, in _save_table
    result = self._do_insert(cls._base_manager, using, fields, update_pk, raw)
  File "C:\Python372\mecheck\lib\site-packages\django\db\models\base.py", line 869, in _do_insert
    using=using, raw=raw)
  File "C:\Python372\mecheck\lib\site-packages\django\db\models\manager.py", line 82, in manager_method
    return getattr(self.get_queryset(), name)(*args, **kwargs)
  File "C:\Python372\mecheck\lib\site-packages\django\db\models\query.py", line 1136, in _insert
    return query.get_compiler(using=using).execute_sql(return_id)
  File "C:\Python372\mecheck\lib\site-packages\django\db\models\sql\compiler.py", line 1288, in execute_sql
    for sql, params in self.as_sql():
  File "C:\Python372\mecheck\lib\site-packages\django\db\models\sql\compiler.py", line 1241, in as_sql
    for obj in self.query.objs
  File "C:\Python372\mecheck\lib\site-packages\django\db\models\sql\compiler.py", line 1241, in <listcomp>
    for obj in self.query.objs
  File "C:\Python372\mecheck\lib\site-packages\django\db\models\sql\compiler.py", line 1240, in <listcomp>
    [self.prepare_value(field, self.pre_save_val(field, obj)) for field in fields]
  File "C:\Python372\mecheck\lib\site-packages\django\db\models\sql\compiler.py", line 1182, in prepare_value
    value = field.get_db_prep_save(value, connection=self.connection)
  File "C:\Python372\mecheck\lib\site-packages\django\db\models\fields\__init__.py", line 790, in get_db_prep_save
    return self.get_db_prep_value(value, connection=connection, prepared=False)
  File "C:\Python372\mecheck\lib\site-packages\django\db\models\fields\__init__.py", line 1273, in get_db_prep_value
    value = self.get_prep_value(value)
  File "C:\Python372\mecheck\lib\site-packages\django\db\models\fields\__init__.py", line 1268, in get_prep_value
    return self.to_python(value)
  File "C:\Python372\mecheck\lib\site-packages\django\db\models\fields\__init__.py", line 1243, in to_python
    params={'value': value},
django.core.exceptions.ValidationError: ['’2020/1/25‘ 必须为合法的日期格式，请使用 YYYY-MM-DD 格式。']
[2021-06-24 10:32:09,959] [basehttp.py:154] [basehttp:log_message] [ERROR]- "POST /DeviceLNV/M_edit/ HTTP/1.1" 500 194960
[2021-06-24 10:33:18,719] [log.py:228] [log:log_response] [ERROR]- Internal Server Error: /DeviceLNV/M_edit/
Traceback (most recent call last):
  File "C:\Python372\mecheck\lib\site-packages\django\core\handlers\exception.py", line 34, in inner
    response = get_response(request)
  File "C:\Python372\mecheck\lib\site-packages\django\core\handlers\base.py", line 126, in _get_response
    response = self.process_exception_by_middleware(e, request)
  File "C:\Python372\mecheck\lib\site-packages\django\core\handlers\base.py", line 124, in _get_response
    response = wrapped_callback(request, *callback_args, **callback_kwargs)
  File "C:\Python372\mecheck\lib\site-packages\django\views\decorators\csrf.py", line 54, in wrapped_view
    return view_func(*args, **kwargs)
  File "C:\djangoproject\DMS\DeviceLNV\views.py", line 3312, in M_edit
    DeviceLNV.objects.create(**modeldata)
  File "C:\Python372\mecheck\lib\site-packages\django\db\models\manager.py", line 82, in manager_method
    return getattr(self.get_queryset(), name)(*args, **kwargs)
  File "C:\Python372\mecheck\lib\site-packages\django\db\models\query.py", line 413, in create
    obj.save(force_insert=True, using=self.db)
  File "C:\Python372\mecheck\lib\site-packages\django\db\models\base.py", line 718, in save
    force_update=force_update, update_fields=update_fields)
  File "C:\Python372\mecheck\lib\site-packages\django\db\models\base.py", line 748, in save_base
    updated = self._save_table(raw, cls, force_insert, force_update, using, update_fields)
  File "C:\Python372\mecheck\lib\site-packages\django\db\models\base.py", line 831, in _save_table
    result = self._do_insert(cls._base_manager, using, fields, update_pk, raw)
  File "C:\Python372\mecheck\lib\site-packages\django\db\models\base.py", line 869, in _do_insert
    using=using, raw=raw)
  File "C:\Python372\mecheck\lib\site-packages\django\db\models\manager.py", line 82, in manager_method
    return getattr(self.get_queryset(), name)(*args, **kwargs)
  File "C:\Python372\mecheck\lib\site-packages\django\db\models\query.py", line 1136, in _insert
    return query.get_compiler(using=using).execute_sql(return_id)
  File "C:\Python372\mecheck\lib\site-packages\django\db\models\sql\compiler.py", line 1288, in execute_sql
    for sql, params in self.as_sql():
  File "C:\Python372\mecheck\lib\site-packages\django\db\models\sql\compiler.py", line 1241, in as_sql
    for obj in self.query.objs
  File "C:\Python372\mecheck\lib\site-packages\django\db\models\sql\compiler.py", line 1241, in <listcomp>
    for obj in self.query.objs
  File "C:\Python372\mecheck\lib\site-packages\django\db\models\sql\compiler.py", line 1240, in <listcomp>
    [self.prepare_value(field, self.pre_save_val(field, obj)) for field in fields]
  File "C:\Python372\mecheck\lib\site-packages\django\db\models\sql\compiler.py", line 1182, in prepare_value
    value = field.get_db_prep_save(value, connection=self.connection)
  File "C:\Python372\mecheck\lib\site-packages\django\db\models\fields\__init__.py", line 790, in get_db_prep_save
    return self.get_db_prep_value(value, connection=connection, prepared=False)
  File "C:\Python372\mecheck\lib\site-packages\django\db\models\fields\__init__.py", line 1273, in get_db_prep_value
    value = self.get_prep_value(value)
  File "C:\Python372\mecheck\lib\site-packages\django\db\models\fields\__init__.py", line 1268, in get_prep_value
    return self.to_python(value)
  File "C:\Python372\mecheck\lib\site-packages\django\db\models\fields\__init__.py", line 1243, in to_python
    params={'value': value},
django.core.exceptions.ValidationError: ['’2020/1/25‘ 必须为合法的日期格式，请使用 YYYY-MM-DD 格式。']
[2021-06-24 10:33:18,725] [basehttp.py:154] [basehttp:log_message] [ERROR]- "POST /DeviceLNV/M_edit/ HTTP/1.1" 500 194960
[2021-06-24 10:34:24,079] [log.py:228] [log:log_response] [ERROR]- Internal Server Error: /DeviceLNV/M_edit/
Traceback (most recent call last):
  File "C:\Python372\mecheck\lib\site-packages\django\core\handlers\exception.py", line 34, in inner
    response = get_response(request)
  File "C:\Python372\mecheck\lib\site-packages\django\core\handlers\base.py", line 126, in _get_response
    response = self.process_exception_by_middleware(e, request)
  File "C:\Python372\mecheck\lib\site-packages\django\core\handlers\base.py", line 124, in _get_response
    response = wrapped_callback(request, *callback_args, **callback_kwargs)
  File "C:\Python372\mecheck\lib\site-packages\django\views\decorators\csrf.py", line 54, in wrapped_view
    return view_func(*args, **kwargs)
  File "C:\djangoproject\DMS\DeviceLNV\views.py", line 3312, in M_edit
    DeviceLNV.objects.create(**modeldata)
  File "C:\Python372\mecheck\lib\site-packages\django\db\models\manager.py", line 82, in manager_method
    return getattr(self.get_queryset(), name)(*args, **kwargs)
  File "C:\Python372\mecheck\lib\site-packages\django\db\models\query.py", line 413, in create
    obj.save(force_insert=True, using=self.db)
  File "C:\Python372\mecheck\lib\site-packages\django\db\models\base.py", line 718, in save
    force_update=force_update, update_fields=update_fields)
  File "C:\Python372\mecheck\lib\site-packages\django\db\models\base.py", line 748, in save_base
    updated = self._save_table(raw, cls, force_insert, force_update, using, update_fields)
  File "C:\Python372\mecheck\lib\site-packages\django\db\models\base.py", line 831, in _save_table
    result = self._do_insert(cls._base_manager, using, fields, update_pk, raw)
  File "C:\Python372\mecheck\lib\site-packages\django\db\models\base.py", line 869, in _do_insert
    using=using, raw=raw)
  File "C:\Python372\mecheck\lib\site-packages\django\db\models\manager.py", line 82, in manager_method
    return getattr(self.get_queryset(), name)(*args, **kwargs)
  File "C:\Python372\mecheck\lib\site-packages\django\db\models\query.py", line 1136, in _insert
    return query.get_compiler(using=using).execute_sql(return_id)
  File "C:\Python372\mecheck\lib\site-packages\django\db\models\sql\compiler.py", line 1288, in execute_sql
    for sql, params in self.as_sql():
  File "C:\Python372\mecheck\lib\site-packages\django\db\models\sql\compiler.py", line 1241, in as_sql
    for obj in self.query.objs
  File "C:\Python372\mecheck\lib\site-packages\django\db\models\sql\compiler.py", line 1241, in <listcomp>
    for obj in self.query.objs
  File "C:\Python372\mecheck\lib\site-packages\django\db\models\sql\compiler.py", line 1240, in <listcomp>
    [self.prepare_value(field, self.pre_save_val(field, obj)) for field in fields]
  File "C:\Python372\mecheck\lib\site-packages\django\db\models\sql\compiler.py", line 1182, in prepare_value
    value = field.get_db_prep_save(value, connection=self.connection)
  File "C:\Python372\mecheck\lib\site-packages\django\db\models\fields\__init__.py", line 790, in get_db_prep_save
    return self.get_db_prep_value(value, connection=connection, prepared=False)
  File "C:\Python372\mecheck\lib\site-packages\django\db\models\fields\__init__.py", line 1273, in get_db_prep_value
    value = self.get_prep_value(value)
  File "C:\Python372\mecheck\lib\site-packages\django\db\models\fields\__init__.py", line 1268, in get_prep_value
    return self.to_python(value)
  File "C:\Python372\mecheck\lib\site-packages\django\db\models\fields\__init__.py", line 1243, in to_python
    params={'value': value},
django.core.exceptions.ValidationError: ['’2020/1/25‘ 必须为合法的日期格式，请使用 YYYY-MM-DD 格式。']
[2021-06-24 10:34:24,082] [basehttp.py:154] [basehttp:log_message] [ERROR]- "POST /DeviceLNV/M_edit/ HTTP/1.1" 500 194960
[2021-06-24 10:35:15,730] [log.py:228] [log:log_response] [ERROR]- Internal Server Error: /DeviceLNV/M_edit/
Traceback (most recent call last):
  File "C:\Python372\mecheck\lib\site-packages\django\core\handlers\exception.py", line 34, in inner
    response = get_response(request)
  File "C:\Python372\mecheck\lib\site-packages\django\core\handlers\base.py", line 126, in _get_response
    response = self.process_exception_by_middleware(e, request)
  File "C:\Python372\mecheck\lib\site-packages\django\core\handlers\base.py", line 124, in _get_response
    response = wrapped_callback(request, *callback_args, **callback_kwargs)
  File "C:\Python372\mecheck\lib\site-packages\django\views\decorators\csrf.py", line 54, in wrapped_view
    return view_func(*args, **kwargs)
  File "C:\djangoproject\DMS\DeviceLNV\views.py", line 3312, in M_edit
    DeviceLNV.objects.create(**modeldata)
  File "C:\Python372\mecheck\lib\site-packages\django\db\models\manager.py", line 82, in manager_method
    return getattr(self.get_queryset(), name)(*args, **kwargs)
  File "C:\Python372\mecheck\lib\site-packages\django\db\models\query.py", line 413, in create
    obj.save(force_insert=True, using=self.db)
  File "C:\Python372\mecheck\lib\site-packages\django\db\models\base.py", line 718, in save
    force_update=force_update, update_fields=update_fields)
  File "C:\Python372\mecheck\lib\site-packages\django\db\models\base.py", line 748, in save_base
    updated = self._save_table(raw, cls, force_insert, force_update, using, update_fields)
  File "C:\Python372\mecheck\lib\site-packages\django\db\models\base.py", line 831, in _save_table
    result = self._do_insert(cls._base_manager, using, fields, update_pk, raw)
  File "C:\Python372\mecheck\lib\site-packages\django\db\models\base.py", line 869, in _do_insert
    using=using, raw=raw)
  File "C:\Python372\mecheck\lib\site-packages\django\db\models\manager.py", line 82, in manager_method
    return getattr(self.get_queryset(), name)(*args, **kwargs)
  File "C:\Python372\mecheck\lib\site-packages\django\db\models\query.py", line 1136, in _insert
    return query.get_compiler(using=using).execute_sql(return_id)
  File "C:\Python372\mecheck\lib\site-packages\django\db\models\sql\compiler.py", line 1288, in execute_sql
    for sql, params in self.as_sql():
  File "C:\Python372\mecheck\lib\site-packages\django\db\models\sql\compiler.py", line 1241, in as_sql
    for obj in self.query.objs
  File "C:\Python372\mecheck\lib\site-packages\django\db\models\sql\compiler.py", line 1241, in <listcomp>
    for obj in self.query.objs
  File "C:\Python372\mecheck\lib\site-packages\django\db\models\sql\compiler.py", line 1240, in <listcomp>
    [self.prepare_value(field, self.pre_save_val(field, obj)) for field in fields]
  File "C:\Python372\mecheck\lib\site-packages\django\db\models\sql\compiler.py", line 1182, in prepare_value
    value = field.get_db_prep_save(value, connection=self.connection)
  File "C:\Python372\mecheck\lib\site-packages\django\db\models\fields\__init__.py", line 790, in get_db_prep_save
    return self.get_db_prep_value(value, connection=connection, prepared=False)
  File "C:\Python372\mecheck\lib\site-packages\django\db\models\fields\__init__.py", line 1273, in get_db_prep_value
    value = self.get_prep_value(value)
  File "C:\Python372\mecheck\lib\site-packages\django\db\models\fields\__init__.py", line 1268, in get_prep_value
    return self.to_python(value)
  File "C:\Python372\mecheck\lib\site-packages\django\db\models\fields\__init__.py", line 1243, in to_python
    params={'value': value},
django.core.exceptions.ValidationError: ['’2020/1/25‘ 必须为合法的日期格式，请使用 YYYY-MM-DD 格式。']
[2021-06-24 10:35:15,733] [basehttp.py:154] [basehttp:log_message] [ERROR]- "POST /DeviceLNV/M_edit/ HTTP/1.1" 500 194958
[2021-06-24 10:37:12,030] [log.py:228] [log:log_response] [ERROR]- Internal Server Error: /DeviceLNV/M_edit/
Traceback (most recent call last):
  File "C:\Python372\mecheck\lib\site-packages\django\core\handlers\exception.py", line 34, in inner
    response = get_response(request)
  File "C:\Python372\mecheck\lib\site-packages\django\core\handlers\base.py", line 126, in _get_response
    response = self.process_exception_by_middleware(e, request)
  File "C:\Python372\mecheck\lib\site-packages\django\core\handlers\base.py", line 124, in _get_response
    response = wrapped_callback(request, *callback_args, **callback_kwargs)
  File "C:\Python372\mecheck\lib\site-packages\django\views\decorators\csrf.py", line 54, in wrapped_view
    return view_func(*args, **kwargs)
  File "C:\djangoproject\DMS\DeviceLNV\views.py", line 3312, in M_edit
    DeviceLNV.objects.create(**modeldata)
  File "C:\Python372\mecheck\lib\site-packages\django\db\models\manager.py", line 82, in manager_method
    return getattr(self.get_queryset(), name)(*args, **kwargs)
  File "C:\Python372\mecheck\lib\site-packages\django\db\models\query.py", line 413, in create
    obj.save(force_insert=True, using=self.db)
  File "C:\Python372\mecheck\lib\site-packages\django\db\models\base.py", line 718, in save
    force_update=force_update, update_fields=update_fields)
  File "C:\Python372\mecheck\lib\site-packages\django\db\models\base.py", line 748, in save_base
    updated = self._save_table(raw, cls, force_insert, force_update, using, update_fields)
  File "C:\Python372\mecheck\lib\site-packages\django\db\models\base.py", line 831, in _save_table
    result = self._do_insert(cls._base_manager, using, fields, update_pk, raw)
  File "C:\Python372\mecheck\lib\site-packages\django\db\models\base.py", line 869, in _do_insert
    using=using, raw=raw)
  File "C:\Python372\mecheck\lib\site-packages\django\db\models\manager.py", line 82, in manager_method
    return getattr(self.get_queryset(), name)(*args, **kwargs)
  File "C:\Python372\mecheck\lib\site-packages\django\db\models\query.py", line 1136, in _insert
    return query.get_compiler(using=using).execute_sql(return_id)
  File "C:\Python372\mecheck\lib\site-packages\django\db\models\sql\compiler.py", line 1288, in execute_sql
    for sql, params in self.as_sql():
  File "C:\Python372\mecheck\lib\site-packages\django\db\models\sql\compiler.py", line 1241, in as_sql
    for obj in self.query.objs
  File "C:\Python372\mecheck\lib\site-packages\django\db\models\sql\compiler.py", line 1241, in <listcomp>
    for obj in self.query.objs
  File "C:\Python372\mecheck\lib\site-packages\django\db\models\sql\compiler.py", line 1240, in <listcomp>
    [self.prepare_value(field, self.pre_save_val(field, obj)) for field in fields]
  File "C:\Python372\mecheck\lib\site-packages\django\db\models\sql\compiler.py", line 1182, in prepare_value
    value = field.get_db_prep_save(value, connection=self.connection)
  File "C:\Python372\mecheck\lib\site-packages\django\db\models\fields\__init__.py", line 790, in get_db_prep_save
    return self.get_db_prep_value(value, connection=connection, prepared=False)
  File "C:\Python372\mecheck\lib\site-packages\django\db\models\fields\__init__.py", line 1273, in get_db_prep_value
    value = self.get_prep_value(value)
  File "C:\Python372\mecheck\lib\site-packages\django\db\models\fields\__init__.py", line 1268, in get_prep_value
    return self.to_python(value)
  File "C:\Python372\mecheck\lib\site-packages\django\db\models\fields\__init__.py", line 1243, in to_python
    params={'value': value},
django.core.exceptions.ValidationError: ['’1/26/2020‘ 必须为合法的日期格式，请使用 YYYY-MM-DD 格式。']
[2021-06-24 10:37:12,033] [basehttp.py:154] [basehttp:log_message] [ERROR]- "POST /DeviceLNV/M_edit/ HTTP/1.1" 500 194759
[2021-06-24 10:42:30,626] [log.py:228] [log:log_response] [ERROR]- Internal Server Error: /DeviceLNV/M_edit/
Traceback (most recent call last):
  File "C:\Python372\mecheck\lib\site-packages\django\core\handlers\exception.py", line 34, in inner
    response = get_response(request)
  File "C:\Python372\mecheck\lib\site-packages\django\core\handlers\base.py", line 126, in _get_response
    response = self.process_exception_by_middleware(e, request)
  File "C:\Python372\mecheck\lib\site-packages\django\core\handlers\base.py", line 124, in _get_response
    response = wrapped_callback(request, *callback_args, **callback_kwargs)
  File "C:\Python372\mecheck\lib\site-packages\django\views\decorators\csrf.py", line 54, in wrapped_view
    return view_func(*args, **kwargs)
  File "C:\djangoproject\DMS\DeviceLNV\views.py", line 3314, in M_edit
    DeviceLNV.objects.create(**modeldata)
  File "C:\Python372\mecheck\lib\site-packages\django\db\models\manager.py", line 82, in manager_method
    return getattr(self.get_queryset(), name)(*args, **kwargs)
  File "C:\Python372\mecheck\lib\site-packages\django\db\models\query.py", line 413, in create
    obj.save(force_insert=True, using=self.db)
  File "C:\Python372\mecheck\lib\site-packages\django\db\models\base.py", line 718, in save
    force_update=force_update, update_fields=update_fields)
  File "C:\Python372\mecheck\lib\site-packages\django\db\models\base.py", line 748, in save_base
    updated = self._save_table(raw, cls, force_insert, force_update, using, update_fields)
  File "C:\Python372\mecheck\lib\site-packages\django\db\models\base.py", line 831, in _save_table
    result = self._do_insert(cls._base_manager, using, fields, update_pk, raw)
  File "C:\Python372\mecheck\lib\site-packages\django\db\models\base.py", line 869, in _do_insert
    using=using, raw=raw)
  File "C:\Python372\mecheck\lib\site-packages\django\db\models\manager.py", line 82, in manager_method
    return getattr(self.get_queryset(), name)(*args, **kwargs)
  File "C:\Python372\mecheck\lib\site-packages\django\db\models\query.py", line 1136, in _insert
    return query.get_compiler(using=using).execute_sql(return_id)
  File "C:\Python372\mecheck\lib\site-packages\django\db\models\sql\compiler.py", line 1288, in execute_sql
    for sql, params in self.as_sql():
  File "C:\Python372\mecheck\lib\site-packages\django\db\models\sql\compiler.py", line 1241, in as_sql
    for obj in self.query.objs
  File "C:\Python372\mecheck\lib\site-packages\django\db\models\sql\compiler.py", line 1241, in <listcomp>
    for obj in self.query.objs
  File "C:\Python372\mecheck\lib\site-packages\django\db\models\sql\compiler.py", line 1240, in <listcomp>
    [self.prepare_value(field, self.pre_save_val(field, obj)) for field in fields]
  File "C:\Python372\mecheck\lib\site-packages\django\db\models\sql\compiler.py", line 1182, in prepare_value
    value = field.get_db_prep_save(value, connection=self.connection)
  File "C:\Python372\mecheck\lib\site-packages\django\db\models\fields\__init__.py", line 790, in get_db_prep_save
    return self.get_db_prep_value(value, connection=connection, prepared=False)
  File "C:\Python372\mecheck\lib\site-packages\django\db\models\fields\__init__.py", line 1273, in get_db_prep_value
    value = self.get_prep_value(value)
  File "C:\Python372\mecheck\lib\site-packages\django\db\models\fields\__init__.py", line 1268, in get_prep_value
    return self.to_python(value)
  File "C:\Python372\mecheck\lib\site-packages\django\db\models\fields\__init__.py", line 1243, in to_python
    params={'value': value},
django.core.exceptions.ValidationError: ['’1/26/2020‘ 必须为合法的日期格式，请使用 YYYY-MM-DD 格式。']
[2021-06-24 10:42:30,630] [basehttp.py:154] [basehttp:log_message] [ERROR]- "POST /DeviceLNV/M_edit/ HTTP/1.1" 500 197383
[2021-06-24 10:42:49,925] [log.py:228] [log:log_response] [ERROR]- Internal Server Error: /DeviceLNV/M_edit/
Traceback (most recent call last):
  File "C:\Python372\mecheck\lib\site-packages\django\core\handlers\exception.py", line 34, in inner
    response = get_response(request)
  File "C:\Python372\mecheck\lib\site-packages\django\core\handlers\base.py", line 126, in _get_response
    response = self.process_exception_by_middleware(e, request)
  File "C:\Python372\mecheck\lib\site-packages\django\core\handlers\base.py", line 124, in _get_response
    response = wrapped_callback(request, *callback_args, **callback_kwargs)
  File "C:\Python372\mecheck\lib\site-packages\django\views\decorators\csrf.py", line 54, in wrapped_view
    return view_func(*args, **kwargs)
  File "C:\djangoproject\DMS\DeviceLNV\views.py", line 3314, in M_edit
    DeviceLNV.objects.create(**modeldata)
  File "C:\Python372\mecheck\lib\site-packages\django\db\models\manager.py", line 82, in manager_method
    return getattr(self.get_queryset(), name)(*args, **kwargs)
  File "C:\Python372\mecheck\lib\site-packages\django\db\models\query.py", line 413, in create
    obj.save(force_insert=True, using=self.db)
  File "C:\Python372\mecheck\lib\site-packages\django\db\models\base.py", line 718, in save
    force_update=force_update, update_fields=update_fields)
  File "C:\Python372\mecheck\lib\site-packages\django\db\models\base.py", line 748, in save_base
    updated = self._save_table(raw, cls, force_insert, force_update, using, update_fields)
  File "C:\Python372\mecheck\lib\site-packages\django\db\models\base.py", line 831, in _save_table
    result = self._do_insert(cls._base_manager, using, fields, update_pk, raw)
  File "C:\Python372\mecheck\lib\site-packages\django\db\models\base.py", line 869, in _do_insert
    using=using, raw=raw)
  File "C:\Python372\mecheck\lib\site-packages\django\db\models\manager.py", line 82, in manager_method
    return getattr(self.get_queryset(), name)(*args, **kwargs)
  File "C:\Python372\mecheck\lib\site-packages\django\db\models\query.py", line 1136, in _insert
    return query.get_compiler(using=using).execute_sql(return_id)
  File "C:\Python372\mecheck\lib\site-packages\django\db\models\sql\compiler.py", line 1288, in execute_sql
    for sql, params in self.as_sql():
  File "C:\Python372\mecheck\lib\site-packages\django\db\models\sql\compiler.py", line 1241, in as_sql
    for obj in self.query.objs
  File "C:\Python372\mecheck\lib\site-packages\django\db\models\sql\compiler.py", line 1241, in <listcomp>
    for obj in self.query.objs
  File "C:\Python372\mecheck\lib\site-packages\django\db\models\sql\compiler.py", line 1240, in <listcomp>
    [self.prepare_value(field, self.pre_save_val(field, obj)) for field in fields]
  File "C:\Python372\mecheck\lib\site-packages\django\db\models\sql\compiler.py", line 1182, in prepare_value
    value = field.get_db_prep_save(value, connection=self.connection)
  File "C:\Python372\mecheck\lib\site-packages\django\db\models\fields\__init__.py", line 790, in get_db_prep_save
    return self.get_db_prep_value(value, connection=connection, prepared=False)
  File "C:\Python372\mecheck\lib\site-packages\django\db\models\fields\__init__.py", line 1273, in get_db_prep_value
    value = self.get_prep_value(value)
  File "C:\Python372\mecheck\lib\site-packages\django\db\models\fields\__init__.py", line 1268, in get_prep_value
    return self.to_python(value)
  File "C:\Python372\mecheck\lib\site-packages\django\db\models\fields\__init__.py", line 1243, in to_python
    params={'value': value},
django.core.exceptions.ValidationError: ['’1/26/2020‘ 必须为合法的日期格式，请使用 YYYY-MM-DD 格式。']
[2021-06-24 10:42:49,928] [basehttp.py:154] [basehttp:log_message] [ERROR]- "POST /DeviceLNV/M_edit/ HTTP/1.1" 500 197383
[2021-06-24 10:44:33,987] [log.py:228] [log:log_response] [ERROR]- Internal Server Error: /DeviceLNV/M_edit/
Traceback (most recent call last):
  File "C:\Python372\mecheck\lib\site-packages\django\core\handlers\exception.py", line 34, in inner
    response = get_response(request)
  File "C:\Python372\mecheck\lib\site-packages\django\core\handlers\base.py", line 126, in _get_response
    response = self.process_exception_by_middleware(e, request)
  File "C:\Python372\mecheck\lib\site-packages\django\core\handlers\base.py", line 124, in _get_response
    response = wrapped_callback(request, *callback_args, **callback_kwargs)
  File "C:\Python372\mecheck\lib\site-packages\django\views\decorators\csrf.py", line 54, in wrapped_view
    return view_func(*args, **kwargs)
  File "C:\djangoproject\DMS\DeviceLNV\views.py", line 3326, in M_edit
    if i.Predict_return and not i.Return_date:
AttributeError: 'DeviceLNV' object has no attribute 'Predict_return'
[2021-06-24 10:44:33,989] [basehttp.py:154] [basehttp:log_message] [ERROR]- "POST /DeviceLNV/M_edit/ HTTP/1.1" 500 99669
[2021-06-24 10:50:42,119] [log.py:228] [log:log_response] [ERROR]- Internal Server Error: /DeviceLNV/M_edit/
Traceback (most recent call last):
  File "C:\Python372\mecheck\lib\site-packages\django\core\handlers\exception.py", line 34, in inner
    response = get_response(request)
  File "C:\Python372\mecheck\lib\site-packages\django\core\handlers\base.py", line 126, in _get_response
    response = self.process_exception_by_middleware(e, request)
  File "C:\Python372\mecheck\lib\site-packages\django\core\handlers\base.py", line 124, in _get_response
    response = wrapped_callback(request, *callback_args, **callback_kwargs)
  File "C:\Python372\mecheck\lib\site-packages\django\views\decorators\csrf.py", line 54, in wrapped_view
    return view_func(*args, **kwargs)
  File "C:\djangoproject\DMS\DeviceLNV\views.py", line 2598, in M_edit
    if i.Predict_return and not i.Return_date:
AttributeError: 'DeviceLNV' object has no attribute 'Predict_return'
[2021-06-24 10:50:42,121] [basehttp.py:154] [basehttp:log_message] [ERROR]- "POST /DeviceLNV/M_edit/ HTTP/1.1" 500 87194
[2021-06-24 10:52:30,273] [log.py:228] [log:log_response] [ERROR]- Internal Server Error: /DeviceLNV/M_edit/
Traceback (most recent call last):
  File "C:\Python372\mecheck\lib\site-packages\django\core\handlers\exception.py", line 34, in inner
    response = get_response(request)
  File "C:\Python372\mecheck\lib\site-packages\django\core\handlers\base.py", line 126, in _get_response
    response = self.process_exception_by_middleware(e, request)
  File "C:\Python372\mecheck\lib\site-packages\django\core\handlers\base.py", line 124, in _get_response
    response = wrapped_callback(request, *callback_args, **callback_kwargs)
  File "C:\Python372\mecheck\lib\site-packages\django\views\decorators\csrf.py", line 54, in wrapped_view
    return view_func(*args, **kwargs)
  File "C:\djangoproject\DMS\DeviceLNV\views.py", line 2598, in M_edit
    if i.Predict_return and not i.Return_date:
AttributeError: 'DeviceLNV' object has no attribute 'Predict_return'
[2021-06-24 10:52:30,276] [basehttp.py:154] [basehttp:log_message] [ERROR]- "POST /DeviceLNV/M_edit/ HTTP/1.1" 500 87194
[2021-06-24 10:53:19,159] [log.py:228] [log:log_response] [ERROR]- Internal Server Error: /DeviceLNV/M_edit/
Traceback (most recent call last):
  File "C:\Python372\mecheck\lib\site-packages\django\db\backends\utils.py", line 85, in _execute
    return self.cursor.execute(sql, params)
  File "C:\Python372\mecheck\lib\site-packages\django\db\backends\mysql\base.py", line 71, in execute
    return self.cursor.execute(query, args)
  File "C:\Python372\mecheck\lib\site-packages\pymysql\cursors.py", line 170, in execute
    result = self._query(query)
  File "C:\Python372\mecheck\lib\site-packages\pymysql\cursors.py", line 328, in _query
    conn.query(q)
  File "C:\Python372\mecheck\lib\site-packages\pymysql\connections.py", line 517, in query
    self._affected_rows = self._read_query_result(unbuffered=unbuffered)
  File "C:\Python372\mecheck\lib\site-packages\pymysql\connections.py", line 732, in _read_query_result
    result.read()
  File "C:\Python372\mecheck\lib\site-packages\pymysql\connections.py", line 1075, in read
    first_packet = self.connection._read_packet()
  File "C:\Python372\mecheck\lib\site-packages\pymysql\connections.py", line 684, in _read_packet
    packet.check_error()
  File "C:\Python372\mecheck\lib\site-packages\pymysql\protocol.py", line 220, in check_error
    err.raise_mysql_exception(self._data)
  File "C:\Python372\mecheck\lib\site-packages\pymysql\err.py", line 109, in raise_mysql_exception
    raise errorclass(errno, errval)
pymysql.err.IntegrityError: (1062, "Duplicate entry '2156' for key 'NID'")

The above exception was the direct cause of the following exception:

Traceback (most recent call last):
  File "C:\Python372\mecheck\lib\site-packages\django\core\handlers\exception.py", line 34, in inner
    response = get_response(request)
  File "C:\Python372\mecheck\lib\site-packages\django\core\handlers\base.py", line 126, in _get_response
    response = self.process_exception_by_middleware(e, request)
  File "C:\Python372\mecheck\lib\site-packages\django\core\handlers\base.py", line 124, in _get_response
    response = wrapped_callback(request, *callback_args, **callback_kwargs)
  File "C:\Python372\mecheck\lib\site-packages\django\views\decorators\csrf.py", line 54, in wrapped_view
    return view_func(*args, **kwargs)
  File "C:\djangoproject\DMS\DeviceLNV\views.py", line 3314, in M_edit
    DeviceLNV.objects.create(**modeldata)
  File "C:\Python372\mecheck\lib\site-packages\django\db\models\manager.py", line 82, in manager_method
    return getattr(self.get_queryset(), name)(*args, **kwargs)
  File "C:\Python372\mecheck\lib\site-packages\django\db\models\query.py", line 413, in create
    obj.save(force_insert=True, using=self.db)
  File "C:\Python372\mecheck\lib\site-packages\django\db\models\base.py", line 718, in save
    force_update=force_update, update_fields=update_fields)
  File "C:\Python372\mecheck\lib\site-packages\django\db\models\base.py", line 748, in save_base
    updated = self._save_table(raw, cls, force_insert, force_update, using, update_fields)
  File "C:\Python372\mecheck\lib\site-packages\django\db\models\base.py", line 831, in _save_table
    result = self._do_insert(cls._base_manager, using, fields, update_pk, raw)
  File "C:\Python372\mecheck\lib\site-packages\django\db\models\base.py", line 869, in _do_insert
    using=using, raw=raw)
  File "C:\Python372\mecheck\lib\site-packages\django\db\models\manager.py", line 82, in manager_method
    return getattr(self.get_queryset(), name)(*args, **kwargs)
  File "C:\Python372\mecheck\lib\site-packages\django\db\models\query.py", line 1136, in _insert
    return query.get_compiler(using=using).execute_sql(return_id)
  File "C:\Python372\mecheck\lib\site-packages\django\db\models\sql\compiler.py", line 1289, in execute_sql
    cursor.execute(sql, params)
  File "C:\Python372\mecheck\lib\site-packages\django\db\backends\utils.py", line 100, in execute
    return super().execute(sql, params)
  File "C:\Python372\mecheck\lib\site-packages\django\db\backends\utils.py", line 68, in execute
    return self._execute_with_wrappers(sql, params, many=False, executor=self._execute)
  File "C:\Python372\mecheck\lib\site-packages\django\db\backends\utils.py", line 77, in _execute_with_wrappers
    return executor(sql, params, many, context)
  File "C:\Python372\mecheck\lib\site-packages\django\db\backends\utils.py", line 85, in _execute
    return self.cursor.execute(sql, params)
  File "C:\Python372\mecheck\lib\site-packages\django\db\utils.py", line 89, in __exit__
    raise dj_exc_value.with_traceback(traceback) from exc_value
  File "C:\Python372\mecheck\lib\site-packages\django\db\backends\utils.py", line 85, in _execute
    return self.cursor.execute(sql, params)
  File "C:\Python372\mecheck\lib\site-packages\django\db\backends\mysql\base.py", line 71, in execute
    return self.cursor.execute(query, args)
  File "C:\Python372\mecheck\lib\site-packages\pymysql\cursors.py", line 170, in execute
    result = self._query(query)
  File "C:\Python372\mecheck\lib\site-packages\pymysql\cursors.py", line 328, in _query
    conn.query(q)
  File "C:\Python372\mecheck\lib\site-packages\pymysql\connections.py", line 517, in query
    self._affected_rows = self._read_query_result(unbuffered=unbuffered)
  File "C:\Python372\mecheck\lib\site-packages\pymysql\connections.py", line 732, in _read_query_result
    result.read()
  File "C:\Python372\mecheck\lib\site-packages\pymysql\connections.py", line 1075, in read
    first_packet = self.connection._read_packet()
  File "C:\Python372\mecheck\lib\site-packages\pymysql\connections.py", line 684, in _read_packet
    packet.check_error()
  File "C:\Python372\mecheck\lib\site-packages\pymysql\protocol.py", line 220, in check_error
    err.raise_mysql_exception(self._data)
  File "C:\Python372\mecheck\lib\site-packages\pymysql\err.py", line 109, in raise_mysql_exception
    raise errorclass(errno, errval)
django.db.utils.IntegrityError: (1062, "Duplicate entry '2156' for key 'NID'")
[2021-06-24 10:53:19,174] [basehttp.py:154] [basehttp:log_message] [ERROR]- "POST /DeviceLNV/M_edit/ HTTP/1.1" 500 285204
[2021-06-24 14:18:31,546] [log.py:228] [log:log_response] [ERROR]- Internal Server Error: /DeviceLNV/M_edit/
Traceback (most recent call last):
  File "C:\Python372\mecheck\lib\site-packages\django\core\handlers\exception.py", line 34, in inner
    response = get_response(request)
  File "C:\Python372\mecheck\lib\site-packages\django\core\handlers\base.py", line 126, in _get_response
    response = self.process_exception_by_middleware(e, request)
  File "C:\Python372\mecheck\lib\site-packages\django\core\handlers\base.py", line 124, in _get_response
    response = wrapped_callback(request, *callback_args, **callback_kwargs)
  File "C:\Python372\mecheck\lib\site-packages\django\views\decorators\csrf.py", line 54, in wrapped_view
    return view_func(*args, **kwargs)
  File "C:\djangoproject\DMS\DeviceLNV\views.py", line 3391, in M_edit
    return HttpResponse(json.dumps(data), content_type="application/json")
  File "C:\Python372\lib\json\__init__.py", line 231, in dumps
    return _default_encoder.encode(obj)
  File "C:\Python372\lib\json\encoder.py", line 199, in encode
    chunks = self.iterencode(o, _one_shot=True)
  File "C:\Python372\lib\json\encoder.py", line 257, in iterencode
    return _iterencode(o, 0)
  File "C:\Python372\lib\json\encoder.py", line 179, in default
    raise TypeError(f'Object of type {o.__class__.__name__} '
TypeError: Object of type date is not JSON serializable
[2021-06-24 14:18:31,548] [basehttp.py:154] [basehttp:log_message] [ERROR]- "POST /DeviceLNV/M_edit/ HTTP/1.1" 500 147234
[2021-06-24 14:19:30,487] [log.py:228] [log:log_response] [ERROR]- Internal Server Error: /DeviceLNV/M_edit/
Traceback (most recent call last):
  File "C:\Python372\mecheck\lib\site-packages\django\core\handlers\exception.py", line 34, in inner
    response = get_response(request)
  File "C:\Python372\mecheck\lib\site-packages\django\core\handlers\base.py", line 126, in _get_response
    response = self.process_exception_by_middleware(e, request)
  File "C:\Python372\mecheck\lib\site-packages\django\core\handlers\base.py", line 124, in _get_response
    response = wrapped_callback(request, *callback_args, **callback_kwargs)
  File "C:\Python372\mecheck\lib\site-packages\django\views\decorators\csrf.py", line 54, in wrapped_view
    return view_func(*args, **kwargs)
  File "C:\djangoproject\DMS\DeviceLNV\views.py", line 3392, in M_edit
    return HttpResponse(json.dumps(data), content_type="application/json")
  File "C:\Python372\lib\json\__init__.py", line 231, in dumps
    return _default_encoder.encode(obj)
  File "C:\Python372\lib\json\encoder.py", line 199, in encode
    chunks = self.iterencode(o, _one_shot=True)
  File "C:\Python372\lib\json\encoder.py", line 257, in iterencode
    return _iterencode(o, 0)
  File "C:\Python372\lib\json\encoder.py", line 179, in default
    raise TypeError(f'Object of type {o.__class__.__name__} '
TypeError: Object of type date is not JSON serializable
[2021-06-24 14:19:30,490] [basehttp.py:154] [basehttp:log_message] [ERROR]- "POST /DeviceLNV/M_edit/ HTTP/1.1" 500 147234
[2021-06-24 14:21:19,520] [log.py:228] [log:log_response] [ERROR]- Internal Server Error: /DeviceLNV/M_edit/
Traceback (most recent call last):
  File "C:\Python372\mecheck\lib\site-packages\django\core\handlers\exception.py", line 34, in inner
    response = get_response(request)
  File "C:\Python372\mecheck\lib\site-packages\django\core\handlers\base.py", line 126, in _get_response
    response = self.process_exception_by_middleware(e, request)
  File "C:\Python372\mecheck\lib\site-packages\django\core\handlers\base.py", line 124, in _get_response
    response = wrapped_callback(request, *callback_args, **callback_kwargs)
  File "C:\Python372\mecheck\lib\site-packages\django\views\decorators\csrf.py", line 54, in wrapped_view
    return view_func(*args, **kwargs)
  File "C:\djangoproject\DMS\DeviceLNV\views.py", line 3392, in M_edit
    return HttpResponse(json.dumps(data), content_type="application/json")
  File "C:\Python372\lib\json\__init__.py", line 231, in dumps
    return _default_encoder.encode(obj)
  File "C:\Python372\lib\json\encoder.py", line 199, in encode
    chunks = self.iterencode(o, _one_shot=True)
  File "C:\Python372\lib\json\encoder.py", line 257, in iterencode
    return _iterencode(o, 0)
  File "C:\Python372\lib\json\encoder.py", line 179, in default
    raise TypeError(f'Object of type {o.__class__.__name__} '
TypeError: Object of type date is not JSON serializable
[2021-06-24 14:21:19,522] [basehttp.py:154] [basehttp:log_message] [ERROR]- "POST /DeviceLNV/M_edit/ HTTP/1.1" 500 147037
[2021-06-24 14:22:28,268] [log.py:228] [log:log_response] [ERROR]- Internal Server Error: /DeviceLNV/M_edit/
Traceback (most recent call last):
  File "C:\Python372\mecheck\lib\site-packages\django\core\handlers\exception.py", line 34, in inner
    response = get_response(request)
  File "C:\Python372\mecheck\lib\site-packages\django\core\handlers\base.py", line 126, in _get_response
    response = self.process_exception_by_middleware(e, request)
  File "C:\Python372\mecheck\lib\site-packages\django\core\handlers\base.py", line 124, in _get_response
    response = wrapped_callback(request, *callback_args, **callback_kwargs)
  File "C:\Python372\mecheck\lib\site-packages\django\views\decorators\csrf.py", line 54, in wrapped_view
    return view_func(*args, **kwargs)
  File "C:\djangoproject\DMS\DeviceLNV\views.py", line 3392, in M_edit
    return HttpResponse(json.dumps(data), content_type="application/json")
  File "C:\Python372\lib\json\__init__.py", line 231, in dumps
    return _default_encoder.encode(obj)
  File "C:\Python372\lib\json\encoder.py", line 199, in encode
    chunks = self.iterencode(o, _one_shot=True)
  File "C:\Python372\lib\json\encoder.py", line 257, in iterencode
    return _iterencode(o, 0)
  File "C:\Python372\lib\json\encoder.py", line 179, in default
    raise TypeError(f'Object of type {o.__class__.__name__} '
TypeError: Object of type date is not JSON serializable
[2021-06-24 14:22:28,272] [basehttp.py:154] [basehttp:log_message] [ERROR]- "POST /DeviceLNV/M_edit/ HTTP/1.1" 500 147177
[2021-06-24 14:26:36,969] [log.py:228] [log:log_response] [ERROR]- Internal Server Error: /DeviceLNV/M_edit/
Traceback (most recent call last):
  File "C:\Python372\mecheck\lib\site-packages\django\core\handlers\exception.py", line 34, in inner
    response = get_response(request)
  File "C:\Python372\mecheck\lib\site-packages\django\core\handlers\base.py", line 126, in _get_response
    response = self.process_exception_by_middleware(e, request)
  File "C:\Python372\mecheck\lib\site-packages\django\core\handlers\base.py", line 124, in _get_response
    response = wrapped_callback(request, *callback_args, **callback_kwargs)
  File "C:\Python372\mecheck\lib\site-packages\django\views\decorators\csrf.py", line 54, in wrapped_view
    return view_func(*args, **kwargs)
  File "C:\djangoproject\DMS\DeviceLNV\views.py", line 3392, in M_edit
    return HttpResponse(json.dumps(data), content_type="application/json")
  File "C:\Python372\lib\json\__init__.py", line 231, in dumps
    return _default_encoder.encode(obj)
  File "C:\Python372\lib\json\encoder.py", line 199, in encode
    chunks = self.iterencode(o, _one_shot=True)
  File "C:\Python372\lib\json\encoder.py", line 257, in iterencode
    return _iterencode(o, 0)
  File "C:\Python372\lib\json\encoder.py", line 179, in default
    raise TypeError(f'Object of type {o.__class__.__name__} '
TypeError: Object of type date is not JSON serializable
[2021-06-24 14:26:36,972] [basehttp.py:154] [basehttp:log_message] [ERROR]- "POST /DeviceLNV/M_edit/ HTTP/1.1" 500 146899
[2021-06-24 14:35:02,664] [log.py:228] [log:log_response] [ERROR]- Internal Server Error: /DeviceLNV/M_edit/
Traceback (most recent call last):
  File "C:\Python372\mecheck\lib\site-packages\django\core\handlers\exception.py", line 34, in inner
    response = get_response(request)
  File "C:\Python372\mecheck\lib\site-packages\django\core\handlers\base.py", line 126, in _get_response
    response = self.process_exception_by_middleware(e, request)
  File "C:\Python372\mecheck\lib\site-packages\django\core\handlers\base.py", line 124, in _get_response
    response = wrapped_callback(request, *callback_args, **callback_kwargs)
  File "C:\Python372\mecheck\lib\site-packages\django\views\decorators\csrf.py", line 54, in wrapped_view
    return view_func(*args, **kwargs)
  File "C:\djangoproject\DMS\DeviceLNV\views.py", line 3022, in M_edit
    DeviceLNV.objects.get(id=i).delete()
  File "C:\Python372\mecheck\lib\site-packages\django\db\models\manager.py", line 82, in manager_method
    return getattr(self.get_queryset(), name)(*args, **kwargs)
  File "C:\Python372\mecheck\lib\site-packages\django\db\models\query.py", line 399, in get
    self.model._meta.object_name
DeviceLNV.models.DeviceLNV.DoesNotExist: DeviceLNV matching query does not exist.
[2021-06-24 14:35:02,667] [basehttp.py:154] [basehttp:log_message] [ERROR]- "POST /DeviceLNV/M_edit/ HTTP/1.1" 500 92901
