[2020-06-23 09:03:28,015] [log.py:228] [log:log_response] [ERROR]- Internal Server Error: /TestPlanSW/TestPlanSW-summary/
Traceback (most recent call last):
  File "C:\Python372\mecheck\lib\site-packages\django\core\handlers\exception.py", line 34, in inner
    response = get_response(request)
  File "C:\Python372\mecheck\lib\site-packages\django\core\handlers\base.py", line 126, in _get_response
    response = self.process_exception_by_middleware(e, request)
  File "C:\Python372\mecheck\lib\site-packages\django\core\handlers\base.py", line 124, in _get_response
    response = wrapped_callback(request, *callback_args, **callback_kwargs)
  File "C:\djangoproject\Reliability_Row_data\TestPlanSW\views.py", line 468, in TestPlanSW_summary
    if not timerange[0]:
IndexError: list index out of range
[2020-06-23 09:03:28,025] [basehttp.py:154] [basehttp:log_message] [ERROR]- "POST /TestPlanSW/TestPlanSW-summary/ HTTP/1.1" 500 77307
[2020-06-23 09:24:24,157] [log.py:228] [log:log_response] [ERROR]- Internal Server Error: /TestPlanSW/TestPlanSW-summary/
Traceback (most recent call last):
  File "C:\Python372\mecheck\lib\site-packages\django\core\handlers\exception.py", line 34, in inner
    response = get_response(request)
  File "C:\Python372\mecheck\lib\site-packages\django\core\handlers\base.py", line 126, in _get_response
    response = self.process_exception_by_middleware(e, request)
  File "C:\Python372\mecheck\lib\site-packages\django\core\handlers\base.py", line 124, in _get_response
    response = wrapped_callback(request, *callback_args, **callback_kwargs)
  File "C:\djangoproject\Reliability_Row_data\TestPlanSW\views.py", line 468, in TestPlanSW_summary
    if not timerange[0]:
IndexError: list index out of range
[2020-06-23 09:24:24,161] [basehttp.py:154] [basehttp:log_message] [ERROR]- "POST /TestPlanSW/TestPlanSW-summary/ HTTP/1.1" 500 77307
[2020-06-23 09:24:35,333] [log.py:228] [log:log_response] [ERROR]- Internal Server Error: /TestPlanSW/TestPlanSW-summary/
Traceback (most recent call last):
  File "C:\Python372\mecheck\lib\site-packages\django\core\handlers\exception.py", line 34, in inner
    response = get_response(request)
  File "C:\Python372\mecheck\lib\site-packages\django\core\handlers\base.py", line 126, in _get_response
    response = self.process_exception_by_middleware(e, request)
  File "C:\Python372\mecheck\lib\site-packages\django\core\handlers\base.py", line 124, in _get_response
    response = wrapped_callback(request, *callback_args, **callback_kwargs)
  File "C:\djangoproject\Reliability_Row_data\TestPlanSW\views.py", line 468, in TestPlanSW_summary
    if not timerange[0]:
IndexError: list index out of range
[2020-06-23 09:24:35,334] [basehttp.py:154] [basehttp:log_message] [ERROR]- "POST /TestPlanSW/TestPlanSW-summary/ HTTP/1.1" 500 77307
[2020-06-23 09:24:45,516] [log.py:228] [log:log_response] [ERROR]- Internal Server Error: /TestPlanSW/TestPlanSW-summary/
Traceback (most recent call last):
  File "C:\Python372\mecheck\lib\site-packages\django\core\handlers\exception.py", line 34, in inner
    response = get_response(request)
  File "C:\Python372\mecheck\lib\site-packages\django\core\handlers\base.py", line 126, in _get_response
    response = self.process_exception_by_middleware(e, request)
  File "C:\Python372\mecheck\lib\site-packages\django\core\handlers\base.py", line 124, in _get_response
    response = wrapped_callback(request, *callback_args, **callback_kwargs)
  File "C:\djangoproject\Reliability_Row_data\TestPlanSW\views.py", line 468, in TestPlanSW_summary
    if not timerange[0]:
IndexError: list index out of range
[2020-06-23 09:24:45,520] [basehttp.py:154] [basehttp:log_message] [ERROR]- "POST /TestPlanSW/TestPlanSW-summary/ HTTP/1.1" 500 77307
[2020-06-23 09:25:03,923] [log.py:228] [log:log_response] [ERROR]- Internal Server Error: /TestPlanSW/TestPlanSW-summary/
Traceback (most recent call last):
  File "C:\Python372\mecheck\lib\site-packages\django\core\handlers\exception.py", line 34, in inner
    response = get_response(request)
  File "C:\Python372\mecheck\lib\site-packages\django\core\handlers\base.py", line 126, in _get_response
    response = self.process_exception_by_middleware(e, request)
  File "C:\Python372\mecheck\lib\site-packages\django\core\handlers\base.py", line 124, in _get_response
    response = wrapped_callback(request, *callback_args, **callback_kwargs)
  File "C:\djangoproject\Reliability_Row_data\TestPlanSW\views.py", line 468, in TestPlanSW_summary
    if not timerange[0]:
IndexError: list index out of range
[2020-06-23 09:25:03,925] [basehttp.py:154] [basehttp:log_message] [ERROR]- "POST /TestPlanSW/TestPlanSW-summary/ HTTP/1.1" 500 77307
[2020-06-23 09:25:09,002] [log.py:228] [log:log_response] [ERROR]- Internal Server Error: /TestPlanSW/TestPlanSW-summary/
Traceback (most recent call last):
  File "C:\Python372\mecheck\lib\site-packages\django\core\handlers\exception.py", line 34, in inner
    response = get_response(request)
  File "C:\Python372\mecheck\lib\site-packages\django\core\handlers\base.py", line 126, in _get_response
    response = self.process_exception_by_middleware(e, request)
  File "C:\Python372\mecheck\lib\site-packages\django\core\handlers\base.py", line 124, in _get_response
    response = wrapped_callback(request, *callback_args, **callback_kwargs)
  File "C:\djangoproject\Reliability_Row_data\TestPlanSW\views.py", line 468, in TestPlanSW_summary
    if not timerange[0]:
IndexError: list index out of range
[2020-06-23 09:25:09,003] [basehttp.py:154] [basehttp:log_message] [ERROR]- "POST /TestPlanSW/TestPlanSW-summary/ HTTP/1.1" 500 77307
[2020-06-23 09:27:02,348] [log.py:228] [log:log_response] [ERROR]- Internal Server Error: /TestPlanSW/TestPlanSW-summary/
Traceback (most recent call last):
  File "C:\Python372\mecheck\lib\site-packages\django\core\handlers\exception.py", line 34, in inner
    response = get_response(request)
  File "C:\Python372\mecheck\lib\site-packages\django\core\handlers\base.py", line 126, in _get_response
    response = self.process_exception_by_middleware(e, request)
  File "C:\Python372\mecheck\lib\site-packages\django\core\handlers\base.py", line 124, in _get_response
    response = wrapped_callback(request, *callback_args, **callback_kwargs)
  File "C:\djangoproject\Reliability_Row_data\TestPlanSW\views.py", line 468, in TestPlanSW_summary
    if not timerange[0]:
IndexError: list index out of range
[2020-06-23 09:27:02,349] [basehttp.py:154] [basehttp:log_message] [ERROR]- "POST /TestPlanSW/TestPlanSW-summary/ HTTP/1.1" 500 77307
[2020-06-23 09:27:33,089] [log.py:228] [log:log_response] [ERROR]- Internal Server Error: /TestPlanSW/TestPlanSW-summary/
Traceback (most recent call last):
  File "C:\Python372\mecheck\lib\site-packages\django\core\handlers\exception.py", line 34, in inner
    response = get_response(request)
  File "C:\Python372\mecheck\lib\site-packages\django\core\handlers\base.py", line 126, in _get_response
    response = self.process_exception_by_middleware(e, request)
  File "C:\Python372\mecheck\lib\site-packages\django\core\handlers\base.py", line 124, in _get_response
    response = wrapped_callback(request, *callback_args, **callback_kwargs)
  File "C:\djangoproject\Reliability_Row_data\TestPlanSW\views.py", line 464, in TestPlanSW_summary
    print(timerange[0])
IndexError: list index out of range
[2020-06-23 09:27:33,093] [basehttp.py:154] [basehttp:log_message] [ERROR]- "POST /TestPlanSW/TestPlanSW-summary/ HTTP/1.1" 500 76828
[2020-06-23 09:27:54,379] [log.py:228] [log:log_response] [ERROR]- Internal Server Error: /TestPlanSW/TestPlanSW-summary/
Traceback (most recent call last):
  File "C:\Python372\mecheck\lib\site-packages\django\core\handlers\exception.py", line 34, in inner
    response = get_response(request)
  File "C:\Python372\mecheck\lib\site-packages\django\core\handlers\base.py", line 126, in _get_response
    response = self.process_exception_by_middleware(e, request)
  File "C:\Python372\mecheck\lib\site-packages\django\core\handlers\base.py", line 124, in _get_response
    response = wrapped_callback(request, *callback_args, **callback_kwargs)
  File "C:\djangoproject\Reliability_Row_data\TestPlanSW\views.py", line 468, in TestPlanSW_summary
    if not timerange[0]:
IndexError: list index out of range
[2020-06-23 09:27:54,385] [basehttp.py:154] [basehttp:log_message] [ERROR]- "POST /TestPlanSW/TestPlanSW-summary/ HTTP/1.1" 500 77302
[2020-06-23 09:29:10,173] [log.py:228] [log:log_response] [ERROR]- Internal Server Error: /TestPlanSW/TestPlanSW-summary/
Traceback (most recent call last):
  File "C:\Python372\mecheck\lib\site-packages\django\core\handlers\exception.py", line 34, in inner
    response = get_response(request)
  File "C:\Python372\mecheck\lib\site-packages\django\core\handlers\base.py", line 126, in _get_response
    response = self.process_exception_by_middleware(e, request)
  File "C:\Python372\mecheck\lib\site-packages\django\core\handlers\base.py", line 124, in _get_response
    response = wrapped_callback(request, *callback_args, **callback_kwargs)
  File "C:\djangoproject\Reliability_Row_data\TestPlanSW\views.py", line 468, in TestPlanSW_summary
    if not timerange[0]:
IndexError: list index out of range
[2020-06-23 09:29:10,174] [basehttp.py:154] [basehttp:log_message] [ERROR]- "POST /TestPlanSW/TestPlanSW-summary/ HTTP/1.1" 500 77302
[2020-06-23 09:41:06,195] [log.py:228] [log:log_response] [ERROR]- Internal Server Error: /TestPlanME/TestPlanME-summary/
Traceback (most recent call last):
  File "C:\Python372\mecheck\lib\site-packages\django\core\handlers\exception.py", line 34, in inner
    response = get_response(request)
  File "C:\Python372\mecheck\lib\site-packages\django\core\handlers\base.py", line 126, in _get_response
    response = self.process_exception_by_middleware(e, request)
  File "C:\Python372\mecheck\lib\site-packages\django\core\handlers\base.py", line 124, in _get_response
    response = wrapped_callback(request, *callback_args, **callback_kwargs)
  File "C:\djangoproject\Reliability_Row_data\TestPlanME\views.py", line 197, in TestPlanME_Summary
    for i in TestProjectME.objects.filter(Customer=Customer).filter(ScheduleBegin=timerange).values(
  File "C:\Python372\mecheck\lib\site-packages\django\db\models\query.py", line 844, in filter
    return self._filter_or_exclude(False, *args, **kwargs)
  File "C:\Python372\mecheck\lib\site-packages\django\db\models\query.py", line 862, in _filter_or_exclude
    clone.query.add_q(Q(*args, **kwargs))
  File "C:\Python372\mecheck\lib\site-packages\django\db\models\sql\query.py", line 1263, in add_q
    clause, _ = self._add_q(q_object, self.used_aliases)
  File "C:\Python372\mecheck\lib\site-packages\django\db\models\sql\query.py", line 1287, in _add_q
    split_subq=split_subq,
  File "C:\Python372\mecheck\lib\site-packages\django\db\models\sql\query.py", line 1225, in build_filter
    condition = self.build_lookup(lookups, col, value)
  File "C:\Python372\mecheck\lib\site-packages\django\db\models\sql\query.py", line 1096, in build_lookup
    lookup = lookup_class(lhs, rhs)
  File "C:\Python372\mecheck\lib\site-packages\django\db\models\lookups.py", line 20, in __init__
    self.rhs = self.get_prep_lookup()
  File "C:\Python372\mecheck\lib\site-packages\django\db\models\lookups.py", line 70, in get_prep_lookup
    return self.lhs.output_field.get_prep_value(self.rhs)
  File "C:\Python372\mecheck\lib\site-packages\django\db\models\fields\__init__.py", line 1268, in get_prep_value
    return self.to_python(value)
  File "C:\Python372\mecheck\lib\site-packages\django\db\models\fields\__init__.py", line 1230, in to_python
    parsed = parse_date(value)
  File "C:\Python372\mecheck\lib\site-packages\django\utils\dateparse.py", line 74, in parse_date
    match = date_re.match(value)
TypeError: expected string or bytes-like object
[2020-06-23 09:41:06,204] [basehttp.py:154] [basehttp:log_message] [ERROR]- "POST /TestPlanME/TestPlanME-summary/ HTTP/1.1" 500 129460
[2020-06-23 13:28:17,654] [log.py:228] [log:log_response] [ERROR]- Internal Server Error: /TestPlanME/TestPlanME-summary/
Traceback (most recent call last):
  File "C:\Python372\mecheck\lib\site-packages\django\core\handlers\exception.py", line 34, in inner
    response = get_response(request)
  File "C:\Python372\mecheck\lib\site-packages\django\core\handlers\base.py", line 126, in _get_response
    response = self.process_exception_by_middleware(e, request)
  File "C:\Python372\mecheck\lib\site-packages\django\core\handlers\base.py", line 124, in _get_response
    response = wrapped_callback(request, *callback_args, **callback_kwargs)
  File "C:\djangoproject\Reliability_Row_data\TestPlanME\views.py", line 456, in TestPlanME_Summary
    mock_data.append({"Project": i["name"]+":"+i["value"], "ID": serchProjectresult.IDs, "Type": serchProjectresult.Type, "SKU": serchProjectresult.SKU,
AttributeError: 'NoneType' object has no attribute 'IDs'
[2020-06-23 13:28:17,655] [basehttp.py:154] [basehttp:log_message] [ERROR]- "POST /TestPlanME/TestPlanME-summary/ HTTP/1.1" 500 83862
[2020-06-23 14:23:33,941] [log.py:228] [log:log_response] [ERROR]- Internal Server Error: /TestPlanME/TestPlanME-summary/
Traceback (most recent call last):
  File "C:\Python372\mecheck\lib\site-packages\django\core\handlers\exception.py", line 34, in inner
    response = get_response(request)
  File "C:\Python372\mecheck\lib\site-packages\django\core\handlers\base.py", line 126, in _get_response
    response = self.process_exception_by_middleware(e, request)
  File "C:\Python372\mecheck\lib\site-packages\django\core\handlers\base.py", line 124, in _get_response
    response = wrapped_callback(request, *callback_args, **callback_kwargs)
  File "C:\djangoproject\Reliability_Row_data\TestPlanME\views.py", line 539, in TestPlanME_Summary
    ProjecttotalATO += j["RegularAttendTime"]
TypeError: unsupported operand type(s) for +=: 'float' and 'NoneType'
[2020-06-23 14:23:33,943] [basehttp.py:154] [basehttp:log_message] [ERROR]- "POST /TestPlanME/TestPlanME-summary/ HTTP/1.1" 500 96593
[2020-06-23 14:25:47,300] [log.py:228] [log:log_response] [ERROR]- Internal Server Error: /TestPlanME/TestPlanME-summary/
Traceback (most recent call last):
  File "C:\Python372\mecheck\lib\site-packages\django\core\handlers\exception.py", line 34, in inner
    response = get_response(request)
  File "C:\Python372\mecheck\lib\site-packages\django\core\handlers\base.py", line 126, in _get_response
    response = self.process_exception_by_middleware(e, request)
  File "C:\Python372\mecheck\lib\site-packages\django\core\handlers\base.py", line 124, in _get_response
    response = wrapped_callback(request, *callback_args, **callback_kwargs)
  File "C:\djangoproject\Reliability_Row_data\TestPlanME\views.py", line 539, in TestPlanME_Summary
    ProjecttotalATO += j["RegularAttendTime"]
TypeError: unsupported operand type(s) for +=: 'float' and 'NoneType'
[2020-06-23 14:25:47,304] [basehttp.py:154] [basehttp:log_message] [ERROR]- "POST /TestPlanME/TestPlanME-summary/ HTTP/1.1" 500 96502
[2020-06-23 14:27:00,987] [log.py:228] [log:log_response] [ERROR]- Internal Server Error: /TestPlanME/TestPlanME-summary/
Traceback (most recent call last):
  File "C:\Python372\mecheck\lib\site-packages\django\core\handlers\exception.py", line 34, in inner
    response = get_response(request)
  File "C:\Python372\mecheck\lib\site-packages\django\core\handlers\base.py", line 126, in _get_response
    response = self.process_exception_by_middleware(e, request)
  File "C:\Python372\mecheck\lib\site-packages\django\core\handlers\base.py", line 124, in _get_response
    response = wrapped_callback(request, *callback_args, **callback_kwargs)
  File "C:\djangoproject\Reliability_Row_data\TestPlanME\views.py", line 539, in TestPlanME_Summary
    ProjecttotalATO += j["RegularAttendTime"]
TypeError: unsupported operand type(s) for +=: 'float' and 'NoneType'
[2020-06-23 14:27:00,988] [basehttp.py:154] [basehttp:log_message] [ERROR]- "POST /TestPlanME/TestPlanME-summary/ HTTP/1.1" 500 95487
[2020-06-23 14:27:48,727] [log.py:228] [log:log_response] [ERROR]- Internal Server Error: /TestPlanME/TestPlanME-summary/
Traceback (most recent call last):
  File "C:\Python372\mecheck\lib\site-packages\django\core\handlers\exception.py", line 34, in inner
    response = get_response(request)
  File "C:\Python372\mecheck\lib\site-packages\django\core\handlers\base.py", line 126, in _get_response
    response = self.process_exception_by_middleware(e, request)
  File "C:\Python372\mecheck\lib\site-packages\django\core\handlers\base.py", line 124, in _get_response
    response = wrapped_callback(request, *callback_args, **callback_kwargs)
  File "C:\djangoproject\Reliability_Row_data\TestPlanME\views.py", line 539, in TestPlanME_Summary
    ProjecttotalATO += j["RegularAttendTime"]
TypeError: unsupported operand type(s) for +=: 'float' and 'NoneType'
[2020-06-23 14:27:48,729] [basehttp.py:154] [basehttp:log_message] [ERROR]- "POST /TestPlanME/TestPlanME-summary/ HTTP/1.1" 500 95485
[2020-06-23 14:28:41,288] [log.py:228] [log:log_response] [ERROR]- Internal Server Error: /TestPlanME/TestPlanME-summary/
Traceback (most recent call last):
  File "C:\Python372\mecheck\lib\site-packages\django\core\handlers\exception.py", line 34, in inner
    response = get_response(request)
  File "C:\Python372\mecheck\lib\site-packages\django\core\handlers\base.py", line 126, in _get_response
    response = self.process_exception_by_middleware(e, request)
  File "C:\Python372\mecheck\lib\site-packages\django\core\handlers\base.py", line 124, in _get_response
    response = wrapped_callback(request, *callback_args, **callback_kwargs)
  File "C:\djangoproject\Reliability_Row_data\TestPlanME\views.py", line 469, in TestPlanME_Summary
    print(check_dic_Project)
NameError: name 'printcheck_dic_Project' is not defined
[2020-06-23 14:28:41,290] [basehttp.py:154] [basehttp:log_message] [ERROR]- "POST /TestPlanME/TestPlanME-summary/ HTTP/1.1" 500 85558
[2020-06-23 14:28:59,838] [log.py:228] [log:log_response] [ERROR]- Internal Server Error: /TestPlanME/TestPlanME-summary/
Traceback (most recent call last):
  File "C:\Python372\mecheck\lib\site-packages\django\core\handlers\exception.py", line 34, in inner
    response = get_response(request)
  File "C:\Python372\mecheck\lib\site-packages\django\core\handlers\base.py", line 126, in _get_response
    response = self.process_exception_by_middleware(e, request)
  File "C:\Python372\mecheck\lib\site-packages\django\core\handlers\base.py", line 124, in _get_response
    response = wrapped_callback(request, *callback_args, **callback_kwargs)
  File "C:\djangoproject\Reliability_Row_data\TestPlanME\views.py", line 469, in TestPlanME_Summary
    print(check_dic_Project)
NameError: name 'printcheck_dic_Project' is not defined
[2020-06-23 14:28:59,839] [basehttp.py:154] [basehttp:log_message] [ERROR]- "POST /TestPlanME/TestPlanME-summary/ HTTP/1.1" 500 85558
[2020-06-23 14:29:16,923] [log.py:228] [log:log_response] [ERROR]- Internal Server Error: /TestPlanME/TestPlanME-summary/
Traceback (most recent call last):
  File "C:\Python372\mecheck\lib\site-packages\django\core\handlers\exception.py", line 34, in inner
    response = get_response(request)
  File "C:\Python372\mecheck\lib\site-packages\django\core\handlers\base.py", line 126, in _get_response
    response = self.process_exception_by_middleware(e, request)
  File "C:\Python372\mecheck\lib\site-packages\django\core\handlers\base.py", line 124, in _get_response
    response = wrapped_callback(request, *callback_args, **callback_kwargs)
  File "C:\djangoproject\Reliability_Row_data\TestPlanME\views.py", line 540, in TestPlanME_Summary
    ProjecttotalATO += j["RegularAttendTime"]
TypeError: unsupported operand type(s) for +=: 'float' and 'NoneType'
[2020-06-23 14:29:16,933] [basehttp.py:154] [basehttp:log_message] [ERROR]- "POST /TestPlanME/TestPlanME-summary/ HTTP/1.1" 500 95527
[2020-06-23 14:35:17,978] [log.py:228] [log:log_response] [ERROR]- Internal Server Error: /TestPlanME/TestPlanME-summary/
Traceback (most recent call last):
  File "C:\Python372\mecheck\lib\site-packages\django\core\handlers\exception.py", line 34, in inner
    response = get_response(request)
  File "C:\Python372\mecheck\lib\site-packages\django\core\handlers\base.py", line 126, in _get_response
    response = self.process_exception_by_middleware(e, request)
  File "C:\Python372\mecheck\lib\site-packages\django\core\handlers\base.py", line 124, in _get_response
    response = wrapped_callback(request, *callback_args, **callback_kwargs)
  File "C:\djangoproject\Reliability_Row_data\TestPlanME\views.py", line 540, in TestPlanME_Summary
    ProjecttotalATO += j["RegularAttendTime"]
TypeError: unsupported operand type(s) for +=: 'float' and 'NoneType'
[2020-06-23 14:35:17,981] [basehttp.py:154] [basehttp:log_message] [ERROR]- "POST /TestPlanME/TestPlanME-summary/ HTTP/1.1" 500 95963
[2020-06-23 14:35:35,241] [log.py:228] [log:log_response] [ERROR]- Internal Server Error: /TestPlanME/TestPlanME-summary/
Traceback (most recent call last):
  File "C:\Python372\mecheck\lib\site-packages\django\core\handlers\exception.py", line 34, in inner
    response = get_response(request)
  File "C:\Python372\mecheck\lib\site-packages\django\core\handlers\base.py", line 126, in _get_response
    response = self.process_exception_by_middleware(e, request)
  File "C:\Python372\mecheck\lib\site-packages\django\core\handlers\base.py", line 124, in _get_response
    response = wrapped_callback(request, *callback_args, **callback_kwargs)
  File "C:\djangoproject\Reliability_Row_data\TestPlanME\views.py", line 540, in TestPlanME_Summary
    ProjecttotalATO += j["RegularAttendTime"]
TypeError: unsupported operand type(s) for +=: 'float' and 'NoneType'
[2020-06-23 14:35:35,243] [basehttp.py:154] [basehttp:log_message] [ERROR]- "POST /TestPlanME/TestPlanME-summary/ HTTP/1.1" 500 96626
[2020-06-23 14:36:44,368] [log.py:228] [log:log_response] [ERROR]- Internal Server Error: /TestPlanME/TestPlanME-summary/
Traceback (most recent call last):
  File "C:\Python372\mecheck\lib\site-packages\django\core\handlers\exception.py", line 34, in inner
    response = get_response(request)
  File "C:\Python372\mecheck\lib\site-packages\django\core\handlers\base.py", line 126, in _get_response
    response = self.process_exception_by_middleware(e, request)
  File "C:\Python372\mecheck\lib\site-packages\django\core\handlers\base.py", line 124, in _get_response
    response = wrapped_callback(request, *callback_args, **callback_kwargs)
  File "C:\djangoproject\Reliability_Row_data\TestPlanME\views.py", line 541, in TestPlanME_Summary
    ProjecttotalATO += j["RegularAttendTime"]
TypeError: unsupported operand type(s) for +=: 'float' and 'NoneType'
[2020-06-23 14:36:44,370] [basehttp.py:154] [basehttp:log_message] [ERROR]- "POST /TestPlanME/TestPlanME-summary/ HTTP/1.1" 500 95740
[2020-06-23 14:38:31,114] [log.py:228] [log:log_response] [ERROR]- Internal Server Error: /TestPlanME/TestPlanME-summary/
Traceback (most recent call last):
  File "C:\Python372\mecheck\lib\site-packages\django\core\handlers\exception.py", line 34, in inner
    response = get_response(request)
  File "C:\Python372\mecheck\lib\site-packages\django\core\handlers\base.py", line 126, in _get_response
    response = self.process_exception_by_middleware(e, request)
  File "C:\Python372\mecheck\lib\site-packages\django\core\handlers\base.py", line 124, in _get_response
    response = wrapped_callback(request, *callback_args, **callback_kwargs)
  File "C:\djangoproject\Reliability_Row_data\TestPlanME\views.py", line 541, in TestPlanME_Summary
    ProjecttotalATO += j["RegularAttendTime"]
TypeError: unsupported operand type(s) for +=: 'float' and 'NoneType'
[2020-06-23 14:38:31,116] [basehttp.py:154] [basehttp:log_message] [ERROR]- "POST /TestPlanME/TestPlanME-summary/ HTTP/1.1" 500 94821
[2020-06-23 16:21:06,963] [basehttp.py:154] [basehttp:log_message] [ERROR]- "POST /TestPlanSW/TestPlanSW-summary/ HTTP/1.1" 500 59
